2020-03-21 12:54:08,854 INFO org.apache.hadoop.yarn.server.resourcemanager.ResourceManager: STARTUP_MSG: 
/************************************************************
STARTUP_MSG: Starting ResourceManager
STARTUP_MSG:   host = dell/127.0.1.1
STARTUP_MSG:   args = []
STARTUP_MSG:   version = 2.7.7
STARTUP_MSG:   build = Unknown -r c1aad84bd27cd79c3d1a7dd58202a8c3ee1ed3ac; compiled by 'stevel' on 2018-07-18T22:47Z
STARTUP_MSG:   java = 1.8.0_131
************************************************************/
2020-03-21 12:54:08,860 INFO org.apache.hadoop.yarn.server.resourcemanager.ResourceManager: registered UNIX signal handlers for [TERM, HUP, INT]
2020-03-21 12:54:09,014 INFO org.apache.hadoop.conf.Configuration: found resource core-site.xml at file:/home/xidian/hadoop-2.7.7/etc/hadoop/core-site.xml
2020-03-21 12:54:09,079 INFO org.apache.hadoop.security.Groups: clearing userToGroupsMap cache
2020-03-21 12:54:09,202 INFO org.apache.hadoop.conf.Configuration: found resource yarn-site.xml at file:/home/xidian/hadoop-2.7.7/etc/hadoop/yarn-site.xml
2020-03-21 12:54:09,340 INFO org.apache.hadoop.yarn.event.AsyncDispatcher: Registering class org.apache.hadoop.yarn.server.resourcemanager.RMFatalEventType for class org.apache.hadoop.yarn.server.resourcemanager.ResourceManager$RMFatalEventDispatcher
2020-03-21 12:54:09,505 INFO org.apache.hadoop.yarn.server.resourcemanager.security.NMTokenSecretManagerInRM: NMTokenKeyRollingInterval: 86400000ms and NMTokenKeyActivationDelay: 900000ms
2020-03-21 12:54:09,508 INFO org.apache.hadoop.yarn.server.resourcemanager.security.RMContainerTokenSecretManager: ContainerTokenKeyRollingInterval: 86400000ms and ContainerTokenKeyActivationDelay: 900000ms
2020-03-21 12:54:09,511 INFO org.apache.hadoop.yarn.server.resourcemanager.security.AMRMTokenSecretManager: AMRMTokenKeyRollingInterval: 86400000ms and AMRMTokenKeyActivationDelay: 900000 ms
2020-03-21 12:54:09,539 INFO org.apache.hadoop.yarn.event.AsyncDispatcher: Registering class org.apache.hadoop.yarn.server.resourcemanager.recovery.RMStateStoreEventType for class org.apache.hadoop.yarn.server.resourcemanager.recovery.RMStateStore$ForwardingEventHandler
2020-03-21 12:54:09,542 INFO org.apache.hadoop.yarn.event.AsyncDispatcher: Registering class org.apache.hadoop.yarn.server.resourcemanager.NodesListManagerEventType for class org.apache.hadoop.yarn.server.resourcemanager.NodesListManager
2020-03-21 12:54:09,542 INFO org.apache.hadoop.yarn.server.resourcemanager.ResourceManager: Using Scheduler: org.apache.hadoop.yarn.server.resourcemanager.scheduler.capacity.CapacityScheduler
2020-03-21 12:54:09,554 INFO org.apache.hadoop.yarn.event.AsyncDispatcher: Registering class org.apache.hadoop.yarn.server.resourcemanager.scheduler.event.SchedulerEventType for class org.apache.hadoop.yarn.server.resourcemanager.ResourceManager$SchedulerEventDispatcher
2020-03-21 12:54:09,555 INFO org.apache.hadoop.yarn.event.AsyncDispatcher: Registering class org.apache.hadoop.yarn.server.resourcemanager.rmapp.RMAppEventType for class org.apache.hadoop.yarn.server.resourcemanager.ResourceManager$ApplicationEventDispatcher
2020-03-21 12:54:09,555 INFO org.apache.hadoop.yarn.event.AsyncDispatcher: Registering class org.apache.hadoop.yarn.server.resourcemanager.rmapp.attempt.RMAppAttemptEventType for class org.apache.hadoop.yarn.server.resourcemanager.ResourceManager$ApplicationAttemptEventDispatcher
2020-03-21 12:54:09,556 INFO org.apache.hadoop.yarn.event.AsyncDispatcher: Registering class org.apache.hadoop.yarn.server.resourcemanager.rmnode.RMNodeEventType for class org.apache.hadoop.yarn.server.resourcemanager.ResourceManager$NodeEventDispatcher
2020-03-21 12:54:09,636 INFO org.apache.hadoop.metrics2.impl.MetricsConfig: loaded properties from hadoop-metrics2.properties
2020-03-21 12:54:09,784 INFO org.apache.hadoop.metrics2.impl.MetricsSystemImpl: Scheduled snapshot period at 10 second(s).
2020-03-21 12:54:09,784 INFO org.apache.hadoop.metrics2.impl.MetricsSystemImpl: ResourceManager metrics system started
2020-03-21 12:54:09,793 INFO org.apache.hadoop.yarn.event.AsyncDispatcher: Registering class org.apache.hadoop.yarn.server.resourcemanager.RMAppManagerEventType for class org.apache.hadoop.yarn.server.resourcemanager.RMAppManager
2020-03-21 12:54:09,799 INFO org.apache.hadoop.yarn.event.AsyncDispatcher: Registering class org.apache.hadoop.yarn.server.resourcemanager.amlauncher.AMLauncherEventType for class org.apache.hadoop.yarn.server.resourcemanager.amlauncher.ApplicationMasterLauncher
2020-03-21 12:54:09,800 INFO org.apache.hadoop.yarn.server.resourcemanager.RMNMInfo: Registered RMNMInfo MBean
2020-03-21 12:54:09,802 INFO org.apache.hadoop.yarn.security.YarnAuthorizationProvider: org.apache.hadoop.yarn.security.ConfiguredYarnAuthorizer is instiantiated.
2020-03-21 12:54:09,802 INFO org.apache.hadoop.util.HostsFileReader: Refreshing hosts (include/exclude) list
2020-03-21 12:54:09,803 INFO org.apache.hadoop.conf.Configuration: found resource capacity-scheduler.xml at file:/home/xidian/hadoop-2.7.7/etc/hadoop/capacity-scheduler.xml
2020-03-21 12:54:09,837 INFO org.apache.hadoop.yarn.server.resourcemanager.scheduler.capacity.CapacitySchedulerConfiguration: max alloc mb per queue for root is undefined
2020-03-21 12:54:09,837 INFO org.apache.hadoop.yarn.server.resourcemanager.scheduler.capacity.CapacitySchedulerConfiguration: max alloc vcore per queue for root is undefined
2020-03-21 12:54:09,840 INFO org.apache.hadoop.yarn.server.resourcemanager.scheduler.capacity.ParentQueue: root, capacity=1.0, asboluteCapacity=1.0, maxCapacity=1.0, asboluteMaxCapacity=1.0, state=RUNNING, acls=ADMINISTER_QUEUE:*SUBMIT_APP:*, labels=*,
, reservationsContinueLooking=true
2020-03-21 12:54:09,840 INFO org.apache.hadoop.yarn.server.resourcemanager.scheduler.capacity.ParentQueue: Initialized parent-queue root name=root, fullname=root
2020-03-21 12:54:09,848 INFO org.apache.hadoop.yarn.server.resourcemanager.scheduler.capacity.CapacitySchedulerConfiguration: max alloc mb per queue for root.default is undefined
2020-03-21 12:54:09,848 INFO org.apache.hadoop.yarn.server.resourcemanager.scheduler.capacity.CapacitySchedulerConfiguration: max alloc vcore per queue for root.default is undefined
2020-03-21 12:54:09,849 INFO org.apache.hadoop.yarn.server.resourcemanager.scheduler.capacity.LeafQueue: Initializing default
capacity = 1.0 [= (float) configuredCapacity / 100 ]
asboluteCapacity = 1.0 [= parentAbsoluteCapacity * capacity ]
maxCapacity = 1.0 [= configuredMaxCapacity ]
absoluteMaxCapacity = 1.0 [= 1.0 maximumCapacity undefined, (parentAbsoluteMaxCapacity * maximumCapacity) / 100 otherwise ]
userLimit = 100 [= configuredUserLimit ]
userLimitFactor = 1.0 [= configuredUserLimitFactor ]
maxApplications = 10000 [= configuredMaximumSystemApplicationsPerQueue or (int)(configuredMaximumSystemApplications * absoluteCapacity)]
maxApplicationsPerUser = 10000 [= (int)(maxApplications * (userLimit / 100.0f) * userLimitFactor) ]
usedCapacity = 0.0 [= usedResourcesMemory / (clusterResourceMemory * absoluteCapacity)]
absoluteUsedCapacity = 0.0 [= usedResourcesMemory / clusterResourceMemory]
maxAMResourcePerQueuePercent = 0.1 [= configuredMaximumAMResourcePercent ]
minimumAllocationFactor = 0.875 [= (float)(maximumAllocationMemory - minimumAllocationMemory) / maximumAllocationMemory ]
maximumAllocation = <memory:8192, vCores:32> [= configuredMaxAllocation ]
numContainers = 0 [= currentNumContainers ]
state = RUNNING [= configuredState ]
acls = ADMINISTER_QUEUE:*SUBMIT_APP:* [= configuredAcls ]
nodeLocalityDelay = 40
labels=*,
nodeLocalityDelay = 40
reservationsContinueLooking = true
preemptionDisabled = true

2020-03-21 12:54:09,849 INFO org.apache.hadoop.yarn.server.resourcemanager.scheduler.capacity.CapacityScheduler: Initialized queue: default: capacity=1.0, absoluteCapacity=1.0, usedResources=<memory:0, vCores:0>, usedCapacity=0.0, absoluteUsedCapacity=0.0, numApps=0, numContainers=0
2020-03-21 12:54:09,849 INFO org.apache.hadoop.yarn.server.resourcemanager.scheduler.capacity.CapacityScheduler: Initialized queue: root: numChildQueue= 1, capacity=1.0, absoluteCapacity=1.0, usedResources=<memory:0, vCores:0>usedCapacity=0.0, numApps=0, numContainers=0
2020-03-21 12:54:09,850 INFO org.apache.hadoop.yarn.server.resourcemanager.scheduler.capacity.CapacityScheduler: Initialized root queue root: numChildQueue= 1, capacity=1.0, absoluteCapacity=1.0, usedResources=<memory:0, vCores:0>usedCapacity=0.0, numApps=0, numContainers=0
2020-03-21 12:54:09,850 INFO org.apache.hadoop.yarn.server.resourcemanager.scheduler.capacity.CapacityScheduler: Initialized queue mappings, override: false
2020-03-21 12:54:09,850 INFO org.apache.hadoop.yarn.server.resourcemanager.scheduler.capacity.CapacityScheduler: Initialized CapacityScheduler with calculator=class org.apache.hadoop.yarn.util.resource.DefaultResourceCalculator, minimumAllocation=<<memory:1024, vCores:1>>, maximumAllocation=<<memory:8192, vCores:32>>, asynchronousScheduling=false, asyncScheduleInterval=5ms
2020-03-21 12:54:09,863 INFO org.apache.hadoop.yarn.server.resourcemanager.metrics.SystemMetricsPublisher: YARN system metrics publishing service is not enabled
2020-03-21 12:54:09,863 INFO org.apache.hadoop.yarn.server.resourcemanager.ResourceManager: Transitioning to active state
2020-03-21 12:54:09,871 INFO org.apache.hadoop.yarn.server.resourcemanager.recovery.RMStateStore: Updating AMRMToken
2020-03-21 12:54:09,872 INFO org.apache.hadoop.yarn.server.resourcemanager.security.RMContainerTokenSecretManager: Rolling master-key for container-tokens
2020-03-21 12:54:09,872 INFO org.apache.hadoop.yarn.server.resourcemanager.security.NMTokenSecretManagerInRM: Rolling master-key for nm-tokens
2020-03-21 12:54:09,872 INFO org.apache.hadoop.security.token.delegation.AbstractDelegationTokenSecretManager: Updating the current master key for generating delegation tokens
2020-03-21 12:54:09,872 INFO org.apache.hadoop.yarn.server.resourcemanager.security.RMDelegationTokenSecretManager: storing master key with keyID 1
2020-03-21 12:54:09,872 INFO org.apache.hadoop.yarn.server.resourcemanager.recovery.RMStateStore: Storing RMDTMasterKey.
2020-03-21 12:54:09,873 INFO org.apache.hadoop.security.token.delegation.AbstractDelegationTokenSecretManager: Starting expired delegation token remover thread, tokenRemoverScanInterval=60 min(s)
2020-03-21 12:54:09,873 INFO org.apache.hadoop.security.token.delegation.AbstractDelegationTokenSecretManager: Updating the current master key for generating delegation tokens
2020-03-21 12:54:09,873 INFO org.apache.hadoop.yarn.server.resourcemanager.security.RMDelegationTokenSecretManager: storing master key with keyID 2
2020-03-21 12:54:09,873 INFO org.apache.hadoop.yarn.server.resourcemanager.recovery.RMStateStore: Storing RMDTMasterKey.
2020-03-21 12:54:09,874 INFO org.apache.hadoop.yarn.event.AsyncDispatcher: Registering class org.apache.hadoop.yarn.nodelabels.event.NodeLabelsStoreEventType for class org.apache.hadoop.yarn.nodelabels.CommonNodeLabelsManager$ForwardingEventHandler
2020-03-21 12:54:09,974 INFO org.apache.hadoop.ipc.CallQueueManager: Using callQueue: class java.util.concurrent.LinkedBlockingQueue queueCapacity: 5000
2020-03-21 12:54:09,995 INFO org.apache.hadoop.ipc.Server: Starting Socket Reader #1 for port 8031
2020-03-21 12:54:10,233 INFO org.apache.hadoop.yarn.factories.impl.pb.RpcServerFactoryPBImpl: Adding protocol org.apache.hadoop.yarn.server.api.ResourceTrackerPB to the server
2020-03-21 12:54:10,234 INFO org.apache.hadoop.ipc.Server: IPC Server Responder: starting
2020-03-21 12:54:10,234 INFO org.apache.hadoop.ipc.Server: IPC Server listener on 8031: starting
2020-03-21 12:54:10,366 INFO org.apache.hadoop.ipc.CallQueueManager: Using callQueue: class java.util.concurrent.LinkedBlockingQueue queueCapacity: 5000
2020-03-21 12:54:10,378 INFO org.apache.hadoop.ipc.Server: Starting Socket Reader #1 for port 8030
2020-03-21 12:54:10,403 INFO org.apache.hadoop.yarn.factories.impl.pb.RpcServerFactoryPBImpl: Adding protocol org.apache.hadoop.yarn.api.ApplicationMasterProtocolPB to the server
2020-03-21 12:54:10,403 INFO org.apache.hadoop.ipc.Server: IPC Server Responder: starting
2020-03-21 12:54:10,403 INFO org.apache.hadoop.ipc.Server: IPC Server listener on 8030: starting
2020-03-21 12:54:10,534 INFO org.apache.hadoop.ipc.CallQueueManager: Using callQueue: class java.util.concurrent.LinkedBlockingQueue queueCapacity: 5000
2020-03-21 12:54:10,536 INFO org.apache.hadoop.ipc.Server: Starting Socket Reader #1 for port 8032
2020-03-21 12:54:10,542 INFO org.apache.hadoop.yarn.factories.impl.pb.RpcServerFactoryPBImpl: Adding protocol org.apache.hadoop.yarn.api.ApplicationClientProtocolPB to the server
2020-03-21 12:54:10,543 INFO org.apache.hadoop.ipc.Server: IPC Server Responder: starting
2020-03-21 12:54:10,543 INFO org.apache.hadoop.ipc.Server: IPC Server listener on 8032: starting
2020-03-21 12:54:10,552 INFO org.apache.hadoop.yarn.server.resourcemanager.ResourceManager: Transitioned to active state
2020-03-21 12:54:10,665 INFO org.mortbay.log: Logging to org.slf4j.impl.Log4jLoggerAdapter(org.mortbay.log) via org.mortbay.log.Slf4jLog
2020-03-21 12:54:10,669 INFO org.apache.hadoop.security.authentication.server.AuthenticationFilter: Unable to initialize FileSignerSecretProvider, falling back to use random secrets.
2020-03-21 12:54:10,673 INFO org.apache.hadoop.http.HttpRequestLog: Http request log for http.requests.resourcemanager is not defined
2020-03-21 12:54:10,677 INFO org.apache.hadoop.http.HttpServer2: Added global filter 'safety' (class=org.apache.hadoop.http.HttpServer2$QuotingInputFilter)
2020-03-21 12:54:10,679 INFO org.apache.hadoop.http.HttpServer2: Added filter RMAuthenticationFilter (class=org.apache.hadoop.yarn.server.security.http.RMAuthenticationFilter) to context cluster
2020-03-21 12:54:10,679 INFO org.apache.hadoop.http.HttpServer2: Added filter RMAuthenticationFilter (class=org.apache.hadoop.yarn.server.security.http.RMAuthenticationFilter) to context logs
2020-03-21 12:54:10,679 INFO org.apache.hadoop.http.HttpServer2: Added filter RMAuthenticationFilter (class=org.apache.hadoop.yarn.server.security.http.RMAuthenticationFilter) to context static
2020-03-21 12:54:10,679 INFO org.apache.hadoop.http.HttpServer2: Added filter static_user_filter (class=org.apache.hadoop.http.lib.StaticUserWebFilter$StaticUserFilter) to context cluster
2020-03-21 12:54:10,679 INFO org.apache.hadoop.http.HttpServer2: Added filter static_user_filter (class=org.apache.hadoop.http.lib.StaticUserWebFilter$StaticUserFilter) to context logs
2020-03-21 12:54:10,679 INFO org.apache.hadoop.http.HttpServer2: Added filter static_user_filter (class=org.apache.hadoop.http.lib.StaticUserWebFilter$StaticUserFilter) to context static
2020-03-21 12:54:10,681 INFO org.apache.hadoop.http.HttpServer2: adding path spec: /cluster/*
2020-03-21 12:54:10,681 INFO org.apache.hadoop.http.HttpServer2: adding path spec: /ws/*
2020-03-21 12:54:10,996 INFO org.apache.hadoop.yarn.webapp.WebApps: Registered webapp guice modules
2020-03-21 12:54:10,997 INFO org.apache.hadoop.http.HttpServer2: Jetty bound to port 8088
2020-03-21 12:54:10,997 INFO org.mortbay.log: jetty-6.1.26
2020-03-21 12:54:11,011 INFO org.mortbay.log: Extract jar:file:/home/xidian/hadoop-2.7.7/share/hadoop/yarn/hadoop-yarn-common-2.7.7.jar!/webapps/cluster to /tmp/Jetty_0_0_0_0_8088_cluster____u0rgz3/webapp
2020-03-21 12:54:11,292 INFO org.apache.hadoop.security.token.delegation.AbstractDelegationTokenSecretManager: Updating the current master key for generating delegation tokens
2020-03-21 12:54:11,293 INFO org.apache.hadoop.security.token.delegation.AbstractDelegationTokenSecretManager: Starting expired delegation token remover thread, tokenRemoverScanInterval=60 min(s)
2020-03-21 12:54:11,293 INFO org.apache.hadoop.security.token.delegation.AbstractDelegationTokenSecretManager: Updating the current master key for generating delegation tokens
2020-03-21 12:54:12,036 INFO org.mortbay.log: Started HttpServer2$SelectChannelConnectorWithSafeStartup@0.0.0.0:8088
2020-03-21 12:54:12,036 INFO org.apache.hadoop.yarn.webapp.WebApps: Web app cluster started at 8088
2020-03-21 12:54:12,113 INFO org.apache.hadoop.ipc.CallQueueManager: Using callQueue: class java.util.concurrent.LinkedBlockingQueue queueCapacity: 100
2020-03-21 12:54:12,113 INFO org.apache.hadoop.ipc.Server: Starting Socket Reader #1 for port 8033
2020-03-21 12:54:12,115 INFO org.apache.hadoop.yarn.factories.impl.pb.RpcServerFactoryPBImpl: Adding protocol org.apache.hadoop.yarn.server.api.ResourceManagerAdministrationProtocolPB to the server
2020-03-21 12:54:12,115 INFO org.apache.hadoop.ipc.Server: IPC Server Responder: starting
2020-03-21 12:54:12,115 INFO org.apache.hadoop.ipc.Server: IPC Server listener on 8033: starting
2020-03-21 12:54:33,372 ERROR org.apache.hadoop.yarn.server.resourcemanager.ResourceManager: RECEIVED SIGNAL 15: SIGTERM
2020-03-21 12:54:33,380 ERROR org.apache.hadoop.security.token.delegation.AbstractDelegationTokenSecretManager: ExpiredTokenRemover received java.lang.InterruptedException: sleep interrupted
2020-03-21 12:54:33,381 INFO org.mortbay.log: Stopped HttpServer2$SelectChannelConnectorWithSafeStartup@0.0.0.0:8088
2020-03-21 12:54:33,482 INFO org.apache.hadoop.ipc.Server: Stopping server on 8032
2020-03-21 12:54:33,484 INFO org.apache.hadoop.ipc.Server: Stopping IPC Server listener on 8032
2020-03-21 12:54:33,484 INFO org.apache.hadoop.ipc.Server: Stopping server on 8033
2020-03-21 12:54:33,485 INFO org.apache.hadoop.ipc.Server: Stopping IPC Server Responder
2020-03-21 12:54:33,485 INFO org.apache.hadoop.ipc.Server: Stopping IPC Server listener on 8033
2020-03-21 12:54:33,485 INFO org.apache.hadoop.ipc.Server: Stopping IPC Server Responder
2020-03-21 12:54:33,485 INFO org.apache.hadoop.yarn.server.resourcemanager.ResourceManager: Transitioning to standby state
2020-03-21 12:54:33,487 WARN org.apache.hadoop.yarn.server.resourcemanager.amlauncher.ApplicationMasterLauncher: org.apache.hadoop.yarn.server.resourcemanager.amlauncher.ApplicationMasterLauncher$LauncherThread interrupted. Returning.
2020-03-21 12:54:33,487 INFO org.apache.hadoop.ipc.Server: Stopping server on 8030
2020-03-21 12:54:33,490 INFO org.apache.hadoop.ipc.Server: Stopping IPC Server listener on 8030
2020-03-21 12:54:33,491 INFO org.apache.hadoop.ipc.Server: Stopping IPC Server Responder
2020-03-21 12:54:33,491 INFO org.apache.hadoop.ipc.Server: Stopping server on 8031
2020-03-21 12:54:33,501 INFO org.apache.hadoop.ipc.Server: Stopping IPC Server listener on 8031
2020-03-21 12:54:33,501 INFO org.apache.hadoop.ipc.Server: Stopping IPC Server Responder
2020-03-21 12:54:33,501 ERROR org.apache.hadoop.yarn.server.resourcemanager.ResourceManager: Returning, interrupted : java.lang.InterruptedException
2020-03-21 12:54:33,501 INFO org.apache.hadoop.yarn.util.AbstractLivelinessMonitor: NMLivelinessMonitor thread interrupted
2020-03-21 12:54:33,503 INFO org.apache.hadoop.yarn.event.AsyncDispatcher: AsyncDispatcher is draining to stop, igonring any new events.
2020-03-21 12:54:33,504 INFO org.apache.hadoop.yarn.util.AbstractLivelinessMonitor: org.apache.hadoop.yarn.server.resourcemanager.rmcontainer.ContainerAllocationExpirer thread interrupted
2020-03-21 12:54:33,504 INFO org.apache.hadoop.yarn.util.AbstractLivelinessMonitor: AMLivelinessMonitor thread interrupted
2020-03-21 12:54:33,504 INFO org.apache.hadoop.yarn.util.AbstractLivelinessMonitor: AMLivelinessMonitor thread interrupted
2020-03-21 12:54:33,504 ERROR org.apache.hadoop.security.token.delegation.AbstractDelegationTokenSecretManager: ExpiredTokenRemover received java.lang.InterruptedException: sleep interrupted
2020-03-21 12:54:33,506 INFO org.apache.hadoop.metrics2.impl.MetricsSystemImpl: Stopping ResourceManager metrics system...
2020-03-21 12:54:33,507 INFO org.apache.hadoop.metrics2.impl.MetricsSystemImpl: ResourceManager metrics system stopped.
2020-03-21 12:54:33,508 INFO org.apache.hadoop.metrics2.impl.MetricsSystemImpl: ResourceManager metrics system shutdown complete.
2020-03-21 12:54:33,508 INFO org.apache.hadoop.yarn.event.AsyncDispatcher: AsyncDispatcher is draining to stop, igonring any new events.
2020-03-21 12:54:33,510 INFO org.apache.hadoop.yarn.server.resourcemanager.ResourceManager: Transitioned to standby state
2020-03-21 12:54:33,510 INFO org.apache.hadoop.yarn.server.resourcemanager.ResourceManager: SHUTDOWN_MSG: 
/************************************************************
SHUTDOWN_MSG: Shutting down ResourceManager at dell/127.0.1.1
************************************************************/
2020-03-21 12:56:50,996 INFO org.apache.hadoop.yarn.server.resourcemanager.ResourceManager: STARTUP_MSG: 
/************************************************************
STARTUP_MSG: Starting ResourceManager
STARTUP_MSG:   host = dell/127.0.1.1
STARTUP_MSG:   args = []
STARTUP_MSG:   version = 2.7.7
STARTUP_MSG:   build = Unknown -r c1aad84bd27cd79c3d1a7dd58202a8c3ee1ed3ac; compiled by 'stevel' on 2018-07-18T22:47Z
STARTUP_MSG:   java = 1.8.0_131
************************************************************/
2020-03-21 12:56:51,001 INFO org.apache.hadoop.yarn.server.resourcemanager.ResourceManager: registered UNIX signal handlers for [TERM, HUP, INT]
2020-03-21 12:56:51,156 INFO org.apache.hadoop.conf.Configuration: found resource core-site.xml at file:/home/xidian/hadoop-2.7.7/etc/hadoop/core-site.xml
2020-03-21 12:56:51,222 INFO org.apache.hadoop.security.Groups: clearing userToGroupsMap cache
2020-03-21 12:56:51,251 INFO org.apache.hadoop.conf.Configuration: found resource yarn-site.xml at file:/home/xidian/hadoop-2.7.7/etc/hadoop/yarn-site.xml
2020-03-21 12:56:51,460 INFO org.apache.hadoop.yarn.event.AsyncDispatcher: Registering class org.apache.hadoop.yarn.server.resourcemanager.RMFatalEventType for class org.apache.hadoop.yarn.server.resourcemanager.ResourceManager$RMFatalEventDispatcher
2020-03-21 12:56:51,596 INFO org.apache.hadoop.yarn.server.resourcemanager.security.NMTokenSecretManagerInRM: NMTokenKeyRollingInterval: 86400000ms and NMTokenKeyActivationDelay: 900000ms
2020-03-21 12:56:51,598 INFO org.apache.hadoop.yarn.server.resourcemanager.security.RMContainerTokenSecretManager: ContainerTokenKeyRollingInterval: 86400000ms and ContainerTokenKeyActivationDelay: 900000ms
2020-03-21 12:56:51,600 INFO org.apache.hadoop.yarn.server.resourcemanager.security.AMRMTokenSecretManager: AMRMTokenKeyRollingInterval: 86400000ms and AMRMTokenKeyActivationDelay: 900000 ms
2020-03-21 12:56:51,617 INFO org.apache.hadoop.yarn.event.AsyncDispatcher: Registering class org.apache.hadoop.yarn.server.resourcemanager.recovery.RMStateStoreEventType for class org.apache.hadoop.yarn.server.resourcemanager.recovery.RMStateStore$ForwardingEventHandler
2020-03-21 12:56:51,618 INFO org.apache.hadoop.yarn.event.AsyncDispatcher: Registering class org.apache.hadoop.yarn.server.resourcemanager.NodesListManagerEventType for class org.apache.hadoop.yarn.server.resourcemanager.NodesListManager
2020-03-21 12:56:51,618 INFO org.apache.hadoop.yarn.server.resourcemanager.ResourceManager: Using Scheduler: org.apache.hadoop.yarn.server.resourcemanager.scheduler.capacity.CapacityScheduler
2020-03-21 12:56:51,626 INFO org.apache.hadoop.yarn.event.AsyncDispatcher: Registering class org.apache.hadoop.yarn.server.resourcemanager.scheduler.event.SchedulerEventType for class org.apache.hadoop.yarn.server.resourcemanager.ResourceManager$SchedulerEventDispatcher
2020-03-21 12:56:51,626 INFO org.apache.hadoop.yarn.event.AsyncDispatcher: Registering class org.apache.hadoop.yarn.server.resourcemanager.rmapp.RMAppEventType for class org.apache.hadoop.yarn.server.resourcemanager.ResourceManager$ApplicationEventDispatcher
2020-03-21 12:56:51,626 INFO org.apache.hadoop.yarn.event.AsyncDispatcher: Registering class org.apache.hadoop.yarn.server.resourcemanager.rmapp.attempt.RMAppAttemptEventType for class org.apache.hadoop.yarn.server.resourcemanager.ResourceManager$ApplicationAttemptEventDispatcher
2020-03-21 12:56:51,627 INFO org.apache.hadoop.yarn.event.AsyncDispatcher: Registering class org.apache.hadoop.yarn.server.resourcemanager.rmnode.RMNodeEventType for class org.apache.hadoop.yarn.server.resourcemanager.ResourceManager$NodeEventDispatcher
2020-03-21 12:56:51,658 INFO org.apache.hadoop.metrics2.impl.MetricsConfig: loaded properties from hadoop-metrics2.properties
2020-03-21 12:56:51,688 INFO org.apache.hadoop.metrics2.impl.MetricsSystemImpl: Scheduled snapshot period at 10 second(s).
2020-03-21 12:56:51,689 INFO org.apache.hadoop.metrics2.impl.MetricsSystemImpl: ResourceManager metrics system started
2020-03-21 12:56:51,695 INFO org.apache.hadoop.yarn.event.AsyncDispatcher: Registering class org.apache.hadoop.yarn.server.resourcemanager.RMAppManagerEventType for class org.apache.hadoop.yarn.server.resourcemanager.RMAppManager
2020-03-21 12:56:51,699 INFO org.apache.hadoop.yarn.event.AsyncDispatcher: Registering class org.apache.hadoop.yarn.server.resourcemanager.amlauncher.AMLauncherEventType for class org.apache.hadoop.yarn.server.resourcemanager.amlauncher.ApplicationMasterLauncher
2020-03-21 12:56:51,700 INFO org.apache.hadoop.yarn.server.resourcemanager.RMNMInfo: Registered RMNMInfo MBean
2020-03-21 12:56:51,701 INFO org.apache.hadoop.yarn.security.YarnAuthorizationProvider: org.apache.hadoop.yarn.security.ConfiguredYarnAuthorizer is instiantiated.
2020-03-21 12:56:51,702 INFO org.apache.hadoop.util.HostsFileReader: Refreshing hosts (include/exclude) list
2020-03-21 12:56:51,702 INFO org.apache.hadoop.conf.Configuration: found resource capacity-scheduler.xml at file:/home/xidian/hadoop-2.7.7/etc/hadoop/capacity-scheduler.xml
2020-03-21 12:56:51,728 INFO org.apache.hadoop.yarn.server.resourcemanager.scheduler.capacity.CapacitySchedulerConfiguration: max alloc mb per queue for root is undefined
2020-03-21 12:56:51,728 INFO org.apache.hadoop.yarn.server.resourcemanager.scheduler.capacity.CapacitySchedulerConfiguration: max alloc vcore per queue for root is undefined
2020-03-21 12:56:51,730 INFO org.apache.hadoop.yarn.server.resourcemanager.scheduler.capacity.ParentQueue: root, capacity=1.0, asboluteCapacity=1.0, maxCapacity=1.0, asboluteMaxCapacity=1.0, state=RUNNING, acls=ADMINISTER_QUEUE:*SUBMIT_APP:*, labels=*,
, reservationsContinueLooking=true
2020-03-21 12:56:51,730 INFO org.apache.hadoop.yarn.server.resourcemanager.scheduler.capacity.ParentQueue: Initialized parent-queue root name=root, fullname=root
2020-03-21 12:56:51,735 INFO org.apache.hadoop.yarn.server.resourcemanager.scheduler.capacity.CapacitySchedulerConfiguration: max alloc mb per queue for root.default is undefined
2020-03-21 12:56:51,735 INFO org.apache.hadoop.yarn.server.resourcemanager.scheduler.capacity.CapacitySchedulerConfiguration: max alloc vcore per queue for root.default is undefined
2020-03-21 12:56:51,735 INFO org.apache.hadoop.yarn.server.resourcemanager.scheduler.capacity.LeafQueue: Initializing default
capacity = 1.0 [= (float) configuredCapacity / 100 ]
asboluteCapacity = 1.0 [= parentAbsoluteCapacity * capacity ]
maxCapacity = 1.0 [= configuredMaxCapacity ]
absoluteMaxCapacity = 1.0 [= 1.0 maximumCapacity undefined, (parentAbsoluteMaxCapacity * maximumCapacity) / 100 otherwise ]
userLimit = 100 [= configuredUserLimit ]
userLimitFactor = 1.0 [= configuredUserLimitFactor ]
maxApplications = 10000 [= configuredMaximumSystemApplicationsPerQueue or (int)(configuredMaximumSystemApplications * absoluteCapacity)]
maxApplicationsPerUser = 10000 [= (int)(maxApplications * (userLimit / 100.0f) * userLimitFactor) ]
usedCapacity = 0.0 [= usedResourcesMemory / (clusterResourceMemory * absoluteCapacity)]
absoluteUsedCapacity = 0.0 [= usedResourcesMemory / clusterResourceMemory]
maxAMResourcePerQueuePercent = 0.1 [= configuredMaximumAMResourcePercent ]
minimumAllocationFactor = 0.875 [= (float)(maximumAllocationMemory - minimumAllocationMemory) / maximumAllocationMemory ]
maximumAllocation = <memory:8192, vCores:32> [= configuredMaxAllocation ]
numContainers = 0 [= currentNumContainers ]
state = RUNNING [= configuredState ]
acls = ADMINISTER_QUEUE:*SUBMIT_APP:* [= configuredAcls ]
nodeLocalityDelay = 40
labels=*,
nodeLocalityDelay = 40
reservationsContinueLooking = true
preemptionDisabled = true

2020-03-21 12:56:51,736 INFO org.apache.hadoop.yarn.server.resourcemanager.scheduler.capacity.CapacityScheduler: Initialized queue: default: capacity=1.0, absoluteCapacity=1.0, usedResources=<memory:0, vCores:0>, usedCapacity=0.0, absoluteUsedCapacity=0.0, numApps=0, numContainers=0
2020-03-21 12:56:51,736 INFO org.apache.hadoop.yarn.server.resourcemanager.scheduler.capacity.CapacityScheduler: Initialized queue: root: numChildQueue= 1, capacity=1.0, absoluteCapacity=1.0, usedResources=<memory:0, vCores:0>usedCapacity=0.0, numApps=0, numContainers=0
2020-03-21 12:56:51,736 INFO org.apache.hadoop.yarn.server.resourcemanager.scheduler.capacity.CapacityScheduler: Initialized root queue root: numChildQueue= 1, capacity=1.0, absoluteCapacity=1.0, usedResources=<memory:0, vCores:0>usedCapacity=0.0, numApps=0, numContainers=0
2020-03-21 12:56:51,736 INFO org.apache.hadoop.yarn.server.resourcemanager.scheduler.capacity.CapacityScheduler: Initialized queue mappings, override: false
2020-03-21 12:56:51,736 INFO org.apache.hadoop.yarn.server.resourcemanager.scheduler.capacity.CapacityScheduler: Initialized CapacityScheduler with calculator=class org.apache.hadoop.yarn.util.resource.DefaultResourceCalculator, minimumAllocation=<<memory:1024, vCores:1>>, maximumAllocation=<<memory:8192, vCores:32>>, asynchronousScheduling=false, asyncScheduleInterval=5ms
2020-03-21 12:56:51,742 INFO org.apache.hadoop.yarn.server.resourcemanager.metrics.SystemMetricsPublisher: YARN system metrics publishing service is not enabled
2020-03-21 12:56:51,742 INFO org.apache.hadoop.yarn.server.resourcemanager.ResourceManager: Transitioning to active state
2020-03-21 12:56:51,749 INFO org.apache.hadoop.yarn.server.resourcemanager.recovery.RMStateStore: Updating AMRMToken
2020-03-21 12:56:51,749 INFO org.apache.hadoop.yarn.server.resourcemanager.security.RMContainerTokenSecretManager: Rolling master-key for container-tokens
2020-03-21 12:56:51,749 INFO org.apache.hadoop.yarn.server.resourcemanager.security.NMTokenSecretManagerInRM: Rolling master-key for nm-tokens
2020-03-21 12:56:51,749 INFO org.apache.hadoop.security.token.delegation.AbstractDelegationTokenSecretManager: Updating the current master key for generating delegation tokens
2020-03-21 12:56:51,750 INFO org.apache.hadoop.yarn.server.resourcemanager.security.RMDelegationTokenSecretManager: storing master key with keyID 1
2020-03-21 12:56:51,750 INFO org.apache.hadoop.yarn.server.resourcemanager.recovery.RMStateStore: Storing RMDTMasterKey.
2020-03-21 12:56:51,750 INFO org.apache.hadoop.security.token.delegation.AbstractDelegationTokenSecretManager: Starting expired delegation token remover thread, tokenRemoverScanInterval=60 min(s)
2020-03-21 12:56:51,750 INFO org.apache.hadoop.security.token.delegation.AbstractDelegationTokenSecretManager: Updating the current master key for generating delegation tokens
2020-03-21 12:56:51,750 INFO org.apache.hadoop.yarn.server.resourcemanager.security.RMDelegationTokenSecretManager: storing master key with keyID 2
2020-03-21 12:56:51,750 INFO org.apache.hadoop.yarn.server.resourcemanager.recovery.RMStateStore: Storing RMDTMasterKey.
2020-03-21 12:56:51,751 INFO org.apache.hadoop.yarn.event.AsyncDispatcher: Registering class org.apache.hadoop.yarn.nodelabels.event.NodeLabelsStoreEventType for class org.apache.hadoop.yarn.nodelabels.CommonNodeLabelsManager$ForwardingEventHandler
2020-03-21 12:56:51,827 INFO org.apache.hadoop.ipc.CallQueueManager: Using callQueue: class java.util.concurrent.LinkedBlockingQueue queueCapacity: 5000
2020-03-21 12:56:51,834 INFO org.apache.hadoop.ipc.Server: Starting Socket Reader #1 for port 8031
2020-03-21 12:56:51,931 INFO org.apache.hadoop.yarn.factories.impl.pb.RpcServerFactoryPBImpl: Adding protocol org.apache.hadoop.yarn.server.api.ResourceTrackerPB to the server
2020-03-21 12:56:51,931 INFO org.apache.hadoop.ipc.Server: IPC Server Responder: starting
2020-03-21 12:56:51,931 INFO org.apache.hadoop.ipc.Server: IPC Server listener on 8031: starting
2020-03-21 12:56:52,009 INFO org.apache.hadoop.ipc.CallQueueManager: Using callQueue: class java.util.concurrent.LinkedBlockingQueue queueCapacity: 5000
2020-03-21 12:56:52,012 INFO org.apache.hadoop.ipc.Server: Starting Socket Reader #1 for port 8030
2020-03-21 12:56:52,018 INFO org.apache.hadoop.yarn.factories.impl.pb.RpcServerFactoryPBImpl: Adding protocol org.apache.hadoop.yarn.api.ApplicationMasterProtocolPB to the server
2020-03-21 12:56:52,018 INFO org.apache.hadoop.ipc.Server: IPC Server Responder: starting
2020-03-21 12:56:52,018 INFO org.apache.hadoop.ipc.Server: IPC Server listener on 8030: starting
2020-03-21 12:56:52,113 INFO org.apache.hadoop.ipc.CallQueueManager: Using callQueue: class java.util.concurrent.LinkedBlockingQueue queueCapacity: 5000
2020-03-21 12:56:52,114 INFO org.apache.hadoop.ipc.Server: Starting Socket Reader #1 for port 8032
2020-03-21 12:56:52,117 INFO org.apache.hadoop.yarn.factories.impl.pb.RpcServerFactoryPBImpl: Adding protocol org.apache.hadoop.yarn.api.ApplicationClientProtocolPB to the server
2020-03-21 12:56:52,117 INFO org.apache.hadoop.ipc.Server: IPC Server Responder: starting
2020-03-21 12:56:52,117 INFO org.apache.hadoop.ipc.Server: IPC Server listener on 8032: starting
2020-03-21 12:56:52,130 INFO org.apache.hadoop.yarn.server.resourcemanager.ResourceManager: Transitioned to active state
2020-03-21 12:56:52,228 INFO org.mortbay.log: Logging to org.slf4j.impl.Log4jLoggerAdapter(org.mortbay.log) via org.mortbay.log.Slf4jLog
2020-03-21 12:56:52,233 INFO org.apache.hadoop.security.authentication.server.AuthenticationFilter: Unable to initialize FileSignerSecretProvider, falling back to use random secrets.
2020-03-21 12:56:52,239 INFO org.apache.hadoop.http.HttpRequestLog: Http request log for http.requests.resourcemanager is not defined
2020-03-21 12:56:52,245 INFO org.apache.hadoop.http.HttpServer2: Added global filter 'safety' (class=org.apache.hadoop.http.HttpServer2$QuotingInputFilter)
2020-03-21 12:56:52,247 INFO org.apache.hadoop.http.HttpServer2: Added filter RMAuthenticationFilter (class=org.apache.hadoop.yarn.server.security.http.RMAuthenticationFilter) to context cluster
2020-03-21 12:56:52,247 INFO org.apache.hadoop.http.HttpServer2: Added filter RMAuthenticationFilter (class=org.apache.hadoop.yarn.server.security.http.RMAuthenticationFilter) to context logs
2020-03-21 12:56:52,247 INFO org.apache.hadoop.http.HttpServer2: Added filter RMAuthenticationFilter (class=org.apache.hadoop.yarn.server.security.http.RMAuthenticationFilter) to context static
2020-03-21 12:56:52,248 INFO org.apache.hadoop.http.HttpServer2: Added filter static_user_filter (class=org.apache.hadoop.http.lib.StaticUserWebFilter$StaticUserFilter) to context cluster
2020-03-21 12:56:52,248 INFO org.apache.hadoop.http.HttpServer2: Added filter static_user_filter (class=org.apache.hadoop.http.lib.StaticUserWebFilter$StaticUserFilter) to context logs
2020-03-21 12:56:52,248 INFO org.apache.hadoop.http.HttpServer2: Added filter static_user_filter (class=org.apache.hadoop.http.lib.StaticUserWebFilter$StaticUserFilter) to context static
2020-03-21 12:56:52,250 INFO org.apache.hadoop.http.HttpServer2: adding path spec: /cluster/*
2020-03-21 12:56:52,250 INFO org.apache.hadoop.http.HttpServer2: adding path spec: /ws/*
2020-03-21 12:56:52,461 INFO org.apache.hadoop.yarn.webapp.WebApps: Registered webapp guice modules
2020-03-21 12:56:52,462 INFO org.apache.hadoop.http.HttpServer2: Jetty bound to port 8088
2020-03-21 12:56:52,462 INFO org.mortbay.log: jetty-6.1.26
2020-03-21 12:56:52,477 INFO org.mortbay.log: Extract jar:file:/home/xidian/hadoop-2.7.7/share/hadoop/yarn/hadoop-yarn-common-2.7.7.jar!/webapps/cluster to /tmp/Jetty_0_0_0_0_8088_cluster____u0rgz3/webapp
2020-03-21 12:56:52,593 INFO org.apache.hadoop.security.token.delegation.AbstractDelegationTokenSecretManager: Updating the current master key for generating delegation tokens
2020-03-21 12:56:52,593 INFO org.apache.hadoop.security.token.delegation.AbstractDelegationTokenSecretManager: Starting expired delegation token remover thread, tokenRemoverScanInterval=60 min(s)
2020-03-21 12:56:52,593 INFO org.apache.hadoop.security.token.delegation.AbstractDelegationTokenSecretManager: Updating the current master key for generating delegation tokens
2020-03-21 12:56:53,342 INFO org.mortbay.log: Started HttpServer2$SelectChannelConnectorWithSafeStartup@0.0.0.0:8088
2020-03-21 12:56:53,343 INFO org.apache.hadoop.yarn.webapp.WebApps: Web app cluster started at 8088
2020-03-21 12:56:53,424 INFO org.apache.hadoop.ipc.CallQueueManager: Using callQueue: class java.util.concurrent.LinkedBlockingQueue queueCapacity: 100
2020-03-21 12:56:53,425 INFO org.apache.hadoop.ipc.Server: Starting Socket Reader #1 for port 8033
2020-03-21 12:56:53,427 INFO org.apache.hadoop.yarn.factories.impl.pb.RpcServerFactoryPBImpl: Adding protocol org.apache.hadoop.yarn.server.api.ResourceManagerAdministrationProtocolPB to the server
2020-03-21 12:56:53,427 INFO org.apache.hadoop.ipc.Server: IPC Server listener on 8033: starting
2020-03-21 12:56:53,427 INFO org.apache.hadoop.ipc.Server: IPC Server Responder: starting
2020-03-21 12:56:54,412 INFO org.apache.hadoop.yarn.util.RackResolver: Resolved dell to /default-rack
2020-03-21 12:56:54,413 INFO org.apache.hadoop.yarn.server.resourcemanager.ResourceTrackerService: NodeManager from node dell(cmPort: 34479 httpPort: 8042) registered with capability: <memory:8192, vCores:8>, assigned nodeId dell:34479
2020-03-21 12:56:54,415 INFO org.apache.hadoop.yarn.server.resourcemanager.rmnode.RMNodeImpl: dell:34479 Node Transitioned from NEW to RUNNING
2020-03-21 12:56:54,417 INFO org.apache.hadoop.yarn.server.resourcemanager.scheduler.capacity.CapacityScheduler: Added node dell:34479 clusterResource: <memory:8192, vCores:8>
2020-03-21 13:06:51,702 INFO org.apache.hadoop.yarn.server.resourcemanager.scheduler.AbstractYarnScheduler: Release request cache is cleaned up
2020-03-21 13:14:48,190 INFO org.apache.hadoop.yarn.server.resourcemanager.ClientRMService: Allocated new applicationId: 1
2020-03-21 13:14:49,170 INFO org.apache.hadoop.yarn.server.resourcemanager.ClientRMService: Application with id 1 submitted by user xidian
2020-03-21 13:14:49,170 INFO org.apache.hadoop.yarn.server.resourcemanager.rmapp.RMAppImpl: Storing application with id application_1584766611743_0001
2020-03-21 13:14:49,170 INFO org.apache.hadoop.yarn.server.resourcemanager.RMAuditLogger: USER=xidian	IP=127.0.0.1	OPERATION=Submit Application Request	TARGET=ClientRMService	RESULT=SUCCESS	APPID=application_1584766611743_0001
2020-03-21 13:14:49,223 INFO org.apache.hadoop.yarn.server.resourcemanager.rmapp.RMAppImpl: application_1584766611743_0001 State change from NEW to NEW_SAVING on event=START
2020-03-21 13:14:49,224 INFO org.apache.hadoop.yarn.server.resourcemanager.recovery.RMStateStore: Storing info for app: application_1584766611743_0001
2020-03-21 13:14:49,224 INFO org.apache.hadoop.yarn.server.resourcemanager.rmapp.RMAppImpl: application_1584766611743_0001 State change from NEW_SAVING to SUBMITTED on event=APP_NEW_SAVED
2020-03-21 13:14:49,226 INFO org.apache.hadoop.yarn.server.resourcemanager.scheduler.capacity.ParentQueue: Application added - appId: application_1584766611743_0001 user: xidian leaf-queue of parent: root #applications: 1
2020-03-21 13:14:49,226 INFO org.apache.hadoop.yarn.server.resourcemanager.scheduler.capacity.CapacityScheduler: Accepted application application_1584766611743_0001 from user: xidian, in queue: default
2020-03-21 13:14:49,232 INFO org.apache.hadoop.yarn.server.resourcemanager.rmapp.RMAppImpl: application_1584766611743_0001 State change from SUBMITTED to ACCEPTED on event=APP_ACCEPTED
2020-03-21 13:14:49,247 INFO org.apache.hadoop.yarn.server.resourcemanager.ApplicationMasterService: Registering app attempt : appattempt_1584766611743_0001_000001
2020-03-21 13:14:49,247 INFO org.apache.hadoop.yarn.server.resourcemanager.rmapp.attempt.RMAppAttemptImpl: appattempt_1584766611743_0001_000001 State change from NEW to SUBMITTED
2020-03-21 13:14:49,254 WARN org.apache.hadoop.yarn.server.resourcemanager.scheduler.capacity.LeafQueue: maximum-am-resource-percent is insufficient to start a single application in queue, it is likely set too low. skipping enforcement to allow at least one application to start
2020-03-21 13:14:49,254 WARN org.apache.hadoop.yarn.server.resourcemanager.scheduler.capacity.LeafQueue: maximum-am-resource-percent is insufficient to start a single application in queue for user, it is likely set too low. skipping enforcement to allow at least one application to start
2020-03-21 13:14:49,254 INFO org.apache.hadoop.yarn.server.resourcemanager.scheduler.capacity.LeafQueue: Application application_1584766611743_0001 from user: xidian activated in queue: default
2020-03-21 13:14:49,254 INFO org.apache.hadoop.yarn.server.resourcemanager.scheduler.capacity.LeafQueue: Application added - appId: application_1584766611743_0001 user: org.apache.hadoop.yarn.server.resourcemanager.scheduler.capacity.LeafQueue$User@54ff8639, leaf-queue: default #user-pending-applications: 0 #user-active-applications: 1 #queue-pending-applications: 0 #queue-active-applications: 1
2020-03-21 13:14:49,254 INFO org.apache.hadoop.yarn.server.resourcemanager.scheduler.capacity.CapacityScheduler: Added Application Attempt appattempt_1584766611743_0001_000001 to scheduler from user xidian in queue default
2020-03-21 13:14:49,256 INFO org.apache.hadoop.yarn.server.resourcemanager.rmapp.attempt.RMAppAttemptImpl: appattempt_1584766611743_0001_000001 State change from SUBMITTED to SCHEDULED
2020-03-21 13:14:49,740 INFO org.apache.hadoop.yarn.server.resourcemanager.rmcontainer.RMContainerImpl: container_1584766611743_0001_01_000001 Container Transitioned from NEW to ALLOCATED
2020-03-21 13:14:49,740 INFO org.apache.hadoop.yarn.server.resourcemanager.RMAuditLogger: USER=xidian	OPERATION=AM Allocated Container	TARGET=SchedulerApp	RESULT=SUCCESS	APPID=application_1584766611743_0001	CONTAINERID=container_1584766611743_0001_01_000001
2020-03-21 13:14:49,740 INFO org.apache.hadoop.yarn.server.resourcemanager.scheduler.SchedulerNode: Assigned container container_1584766611743_0001_01_000001 of capacity <memory:2048, vCores:1> on host dell:34479, which has 1 containers, <memory:2048, vCores:1> used and <memory:6144, vCores:7> available after allocation
2020-03-21 13:14:49,740 INFO org.apache.hadoop.yarn.server.resourcemanager.scheduler.capacity.LeafQueue: assignedContainer application attempt=appattempt_1584766611743_0001_000001 container=Container: [ContainerId: container_1584766611743_0001_01_000001, NodeId: dell:34479, NodeHttpAddress: dell:8042, Resource: <memory:2048, vCores:1>, Priority: 0, Token: null, ] queue=default: capacity=1.0, absoluteCapacity=1.0, usedResources=<memory:0, vCores:0>, usedCapacity=0.0, absoluteUsedCapacity=0.0, numApps=1, numContainers=0 clusterResource=<memory:8192, vCores:8> type=OFF_SWITCH requestedPartition=
2020-03-21 13:14:49,741 INFO org.apache.hadoop.yarn.server.resourcemanager.scheduler.capacity.ParentQueue: Re-sorting assigned queue: root.default stats: default: capacity=1.0, absoluteCapacity=1.0, usedResources=<memory:2048, vCores:1>, usedCapacity=0.25, absoluteUsedCapacity=0.25, numApps=1, numContainers=1
2020-03-21 13:14:49,741 INFO org.apache.hadoop.yarn.server.resourcemanager.scheduler.capacity.ParentQueue: assignedContainer queue=root usedCapacity=0.25 absoluteUsedCapacity=0.25 used=<memory:2048, vCores:1> cluster=<memory:8192, vCores:8>
2020-03-21 13:14:49,751 INFO org.apache.hadoop.yarn.server.resourcemanager.security.NMTokenSecretManagerInRM: Sending NMToken for nodeId : dell:34479 for container : container_1584766611743_0001_01_000001
2020-03-21 13:14:49,757 INFO org.apache.hadoop.yarn.server.resourcemanager.rmcontainer.RMContainerImpl: container_1584766611743_0001_01_000001 Container Transitioned from ALLOCATED to ACQUIRED
2020-03-21 13:14:49,757 INFO org.apache.hadoop.yarn.server.resourcemanager.security.NMTokenSecretManagerInRM: Clear node set for appattempt_1584766611743_0001_000001
2020-03-21 13:14:49,759 INFO org.apache.hadoop.yarn.server.resourcemanager.rmapp.attempt.RMAppAttemptImpl: Storing attempt: AppId: application_1584766611743_0001 AttemptId: appattempt_1584766611743_0001_000001 MasterContainer: Container: [ContainerId: container_1584766611743_0001_01_000001, NodeId: dell:34479, NodeHttpAddress: dell:8042, Resource: <memory:2048, vCores:1>, Priority: 0, Token: Token { kind: ContainerToken, service: 127.0.1.1:34479 }, ]
2020-03-21 13:14:49,808 INFO org.apache.hadoop.yarn.server.resourcemanager.rmapp.attempt.RMAppAttemptImpl: appattempt_1584766611743_0001_000001 State change from SCHEDULED to ALLOCATED_SAVING
2020-03-21 13:14:49,809 INFO org.apache.hadoop.yarn.server.resourcemanager.rmapp.attempt.RMAppAttemptImpl: appattempt_1584766611743_0001_000001 State change from ALLOCATED_SAVING to ALLOCATED
2020-03-21 13:14:49,811 INFO org.apache.hadoop.yarn.server.resourcemanager.amlauncher.AMLauncher: Launching masterappattempt_1584766611743_0001_000001
2020-03-21 13:14:49,827 INFO org.apache.hadoop.yarn.server.resourcemanager.amlauncher.AMLauncher: Setting up container Container: [ContainerId: container_1584766611743_0001_01_000001, NodeId: dell:34479, NodeHttpAddress: dell:8042, Resource: <memory:2048, vCores:1>, Priority: 0, Token: Token { kind: ContainerToken, service: 127.0.1.1:34479 }, ] for AM appattempt_1584766611743_0001_000001
2020-03-21 13:14:49,827 INFO org.apache.hadoop.yarn.server.resourcemanager.amlauncher.AMLauncher: Command to launch container container_1584766611743_0001_01_000001 : $JAVA_HOME/bin/java -Djava.io.tmpdir=$PWD/tmp -Dlog4j.configuration=container-log4j.properties -Dyarn.app.container.log.dir=<LOG_DIR> -Dyarn.app.container.log.filesize=0 -Dhadoop.root.logger=INFO,CLA -Dhadoop.root.logfile=syslog  -Xmx1024m org.apache.hadoop.mapreduce.v2.app.MRAppMaster 1><LOG_DIR>/stdout 2><LOG_DIR>/stderr 
2020-03-21 13:14:49,828 INFO org.apache.hadoop.yarn.server.resourcemanager.security.AMRMTokenSecretManager: Create AMRMToken for ApplicationAttempt: appattempt_1584766611743_0001_000001
2020-03-21 13:14:49,830 INFO org.apache.hadoop.yarn.server.resourcemanager.security.AMRMTokenSecretManager: Creating password for appattempt_1584766611743_0001_000001
2020-03-21 13:14:50,040 INFO org.apache.hadoop.yarn.server.resourcemanager.amlauncher.AMLauncher: Done launching container Container: [ContainerId: container_1584766611743_0001_01_000001, NodeId: dell:34479, NodeHttpAddress: dell:8042, Resource: <memory:2048, vCores:1>, Priority: 0, Token: Token { kind: ContainerToken, service: 127.0.1.1:34479 }, ] for AM appattempt_1584766611743_0001_000001
2020-03-21 13:14:50,041 INFO org.apache.hadoop.yarn.server.resourcemanager.rmapp.attempt.RMAppAttemptImpl: appattempt_1584766611743_0001_000001 State change from ALLOCATED to LAUNCHED
2020-03-21 13:14:50,733 INFO org.apache.hadoop.yarn.server.resourcemanager.rmcontainer.RMContainerImpl: container_1584766611743_0001_01_000001 Container Transitioned from ACQUIRED to RUNNING
2020-03-21 13:14:52,736 INFO org.apache.hadoop.yarn.server.resourcemanager.rmcontainer.RMContainerImpl: container_1584766611743_0001_01_000001 Container Transitioned from RUNNING to COMPLETED
2020-03-21 13:14:52,736 INFO org.apache.hadoop.yarn.server.resourcemanager.scheduler.common.fica.FiCaSchedulerApp: Completed container: container_1584766611743_0001_01_000001 in state: COMPLETED event:FINISHED
2020-03-21 13:14:52,736 INFO org.apache.hadoop.yarn.server.resourcemanager.RMAuditLogger: USER=xidian	OPERATION=AM Released Container	TARGET=SchedulerApp	RESULT=SUCCESS	APPID=application_1584766611743_0001	CONTAINERID=container_1584766611743_0001_01_000001
2020-03-21 13:14:52,736 INFO org.apache.hadoop.yarn.server.resourcemanager.scheduler.SchedulerNode: Released container container_1584766611743_0001_01_000001 of capacity <memory:2048, vCores:1> on host dell:34479, which currently has 0 containers, <memory:0, vCores:0> used and <memory:8192, vCores:8> available, release resources=true
2020-03-21 13:14:52,737 INFO org.apache.hadoop.yarn.server.resourcemanager.scheduler.capacity.LeafQueue: default used=<memory:0, vCores:0> numContainers=0 user=xidian user-resources=<memory:0, vCores:0>
2020-03-21 13:14:52,737 INFO org.apache.hadoop.yarn.server.resourcemanager.scheduler.capacity.LeafQueue: completedContainer container=Container: [ContainerId: container_1584766611743_0001_01_000001, NodeId: dell:34479, NodeHttpAddress: dell:8042, Resource: <memory:2048, vCores:1>, Priority: 0, Token: Token { kind: ContainerToken, service: 127.0.1.1:34479 }, ] queue=default: capacity=1.0, absoluteCapacity=1.0, usedResources=<memory:0, vCores:0>, usedCapacity=0.0, absoluteUsedCapacity=0.0, numApps=1, numContainers=0 cluster=<memory:8192, vCores:8>
2020-03-21 13:14:52,737 INFO org.apache.hadoop.yarn.server.resourcemanager.scheduler.capacity.ParentQueue: completedContainer queue=root usedCapacity=0.0 absoluteUsedCapacity=0.0 used=<memory:0, vCores:0> cluster=<memory:8192, vCores:8>
2020-03-21 13:14:52,737 INFO org.apache.hadoop.yarn.server.resourcemanager.scheduler.capacity.ParentQueue: Re-sorting completed queue: root.default stats: default: capacity=1.0, absoluteCapacity=1.0, usedResources=<memory:0, vCores:0>, usedCapacity=0.0, absoluteUsedCapacity=0.0, numApps=1, numContainers=0
2020-03-21 13:14:52,737 INFO org.apache.hadoop.yarn.server.resourcemanager.scheduler.capacity.CapacityScheduler: Application attempt appattempt_1584766611743_0001_000001 released container container_1584766611743_0001_01_000001 on node: host: dell:34479 #containers=0 available=<memory:8192, vCores:8> used=<memory:0, vCores:0> with event: FINISHED
2020-03-21 13:14:52,739 INFO org.apache.hadoop.yarn.server.resourcemanager.rmapp.attempt.RMAppAttemptImpl: Updating application attempt appattempt_1584766611743_0001_000001 with final state: FAILED, and exit status: -1
2020-03-21 13:14:52,739 INFO org.apache.hadoop.yarn.server.resourcemanager.rmapp.attempt.RMAppAttemptImpl: appattempt_1584766611743_0001_000001 State change from LAUNCHED to FINAL_SAVING
2020-03-21 13:14:52,739 INFO org.apache.hadoop.yarn.server.resourcemanager.ApplicationMasterService: Unregistering app attempt : appattempt_1584766611743_0001_000001
2020-03-21 13:14:52,740 INFO org.apache.hadoop.yarn.server.resourcemanager.security.AMRMTokenSecretManager: Application finished, removing password for appattempt_1584766611743_0001_000001
2020-03-21 13:14:52,740 INFO org.apache.hadoop.yarn.server.resourcemanager.rmapp.attempt.RMAppAttemptImpl: appattempt_1584766611743_0001_000001 State change from FINAL_SAVING to FAILED
2020-03-21 13:14:52,740 INFO org.apache.hadoop.yarn.server.resourcemanager.rmapp.RMAppImpl: The number of failed attempts is 1. The max attempts is 2
2020-03-21 13:14:52,740 INFO org.apache.hadoop.yarn.server.resourcemanager.ApplicationMasterService: Registering app attempt : appattempt_1584766611743_0001_000002
2020-03-21 13:14:52,740 INFO org.apache.hadoop.yarn.server.resourcemanager.scheduler.capacity.CapacityScheduler: Application Attempt appattempt_1584766611743_0001_000001 is done. finalState=FAILED
2020-03-21 13:14:52,740 INFO org.apache.hadoop.yarn.server.resourcemanager.rmapp.attempt.RMAppAttemptImpl: appattempt_1584766611743_0001_000002 State change from NEW to SUBMITTED
2020-03-21 13:14:52,740 INFO org.apache.hadoop.yarn.server.resourcemanager.scheduler.AppSchedulingInfo: Application application_1584766611743_0001 requests cleared
2020-03-21 13:14:52,741 INFO org.apache.hadoop.yarn.server.resourcemanager.scheduler.capacity.LeafQueue: Application removed - appId: application_1584766611743_0001 user: xidian queue: default #user-pending-applications: 0 #user-active-applications: 0 #queue-pending-applications: 0 #queue-active-applications: 0
2020-03-21 13:14:52,741 WARN org.apache.hadoop.yarn.server.resourcemanager.scheduler.capacity.LeafQueue: maximum-am-resource-percent is insufficient to start a single application in queue, it is likely set too low. skipping enforcement to allow at least one application to start
2020-03-21 13:14:52,741 WARN org.apache.hadoop.yarn.server.resourcemanager.scheduler.capacity.LeafQueue: maximum-am-resource-percent is insufficient to start a single application in queue for user, it is likely set too low. skipping enforcement to allow at least one application to start
2020-03-21 13:14:52,741 INFO org.apache.hadoop.yarn.server.resourcemanager.scheduler.capacity.LeafQueue: Application application_1584766611743_0001 from user: xidian activated in queue: default
2020-03-21 13:14:52,741 INFO org.apache.hadoop.yarn.server.resourcemanager.scheduler.capacity.LeafQueue: Application added - appId: application_1584766611743_0001 user: org.apache.hadoop.yarn.server.resourcemanager.scheduler.capacity.LeafQueue$User@7d94b761, leaf-queue: default #user-pending-applications: 0 #user-active-applications: 1 #queue-pending-applications: 0 #queue-active-applications: 1
2020-03-21 13:14:52,741 INFO org.apache.hadoop.yarn.server.resourcemanager.scheduler.capacity.CapacityScheduler: Added Application Attempt appattempt_1584766611743_0001_000002 to scheduler from user xidian in queue default
2020-03-21 13:14:52,741 INFO org.apache.hadoop.yarn.server.resourcemanager.rmapp.attempt.RMAppAttemptImpl: appattempt_1584766611743_0001_000002 State change from SUBMITTED to SCHEDULED
2020-03-21 13:14:53,737 INFO org.apache.hadoop.yarn.server.resourcemanager.rmcontainer.RMContainerImpl: container_1584766611743_0001_02_000001 Container Transitioned from NEW to ALLOCATED
2020-03-21 13:14:53,737 INFO org.apache.hadoop.yarn.server.resourcemanager.RMAuditLogger: USER=xidian	OPERATION=AM Allocated Container	TARGET=SchedulerApp	RESULT=SUCCESS	APPID=application_1584766611743_0001	CONTAINERID=container_1584766611743_0001_02_000001
2020-03-21 13:14:53,738 INFO org.apache.hadoop.yarn.server.resourcemanager.scheduler.SchedulerNode: Assigned container container_1584766611743_0001_02_000001 of capacity <memory:2048, vCores:1> on host dell:34479, which has 1 containers, <memory:2048, vCores:1> used and <memory:6144, vCores:7> available after allocation
2020-03-21 13:14:53,738 INFO org.apache.hadoop.yarn.server.resourcemanager.scheduler.capacity.LeafQueue: assignedContainer application attempt=appattempt_1584766611743_0001_000002 container=Container: [ContainerId: container_1584766611743_0001_02_000001, NodeId: dell:34479, NodeHttpAddress: dell:8042, Resource: <memory:2048, vCores:1>, Priority: 0, Token: null, ] queue=default: capacity=1.0, absoluteCapacity=1.0, usedResources=<memory:0, vCores:0>, usedCapacity=0.0, absoluteUsedCapacity=0.0, numApps=1, numContainers=0 clusterResource=<memory:8192, vCores:8> type=OFF_SWITCH requestedPartition=
2020-03-21 13:14:53,738 INFO org.apache.hadoop.yarn.server.resourcemanager.scheduler.capacity.ParentQueue: Re-sorting assigned queue: root.default stats: default: capacity=1.0, absoluteCapacity=1.0, usedResources=<memory:2048, vCores:1>, usedCapacity=0.25, absoluteUsedCapacity=0.25, numApps=1, numContainers=1
2020-03-21 13:14:53,738 INFO org.apache.hadoop.yarn.server.resourcemanager.scheduler.capacity.ParentQueue: assignedContainer queue=root usedCapacity=0.25 absoluteUsedCapacity=0.25 used=<memory:2048, vCores:1> cluster=<memory:8192, vCores:8>
2020-03-21 13:14:53,740 INFO org.apache.hadoop.yarn.server.resourcemanager.security.NMTokenSecretManagerInRM: Sending NMToken for nodeId : dell:34479 for container : container_1584766611743_0001_02_000001
2020-03-21 13:14:53,743 INFO org.apache.hadoop.yarn.server.resourcemanager.rmcontainer.RMContainerImpl: container_1584766611743_0001_02_000001 Container Transitioned from ALLOCATED to ACQUIRED
2020-03-21 13:14:53,744 INFO org.apache.hadoop.yarn.server.resourcemanager.security.NMTokenSecretManagerInRM: Clear node set for appattempt_1584766611743_0001_000002
2020-03-21 13:14:53,744 INFO org.apache.hadoop.yarn.server.resourcemanager.rmapp.attempt.RMAppAttemptImpl: Storing attempt: AppId: application_1584766611743_0001 AttemptId: appattempt_1584766611743_0001_000002 MasterContainer: Container: [ContainerId: container_1584766611743_0001_02_000001, NodeId: dell:34479, NodeHttpAddress: dell:8042, Resource: <memory:2048, vCores:1>, Priority: 0, Token: Token { kind: ContainerToken, service: 127.0.1.1:34479 }, ]
2020-03-21 13:14:53,744 INFO org.apache.hadoop.yarn.server.resourcemanager.rmapp.attempt.RMAppAttemptImpl: appattempt_1584766611743_0001_000002 State change from SCHEDULED to ALLOCATED_SAVING
2020-03-21 13:14:53,744 INFO org.apache.hadoop.yarn.server.resourcemanager.rmapp.attempt.RMAppAttemptImpl: appattempt_1584766611743_0001_000002 State change from ALLOCATED_SAVING to ALLOCATED
2020-03-21 13:14:53,746 INFO org.apache.hadoop.yarn.server.resourcemanager.amlauncher.AMLauncher: Launching masterappattempt_1584766611743_0001_000002
2020-03-21 13:14:53,750 INFO org.apache.hadoop.yarn.server.resourcemanager.amlauncher.AMLauncher: Setting up container Container: [ContainerId: container_1584766611743_0001_02_000001, NodeId: dell:34479, NodeHttpAddress: dell:8042, Resource: <memory:2048, vCores:1>, Priority: 0, Token: Token { kind: ContainerToken, service: 127.0.1.1:34479 }, ] for AM appattempt_1584766611743_0001_000002
2020-03-21 13:14:53,751 INFO org.apache.hadoop.yarn.server.resourcemanager.amlauncher.AMLauncher: Command to launch container container_1584766611743_0001_02_000001 : $JAVA_HOME/bin/java -Djava.io.tmpdir=$PWD/tmp -Dlog4j.configuration=container-log4j.properties -Dyarn.app.container.log.dir=<LOG_DIR> -Dyarn.app.container.log.filesize=0 -Dhadoop.root.logger=INFO,CLA -Dhadoop.root.logfile=syslog  -Xmx1024m org.apache.hadoop.mapreduce.v2.app.MRAppMaster 1><LOG_DIR>/stdout 2><LOG_DIR>/stderr 
2020-03-21 13:14:53,751 INFO org.apache.hadoop.yarn.server.resourcemanager.security.AMRMTokenSecretManager: Create AMRMToken for ApplicationAttempt: appattempt_1584766611743_0001_000002
2020-03-21 13:14:53,751 INFO org.apache.hadoop.yarn.server.resourcemanager.security.AMRMTokenSecretManager: Creating password for appattempt_1584766611743_0001_000002
2020-03-21 13:14:53,759 INFO org.apache.hadoop.yarn.server.resourcemanager.amlauncher.AMLauncher: Done launching container Container: [ContainerId: container_1584766611743_0001_02_000001, NodeId: dell:34479, NodeHttpAddress: dell:8042, Resource: <memory:2048, vCores:1>, Priority: 0, Token: Token { kind: ContainerToken, service: 127.0.1.1:34479 }, ] for AM appattempt_1584766611743_0001_000002
2020-03-21 13:14:53,759 INFO org.apache.hadoop.yarn.server.resourcemanager.rmapp.attempt.RMAppAttemptImpl: appattempt_1584766611743_0001_000002 State change from ALLOCATED to LAUNCHED
2020-03-21 13:14:54,741 INFO org.apache.hadoop.yarn.server.resourcemanager.rmcontainer.RMContainerImpl: container_1584766611743_0001_02_000001 Container Transitioned from ACQUIRED to RUNNING
2020-03-21 13:14:55,894 INFO org.apache.hadoop.yarn.server.resourcemanager.rmcontainer.RMContainerImpl: container_1584766611743_0001_02_000001 Container Transitioned from RUNNING to COMPLETED
2020-03-21 13:14:55,894 INFO org.apache.hadoop.yarn.server.resourcemanager.scheduler.common.fica.FiCaSchedulerApp: Completed container: container_1584766611743_0001_02_000001 in state: COMPLETED event:FINISHED
2020-03-21 13:14:55,894 INFO org.apache.hadoop.yarn.server.resourcemanager.RMAuditLogger: USER=xidian	OPERATION=AM Released Container	TARGET=SchedulerApp	RESULT=SUCCESS	APPID=application_1584766611743_0001	CONTAINERID=container_1584766611743_0001_02_000001
2020-03-21 13:14:55,894 INFO org.apache.hadoop.yarn.server.resourcemanager.scheduler.SchedulerNode: Released container container_1584766611743_0001_02_000001 of capacity <memory:2048, vCores:1> on host dell:34479, which currently has 0 containers, <memory:0, vCores:0> used and <memory:8192, vCores:8> available, release resources=true
2020-03-21 13:14:55,894 INFO org.apache.hadoop.yarn.server.resourcemanager.rmapp.attempt.RMAppAttemptImpl: Updating application attempt appattempt_1584766611743_0001_000002 with final state: FAILED, and exit status: -1
2020-03-21 13:14:55,894 INFO org.apache.hadoop.yarn.server.resourcemanager.scheduler.capacity.LeafQueue: default used=<memory:0, vCores:0> numContainers=0 user=xidian user-resources=<memory:0, vCores:0>
2020-03-21 13:14:55,894 INFO org.apache.hadoop.yarn.server.resourcemanager.rmapp.attempt.RMAppAttemptImpl: appattempt_1584766611743_0001_000002 State change from LAUNCHED to FINAL_SAVING
2020-03-21 13:14:55,894 INFO org.apache.hadoop.yarn.server.resourcemanager.scheduler.capacity.LeafQueue: completedContainer container=Container: [ContainerId: container_1584766611743_0001_02_000001, NodeId: dell:34479, NodeHttpAddress: dell:8042, Resource: <memory:2048, vCores:1>, Priority: 0, Token: Token { kind: ContainerToken, service: 127.0.1.1:34479 }, ] queue=default: capacity=1.0, absoluteCapacity=1.0, usedResources=<memory:0, vCores:0>, usedCapacity=0.0, absoluteUsedCapacity=0.0, numApps=1, numContainers=0 cluster=<memory:8192, vCores:8>
2020-03-21 13:14:55,894 INFO org.apache.hadoop.yarn.server.resourcemanager.ApplicationMasterService: Unregistering app attempt : appattempt_1584766611743_0001_000002
2020-03-21 13:14:55,894 INFO org.apache.hadoop.yarn.server.resourcemanager.scheduler.capacity.ParentQueue: completedContainer queue=root usedCapacity=0.0 absoluteUsedCapacity=0.0 used=<memory:0, vCores:0> cluster=<memory:8192, vCores:8>
2020-03-21 13:14:55,895 INFO org.apache.hadoop.yarn.server.resourcemanager.security.AMRMTokenSecretManager: Application finished, removing password for appattempt_1584766611743_0001_000002
2020-03-21 13:14:55,895 INFO org.apache.hadoop.yarn.server.resourcemanager.scheduler.capacity.ParentQueue: Re-sorting completed queue: root.default stats: default: capacity=1.0, absoluteCapacity=1.0, usedResources=<memory:0, vCores:0>, usedCapacity=0.0, absoluteUsedCapacity=0.0, numApps=1, numContainers=0
2020-03-21 13:14:55,895 INFO org.apache.hadoop.yarn.server.resourcemanager.rmapp.attempt.RMAppAttemptImpl: appattempt_1584766611743_0001_000002 State change from FINAL_SAVING to FAILED
2020-03-21 13:14:55,895 INFO org.apache.hadoop.yarn.server.resourcemanager.scheduler.capacity.CapacityScheduler: Application attempt appattempt_1584766611743_0001_000002 released container container_1584766611743_0001_02_000001 on node: host: dell:34479 #containers=0 available=<memory:8192, vCores:8> used=<memory:0, vCores:0> with event: FINISHED
2020-03-21 13:14:55,895 INFO org.apache.hadoop.yarn.server.resourcemanager.rmapp.RMAppImpl: The number of failed attempts is 2. The max attempts is 2
2020-03-21 13:14:55,895 INFO org.apache.hadoop.yarn.server.resourcemanager.rmapp.RMAppImpl: Updating application application_1584766611743_0001 with final state: FAILED
2020-03-21 13:14:55,896 INFO org.apache.hadoop.yarn.server.resourcemanager.rmapp.RMAppImpl: application_1584766611743_0001 State change from ACCEPTED to FINAL_SAVING on event=ATTEMPT_FAILED
2020-03-21 13:14:55,896 INFO org.apache.hadoop.yarn.server.resourcemanager.recovery.RMStateStore: Updating info for app: application_1584766611743_0001
2020-03-21 13:14:55,896 INFO org.apache.hadoop.yarn.server.resourcemanager.scheduler.capacity.CapacityScheduler: Application Attempt appattempt_1584766611743_0001_000002 is done. finalState=FAILED
2020-03-21 13:14:55,896 INFO org.apache.hadoop.yarn.server.resourcemanager.rmapp.RMAppImpl: Application application_1584766611743_0001 failed 2 times due to AM Container for appattempt_1584766611743_0001_000002 exited with  exitCode: -1
For more detailed output, check application tracking page:http://dell:8088/cluster/app/application_1584766611743_0001Then, click on links to logs of each attempt.
Diagnostics: Container image must not be null
Failing this attempt. Failing the application.
2020-03-21 13:14:55,896 INFO org.apache.hadoop.yarn.server.resourcemanager.scheduler.AppSchedulingInfo: Application application_1584766611743_0001 requests cleared
2020-03-21 13:14:55,896 INFO org.apache.hadoop.yarn.server.resourcemanager.scheduler.capacity.LeafQueue: Application removed - appId: application_1584766611743_0001 user: xidian queue: default #user-pending-applications: 0 #user-active-applications: 0 #queue-pending-applications: 0 #queue-active-applications: 0
2020-03-21 13:14:55,896 INFO org.apache.hadoop.yarn.server.resourcemanager.rmapp.RMAppImpl: application_1584766611743_0001 State change from FINAL_SAVING to FAILED on event=APP_UPDATE_SAVED
2020-03-21 13:14:55,897 INFO org.apache.hadoop.yarn.server.resourcemanager.scheduler.capacity.ParentQueue: Application removed - appId: application_1584766611743_0001 user: xidian leaf-queue of parent: root #applications: 0
2020-03-21 13:14:55,897 WARN org.apache.hadoop.yarn.server.resourcemanager.RMAuditLogger: USER=xidian	OPERATION=Application Finished - Failed	TARGET=RMAppManager	RESULT=FAILURE	DESCRIPTION=App failed with state: FAILED	PERMISSIONS=Application application_1584766611743_0001 failed 2 times due to AM Container for appattempt_1584766611743_0001_000002 exited with  exitCode: -1
For more detailed output, check application tracking page:http://dell:8088/cluster/app/application_1584766611743_0001Then, click on links to logs of each attempt.
Diagnostics: Container image must not be null
Failing this attempt. Failing the application.	APPID=application_1584766611743_0001
2020-03-21 13:14:55,898 INFO org.apache.hadoop.yarn.server.resourcemanager.RMAppManager$ApplicationSummary: appId=application_1584766611743_0001,name=word count,user=xidian,queue=default,state=FAILED,trackingUrl=http://dell:8088/cluster/app/application_1584766611743_0001,appMasterHost=N/A,startTime=1584767689169,finishTime=1584767695895,finalStatus=FAILED,memorySeconds=10552,vcoreSeconds=4,preemptedAMContainers=0,preemptedNonAMContainers=0,preemptedResources=<memory:0\, vCores:0>,applicationType=MAPREDUCE
2020-03-21 13:17:42,568 INFO org.apache.hadoop.yarn.server.resourcemanager.ClientRMService: Allocated new applicationId: 2
2020-03-21 13:17:43,355 INFO org.apache.hadoop.yarn.server.resourcemanager.ClientRMService: Application with id 2 submitted by user xidian
2020-03-21 13:17:43,355 INFO org.apache.hadoop.yarn.server.resourcemanager.rmapp.RMAppImpl: Storing application with id application_1584766611743_0002
2020-03-21 13:17:43,355 INFO org.apache.hadoop.yarn.server.resourcemanager.rmapp.RMAppImpl: application_1584766611743_0002 State change from NEW to NEW_SAVING on event=START
2020-03-21 13:17:43,355 INFO org.apache.hadoop.yarn.server.resourcemanager.recovery.RMStateStore: Storing info for app: application_1584766611743_0002
2020-03-21 13:17:43,355 INFO org.apache.hadoop.yarn.server.resourcemanager.RMAuditLogger: USER=xidian	IP=127.0.0.1	OPERATION=Submit Application Request	TARGET=ClientRMService	RESULT=SUCCESS	APPID=application_1584766611743_0002
2020-03-21 13:17:43,355 INFO org.apache.hadoop.yarn.server.resourcemanager.rmapp.RMAppImpl: application_1584766611743_0002 State change from NEW_SAVING to SUBMITTED on event=APP_NEW_SAVED
2020-03-21 13:17:43,356 INFO org.apache.hadoop.yarn.server.resourcemanager.scheduler.capacity.ParentQueue: Application added - appId: application_1584766611743_0002 user: xidian leaf-queue of parent: root #applications: 1
2020-03-21 13:17:43,356 INFO org.apache.hadoop.yarn.server.resourcemanager.scheduler.capacity.CapacityScheduler: Accepted application application_1584766611743_0002 from user: xidian, in queue: default
2020-03-21 13:17:43,356 INFO org.apache.hadoop.yarn.server.resourcemanager.rmapp.RMAppImpl: application_1584766611743_0002 State change from SUBMITTED to ACCEPTED on event=APP_ACCEPTED
2020-03-21 13:17:43,356 INFO org.apache.hadoop.yarn.server.resourcemanager.ApplicationMasterService: Registering app attempt : appattempt_1584766611743_0002_000001
2020-03-21 13:17:43,356 INFO org.apache.hadoop.yarn.server.resourcemanager.rmapp.attempt.RMAppAttemptImpl: appattempt_1584766611743_0002_000001 State change from NEW to SUBMITTED
2020-03-21 13:17:43,356 WARN org.apache.hadoop.yarn.server.resourcemanager.scheduler.capacity.LeafQueue: maximum-am-resource-percent is insufficient to start a single application in queue, it is likely set too low. skipping enforcement to allow at least one application to start
2020-03-21 13:17:43,356 WARN org.apache.hadoop.yarn.server.resourcemanager.scheduler.capacity.LeafQueue: maximum-am-resource-percent is insufficient to start a single application in queue for user, it is likely set too low. skipping enforcement to allow at least one application to start
2020-03-21 13:17:43,356 INFO org.apache.hadoop.yarn.server.resourcemanager.scheduler.capacity.LeafQueue: Application application_1584766611743_0002 from user: xidian activated in queue: default
2020-03-21 13:17:43,356 INFO org.apache.hadoop.yarn.server.resourcemanager.scheduler.capacity.LeafQueue: Application added - appId: application_1584766611743_0002 user: org.apache.hadoop.yarn.server.resourcemanager.scheduler.capacity.LeafQueue$User@71de54b8, leaf-queue: default #user-pending-applications: 0 #user-active-applications: 1 #queue-pending-applications: 0 #queue-active-applications: 1
2020-03-21 13:17:43,356 INFO org.apache.hadoop.yarn.server.resourcemanager.scheduler.capacity.CapacityScheduler: Added Application Attempt appattempt_1584766611743_0002_000001 to scheduler from user xidian in queue default
2020-03-21 13:17:43,357 INFO org.apache.hadoop.yarn.server.resourcemanager.rmapp.attempt.RMAppAttemptImpl: appattempt_1584766611743_0002_000001 State change from SUBMITTED to SCHEDULED
2020-03-21 13:17:44,119 INFO org.apache.hadoop.yarn.server.resourcemanager.rmcontainer.RMContainerImpl: container_1584766611743_0002_01_000001 Container Transitioned from NEW to ALLOCATED
2020-03-21 13:17:44,119 INFO org.apache.hadoop.yarn.server.resourcemanager.RMAuditLogger: USER=xidian	OPERATION=AM Allocated Container	TARGET=SchedulerApp	RESULT=SUCCESS	APPID=application_1584766611743_0002	CONTAINERID=container_1584766611743_0002_01_000001
2020-03-21 13:17:44,119 INFO org.apache.hadoop.yarn.server.resourcemanager.scheduler.SchedulerNode: Assigned container container_1584766611743_0002_01_000001 of capacity <memory:2048, vCores:1> on host dell:34479, which has 1 containers, <memory:2048, vCores:1> used and <memory:6144, vCores:7> available after allocation
2020-03-21 13:17:44,120 INFO org.apache.hadoop.yarn.server.resourcemanager.scheduler.capacity.LeafQueue: assignedContainer application attempt=appattempt_1584766611743_0002_000001 container=Container: [ContainerId: container_1584766611743_0002_01_000001, NodeId: dell:34479, NodeHttpAddress: dell:8042, Resource: <memory:2048, vCores:1>, Priority: 0, Token: null, ] queue=default: capacity=1.0, absoluteCapacity=1.0, usedResources=<memory:0, vCores:0>, usedCapacity=0.0, absoluteUsedCapacity=0.0, numApps=1, numContainers=0 clusterResource=<memory:8192, vCores:8> type=OFF_SWITCH requestedPartition=
2020-03-21 13:17:44,120 INFO org.apache.hadoop.yarn.server.resourcemanager.scheduler.capacity.ParentQueue: Re-sorting assigned queue: root.default stats: default: capacity=1.0, absoluteCapacity=1.0, usedResources=<memory:2048, vCores:1>, usedCapacity=0.25, absoluteUsedCapacity=0.25, numApps=1, numContainers=1
2020-03-21 13:17:44,120 INFO org.apache.hadoop.yarn.server.resourcemanager.scheduler.capacity.ParentQueue: assignedContainer queue=root usedCapacity=0.25 absoluteUsedCapacity=0.25 used=<memory:2048, vCores:1> cluster=<memory:8192, vCores:8>
2020-03-21 13:17:44,121 INFO org.apache.hadoop.yarn.server.resourcemanager.security.NMTokenSecretManagerInRM: Sending NMToken for nodeId : dell:34479 for container : container_1584766611743_0002_01_000001
2020-03-21 13:17:44,127 INFO org.apache.hadoop.yarn.server.resourcemanager.rmcontainer.RMContainerImpl: container_1584766611743_0002_01_000001 Container Transitioned from ALLOCATED to ACQUIRED
2020-03-21 13:17:44,127 INFO org.apache.hadoop.yarn.server.resourcemanager.security.NMTokenSecretManagerInRM: Clear node set for appattempt_1584766611743_0002_000001
2020-03-21 13:17:44,128 INFO org.apache.hadoop.yarn.server.resourcemanager.rmapp.attempt.RMAppAttemptImpl: Storing attempt: AppId: application_1584766611743_0002 AttemptId: appattempt_1584766611743_0002_000001 MasterContainer: Container: [ContainerId: container_1584766611743_0002_01_000001, NodeId: dell:34479, NodeHttpAddress: dell:8042, Resource: <memory:2048, vCores:1>, Priority: 0, Token: Token { kind: ContainerToken, service: 127.0.1.1:34479 }, ]
2020-03-21 13:17:44,128 INFO org.apache.hadoop.yarn.server.resourcemanager.rmapp.attempt.RMAppAttemptImpl: appattempt_1584766611743_0002_000001 State change from SCHEDULED to ALLOCATED_SAVING
2020-03-21 13:17:44,128 INFO org.apache.hadoop.yarn.server.resourcemanager.rmapp.attempt.RMAppAttemptImpl: appattempt_1584766611743_0002_000001 State change from ALLOCATED_SAVING to ALLOCATED
2020-03-21 13:17:44,129 INFO org.apache.hadoop.yarn.server.resourcemanager.amlauncher.AMLauncher: Launching masterappattempt_1584766611743_0002_000001
2020-03-21 13:17:44,133 INFO org.apache.hadoop.yarn.server.resourcemanager.amlauncher.AMLauncher: Setting up container Container: [ContainerId: container_1584766611743_0002_01_000001, NodeId: dell:34479, NodeHttpAddress: dell:8042, Resource: <memory:2048, vCores:1>, Priority: 0, Token: Token { kind: ContainerToken, service: 127.0.1.1:34479 }, ] for AM appattempt_1584766611743_0002_000001
2020-03-21 13:17:44,133 INFO org.apache.hadoop.yarn.server.resourcemanager.amlauncher.AMLauncher: Command to launch container container_1584766611743_0002_01_000001 : $JAVA_HOME/bin/java -Djava.io.tmpdir=$PWD/tmp -Dlog4j.configuration=container-log4j.properties -Dyarn.app.container.log.dir=<LOG_DIR> -Dyarn.app.container.log.filesize=0 -Dhadoop.root.logger=INFO,CLA -Dhadoop.root.logfile=syslog  -Xmx1024m org.apache.hadoop.mapreduce.v2.app.MRAppMaster 1><LOG_DIR>/stdout 2><LOG_DIR>/stderr 
2020-03-21 13:17:44,134 INFO org.apache.hadoop.yarn.server.resourcemanager.security.AMRMTokenSecretManager: Create AMRMToken for ApplicationAttempt: appattempt_1584766611743_0002_000001
2020-03-21 13:17:44,134 INFO org.apache.hadoop.yarn.server.resourcemanager.security.AMRMTokenSecretManager: Creating password for appattempt_1584766611743_0002_000001
2020-03-21 13:17:44,144 INFO org.apache.hadoop.yarn.server.resourcemanager.amlauncher.AMLauncher: Done launching container Container: [ContainerId: container_1584766611743_0002_01_000001, NodeId: dell:34479, NodeHttpAddress: dell:8042, Resource: <memory:2048, vCores:1>, Priority: 0, Token: Token { kind: ContainerToken, service: 127.0.1.1:34479 }, ] for AM appattempt_1584766611743_0002_000001
2020-03-21 13:17:44,144 INFO org.apache.hadoop.yarn.server.resourcemanager.rmapp.attempt.RMAppAttemptImpl: appattempt_1584766611743_0002_000001 State change from ALLOCATED to LAUNCHED
2020-03-21 13:17:45,120 INFO org.apache.hadoop.yarn.server.resourcemanager.rmcontainer.RMContainerImpl: container_1584766611743_0002_01_000001 Container Transitioned from ACQUIRED to RUNNING
2020-03-21 13:17:46,406 INFO org.apache.hadoop.yarn.server.resourcemanager.rmcontainer.RMContainerImpl: container_1584766611743_0002_01_000001 Container Transitioned from RUNNING to COMPLETED
2020-03-21 13:17:46,406 INFO org.apache.hadoop.yarn.server.resourcemanager.scheduler.common.fica.FiCaSchedulerApp: Completed container: container_1584766611743_0002_01_000001 in state: COMPLETED event:FINISHED
2020-03-21 13:17:46,406 INFO org.apache.hadoop.yarn.server.resourcemanager.RMAuditLogger: USER=xidian	OPERATION=AM Released Container	TARGET=SchedulerApp	RESULT=SUCCESS	APPID=application_1584766611743_0002	CONTAINERID=container_1584766611743_0002_01_000001
2020-03-21 13:17:46,406 INFO org.apache.hadoop.yarn.server.resourcemanager.scheduler.SchedulerNode: Released container container_1584766611743_0002_01_000001 of capacity <memory:2048, vCores:1> on host dell:34479, which currently has 0 containers, <memory:0, vCores:0> used and <memory:8192, vCores:8> available, release resources=true
2020-03-21 13:17:46,406 INFO org.apache.hadoop.yarn.server.resourcemanager.rmapp.attempt.RMAppAttemptImpl: Updating application attempt appattempt_1584766611743_0002_000001 with final state: FAILED, and exit status: 126
2020-03-21 13:17:46,406 INFO org.apache.hadoop.yarn.server.resourcemanager.rmapp.attempt.RMAppAttemptImpl: appattempt_1584766611743_0002_000001 State change from LAUNCHED to FINAL_SAVING
2020-03-21 13:17:46,406 INFO org.apache.hadoop.yarn.server.resourcemanager.scheduler.capacity.LeafQueue: default used=<memory:0, vCores:0> numContainers=0 user=xidian user-resources=<memory:0, vCores:0>
2020-03-21 13:17:46,406 INFO org.apache.hadoop.yarn.server.resourcemanager.ApplicationMasterService: Unregistering app attempt : appattempt_1584766611743_0002_000001
2020-03-21 13:17:46,406 INFO org.apache.hadoop.yarn.server.resourcemanager.security.AMRMTokenSecretManager: Application finished, removing password for appattempt_1584766611743_0002_000001
2020-03-21 13:17:46,406 INFO org.apache.hadoop.yarn.server.resourcemanager.scheduler.capacity.LeafQueue: completedContainer container=Container: [ContainerId: container_1584766611743_0002_01_000001, NodeId: dell:34479, NodeHttpAddress: dell:8042, Resource: <memory:2048, vCores:1>, Priority: 0, Token: Token { kind: ContainerToken, service: 127.0.1.1:34479 }, ] queue=default: capacity=1.0, absoluteCapacity=1.0, usedResources=<memory:0, vCores:0>, usedCapacity=0.0, absoluteUsedCapacity=0.0, numApps=1, numContainers=0 cluster=<memory:8192, vCores:8>
2020-03-21 13:17:46,406 INFO org.apache.hadoop.yarn.server.resourcemanager.scheduler.capacity.ParentQueue: completedContainer queue=root usedCapacity=0.0 absoluteUsedCapacity=0.0 used=<memory:0, vCores:0> cluster=<memory:8192, vCores:8>
2020-03-21 13:17:46,406 INFO org.apache.hadoop.yarn.server.resourcemanager.rmapp.attempt.RMAppAttemptImpl: appattempt_1584766611743_0002_000001 State change from FINAL_SAVING to FAILED
2020-03-21 13:17:46,407 INFO org.apache.hadoop.yarn.server.resourcemanager.rmapp.RMAppImpl: The number of failed attempts is 1. The max attempts is 2
2020-03-21 13:17:46,407 INFO org.apache.hadoop.yarn.server.resourcemanager.scheduler.capacity.ParentQueue: Re-sorting completed queue: root.default stats: default: capacity=1.0, absoluteCapacity=1.0, usedResources=<memory:0, vCores:0>, usedCapacity=0.0, absoluteUsedCapacity=0.0, numApps=1, numContainers=0
2020-03-21 13:17:46,407 INFO org.apache.hadoop.yarn.server.resourcemanager.scheduler.capacity.CapacityScheduler: Application attempt appattempt_1584766611743_0002_000001 released container container_1584766611743_0002_01_000001 on node: host: dell:34479 #containers=0 available=<memory:8192, vCores:8> used=<memory:0, vCores:0> with event: FINISHED
2020-03-21 13:17:46,407 INFO org.apache.hadoop.yarn.server.resourcemanager.ApplicationMasterService: Registering app attempt : appattempt_1584766611743_0002_000002
2020-03-21 13:17:46,407 INFO org.apache.hadoop.yarn.server.resourcemanager.rmapp.attempt.RMAppAttemptImpl: appattempt_1584766611743_0002_000002 State change from NEW to SUBMITTED
2020-03-21 13:17:46,407 INFO org.apache.hadoop.yarn.server.resourcemanager.scheduler.capacity.CapacityScheduler: Application Attempt appattempt_1584766611743_0002_000001 is done. finalState=FAILED
2020-03-21 13:17:46,407 INFO org.apache.hadoop.yarn.server.resourcemanager.scheduler.AppSchedulingInfo: Application application_1584766611743_0002 requests cleared
2020-03-21 13:17:46,407 INFO org.apache.hadoop.yarn.server.resourcemanager.scheduler.capacity.LeafQueue: Application removed - appId: application_1584766611743_0002 user: xidian queue: default #user-pending-applications: 0 #user-active-applications: 0 #queue-pending-applications: 0 #queue-active-applications: 0
2020-03-21 13:17:46,407 WARN org.apache.hadoop.yarn.server.resourcemanager.scheduler.capacity.LeafQueue: maximum-am-resource-percent is insufficient to start a single application in queue, it is likely set too low. skipping enforcement to allow at least one application to start
2020-03-21 13:17:46,407 WARN org.apache.hadoop.yarn.server.resourcemanager.scheduler.capacity.LeafQueue: maximum-am-resource-percent is insufficient to start a single application in queue for user, it is likely set too low. skipping enforcement to allow at least one application to start
2020-03-21 13:17:46,407 INFO org.apache.hadoop.yarn.server.resourcemanager.scheduler.capacity.LeafQueue: Application application_1584766611743_0002 from user: xidian activated in queue: default
2020-03-21 13:17:46,407 INFO org.apache.hadoop.yarn.server.resourcemanager.scheduler.capacity.LeafQueue: Application added - appId: application_1584766611743_0002 user: org.apache.hadoop.yarn.server.resourcemanager.scheduler.capacity.LeafQueue$User@2929ca5d, leaf-queue: default #user-pending-applications: 0 #user-active-applications: 1 #queue-pending-applications: 0 #queue-active-applications: 1
2020-03-21 13:17:46,407 INFO org.apache.hadoop.yarn.server.resourcemanager.scheduler.capacity.CapacityScheduler: Added Application Attempt appattempt_1584766611743_0002_000002 to scheduler from user xidian in queue default
2020-03-21 13:17:46,408 INFO org.apache.hadoop.yarn.server.resourcemanager.rmapp.attempt.RMAppAttemptImpl: appattempt_1584766611743_0002_000002 State change from SUBMITTED to SCHEDULED
2020-03-21 13:17:47,408 INFO org.apache.hadoop.yarn.server.resourcemanager.rmcontainer.RMContainerImpl: container_1584766611743_0002_02_000001 Container Transitioned from NEW to ALLOCATED
2020-03-21 13:17:47,408 INFO org.apache.hadoop.yarn.server.resourcemanager.RMAuditLogger: USER=xidian	OPERATION=AM Allocated Container	TARGET=SchedulerApp	RESULT=SUCCESS	APPID=application_1584766611743_0002	CONTAINERID=container_1584766611743_0002_02_000001
2020-03-21 13:17:47,408 INFO org.apache.hadoop.yarn.server.resourcemanager.scheduler.SchedulerNode: Assigned container container_1584766611743_0002_02_000001 of capacity <memory:2048, vCores:1> on host dell:34479, which has 1 containers, <memory:2048, vCores:1> used and <memory:6144, vCores:7> available after allocation
2020-03-21 13:17:47,408 INFO org.apache.hadoop.yarn.server.resourcemanager.scheduler.capacity.LeafQueue: assignedContainer application attempt=appattempt_1584766611743_0002_000002 container=Container: [ContainerId: container_1584766611743_0002_02_000001, NodeId: dell:34479, NodeHttpAddress: dell:8042, Resource: <memory:2048, vCores:1>, Priority: 0, Token: null, ] queue=default: capacity=1.0, absoluteCapacity=1.0, usedResources=<memory:0, vCores:0>, usedCapacity=0.0, absoluteUsedCapacity=0.0, numApps=1, numContainers=0 clusterResource=<memory:8192, vCores:8> type=OFF_SWITCH requestedPartition=
2020-03-21 13:17:47,409 INFO org.apache.hadoop.yarn.server.resourcemanager.scheduler.capacity.ParentQueue: Re-sorting assigned queue: root.default stats: default: capacity=1.0, absoluteCapacity=1.0, usedResources=<memory:2048, vCores:1>, usedCapacity=0.25, absoluteUsedCapacity=0.25, numApps=1, numContainers=1
2020-03-21 13:17:47,409 INFO org.apache.hadoop.yarn.server.resourcemanager.scheduler.capacity.ParentQueue: assignedContainer queue=root usedCapacity=0.25 absoluteUsedCapacity=0.25 used=<memory:2048, vCores:1> cluster=<memory:8192, vCores:8>
2020-03-21 13:17:47,411 INFO org.apache.hadoop.yarn.server.resourcemanager.security.NMTokenSecretManagerInRM: Sending NMToken for nodeId : dell:34479 for container : container_1584766611743_0002_02_000001
2020-03-21 13:17:47,413 INFO org.apache.hadoop.yarn.server.resourcemanager.rmcontainer.RMContainerImpl: container_1584766611743_0002_02_000001 Container Transitioned from ALLOCATED to ACQUIRED
2020-03-21 13:17:47,413 INFO org.apache.hadoop.yarn.server.resourcemanager.security.NMTokenSecretManagerInRM: Clear node set for appattempt_1584766611743_0002_000002
2020-03-21 13:17:47,413 INFO org.apache.hadoop.yarn.server.resourcemanager.rmapp.attempt.RMAppAttemptImpl: Storing attempt: AppId: application_1584766611743_0002 AttemptId: appattempt_1584766611743_0002_000002 MasterContainer: Container: [ContainerId: container_1584766611743_0002_02_000001, NodeId: dell:34479, NodeHttpAddress: dell:8042, Resource: <memory:2048, vCores:1>, Priority: 0, Token: Token { kind: ContainerToken, service: 127.0.1.1:34479 }, ]
2020-03-21 13:17:47,413 INFO org.apache.hadoop.yarn.server.resourcemanager.rmapp.attempt.RMAppAttemptImpl: appattempt_1584766611743_0002_000002 State change from SCHEDULED to ALLOCATED_SAVING
2020-03-21 13:17:47,413 INFO org.apache.hadoop.yarn.server.resourcemanager.rmapp.attempt.RMAppAttemptImpl: appattempt_1584766611743_0002_000002 State change from ALLOCATED_SAVING to ALLOCATED
2020-03-21 13:17:47,413 INFO org.apache.hadoop.yarn.server.resourcemanager.amlauncher.AMLauncher: Launching masterappattempt_1584766611743_0002_000002
2020-03-21 13:17:47,416 INFO org.apache.hadoop.yarn.server.resourcemanager.amlauncher.AMLauncher: Setting up container Container: [ContainerId: container_1584766611743_0002_02_000001, NodeId: dell:34479, NodeHttpAddress: dell:8042, Resource: <memory:2048, vCores:1>, Priority: 0, Token: Token { kind: ContainerToken, service: 127.0.1.1:34479 }, ] for AM appattempt_1584766611743_0002_000002
2020-03-21 13:17:47,416 INFO org.apache.hadoop.yarn.server.resourcemanager.amlauncher.AMLauncher: Command to launch container container_1584766611743_0002_02_000001 : $JAVA_HOME/bin/java -Djava.io.tmpdir=$PWD/tmp -Dlog4j.configuration=container-log4j.properties -Dyarn.app.container.log.dir=<LOG_DIR> -Dyarn.app.container.log.filesize=0 -Dhadoop.root.logger=INFO,CLA -Dhadoop.root.logfile=syslog  -Xmx1024m org.apache.hadoop.mapreduce.v2.app.MRAppMaster 1><LOG_DIR>/stdout 2><LOG_DIR>/stderr 
2020-03-21 13:17:47,416 INFO org.apache.hadoop.yarn.server.resourcemanager.security.AMRMTokenSecretManager: Create AMRMToken for ApplicationAttempt: appattempt_1584766611743_0002_000002
2020-03-21 13:17:47,416 INFO org.apache.hadoop.yarn.server.resourcemanager.security.AMRMTokenSecretManager: Creating password for appattempt_1584766611743_0002_000002
2020-03-21 13:17:47,422 INFO org.apache.hadoop.yarn.server.resourcemanager.amlauncher.AMLauncher: Done launching container Container: [ContainerId: container_1584766611743_0002_02_000001, NodeId: dell:34479, NodeHttpAddress: dell:8042, Resource: <memory:2048, vCores:1>, Priority: 0, Token: Token { kind: ContainerToken, service: 127.0.1.1:34479 }, ] for AM appattempt_1584766611743_0002_000002
2020-03-21 13:17:47,422 INFO org.apache.hadoop.yarn.server.resourcemanager.rmapp.attempt.RMAppAttemptImpl: appattempt_1584766611743_0002_000002 State change from ALLOCATED to LAUNCHED
2020-03-21 13:17:48,411 INFO org.apache.hadoop.yarn.server.resourcemanager.rmcontainer.RMContainerImpl: container_1584766611743_0002_02_000001 Container Transitioned from ACQUIRED to RUNNING
2020-03-21 13:17:49,641 INFO org.apache.hadoop.yarn.server.resourcemanager.rmcontainer.RMContainerImpl: container_1584766611743_0002_02_000001 Container Transitioned from RUNNING to COMPLETED
2020-03-21 13:17:49,642 INFO org.apache.hadoop.yarn.server.resourcemanager.scheduler.common.fica.FiCaSchedulerApp: Completed container: container_1584766611743_0002_02_000001 in state: COMPLETED event:FINISHED
2020-03-21 13:17:49,642 INFO org.apache.hadoop.yarn.server.resourcemanager.RMAuditLogger: USER=xidian	OPERATION=AM Released Container	TARGET=SchedulerApp	RESULT=SUCCESS	APPID=application_1584766611743_0002	CONTAINERID=container_1584766611743_0002_02_000001
2020-03-21 13:17:49,642 INFO org.apache.hadoop.yarn.server.resourcemanager.scheduler.SchedulerNode: Released container container_1584766611743_0002_02_000001 of capacity <memory:2048, vCores:1> on host dell:34479, which currently has 0 containers, <memory:0, vCores:0> used and <memory:8192, vCores:8> available, release resources=true
2020-03-21 13:17:49,642 INFO org.apache.hadoop.yarn.server.resourcemanager.scheduler.capacity.LeafQueue: default used=<memory:0, vCores:0> numContainers=0 user=xidian user-resources=<memory:0, vCores:0>
2020-03-21 13:17:49,642 INFO org.apache.hadoop.yarn.server.resourcemanager.rmapp.attempt.RMAppAttemptImpl: Updating application attempt appattempt_1584766611743_0002_000002 with final state: FAILED, and exit status: 126
2020-03-21 13:17:49,642 INFO org.apache.hadoop.yarn.server.resourcemanager.scheduler.capacity.LeafQueue: completedContainer container=Container: [ContainerId: container_1584766611743_0002_02_000001, NodeId: dell:34479, NodeHttpAddress: dell:8042, Resource: <memory:2048, vCores:1>, Priority: 0, Token: Token { kind: ContainerToken, service: 127.0.1.1:34479 }, ] queue=default: capacity=1.0, absoluteCapacity=1.0, usedResources=<memory:0, vCores:0>, usedCapacity=0.0, absoluteUsedCapacity=0.0, numApps=1, numContainers=0 cluster=<memory:8192, vCores:8>
2020-03-21 13:17:49,642 INFO org.apache.hadoop.yarn.server.resourcemanager.rmapp.attempt.RMAppAttemptImpl: appattempt_1584766611743_0002_000002 State change from LAUNCHED to FINAL_SAVING
2020-03-21 13:17:49,642 INFO org.apache.hadoop.yarn.server.resourcemanager.scheduler.capacity.ParentQueue: completedContainer queue=root usedCapacity=0.0 absoluteUsedCapacity=0.0 used=<memory:0, vCores:0> cluster=<memory:8192, vCores:8>
2020-03-21 13:17:49,642 INFO org.apache.hadoop.yarn.server.resourcemanager.ApplicationMasterService: Unregistering app attempt : appattempt_1584766611743_0002_000002
2020-03-21 13:17:49,642 INFO org.apache.hadoop.yarn.server.resourcemanager.security.AMRMTokenSecretManager: Application finished, removing password for appattempt_1584766611743_0002_000002
2020-03-21 13:17:49,642 INFO org.apache.hadoop.yarn.server.resourcemanager.scheduler.capacity.ParentQueue: Re-sorting completed queue: root.default stats: default: capacity=1.0, absoluteCapacity=1.0, usedResources=<memory:0, vCores:0>, usedCapacity=0.0, absoluteUsedCapacity=0.0, numApps=1, numContainers=0
2020-03-21 13:17:49,643 INFO org.apache.hadoop.yarn.server.resourcemanager.rmapp.attempt.RMAppAttemptImpl: appattempt_1584766611743_0002_000002 State change from FINAL_SAVING to FAILED
2020-03-21 13:17:49,643 INFO org.apache.hadoop.yarn.server.resourcemanager.rmapp.RMAppImpl: The number of failed attempts is 2. The max attempts is 2
2020-03-21 13:17:49,643 INFO org.apache.hadoop.yarn.server.resourcemanager.scheduler.capacity.CapacityScheduler: Application attempt appattempt_1584766611743_0002_000002 released container container_1584766611743_0002_02_000001 on node: host: dell:34479 #containers=0 available=<memory:8192, vCores:8> used=<memory:0, vCores:0> with event: FINISHED
2020-03-21 13:17:49,643 INFO org.apache.hadoop.yarn.server.resourcemanager.rmapp.RMAppImpl: Updating application application_1584766611743_0002 with final state: FAILED
2020-03-21 13:17:49,643 INFO org.apache.hadoop.yarn.server.resourcemanager.rmapp.RMAppImpl: application_1584766611743_0002 State change from ACCEPTED to FINAL_SAVING on event=ATTEMPT_FAILED
2020-03-21 13:17:49,643 INFO org.apache.hadoop.yarn.server.resourcemanager.recovery.RMStateStore: Updating info for app: application_1584766611743_0002
2020-03-21 13:17:49,643 INFO org.apache.hadoop.yarn.server.resourcemanager.scheduler.capacity.CapacityScheduler: Application Attempt appattempt_1584766611743_0002_000002 is done. finalState=FAILED
2020-03-21 13:17:49,643 INFO org.apache.hadoop.yarn.server.resourcemanager.rmapp.RMAppImpl: Application application_1584766611743_0002 failed 2 times due to AM Container for appattempt_1584766611743_0002_000002 exited with  exitCode: 126
For more detailed output, check application tracking page:http://dell:8088/cluster/app/application_1584766611743_0002Then, click on links to logs of each attempt.
Diagnostics: Exception from container-launch: 
ExitCodeException exitCode=126: Got permission denied while trying to connect to the Docker daemon socket at unix:///var/run/docker.sock: Get http://%2Fvar%2Frun%2Fdocker.sock/v1.40/containers/container_1584766611743_0002_02_000001/json: dial unix /var/run/docker.sock: connect: permission denied
/usr/bin/docker: Got permission denied while trying to connect to the Docker daemon socket at unix:///var/run/docker.sock: Post http://%2Fvar%2Frun%2Fdocker.sock/v1.40/containers/create?name=container_1584766611743_0002_02_000001: dial unix /var/run/docker.sock: connect: permission denied.
See '/usr/bin/docker run --help'.

	at org.apache.hadoop.util.Shell.runCommand(Shell.java:585)
	at org.apache.hadoop.util.Shell.run(Shell.java:482)
	at org.apache.hadoop.util.Shell$ShellCommandExecutor.execute(Shell.java:776)
	at org.apache.hadoop.yarn.server.nodemanager.DockerContainerExecutor.launchContainer(DockerContainerExecutor.java:247)
	at org.apache.hadoop.yarn.server.nodemanager.containermanager.launcher.ContainerLaunch.call(ContainerLaunch.java:302)
	at org.apache.hadoop.yarn.server.nodemanager.containermanager.launcher.ContainerLaunch.call(ContainerLaunch.java:82)
	at java.util.concurrent.FutureTask.run(FutureTask.java:266)
	at java.util.concurrent.ThreadPoolExecutor.runWorker(ThreadPoolExecutor.java:1142)
	at java.util.concurrent.ThreadPoolExecutor$Worker.run(ThreadPoolExecutor.java:617)
	at java.lang.Thread.run(Thread.java:748)


Container exited with a non-zero exit code 126
Failing this attempt. Failing the application.
2020-03-21 13:17:49,643 INFO org.apache.hadoop.yarn.server.resourcemanager.scheduler.AppSchedulingInfo: Application application_1584766611743_0002 requests cleared
2020-03-21 13:17:49,643 INFO org.apache.hadoop.yarn.server.resourcemanager.rmapp.RMAppImpl: application_1584766611743_0002 State change from FINAL_SAVING to FAILED on event=APP_UPDATE_SAVED
2020-03-21 13:17:49,644 INFO org.apache.hadoop.yarn.server.resourcemanager.scheduler.capacity.LeafQueue: Application removed - appId: application_1584766611743_0002 user: xidian queue: default #user-pending-applications: 0 #user-active-applications: 0 #queue-pending-applications: 0 #queue-active-applications: 0
2020-03-21 13:17:49,644 WARN org.apache.hadoop.yarn.server.resourcemanager.RMAuditLogger: USER=xidian	OPERATION=Application Finished - Failed	TARGET=RMAppManager	RESULT=FAILURE	DESCRIPTION=App failed with state: FAILED	PERMISSIONS=Application application_1584766611743_0002 failed 2 times due to AM Container for appattempt_1584766611743_0002_000002 exited with  exitCode: 126
For more detailed output, check application tracking page:http://dell:8088/cluster/app/application_1584766611743_0002Then, click on links to logs of each attempt.
Diagnostics: Exception from container-launch: 
ExitCodeException exitCode=126: Got permission denied while trying to connect to the Docker daemon socket at unix:///var/run/docker.sock: Get http://%2Fvar%2Frun%2Fdocker.sock/v1.40/containers/container_1584766611743_0002_02_000001/json: dial unix /var/run/docker.sock: connect: permission denied
/usr/bin/docker: Got permission denied while trying to connect to the Docker daemon socket at unix:///var/run/docker.sock: Post http://%2Fvar%2Frun%2Fdocker.sock/v1.40/containers/create?name=container_1584766611743_0002_02_000001: dial unix /var/run/docker.sock: connect: permission denied.
See '/usr/bin/docker run --help'.

	at org.apache.hadoop.util.Shell.runCommand(Shell.java:585)
	at org.apache.hadoop.util.Shell.run(Shell.java:482)
	at org.apache.hadoop.util.Shell$ShellCommandExecutor.execute(Shell.java:776)
	at org.apache.hadoop.yarn.server.nodemanager.DockerContainerExecutor.launchContainer(DockerContainerExecutor.java:247)
	at org.apache.hadoop.yarn.server.nodemanager.containermanager.launcher.ContainerLaunch.call(ContainerLaunch.java:302)
	at org.apache.hadoop.yarn.server.nodemanager.containermanager.launcher.ContainerLaunch.call(ContainerLaunch.java:82)
	at java.util.concurrent.FutureTask.run(FutureTask.java:266)
	at java.util.concurrent.ThreadPoolExecutor.runWorker(ThreadPoolExecutor.java:1142)
	at java.util.concurrent.ThreadPoolExecutor$Worker.run(ThreadPoolExecutor.java:617)
	at java.lang.Thread.run(Thread.java:748)


Container exited with a non-zero exit code 126
Failing this attempt. Failing the application.	APPID=application_1584766611743_0002
2020-03-21 13:17:49,644 INFO org.apache.hadoop.yarn.server.resourcemanager.scheduler.capacity.ParentQueue: Application removed - appId: application_1584766611743_0002 user: xidian leaf-queue of parent: root #applications: 0
2020-03-21 13:17:49,644 INFO org.apache.hadoop.yarn.server.resourcemanager.RMAppManager$ApplicationSummary: appId=application_1584766611743_0002,name=word count,user=xidian,queue=default,state=FAILED,trackingUrl=http://dell:8088/cluster/app/application_1584766611743_0002,appMasterHost=N/A,startTime=1584767863355,finishTime=1584767869643,finalStatus=FAILED,memorySeconds=9256,vcoreSeconds=4,preemptedAMContainers=0,preemptedNonAMContainers=0,preemptedResources=<memory:0\, vCores:0>,applicationType=MAPREDUCE
2020-03-21 13:20:48,627 INFO org.apache.hadoop.yarn.server.resourcemanager.ClientRMService: Allocated new applicationId: 3
2020-03-21 13:20:49,409 INFO org.apache.hadoop.yarn.server.resourcemanager.ClientRMService: Application with id 3 submitted by user xidian
2020-03-21 13:20:49,409 INFO org.apache.hadoop.yarn.server.resourcemanager.rmapp.RMAppImpl: Storing application with id application_1584766611743_0003
2020-03-21 13:20:49,409 INFO org.apache.hadoop.yarn.server.resourcemanager.RMAuditLogger: USER=xidian	IP=127.0.0.1	OPERATION=Submit Application Request	TARGET=ClientRMService	RESULT=SUCCESS	APPID=application_1584766611743_0003
2020-03-21 13:20:49,409 INFO org.apache.hadoop.yarn.server.resourcemanager.recovery.RMStateStore: Storing info for app: application_1584766611743_0003
2020-03-21 13:20:49,409 INFO org.apache.hadoop.yarn.server.resourcemanager.rmapp.RMAppImpl: application_1584766611743_0003 State change from NEW to NEW_SAVING on event=START
2020-03-21 13:20:49,409 INFO org.apache.hadoop.yarn.server.resourcemanager.rmapp.RMAppImpl: application_1584766611743_0003 State change from NEW_SAVING to SUBMITTED on event=APP_NEW_SAVED
2020-03-21 13:20:49,409 INFO org.apache.hadoop.yarn.server.resourcemanager.scheduler.capacity.ParentQueue: Application added - appId: application_1584766611743_0003 user: xidian leaf-queue of parent: root #applications: 1
2020-03-21 13:20:49,409 INFO org.apache.hadoop.yarn.server.resourcemanager.scheduler.capacity.CapacityScheduler: Accepted application application_1584766611743_0003 from user: xidian, in queue: default
2020-03-21 13:20:49,410 INFO org.apache.hadoop.yarn.server.resourcemanager.rmapp.RMAppImpl: application_1584766611743_0003 State change from SUBMITTED to ACCEPTED on event=APP_ACCEPTED
2020-03-21 13:20:49,410 INFO org.apache.hadoop.yarn.server.resourcemanager.ApplicationMasterService: Registering app attempt : appattempt_1584766611743_0003_000001
2020-03-21 13:20:49,410 INFO org.apache.hadoop.yarn.server.resourcemanager.rmapp.attempt.RMAppAttemptImpl: appattempt_1584766611743_0003_000001 State change from NEW to SUBMITTED
2020-03-21 13:20:49,410 WARN org.apache.hadoop.yarn.server.resourcemanager.scheduler.capacity.LeafQueue: maximum-am-resource-percent is insufficient to start a single application in queue, it is likely set too low. skipping enforcement to allow at least one application to start
2020-03-21 13:20:49,410 WARN org.apache.hadoop.yarn.server.resourcemanager.scheduler.capacity.LeafQueue: maximum-am-resource-percent is insufficient to start a single application in queue for user, it is likely set too low. skipping enforcement to allow at least one application to start
2020-03-21 13:20:49,410 INFO org.apache.hadoop.yarn.server.resourcemanager.scheduler.capacity.LeafQueue: Application application_1584766611743_0003 from user: xidian activated in queue: default
2020-03-21 13:20:49,410 INFO org.apache.hadoop.yarn.server.resourcemanager.scheduler.capacity.LeafQueue: Application added - appId: application_1584766611743_0003 user: org.apache.hadoop.yarn.server.resourcemanager.scheduler.capacity.LeafQueue$User@1906f0fd, leaf-queue: default #user-pending-applications: 0 #user-active-applications: 1 #queue-pending-applications: 0 #queue-active-applications: 1
2020-03-21 13:20:49,410 INFO org.apache.hadoop.yarn.server.resourcemanager.scheduler.capacity.CapacityScheduler: Added Application Attempt appattempt_1584766611743_0003_000001 to scheduler from user xidian in queue default
2020-03-21 13:20:49,411 INFO org.apache.hadoop.yarn.server.resourcemanager.rmapp.attempt.RMAppAttemptImpl: appattempt_1584766611743_0003_000001 State change from SUBMITTED to SCHEDULED
2020-03-21 13:20:49,902 INFO org.apache.hadoop.yarn.server.resourcemanager.rmcontainer.RMContainerImpl: container_1584766611743_0003_01_000001 Container Transitioned from NEW to ALLOCATED
2020-03-21 13:20:49,902 INFO org.apache.hadoop.yarn.server.resourcemanager.RMAuditLogger: USER=xidian	OPERATION=AM Allocated Container	TARGET=SchedulerApp	RESULT=SUCCESS	APPID=application_1584766611743_0003	CONTAINERID=container_1584766611743_0003_01_000001
2020-03-21 13:20:49,902 INFO org.apache.hadoop.yarn.server.resourcemanager.scheduler.SchedulerNode: Assigned container container_1584766611743_0003_01_000001 of capacity <memory:2048, vCores:1> on host dell:34479, which has 1 containers, <memory:2048, vCores:1> used and <memory:6144, vCores:7> available after allocation
2020-03-21 13:20:49,902 INFO org.apache.hadoop.yarn.server.resourcemanager.scheduler.capacity.LeafQueue: assignedContainer application attempt=appattempt_1584766611743_0003_000001 container=Container: [ContainerId: container_1584766611743_0003_01_000001, NodeId: dell:34479, NodeHttpAddress: dell:8042, Resource: <memory:2048, vCores:1>, Priority: 0, Token: null, ] queue=default: capacity=1.0, absoluteCapacity=1.0, usedResources=<memory:0, vCores:0>, usedCapacity=0.0, absoluteUsedCapacity=0.0, numApps=1, numContainers=0 clusterResource=<memory:8192, vCores:8> type=OFF_SWITCH requestedPartition=
2020-03-21 13:20:49,902 INFO org.apache.hadoop.yarn.server.resourcemanager.scheduler.capacity.ParentQueue: Re-sorting assigned queue: root.default stats: default: capacity=1.0, absoluteCapacity=1.0, usedResources=<memory:2048, vCores:1>, usedCapacity=0.25, absoluteUsedCapacity=0.25, numApps=1, numContainers=1
2020-03-21 13:20:49,902 INFO org.apache.hadoop.yarn.server.resourcemanager.scheduler.capacity.ParentQueue: assignedContainer queue=root usedCapacity=0.25 absoluteUsedCapacity=0.25 used=<memory:2048, vCores:1> cluster=<memory:8192, vCores:8>
2020-03-21 13:20:49,902 INFO org.apache.hadoop.yarn.server.resourcemanager.security.NMTokenSecretManagerInRM: Sending NMToken for nodeId : dell:34479 for container : container_1584766611743_0003_01_000001
2020-03-21 13:20:49,903 INFO org.apache.hadoop.yarn.server.resourcemanager.rmcontainer.RMContainerImpl: container_1584766611743_0003_01_000001 Container Transitioned from ALLOCATED to ACQUIRED
2020-03-21 13:20:49,903 INFO org.apache.hadoop.yarn.server.resourcemanager.security.NMTokenSecretManagerInRM: Clear node set for appattempt_1584766611743_0003_000001
2020-03-21 13:20:49,903 INFO org.apache.hadoop.yarn.server.resourcemanager.rmapp.attempt.RMAppAttemptImpl: Storing attempt: AppId: application_1584766611743_0003 AttemptId: appattempt_1584766611743_0003_000001 MasterContainer: Container: [ContainerId: container_1584766611743_0003_01_000001, NodeId: dell:34479, NodeHttpAddress: dell:8042, Resource: <memory:2048, vCores:1>, Priority: 0, Token: Token { kind: ContainerToken, service: 127.0.1.1:34479 }, ]
2020-03-21 13:20:49,903 INFO org.apache.hadoop.yarn.server.resourcemanager.rmapp.attempt.RMAppAttemptImpl: appattempt_1584766611743_0003_000001 State change from SCHEDULED to ALLOCATED_SAVING
2020-03-21 13:20:49,903 INFO org.apache.hadoop.yarn.server.resourcemanager.rmapp.attempt.RMAppAttemptImpl: appattempt_1584766611743_0003_000001 State change from ALLOCATED_SAVING to ALLOCATED
2020-03-21 13:20:49,904 INFO org.apache.hadoop.yarn.server.resourcemanager.amlauncher.AMLauncher: Launching masterappattempt_1584766611743_0003_000001
2020-03-21 13:20:49,905 INFO org.apache.hadoop.yarn.server.resourcemanager.amlauncher.AMLauncher: Setting up container Container: [ContainerId: container_1584766611743_0003_01_000001, NodeId: dell:34479, NodeHttpAddress: dell:8042, Resource: <memory:2048, vCores:1>, Priority: 0, Token: Token { kind: ContainerToken, service: 127.0.1.1:34479 }, ] for AM appattempt_1584766611743_0003_000001
2020-03-21 13:20:49,905 INFO org.apache.hadoop.yarn.server.resourcemanager.amlauncher.AMLauncher: Command to launch container container_1584766611743_0003_01_000001 : $JAVA_HOME/bin/java -Djava.io.tmpdir=$PWD/tmp -Dlog4j.configuration=container-log4j.properties -Dyarn.app.container.log.dir=<LOG_DIR> -Dyarn.app.container.log.filesize=0 -Dhadoop.root.logger=INFO,CLA -Dhadoop.root.logfile=syslog  -Xmx1024m org.apache.hadoop.mapreduce.v2.app.MRAppMaster 1><LOG_DIR>/stdout 2><LOG_DIR>/stderr 
2020-03-21 13:20:49,905 INFO org.apache.hadoop.yarn.server.resourcemanager.security.AMRMTokenSecretManager: Create AMRMToken for ApplicationAttempt: appattempt_1584766611743_0003_000001
2020-03-21 13:20:49,905 INFO org.apache.hadoop.yarn.server.resourcemanager.security.AMRMTokenSecretManager: Creating password for appattempt_1584766611743_0003_000001
2020-03-21 13:20:49,912 INFO org.apache.hadoop.yarn.server.resourcemanager.amlauncher.AMLauncher: Done launching container Container: [ContainerId: container_1584766611743_0003_01_000001, NodeId: dell:34479, NodeHttpAddress: dell:8042, Resource: <memory:2048, vCores:1>, Priority: 0, Token: Token { kind: ContainerToken, service: 127.0.1.1:34479 }, ] for AM appattempt_1584766611743_0003_000001
2020-03-21 13:20:49,912 INFO org.apache.hadoop.yarn.server.resourcemanager.rmapp.attempt.RMAppAttemptImpl: appattempt_1584766611743_0003_000001 State change from ALLOCATED to LAUNCHED
2020-03-21 13:20:50,904 INFO org.apache.hadoop.yarn.server.resourcemanager.rmcontainer.RMContainerImpl: container_1584766611743_0003_01_000001 Container Transitioned from ACQUIRED to RUNNING
2020-03-21 13:20:52,167 INFO org.apache.hadoop.yarn.server.resourcemanager.rmcontainer.RMContainerImpl: container_1584766611743_0003_01_000001 Container Transitioned from RUNNING to COMPLETED
2020-03-21 13:20:52,167 INFO org.apache.hadoop.yarn.server.resourcemanager.scheduler.common.fica.FiCaSchedulerApp: Completed container: container_1584766611743_0003_01_000001 in state: COMPLETED event:FINISHED
2020-03-21 13:20:52,167 INFO org.apache.hadoop.yarn.server.resourcemanager.RMAuditLogger: USER=xidian	OPERATION=AM Released Container	TARGET=SchedulerApp	RESULT=SUCCESS	APPID=application_1584766611743_0003	CONTAINERID=container_1584766611743_0003_01_000001
2020-03-21 13:20:52,167 INFO org.apache.hadoop.yarn.server.resourcemanager.scheduler.SchedulerNode: Released container container_1584766611743_0003_01_000001 of capacity <memory:2048, vCores:1> on host dell:34479, which currently has 0 containers, <memory:0, vCores:0> used and <memory:8192, vCores:8> available, release resources=true
2020-03-21 13:20:52,168 INFO org.apache.hadoop.yarn.server.resourcemanager.scheduler.capacity.LeafQueue: default used=<memory:0, vCores:0> numContainers=0 user=xidian user-resources=<memory:0, vCores:0>
2020-03-21 13:20:52,168 INFO org.apache.hadoop.yarn.server.resourcemanager.rmapp.attempt.RMAppAttemptImpl: Updating application attempt appattempt_1584766611743_0003_000001 with final state: FAILED, and exit status: 126
2020-03-21 13:20:52,168 INFO org.apache.hadoop.yarn.server.resourcemanager.scheduler.capacity.LeafQueue: completedContainer container=Container: [ContainerId: container_1584766611743_0003_01_000001, NodeId: dell:34479, NodeHttpAddress: dell:8042, Resource: <memory:2048, vCores:1>, Priority: 0, Token: Token { kind: ContainerToken, service: 127.0.1.1:34479 }, ] queue=default: capacity=1.0, absoluteCapacity=1.0, usedResources=<memory:0, vCores:0>, usedCapacity=0.0, absoluteUsedCapacity=0.0, numApps=1, numContainers=0 cluster=<memory:8192, vCores:8>
2020-03-21 13:20:52,168 INFO org.apache.hadoop.yarn.server.resourcemanager.rmapp.attempt.RMAppAttemptImpl: appattempt_1584766611743_0003_000001 State change from LAUNCHED to FINAL_SAVING
2020-03-21 13:20:52,168 INFO org.apache.hadoop.yarn.server.resourcemanager.scheduler.capacity.ParentQueue: completedContainer queue=root usedCapacity=0.0 absoluteUsedCapacity=0.0 used=<memory:0, vCores:0> cluster=<memory:8192, vCores:8>
2020-03-21 13:20:52,168 INFO org.apache.hadoop.yarn.server.resourcemanager.ApplicationMasterService: Unregistering app attempt : appattempt_1584766611743_0003_000001
2020-03-21 13:20:52,168 INFO org.apache.hadoop.yarn.server.resourcemanager.security.AMRMTokenSecretManager: Application finished, removing password for appattempt_1584766611743_0003_000001
2020-03-21 13:20:52,168 INFO org.apache.hadoop.yarn.server.resourcemanager.scheduler.capacity.ParentQueue: Re-sorting completed queue: root.default stats: default: capacity=1.0, absoluteCapacity=1.0, usedResources=<memory:0, vCores:0>, usedCapacity=0.0, absoluteUsedCapacity=0.0, numApps=1, numContainers=0
2020-03-21 13:20:52,168 INFO org.apache.hadoop.yarn.server.resourcemanager.rmapp.attempt.RMAppAttemptImpl: appattempt_1584766611743_0003_000001 State change from FINAL_SAVING to FAILED
2020-03-21 13:20:52,168 INFO org.apache.hadoop.yarn.server.resourcemanager.scheduler.capacity.CapacityScheduler: Application attempt appattempt_1584766611743_0003_000001 released container container_1584766611743_0003_01_000001 on node: host: dell:34479 #containers=0 available=<memory:8192, vCores:8> used=<memory:0, vCores:0> with event: FINISHED
2020-03-21 13:20:52,168 INFO org.apache.hadoop.yarn.server.resourcemanager.rmapp.RMAppImpl: The number of failed attempts is 1. The max attempts is 2
2020-03-21 13:20:52,169 INFO org.apache.hadoop.yarn.server.resourcemanager.scheduler.capacity.CapacityScheduler: Application Attempt appattempt_1584766611743_0003_000001 is done. finalState=FAILED
2020-03-21 13:20:52,169 INFO org.apache.hadoop.yarn.server.resourcemanager.ApplicationMasterService: Registering app attempt : appattempt_1584766611743_0003_000002
2020-03-21 13:20:52,169 INFO org.apache.hadoop.yarn.server.resourcemanager.scheduler.AppSchedulingInfo: Application application_1584766611743_0003 requests cleared
2020-03-21 13:20:52,169 INFO org.apache.hadoop.yarn.server.resourcemanager.rmapp.attempt.RMAppAttemptImpl: appattempt_1584766611743_0003_000002 State change from NEW to SUBMITTED
2020-03-21 13:20:52,169 INFO org.apache.hadoop.yarn.server.resourcemanager.scheduler.capacity.LeafQueue: Application removed - appId: application_1584766611743_0003 user: xidian queue: default #user-pending-applications: 0 #user-active-applications: 0 #queue-pending-applications: 0 #queue-active-applications: 0
2020-03-21 13:20:52,169 WARN org.apache.hadoop.yarn.server.resourcemanager.scheduler.capacity.LeafQueue: maximum-am-resource-percent is insufficient to start a single application in queue, it is likely set too low. skipping enforcement to allow at least one application to start
2020-03-21 13:20:52,169 WARN org.apache.hadoop.yarn.server.resourcemanager.scheduler.capacity.LeafQueue: maximum-am-resource-percent is insufficient to start a single application in queue for user, it is likely set too low. skipping enforcement to allow at least one application to start
2020-03-21 13:20:52,169 INFO org.apache.hadoop.yarn.server.resourcemanager.scheduler.capacity.LeafQueue: Application application_1584766611743_0003 from user: xidian activated in queue: default
2020-03-21 13:20:52,169 INFO org.apache.hadoop.yarn.server.resourcemanager.scheduler.capacity.LeafQueue: Application added - appId: application_1584766611743_0003 user: org.apache.hadoop.yarn.server.resourcemanager.scheduler.capacity.LeafQueue$User@5125db2, leaf-queue: default #user-pending-applications: 0 #user-active-applications: 1 #queue-pending-applications: 0 #queue-active-applications: 1
2020-03-21 13:20:52,169 INFO org.apache.hadoop.yarn.server.resourcemanager.scheduler.capacity.CapacityScheduler: Added Application Attempt appattempt_1584766611743_0003_000002 to scheduler from user xidian in queue default
2020-03-21 13:20:52,169 INFO org.apache.hadoop.yarn.server.resourcemanager.rmapp.attempt.RMAppAttemptImpl: appattempt_1584766611743_0003_000002 State change from SUBMITTED to SCHEDULED
2020-03-21 13:20:53,169 INFO org.apache.hadoop.yarn.server.resourcemanager.rmcontainer.RMContainerImpl: container_1584766611743_0003_02_000001 Container Transitioned from NEW to ALLOCATED
2020-03-21 13:20:53,169 INFO org.apache.hadoop.yarn.server.resourcemanager.RMAuditLogger: USER=xidian	OPERATION=AM Allocated Container	TARGET=SchedulerApp	RESULT=SUCCESS	APPID=application_1584766611743_0003	CONTAINERID=container_1584766611743_0003_02_000001
2020-03-21 13:20:53,169 INFO org.apache.hadoop.yarn.server.resourcemanager.scheduler.SchedulerNode: Assigned container container_1584766611743_0003_02_000001 of capacity <memory:2048, vCores:1> on host dell:34479, which has 1 containers, <memory:2048, vCores:1> used and <memory:6144, vCores:7> available after allocation
2020-03-21 13:20:53,170 INFO org.apache.hadoop.yarn.server.resourcemanager.scheduler.capacity.LeafQueue: assignedContainer application attempt=appattempt_1584766611743_0003_000002 container=Container: [ContainerId: container_1584766611743_0003_02_000001, NodeId: dell:34479, NodeHttpAddress: dell:8042, Resource: <memory:2048, vCores:1>, Priority: 0, Token: null, ] queue=default: capacity=1.0, absoluteCapacity=1.0, usedResources=<memory:0, vCores:0>, usedCapacity=0.0, absoluteUsedCapacity=0.0, numApps=1, numContainers=0 clusterResource=<memory:8192, vCores:8> type=OFF_SWITCH requestedPartition=
2020-03-21 13:20:53,170 INFO org.apache.hadoop.yarn.server.resourcemanager.scheduler.capacity.ParentQueue: Re-sorting assigned queue: root.default stats: default: capacity=1.0, absoluteCapacity=1.0, usedResources=<memory:2048, vCores:1>, usedCapacity=0.25, absoluteUsedCapacity=0.25, numApps=1, numContainers=1
2020-03-21 13:20:53,171 INFO org.apache.hadoop.yarn.server.resourcemanager.scheduler.capacity.ParentQueue: assignedContainer queue=root usedCapacity=0.25 absoluteUsedCapacity=0.25 used=<memory:2048, vCores:1> cluster=<memory:8192, vCores:8>
2020-03-21 13:20:53,173 INFO org.apache.hadoop.yarn.server.resourcemanager.security.NMTokenSecretManagerInRM: Sending NMToken for nodeId : dell:34479 for container : container_1584766611743_0003_02_000001
2020-03-21 13:20:53,175 INFO org.apache.hadoop.yarn.server.resourcemanager.rmcontainer.RMContainerImpl: container_1584766611743_0003_02_000001 Container Transitioned from ALLOCATED to ACQUIRED
2020-03-21 13:20:53,175 INFO org.apache.hadoop.yarn.server.resourcemanager.security.NMTokenSecretManagerInRM: Clear node set for appattempt_1584766611743_0003_000002
2020-03-21 13:20:53,175 INFO org.apache.hadoop.yarn.server.resourcemanager.rmapp.attempt.RMAppAttemptImpl: Storing attempt: AppId: application_1584766611743_0003 AttemptId: appattempt_1584766611743_0003_000002 MasterContainer: Container: [ContainerId: container_1584766611743_0003_02_000001, NodeId: dell:34479, NodeHttpAddress: dell:8042, Resource: <memory:2048, vCores:1>, Priority: 0, Token: Token { kind: ContainerToken, service: 127.0.1.1:34479 }, ]
2020-03-21 13:20:53,175 INFO org.apache.hadoop.yarn.server.resourcemanager.rmapp.attempt.RMAppAttemptImpl: appattempt_1584766611743_0003_000002 State change from SCHEDULED to ALLOCATED_SAVING
2020-03-21 13:20:53,175 INFO org.apache.hadoop.yarn.server.resourcemanager.rmapp.attempt.RMAppAttemptImpl: appattempt_1584766611743_0003_000002 State change from ALLOCATED_SAVING to ALLOCATED
2020-03-21 13:20:53,175 INFO org.apache.hadoop.yarn.server.resourcemanager.amlauncher.AMLauncher: Launching masterappattempt_1584766611743_0003_000002
2020-03-21 13:20:53,176 INFO org.apache.hadoop.yarn.server.resourcemanager.amlauncher.AMLauncher: Setting up container Container: [ContainerId: container_1584766611743_0003_02_000001, NodeId: dell:34479, NodeHttpAddress: dell:8042, Resource: <memory:2048, vCores:1>, Priority: 0, Token: Token { kind: ContainerToken, service: 127.0.1.1:34479 }, ] for AM appattempt_1584766611743_0003_000002
2020-03-21 13:20:53,176 INFO org.apache.hadoop.yarn.server.resourcemanager.amlauncher.AMLauncher: Command to launch container container_1584766611743_0003_02_000001 : $JAVA_HOME/bin/java -Djava.io.tmpdir=$PWD/tmp -Dlog4j.configuration=container-log4j.properties -Dyarn.app.container.log.dir=<LOG_DIR> -Dyarn.app.container.log.filesize=0 -Dhadoop.root.logger=INFO,CLA -Dhadoop.root.logfile=syslog  -Xmx1024m org.apache.hadoop.mapreduce.v2.app.MRAppMaster 1><LOG_DIR>/stdout 2><LOG_DIR>/stderr 
2020-03-21 13:20:53,176 INFO org.apache.hadoop.yarn.server.resourcemanager.security.AMRMTokenSecretManager: Create AMRMToken for ApplicationAttempt: appattempt_1584766611743_0003_000002
2020-03-21 13:20:53,176 INFO org.apache.hadoop.yarn.server.resourcemanager.security.AMRMTokenSecretManager: Creating password for appattempt_1584766611743_0003_000002
2020-03-21 13:20:53,182 INFO org.apache.hadoop.yarn.server.resourcemanager.amlauncher.AMLauncher: Done launching container Container: [ContainerId: container_1584766611743_0003_02_000001, NodeId: dell:34479, NodeHttpAddress: dell:8042, Resource: <memory:2048, vCores:1>, Priority: 0, Token: Token { kind: ContainerToken, service: 127.0.1.1:34479 }, ] for AM appattempt_1584766611743_0003_000002
2020-03-21 13:20:53,182 INFO org.apache.hadoop.yarn.server.resourcemanager.rmapp.attempt.RMAppAttemptImpl: appattempt_1584766611743_0003_000002 State change from ALLOCATED to LAUNCHED
2020-03-21 13:20:54,172 INFO org.apache.hadoop.yarn.server.resourcemanager.rmcontainer.RMContainerImpl: container_1584766611743_0003_02_000001 Container Transitioned from ACQUIRED to RUNNING
2020-03-21 13:20:55,369 INFO org.apache.hadoop.yarn.server.resourcemanager.rmcontainer.RMContainerImpl: container_1584766611743_0003_02_000001 Container Transitioned from RUNNING to COMPLETED
2020-03-21 13:20:55,369 INFO org.apache.hadoop.yarn.server.resourcemanager.scheduler.common.fica.FiCaSchedulerApp: Completed container: container_1584766611743_0003_02_000001 in state: COMPLETED event:FINISHED
2020-03-21 13:20:55,369 INFO org.apache.hadoop.yarn.server.resourcemanager.RMAuditLogger: USER=xidian	OPERATION=AM Released Container	TARGET=SchedulerApp	RESULT=SUCCESS	APPID=application_1584766611743_0003	CONTAINERID=container_1584766611743_0003_02_000001
2020-03-21 13:20:55,369 INFO org.apache.hadoop.yarn.server.resourcemanager.scheduler.SchedulerNode: Released container container_1584766611743_0003_02_000001 of capacity <memory:2048, vCores:1> on host dell:34479, which currently has 0 containers, <memory:0, vCores:0> used and <memory:8192, vCores:8> available, release resources=true
2020-03-21 13:20:55,369 INFO org.apache.hadoop.yarn.server.resourcemanager.scheduler.capacity.LeafQueue: default used=<memory:0, vCores:0> numContainers=0 user=xidian user-resources=<memory:0, vCores:0>
2020-03-21 13:20:55,369 INFO org.apache.hadoop.yarn.server.resourcemanager.rmapp.attempt.RMAppAttemptImpl: Updating application attempt appattempt_1584766611743_0003_000002 with final state: FAILED, and exit status: 126
2020-03-21 13:20:55,369 INFO org.apache.hadoop.yarn.server.resourcemanager.scheduler.capacity.LeafQueue: completedContainer container=Container: [ContainerId: container_1584766611743_0003_02_000001, NodeId: dell:34479, NodeHttpAddress: dell:8042, Resource: <memory:2048, vCores:1>, Priority: 0, Token: Token { kind: ContainerToken, service: 127.0.1.1:34479 }, ] queue=default: capacity=1.0, absoluteCapacity=1.0, usedResources=<memory:0, vCores:0>, usedCapacity=0.0, absoluteUsedCapacity=0.0, numApps=1, numContainers=0 cluster=<memory:8192, vCores:8>
2020-03-21 13:20:55,369 INFO org.apache.hadoop.yarn.server.resourcemanager.rmapp.attempt.RMAppAttemptImpl: appattempt_1584766611743_0003_000002 State change from LAUNCHED to FINAL_SAVING
2020-03-21 13:20:55,369 INFO org.apache.hadoop.yarn.server.resourcemanager.scheduler.capacity.ParentQueue: completedContainer queue=root usedCapacity=0.0 absoluteUsedCapacity=0.0 used=<memory:0, vCores:0> cluster=<memory:8192, vCores:8>
2020-03-21 13:20:55,369 INFO org.apache.hadoop.yarn.server.resourcemanager.scheduler.capacity.ParentQueue: Re-sorting completed queue: root.default stats: default: capacity=1.0, absoluteCapacity=1.0, usedResources=<memory:0, vCores:0>, usedCapacity=0.0, absoluteUsedCapacity=0.0, numApps=1, numContainers=0
2020-03-21 13:20:55,369 INFO org.apache.hadoop.yarn.server.resourcemanager.scheduler.capacity.CapacityScheduler: Application attempt appattempt_1584766611743_0003_000002 released container container_1584766611743_0003_02_000001 on node: host: dell:34479 #containers=0 available=<memory:8192, vCores:8> used=<memory:0, vCores:0> with event: FINISHED
2020-03-21 13:20:55,369 INFO org.apache.hadoop.yarn.server.resourcemanager.ApplicationMasterService: Unregistering app attempt : appattempt_1584766611743_0003_000002
2020-03-21 13:20:55,369 INFO org.apache.hadoop.yarn.server.resourcemanager.security.AMRMTokenSecretManager: Application finished, removing password for appattempt_1584766611743_0003_000002
2020-03-21 13:20:55,369 INFO org.apache.hadoop.yarn.server.resourcemanager.rmapp.attempt.RMAppAttemptImpl: appattempt_1584766611743_0003_000002 State change from FINAL_SAVING to FAILED
2020-03-21 13:20:55,369 INFO org.apache.hadoop.yarn.server.resourcemanager.rmapp.RMAppImpl: The number of failed attempts is 2. The max attempts is 2
2020-03-21 13:20:55,369 INFO org.apache.hadoop.yarn.server.resourcemanager.rmapp.RMAppImpl: Updating application application_1584766611743_0003 with final state: FAILED
2020-03-21 13:20:55,369 INFO org.apache.hadoop.yarn.server.resourcemanager.rmapp.RMAppImpl: application_1584766611743_0003 State change from ACCEPTED to FINAL_SAVING on event=ATTEMPT_FAILED
2020-03-21 13:20:55,370 INFO org.apache.hadoop.yarn.server.resourcemanager.recovery.RMStateStore: Updating info for app: application_1584766611743_0003
2020-03-21 13:20:55,370 INFO org.apache.hadoop.yarn.server.resourcemanager.scheduler.capacity.CapacityScheduler: Application Attempt appattempt_1584766611743_0003_000002 is done. finalState=FAILED
2020-03-21 13:20:55,370 INFO org.apache.hadoop.yarn.server.resourcemanager.scheduler.AppSchedulingInfo: Application application_1584766611743_0003 requests cleared
2020-03-21 13:20:55,370 INFO org.apache.hadoop.yarn.server.resourcemanager.rmapp.RMAppImpl: Application application_1584766611743_0003 failed 2 times due to AM Container for appattempt_1584766611743_0003_000002 exited with  exitCode: 126
For more detailed output, check application tracking page:http://dell:8088/cluster/app/application_1584766611743_0003Then, click on links to logs of each attempt.
Diagnostics: Exception from container-launch: 
ExitCodeException exitCode=126: Got permission denied while trying to connect to the Docker daemon socket at unix:///var/run/docker.sock: Get http://%2Fvar%2Frun%2Fdocker.sock/v1.40/containers/container_1584766611743_0003_02_000001/json: dial unix /var/run/docker.sock: connect: permission denied
/usr/bin/docker: Got permission denied while trying to connect to the Docker daemon socket at unix:///var/run/docker.sock: Post http://%2Fvar%2Frun%2Fdocker.sock/v1.40/containers/create?name=container_1584766611743_0003_02_000001: dial unix /var/run/docker.sock: connect: permission denied.
See '/usr/bin/docker run --help'.

	at org.apache.hadoop.util.Shell.runCommand(Shell.java:585)
	at org.apache.hadoop.util.Shell.run(Shell.java:482)
	at org.apache.hadoop.util.Shell$ShellCommandExecutor.execute(Shell.java:776)
	at org.apache.hadoop.yarn.server.nodemanager.DockerContainerExecutor.launchContainer(DockerContainerExecutor.java:247)
	at org.apache.hadoop.yarn.server.nodemanager.containermanager.launcher.ContainerLaunch.call(ContainerLaunch.java:302)
	at org.apache.hadoop.yarn.server.nodemanager.containermanager.launcher.ContainerLaunch.call(ContainerLaunch.java:82)
	at java.util.concurrent.FutureTask.run(FutureTask.java:266)
	at java.util.concurrent.ThreadPoolExecutor.runWorker(ThreadPoolExecutor.java:1142)
	at java.util.concurrent.ThreadPoolExecutor$Worker.run(ThreadPoolExecutor.java:617)
	at java.lang.Thread.run(Thread.java:748)


Container exited with a non-zero exit code 126
Failing this attempt. Failing the application.
2020-03-21 13:20:55,370 INFO org.apache.hadoop.yarn.server.resourcemanager.rmapp.RMAppImpl: application_1584766611743_0003 State change from FINAL_SAVING to FAILED on event=APP_UPDATE_SAVED
2020-03-21 13:20:55,370 INFO org.apache.hadoop.yarn.server.resourcemanager.scheduler.capacity.LeafQueue: Application removed - appId: application_1584766611743_0003 user: xidian queue: default #user-pending-applications: 0 #user-active-applications: 0 #queue-pending-applications: 0 #queue-active-applications: 0
2020-03-21 13:20:55,370 INFO org.apache.hadoop.yarn.server.resourcemanager.scheduler.capacity.ParentQueue: Application removed - appId: application_1584766611743_0003 user: xidian leaf-queue of parent: root #applications: 0
2020-03-21 13:20:55,370 WARN org.apache.hadoop.yarn.server.resourcemanager.RMAuditLogger: USER=xidian	OPERATION=Application Finished - Failed	TARGET=RMAppManager	RESULT=FAILURE	DESCRIPTION=App failed with state: FAILED	PERMISSIONS=Application application_1584766611743_0003 failed 2 times due to AM Container for appattempt_1584766611743_0003_000002 exited with  exitCode: 126
For more detailed output, check application tracking page:http://dell:8088/cluster/app/application_1584766611743_0003Then, click on links to logs of each attempt.
Diagnostics: Exception from container-launch: 
ExitCodeException exitCode=126: Got permission denied while trying to connect to the Docker daemon socket at unix:///var/run/docker.sock: Get http://%2Fvar%2Frun%2Fdocker.sock/v1.40/containers/container_1584766611743_0003_02_000001/json: dial unix /var/run/docker.sock: connect: permission denied
/usr/bin/docker: Got permission denied while trying to connect to the Docker daemon socket at unix:///var/run/docker.sock: Post http://%2Fvar%2Frun%2Fdocker.sock/v1.40/containers/create?name=container_1584766611743_0003_02_000001: dial unix /var/run/docker.sock: connect: permission denied.
See '/usr/bin/docker run --help'.

	at org.apache.hadoop.util.Shell.runCommand(Shell.java:585)
	at org.apache.hadoop.util.Shell.run(Shell.java:482)
	at org.apache.hadoop.util.Shell$ShellCommandExecutor.execute(Shell.java:776)
	at org.apache.hadoop.yarn.server.nodemanager.DockerContainerExecutor.launchContainer(DockerContainerExecutor.java:247)
	at org.apache.hadoop.yarn.server.nodemanager.containermanager.launcher.ContainerLaunch.call(ContainerLaunch.java:302)
	at org.apache.hadoop.yarn.server.nodemanager.containermanager.launcher.ContainerLaunch.call(ContainerLaunch.java:82)
	at java.util.concurrent.FutureTask.run(FutureTask.java:266)
	at java.util.concurrent.ThreadPoolExecutor.runWorker(ThreadPoolExecutor.java:1142)
	at java.util.concurrent.ThreadPoolExecutor$Worker.run(ThreadPoolExecutor.java:617)
	at java.lang.Thread.run(Thread.java:748)


Container exited with a non-zero exit code 126
Failing this attempt. Failing the application.	APPID=application_1584766611743_0003
2020-03-21 13:20:55,370 INFO org.apache.hadoop.yarn.server.resourcemanager.RMAppManager$ApplicationSummary: appId=application_1584766611743_0003,name=word count,user=xidian,queue=default,state=FAILED,trackingUrl=http://dell:8088/cluster/app/application_1584766611743_0003,appMasterHost=N/A,startTime=1584768049408,finishTime=1584768055369,finalStatus=FAILED,memorySeconds=9143,vcoreSeconds=4,preemptedAMContainers=0,preemptedNonAMContainers=0,preemptedResources=<memory:0\, vCores:0>,applicationType=MAPREDUCE
2020-03-21 14:59:54,249 INFO org.apache.hadoop.yarn.server.resourcemanager.ClientRMService: Allocated new applicationId: 4
2020-03-21 14:59:55,026 INFO org.apache.hadoop.yarn.server.resourcemanager.ClientRMService: Application with id 4 submitted by user xidian
2020-03-21 14:59:55,026 INFO org.apache.hadoop.yarn.server.resourcemanager.rmapp.RMAppImpl: Storing application with id application_1584766611743_0004
2020-03-21 14:59:55,026 INFO org.apache.hadoop.yarn.server.resourcemanager.RMAuditLogger: USER=xidian	IP=127.0.0.1	OPERATION=Submit Application Request	TARGET=ClientRMService	RESULT=SUCCESS	APPID=application_1584766611743_0004
2020-03-21 14:59:55,026 INFO org.apache.hadoop.yarn.server.resourcemanager.rmapp.RMAppImpl: application_1584766611743_0004 State change from NEW to NEW_SAVING on event=START
2020-03-21 14:59:55,026 INFO org.apache.hadoop.yarn.server.resourcemanager.recovery.RMStateStore: Storing info for app: application_1584766611743_0004
2020-03-21 14:59:55,027 INFO org.apache.hadoop.yarn.server.resourcemanager.rmapp.RMAppImpl: application_1584766611743_0004 State change from NEW_SAVING to SUBMITTED on event=APP_NEW_SAVED
2020-03-21 14:59:55,027 INFO org.apache.hadoop.yarn.server.resourcemanager.scheduler.capacity.ParentQueue: Application added - appId: application_1584766611743_0004 user: xidian leaf-queue of parent: root #applications: 1
2020-03-21 14:59:55,027 INFO org.apache.hadoop.yarn.server.resourcemanager.scheduler.capacity.CapacityScheduler: Accepted application application_1584766611743_0004 from user: xidian, in queue: default
2020-03-21 14:59:55,027 INFO org.apache.hadoop.yarn.server.resourcemanager.rmapp.RMAppImpl: application_1584766611743_0004 State change from SUBMITTED to ACCEPTED on event=APP_ACCEPTED
2020-03-21 14:59:55,027 INFO org.apache.hadoop.yarn.server.resourcemanager.ApplicationMasterService: Registering app attempt : appattempt_1584766611743_0004_000001
2020-03-21 14:59:55,027 INFO org.apache.hadoop.yarn.server.resourcemanager.rmapp.attempt.RMAppAttemptImpl: appattempt_1584766611743_0004_000001 State change from NEW to SUBMITTED
2020-03-21 14:59:55,027 WARN org.apache.hadoop.yarn.server.resourcemanager.scheduler.capacity.LeafQueue: maximum-am-resource-percent is insufficient to start a single application in queue, it is likely set too low. skipping enforcement to allow at least one application to start
2020-03-21 14:59:55,027 WARN org.apache.hadoop.yarn.server.resourcemanager.scheduler.capacity.LeafQueue: maximum-am-resource-percent is insufficient to start a single application in queue for user, it is likely set too low. skipping enforcement to allow at least one application to start
2020-03-21 14:59:55,027 INFO org.apache.hadoop.yarn.server.resourcemanager.scheduler.capacity.LeafQueue: Application application_1584766611743_0004 from user: xidian activated in queue: default
2020-03-21 14:59:55,027 INFO org.apache.hadoop.yarn.server.resourcemanager.scheduler.capacity.LeafQueue: Application added - appId: application_1584766611743_0004 user: org.apache.hadoop.yarn.server.resourcemanager.scheduler.capacity.LeafQueue$User@6eab23c, leaf-queue: default #user-pending-applications: 0 #user-active-applications: 1 #queue-pending-applications: 0 #queue-active-applications: 1
2020-03-21 14:59:55,027 INFO org.apache.hadoop.yarn.server.resourcemanager.scheduler.capacity.CapacityScheduler: Added Application Attempt appattempt_1584766611743_0004_000001 to scheduler from user xidian in queue default
2020-03-21 14:59:55,028 INFO org.apache.hadoop.yarn.server.resourcemanager.rmapp.attempt.RMAppAttemptImpl: appattempt_1584766611743_0004_000001 State change from SUBMITTED to SCHEDULED
2020-03-21 14:59:55,766 INFO org.apache.hadoop.yarn.server.resourcemanager.rmcontainer.RMContainerImpl: container_1584766611743_0004_01_000001 Container Transitioned from NEW to ALLOCATED
2020-03-21 14:59:55,766 INFO org.apache.hadoop.yarn.server.resourcemanager.RMAuditLogger: USER=xidian	OPERATION=AM Allocated Container	TARGET=SchedulerApp	RESULT=SUCCESS	APPID=application_1584766611743_0004	CONTAINERID=container_1584766611743_0004_01_000001
2020-03-21 14:59:55,766 INFO org.apache.hadoop.yarn.server.resourcemanager.scheduler.SchedulerNode: Assigned container container_1584766611743_0004_01_000001 of capacity <memory:2048, vCores:1> on host dell:34479, which has 1 containers, <memory:2048, vCores:1> used and <memory:6144, vCores:7> available after allocation
2020-03-21 14:59:55,766 INFO org.apache.hadoop.yarn.server.resourcemanager.scheduler.capacity.LeafQueue: assignedContainer application attempt=appattempt_1584766611743_0004_000001 container=Container: [ContainerId: container_1584766611743_0004_01_000001, NodeId: dell:34479, NodeHttpAddress: dell:8042, Resource: <memory:2048, vCores:1>, Priority: 0, Token: null, ] queue=default: capacity=1.0, absoluteCapacity=1.0, usedResources=<memory:0, vCores:0>, usedCapacity=0.0, absoluteUsedCapacity=0.0, numApps=1, numContainers=0 clusterResource=<memory:8192, vCores:8> type=OFF_SWITCH requestedPartition=
2020-03-21 14:59:55,767 INFO org.apache.hadoop.yarn.server.resourcemanager.scheduler.capacity.ParentQueue: Re-sorting assigned queue: root.default stats: default: capacity=1.0, absoluteCapacity=1.0, usedResources=<memory:2048, vCores:1>, usedCapacity=0.25, absoluteUsedCapacity=0.25, numApps=1, numContainers=1
2020-03-21 14:59:55,767 INFO org.apache.hadoop.yarn.server.resourcemanager.scheduler.capacity.ParentQueue: assignedContainer queue=root usedCapacity=0.25 absoluteUsedCapacity=0.25 used=<memory:2048, vCores:1> cluster=<memory:8192, vCores:8>
2020-03-21 14:59:55,768 INFO org.apache.hadoop.yarn.server.resourcemanager.security.NMTokenSecretManagerInRM: Sending NMToken for nodeId : dell:34479 for container : container_1584766611743_0004_01_000001
2020-03-21 14:59:55,770 INFO org.apache.hadoop.yarn.server.resourcemanager.rmcontainer.RMContainerImpl: container_1584766611743_0004_01_000001 Container Transitioned from ALLOCATED to ACQUIRED
2020-03-21 14:59:55,771 INFO org.apache.hadoop.yarn.server.resourcemanager.security.NMTokenSecretManagerInRM: Clear node set for appattempt_1584766611743_0004_000001
2020-03-21 14:59:55,771 INFO org.apache.hadoop.yarn.server.resourcemanager.rmapp.attempt.RMAppAttemptImpl: Storing attempt: AppId: application_1584766611743_0004 AttemptId: appattempt_1584766611743_0004_000001 MasterContainer: Container: [ContainerId: container_1584766611743_0004_01_000001, NodeId: dell:34479, NodeHttpAddress: dell:8042, Resource: <memory:2048, vCores:1>, Priority: 0, Token: Token { kind: ContainerToken, service: 127.0.1.1:34479 }, ]
2020-03-21 14:59:55,771 INFO org.apache.hadoop.yarn.server.resourcemanager.rmapp.attempt.RMAppAttemptImpl: appattempt_1584766611743_0004_000001 State change from SCHEDULED to ALLOCATED_SAVING
2020-03-21 14:59:55,771 INFO org.apache.hadoop.yarn.server.resourcemanager.rmapp.attempt.RMAppAttemptImpl: appattempt_1584766611743_0004_000001 State change from ALLOCATED_SAVING to ALLOCATED
2020-03-21 14:59:55,772 INFO org.apache.hadoop.yarn.server.resourcemanager.amlauncher.AMLauncher: Launching masterappattempt_1584766611743_0004_000001
2020-03-21 14:59:55,776 INFO org.apache.hadoop.yarn.server.resourcemanager.amlauncher.AMLauncher: Setting up container Container: [ContainerId: container_1584766611743_0004_01_000001, NodeId: dell:34479, NodeHttpAddress: dell:8042, Resource: <memory:2048, vCores:1>, Priority: 0, Token: Token { kind: ContainerToken, service: 127.0.1.1:34479 }, ] for AM appattempt_1584766611743_0004_000001
2020-03-21 14:59:55,777 INFO org.apache.hadoop.yarn.server.resourcemanager.amlauncher.AMLauncher: Command to launch container container_1584766611743_0004_01_000001 : $JAVA_HOME/bin/java -Djava.io.tmpdir=$PWD/tmp -Dlog4j.configuration=container-log4j.properties -Dyarn.app.container.log.dir=<LOG_DIR> -Dyarn.app.container.log.filesize=0 -Dhadoop.root.logger=INFO,CLA -Dhadoop.root.logfile=syslog  -Xmx1024m org.apache.hadoop.mapreduce.v2.app.MRAppMaster 1><LOG_DIR>/stdout 2><LOG_DIR>/stderr 
2020-03-21 14:59:55,777 INFO org.apache.hadoop.yarn.server.resourcemanager.security.AMRMTokenSecretManager: Create AMRMToken for ApplicationAttempt: appattempt_1584766611743_0004_000001
2020-03-21 14:59:55,777 INFO org.apache.hadoop.yarn.server.resourcemanager.security.AMRMTokenSecretManager: Creating password for appattempt_1584766611743_0004_000001
2020-03-21 14:59:55,799 INFO org.apache.hadoop.yarn.server.resourcemanager.amlauncher.AMLauncher: Done launching container Container: [ContainerId: container_1584766611743_0004_01_000001, NodeId: dell:34479, NodeHttpAddress: dell:8042, Resource: <memory:2048, vCores:1>, Priority: 0, Token: Token { kind: ContainerToken, service: 127.0.1.1:34479 }, ] for AM appattempt_1584766611743_0004_000001
2020-03-21 14:59:55,799 INFO org.apache.hadoop.yarn.server.resourcemanager.rmapp.attempt.RMAppAttemptImpl: appattempt_1584766611743_0004_000001 State change from ALLOCATED to LAUNCHED
2020-03-21 14:59:56,768 INFO org.apache.hadoop.yarn.server.resourcemanager.rmcontainer.RMContainerImpl: container_1584766611743_0004_01_000001 Container Transitioned from ACQUIRED to RUNNING
2020-03-21 14:59:58,092 INFO org.apache.hadoop.yarn.server.resourcemanager.rmcontainer.RMContainerImpl: container_1584766611743_0004_01_000001 Container Transitioned from RUNNING to COMPLETED
2020-03-21 14:59:58,092 INFO org.apache.hadoop.yarn.server.resourcemanager.scheduler.common.fica.FiCaSchedulerApp: Completed container: container_1584766611743_0004_01_000001 in state: COMPLETED event:FINISHED
2020-03-21 14:59:58,092 INFO org.apache.hadoop.yarn.server.resourcemanager.RMAuditLogger: USER=xidian	OPERATION=AM Released Container	TARGET=SchedulerApp	RESULT=SUCCESS	APPID=application_1584766611743_0004	CONTAINERID=container_1584766611743_0004_01_000001
2020-03-21 14:59:58,092 INFO org.apache.hadoop.yarn.server.resourcemanager.scheduler.SchedulerNode: Released container container_1584766611743_0004_01_000001 of capacity <memory:2048, vCores:1> on host dell:34479, which currently has 0 containers, <memory:0, vCores:0> used and <memory:8192, vCores:8> available, release resources=true
2020-03-21 14:59:58,092 INFO org.apache.hadoop.yarn.server.resourcemanager.scheduler.capacity.LeafQueue: default used=<memory:0, vCores:0> numContainers=0 user=xidian user-resources=<memory:0, vCores:0>
2020-03-21 14:59:58,092 INFO org.apache.hadoop.yarn.server.resourcemanager.scheduler.capacity.LeafQueue: completedContainer container=Container: [ContainerId: container_1584766611743_0004_01_000001, NodeId: dell:34479, NodeHttpAddress: dell:8042, Resource: <memory:2048, vCores:1>, Priority: 0, Token: Token { kind: ContainerToken, service: 127.0.1.1:34479 }, ] queue=default: capacity=1.0, absoluteCapacity=1.0, usedResources=<memory:0, vCores:0>, usedCapacity=0.0, absoluteUsedCapacity=0.0, numApps=1, numContainers=0 cluster=<memory:8192, vCores:8>
2020-03-21 14:59:58,092 INFO org.apache.hadoop.yarn.server.resourcemanager.rmapp.attempt.RMAppAttemptImpl: Updating application attempt appattempt_1584766611743_0004_000001 with final state: FAILED, and exit status: 126
2020-03-21 14:59:58,092 INFO org.apache.hadoop.yarn.server.resourcemanager.scheduler.capacity.ParentQueue: completedContainer queue=root usedCapacity=0.0 absoluteUsedCapacity=0.0 used=<memory:0, vCores:0> cluster=<memory:8192, vCores:8>
2020-03-21 14:59:58,092 INFO org.apache.hadoop.yarn.server.resourcemanager.rmapp.attempt.RMAppAttemptImpl: appattempt_1584766611743_0004_000001 State change from LAUNCHED to FINAL_SAVING
2020-03-21 14:59:58,092 INFO org.apache.hadoop.yarn.server.resourcemanager.scheduler.capacity.ParentQueue: Re-sorting completed queue: root.default stats: default: capacity=1.0, absoluteCapacity=1.0, usedResources=<memory:0, vCores:0>, usedCapacity=0.0, absoluteUsedCapacity=0.0, numApps=1, numContainers=0
2020-03-21 14:59:58,093 INFO org.apache.hadoop.yarn.server.resourcemanager.scheduler.capacity.CapacityScheduler: Application attempt appattempt_1584766611743_0004_000001 released container container_1584766611743_0004_01_000001 on node: host: dell:34479 #containers=0 available=<memory:8192, vCores:8> used=<memory:0, vCores:0> with event: FINISHED
2020-03-21 14:59:58,093 INFO org.apache.hadoop.yarn.server.resourcemanager.ApplicationMasterService: Unregistering app attempt : appattempt_1584766611743_0004_000001
2020-03-21 14:59:58,093 INFO org.apache.hadoop.yarn.server.resourcemanager.security.AMRMTokenSecretManager: Application finished, removing password for appattempt_1584766611743_0004_000001
2020-03-21 14:59:58,093 INFO org.apache.hadoop.yarn.server.resourcemanager.rmapp.attempt.RMAppAttemptImpl: appattempt_1584766611743_0004_000001 State change from FINAL_SAVING to FAILED
2020-03-21 14:59:58,093 INFO org.apache.hadoop.yarn.server.resourcemanager.rmapp.RMAppImpl: The number of failed attempts is 1. The max attempts is 2
2020-03-21 14:59:58,093 INFO org.apache.hadoop.yarn.server.resourcemanager.ApplicationMasterService: Registering app attempt : appattempt_1584766611743_0004_000002
2020-03-21 14:59:58,093 INFO org.apache.hadoop.yarn.server.resourcemanager.scheduler.capacity.CapacityScheduler: Application Attempt appattempt_1584766611743_0004_000001 is done. finalState=FAILED
2020-03-21 14:59:58,093 INFO org.apache.hadoop.yarn.server.resourcemanager.rmapp.attempt.RMAppAttemptImpl: appattempt_1584766611743_0004_000002 State change from NEW to SUBMITTED
2020-03-21 14:59:58,093 INFO org.apache.hadoop.yarn.server.resourcemanager.scheduler.AppSchedulingInfo: Application application_1584766611743_0004 requests cleared
2020-03-21 14:59:58,093 INFO org.apache.hadoop.yarn.server.resourcemanager.scheduler.capacity.LeafQueue: Application removed - appId: application_1584766611743_0004 user: xidian queue: default #user-pending-applications: 0 #user-active-applications: 0 #queue-pending-applications: 0 #queue-active-applications: 0
2020-03-21 14:59:58,093 WARN org.apache.hadoop.yarn.server.resourcemanager.scheduler.capacity.LeafQueue: maximum-am-resource-percent is insufficient to start a single application in queue, it is likely set too low. skipping enforcement to allow at least one application to start
2020-03-21 14:59:58,093 WARN org.apache.hadoop.yarn.server.resourcemanager.scheduler.capacity.LeafQueue: maximum-am-resource-percent is insufficient to start a single application in queue for user, it is likely set too low. skipping enforcement to allow at least one application to start
2020-03-21 14:59:58,093 INFO org.apache.hadoop.yarn.server.resourcemanager.scheduler.capacity.LeafQueue: Application application_1584766611743_0004 from user: xidian activated in queue: default
2020-03-21 14:59:58,093 INFO org.apache.hadoop.yarn.server.resourcemanager.scheduler.capacity.LeafQueue: Application added - appId: application_1584766611743_0004 user: org.apache.hadoop.yarn.server.resourcemanager.scheduler.capacity.LeafQueue$User@6176fb9e, leaf-queue: default #user-pending-applications: 0 #user-active-applications: 1 #queue-pending-applications: 0 #queue-active-applications: 1
2020-03-21 14:59:58,093 INFO org.apache.hadoop.yarn.server.resourcemanager.scheduler.capacity.CapacityScheduler: Added Application Attempt appattempt_1584766611743_0004_000002 to scheduler from user xidian in queue default
2020-03-21 14:59:58,093 INFO org.apache.hadoop.yarn.server.resourcemanager.rmapp.attempt.RMAppAttemptImpl: appattempt_1584766611743_0004_000002 State change from SUBMITTED to SCHEDULED
2020-03-21 14:59:59,093 INFO org.apache.hadoop.yarn.server.resourcemanager.rmcontainer.RMContainerImpl: container_1584766611743_0004_02_000001 Container Transitioned from NEW to ALLOCATED
2020-03-21 14:59:59,093 INFO org.apache.hadoop.yarn.server.resourcemanager.RMAuditLogger: USER=xidian	OPERATION=AM Allocated Container	TARGET=SchedulerApp	RESULT=SUCCESS	APPID=application_1584766611743_0004	CONTAINERID=container_1584766611743_0004_02_000001
2020-03-21 14:59:59,093 INFO org.apache.hadoop.yarn.server.resourcemanager.scheduler.SchedulerNode: Assigned container container_1584766611743_0004_02_000001 of capacity <memory:2048, vCores:1> on host dell:34479, which has 1 containers, <memory:2048, vCores:1> used and <memory:6144, vCores:7> available after allocation
2020-03-21 14:59:59,093 INFO org.apache.hadoop.yarn.server.resourcemanager.scheduler.capacity.LeafQueue: assignedContainer application attempt=appattempt_1584766611743_0004_000002 container=Container: [ContainerId: container_1584766611743_0004_02_000001, NodeId: dell:34479, NodeHttpAddress: dell:8042, Resource: <memory:2048, vCores:1>, Priority: 0, Token: null, ] queue=default: capacity=1.0, absoluteCapacity=1.0, usedResources=<memory:0, vCores:0>, usedCapacity=0.0, absoluteUsedCapacity=0.0, numApps=1, numContainers=0 clusterResource=<memory:8192, vCores:8> type=OFF_SWITCH requestedPartition=
2020-03-21 14:59:59,093 INFO org.apache.hadoop.yarn.server.resourcemanager.scheduler.capacity.ParentQueue: Re-sorting assigned queue: root.default stats: default: capacity=1.0, absoluteCapacity=1.0, usedResources=<memory:2048, vCores:1>, usedCapacity=0.25, absoluteUsedCapacity=0.25, numApps=1, numContainers=1
2020-03-21 14:59:59,093 INFO org.apache.hadoop.yarn.server.resourcemanager.scheduler.capacity.ParentQueue: assignedContainer queue=root usedCapacity=0.25 absoluteUsedCapacity=0.25 used=<memory:2048, vCores:1> cluster=<memory:8192, vCores:8>
2020-03-21 14:59:59,100 INFO org.apache.hadoop.yarn.server.resourcemanager.security.NMTokenSecretManagerInRM: Sending NMToken for nodeId : dell:34479 for container : container_1584766611743_0004_02_000001
2020-03-21 14:59:59,103 INFO org.apache.hadoop.yarn.server.resourcemanager.rmcontainer.RMContainerImpl: container_1584766611743_0004_02_000001 Container Transitioned from ALLOCATED to ACQUIRED
2020-03-21 14:59:59,103 INFO org.apache.hadoop.yarn.server.resourcemanager.security.NMTokenSecretManagerInRM: Clear node set for appattempt_1584766611743_0004_000002
2020-03-21 14:59:59,103 INFO org.apache.hadoop.yarn.server.resourcemanager.rmapp.attempt.RMAppAttemptImpl: Storing attempt: AppId: application_1584766611743_0004 AttemptId: appattempt_1584766611743_0004_000002 MasterContainer: Container: [ContainerId: container_1584766611743_0004_02_000001, NodeId: dell:34479, NodeHttpAddress: dell:8042, Resource: <memory:2048, vCores:1>, Priority: 0, Token: Token { kind: ContainerToken, service: 127.0.1.1:34479 }, ]
2020-03-21 14:59:59,103 INFO org.apache.hadoop.yarn.server.resourcemanager.rmapp.attempt.RMAppAttemptImpl: appattempt_1584766611743_0004_000002 State change from SCHEDULED to ALLOCATED_SAVING
2020-03-21 14:59:59,103 INFO org.apache.hadoop.yarn.server.resourcemanager.rmapp.attempt.RMAppAttemptImpl: appattempt_1584766611743_0004_000002 State change from ALLOCATED_SAVING to ALLOCATED
2020-03-21 14:59:59,103 INFO org.apache.hadoop.yarn.server.resourcemanager.amlauncher.AMLauncher: Launching masterappattempt_1584766611743_0004_000002
2020-03-21 14:59:59,104 INFO org.apache.hadoop.yarn.server.resourcemanager.amlauncher.AMLauncher: Setting up container Container: [ContainerId: container_1584766611743_0004_02_000001, NodeId: dell:34479, NodeHttpAddress: dell:8042, Resource: <memory:2048, vCores:1>, Priority: 0, Token: Token { kind: ContainerToken, service: 127.0.1.1:34479 }, ] for AM appattempt_1584766611743_0004_000002
2020-03-21 14:59:59,104 INFO org.apache.hadoop.yarn.server.resourcemanager.amlauncher.AMLauncher: Command to launch container container_1584766611743_0004_02_000001 : $JAVA_HOME/bin/java -Djava.io.tmpdir=$PWD/tmp -Dlog4j.configuration=container-log4j.properties -Dyarn.app.container.log.dir=<LOG_DIR> -Dyarn.app.container.log.filesize=0 -Dhadoop.root.logger=INFO,CLA -Dhadoop.root.logfile=syslog  -Xmx1024m org.apache.hadoop.mapreduce.v2.app.MRAppMaster 1><LOG_DIR>/stdout 2><LOG_DIR>/stderr 
2020-03-21 14:59:59,105 INFO org.apache.hadoop.yarn.server.resourcemanager.security.AMRMTokenSecretManager: Create AMRMToken for ApplicationAttempt: appattempt_1584766611743_0004_000002
2020-03-21 14:59:59,105 INFO org.apache.hadoop.yarn.server.resourcemanager.security.AMRMTokenSecretManager: Creating password for appattempt_1584766611743_0004_000002
2020-03-21 14:59:59,111 INFO org.apache.hadoop.yarn.server.resourcemanager.amlauncher.AMLauncher: Done launching container Container: [ContainerId: container_1584766611743_0004_02_000001, NodeId: dell:34479, NodeHttpAddress: dell:8042, Resource: <memory:2048, vCores:1>, Priority: 0, Token: Token { kind: ContainerToken, service: 127.0.1.1:34479 }, ] for AM appattempt_1584766611743_0004_000002
2020-03-21 14:59:59,112 INFO org.apache.hadoop.yarn.server.resourcemanager.rmapp.attempt.RMAppAttemptImpl: appattempt_1584766611743_0004_000002 State change from ALLOCATED to LAUNCHED
2020-03-21 15:00:00,098 INFO org.apache.hadoop.yarn.server.resourcemanager.rmcontainer.RMContainerImpl: container_1584766611743_0004_02_000001 Container Transitioned from ACQUIRED to RUNNING
2020-03-21 15:00:01,308 INFO org.apache.hadoop.yarn.server.resourcemanager.rmcontainer.RMContainerImpl: container_1584766611743_0004_02_000001 Container Transitioned from RUNNING to COMPLETED
2020-03-21 15:00:01,309 INFO org.apache.hadoop.yarn.server.resourcemanager.scheduler.common.fica.FiCaSchedulerApp: Completed container: container_1584766611743_0004_02_000001 in state: COMPLETED event:FINISHED
2020-03-21 15:00:01,309 INFO org.apache.hadoop.yarn.server.resourcemanager.RMAuditLogger: USER=xidian	OPERATION=AM Released Container	TARGET=SchedulerApp	RESULT=SUCCESS	APPID=application_1584766611743_0004	CONTAINERID=container_1584766611743_0004_02_000001
2020-03-21 15:00:01,309 INFO org.apache.hadoop.yarn.server.resourcemanager.scheduler.SchedulerNode: Released container container_1584766611743_0004_02_000001 of capacity <memory:2048, vCores:1> on host dell:34479, which currently has 0 containers, <memory:0, vCores:0> used and <memory:8192, vCores:8> available, release resources=true
2020-03-21 15:00:01,309 INFO org.apache.hadoop.yarn.server.resourcemanager.scheduler.capacity.LeafQueue: default used=<memory:0, vCores:0> numContainers=0 user=xidian user-resources=<memory:0, vCores:0>
2020-03-21 15:00:01,309 INFO org.apache.hadoop.yarn.server.resourcemanager.scheduler.capacity.LeafQueue: completedContainer container=Container: [ContainerId: container_1584766611743_0004_02_000001, NodeId: dell:34479, NodeHttpAddress: dell:8042, Resource: <memory:2048, vCores:1>, Priority: 0, Token: Token { kind: ContainerToken, service: 127.0.1.1:34479 }, ] queue=default: capacity=1.0, absoluteCapacity=1.0, usedResources=<memory:0, vCores:0>, usedCapacity=0.0, absoluteUsedCapacity=0.0, numApps=1, numContainers=0 cluster=<memory:8192, vCores:8>
2020-03-21 15:00:01,309 INFO org.apache.hadoop.yarn.server.resourcemanager.scheduler.capacity.ParentQueue: completedContainer queue=root usedCapacity=0.0 absoluteUsedCapacity=0.0 used=<memory:0, vCores:0> cluster=<memory:8192, vCores:8>
2020-03-21 15:00:01,309 INFO org.apache.hadoop.yarn.server.resourcemanager.scheduler.capacity.ParentQueue: Re-sorting completed queue: root.default stats: default: capacity=1.0, absoluteCapacity=1.0, usedResources=<memory:0, vCores:0>, usedCapacity=0.0, absoluteUsedCapacity=0.0, numApps=1, numContainers=0
2020-03-21 15:00:01,309 INFO org.apache.hadoop.yarn.server.resourcemanager.scheduler.capacity.CapacityScheduler: Application attempt appattempt_1584766611743_0004_000002 released container container_1584766611743_0004_02_000001 on node: host: dell:34479 #containers=0 available=<memory:8192, vCores:8> used=<memory:0, vCores:0> with event: FINISHED
2020-03-21 15:00:01,309 INFO org.apache.hadoop.yarn.server.resourcemanager.rmapp.attempt.RMAppAttemptImpl: Updating application attempt appattempt_1584766611743_0004_000002 with final state: FAILED, and exit status: 126
2020-03-21 15:00:01,309 INFO org.apache.hadoop.yarn.server.resourcemanager.rmapp.attempt.RMAppAttemptImpl: appattempt_1584766611743_0004_000002 State change from LAUNCHED to FINAL_SAVING
2020-03-21 15:00:01,309 INFO org.apache.hadoop.yarn.server.resourcemanager.ApplicationMasterService: Unregistering app attempt : appattempt_1584766611743_0004_000002
2020-03-21 15:00:01,309 INFO org.apache.hadoop.yarn.server.resourcemanager.security.AMRMTokenSecretManager: Application finished, removing password for appattempt_1584766611743_0004_000002
2020-03-21 15:00:01,309 INFO org.apache.hadoop.yarn.server.resourcemanager.rmapp.attempt.RMAppAttemptImpl: appattempt_1584766611743_0004_000002 State change from FINAL_SAVING to FAILED
2020-03-21 15:00:01,309 INFO org.apache.hadoop.yarn.server.resourcemanager.rmapp.RMAppImpl: The number of failed attempts is 2. The max attempts is 2
2020-03-21 15:00:01,309 INFO org.apache.hadoop.yarn.server.resourcemanager.rmapp.RMAppImpl: Updating application application_1584766611743_0004 with final state: FAILED
2020-03-21 15:00:01,310 INFO org.apache.hadoop.yarn.server.resourcemanager.rmapp.RMAppImpl: application_1584766611743_0004 State change from ACCEPTED to FINAL_SAVING on event=ATTEMPT_FAILED
2020-03-21 15:00:01,310 INFO org.apache.hadoop.yarn.server.resourcemanager.recovery.RMStateStore: Updating info for app: application_1584766611743_0004
2020-03-21 15:00:01,310 INFO org.apache.hadoop.yarn.server.resourcemanager.scheduler.capacity.CapacityScheduler: Application Attempt appattempt_1584766611743_0004_000002 is done. finalState=FAILED
2020-03-21 15:00:01,310 INFO org.apache.hadoop.yarn.server.resourcemanager.rmapp.RMAppImpl: Application application_1584766611743_0004 failed 2 times due to AM Container for appattempt_1584766611743_0004_000002 exited with  exitCode: 126
For more detailed output, check application tracking page:http://dell:8088/cluster/app/application_1584766611743_0004Then, click on links to logs of each attempt.
Diagnostics: Exception from container-launch: 
ExitCodeException exitCode=126: Got permission denied while trying to connect to the Docker daemon socket at unix:///var/run/docker.sock: Get http://%2Fvar%2Frun%2Fdocker.sock/v1.40/containers/container_1584766611743_0004_02_000001/json: dial unix /var/run/docker.sock: connect: permission denied
/usr/bin/docker: Got permission denied while trying to connect to the Docker daemon socket at unix:///var/run/docker.sock: Post http://%2Fvar%2Frun%2Fdocker.sock/v1.40/containers/create?name=container_1584766611743_0004_02_000001: dial unix /var/run/docker.sock: connect: permission denied.
See '/usr/bin/docker run --help'.

	at org.apache.hadoop.util.Shell.runCommand(Shell.java:585)
	at org.apache.hadoop.util.Shell.run(Shell.java:482)
	at org.apache.hadoop.util.Shell$ShellCommandExecutor.execute(Shell.java:776)
	at org.apache.hadoop.yarn.server.nodemanager.DockerContainerExecutor.launchContainer(DockerContainerExecutor.java:247)
	at org.apache.hadoop.yarn.server.nodemanager.containermanager.launcher.ContainerLaunch.call(ContainerLaunch.java:302)
	at org.apache.hadoop.yarn.server.nodemanager.containermanager.launcher.ContainerLaunch.call(ContainerLaunch.java:82)
	at java.util.concurrent.FutureTask.run(FutureTask.java:266)
	at java.util.concurrent.ThreadPoolExecutor.runWorker(ThreadPoolExecutor.java:1142)
	at java.util.concurrent.ThreadPoolExecutor$Worker.run(ThreadPoolExecutor.java:617)
	at java.lang.Thread.run(Thread.java:748)


Container exited with a non-zero exit code 126
Failing this attempt. Failing the application.
2020-03-21 15:00:01,310 INFO org.apache.hadoop.yarn.server.resourcemanager.scheduler.AppSchedulingInfo: Application application_1584766611743_0004 requests cleared
2020-03-21 15:00:01,310 INFO org.apache.hadoop.yarn.server.resourcemanager.rmapp.RMAppImpl: application_1584766611743_0004 State change from FINAL_SAVING to FAILED on event=APP_UPDATE_SAVED
2020-03-21 15:00:01,310 WARN org.apache.hadoop.yarn.server.resourcemanager.RMAuditLogger: USER=xidian	OPERATION=Application Finished - Failed	TARGET=RMAppManager	RESULT=FAILURE	DESCRIPTION=App failed with state: FAILED	PERMISSIONS=Application application_1584766611743_0004 failed 2 times due to AM Container for appattempt_1584766611743_0004_000002 exited with  exitCode: 126
For more detailed output, check application tracking page:http://dell:8088/cluster/app/application_1584766611743_0004Then, click on links to logs of each attempt.
Diagnostics: Exception from container-launch: 
ExitCodeException exitCode=126: Got permission denied while trying to connect to the Docker daemon socket at unix:///var/run/docker.sock: Get http://%2Fvar%2Frun%2Fdocker.sock/v1.40/containers/container_1584766611743_0004_02_000001/json: dial unix /var/run/docker.sock: connect: permission denied
/usr/bin/docker: Got permission denied while trying to connect to the Docker daemon socket at unix:///var/run/docker.sock: Post http://%2Fvar%2Frun%2Fdocker.sock/v1.40/containers/create?name=container_1584766611743_0004_02_000001: dial unix /var/run/docker.sock: connect: permission denied.
See '/usr/bin/docker run --help'.

	at org.apache.hadoop.util.Shell.runCommand(Shell.java:585)
	at org.apache.hadoop.util.Shell.run(Shell.java:482)
	at org.apache.hadoop.util.Shell$ShellCommandExecutor.execute(Shell.java:776)
	at org.apache.hadoop.yarn.server.nodemanager.DockerContainerExecutor.launchContainer(DockerContainerExecutor.java:247)
	at org.apache.hadoop.yarn.server.nodemanager.containermanager.launcher.ContainerLaunch.call(ContainerLaunch.java:302)
	at org.apache.hadoop.yarn.server.nodemanager.containermanager.launcher.ContainerLaunch.call(ContainerLaunch.java:82)
	at java.util.concurrent.FutureTask.run(FutureTask.java:266)
	at java.util.concurrent.ThreadPoolExecutor.runWorker(ThreadPoolExecutor.java:1142)
	at java.util.concurrent.ThreadPoolExecutor$Worker.run(ThreadPoolExecutor.java:617)
	at java.lang.Thread.run(Thread.java:748)


Container exited with a non-zero exit code 126
Failing this attempt. Failing the application.	APPID=application_1584766611743_0004
2020-03-21 15:00:01,310 INFO org.apache.hadoop.yarn.server.resourcemanager.scheduler.capacity.LeafQueue: Application removed - appId: application_1584766611743_0004 user: xidian queue: default #user-pending-applications: 0 #user-active-applications: 0 #queue-pending-applications: 0 #queue-active-applications: 0
2020-03-21 15:00:01,310 INFO org.apache.hadoop.yarn.server.resourcemanager.scheduler.capacity.ParentQueue: Application removed - appId: application_1584766611743_0004 user: xidian leaf-queue of parent: root #applications: 0
2020-03-21 15:00:01,310 INFO org.apache.hadoop.yarn.server.resourcemanager.RMAppManager$ApplicationSummary: appId=application_1584766611743_0004,name=word count,user=xidian,queue=default,state=FAILED,trackingUrl=http://dell:8088/cluster/app/application_1584766611743_0004,appMasterHost=N/A,startTime=1584773995026,finishTime=1584774001309,finalStatus=FAILED,memorySeconds=9301,vcoreSeconds=4,preemptedAMContainers=0,preemptedNonAMContainers=0,preemptedResources=<memory:0\, vCores:0>,applicationType=MAPREDUCE
2020-03-21 15:54:12,394 INFO org.apache.hadoop.yarn.server.resourcemanager.ClientRMService: Allocated new applicationId: 5
2020-03-21 15:54:13,160 INFO org.apache.hadoop.yarn.server.resourcemanager.ClientRMService: Application with id 5 submitted by user xidian
2020-03-21 15:54:13,160 INFO org.apache.hadoop.yarn.server.resourcemanager.rmapp.RMAppImpl: Storing application with id application_1584766611743_0005
2020-03-21 15:54:13,160 INFO org.apache.hadoop.yarn.server.resourcemanager.rmapp.RMAppImpl: application_1584766611743_0005 State change from NEW to NEW_SAVING on event=START
2020-03-21 15:54:13,160 INFO org.apache.hadoop.yarn.server.resourcemanager.RMAuditLogger: USER=xidian	IP=127.0.0.1	OPERATION=Submit Application Request	TARGET=ClientRMService	RESULT=SUCCESS	APPID=application_1584766611743_0005
2020-03-21 15:54:13,160 INFO org.apache.hadoop.yarn.server.resourcemanager.recovery.RMStateStore: Storing info for app: application_1584766611743_0005
2020-03-21 15:54:13,161 INFO org.apache.hadoop.yarn.server.resourcemanager.rmapp.RMAppImpl: application_1584766611743_0005 State change from NEW_SAVING to SUBMITTED on event=APP_NEW_SAVED
2020-03-21 15:54:13,161 INFO org.apache.hadoop.yarn.server.resourcemanager.scheduler.capacity.ParentQueue: Application added - appId: application_1584766611743_0005 user: xidian leaf-queue of parent: root #applications: 1
2020-03-21 15:54:13,161 INFO org.apache.hadoop.yarn.server.resourcemanager.scheduler.capacity.CapacityScheduler: Accepted application application_1584766611743_0005 from user: xidian, in queue: default
2020-03-21 15:54:13,161 INFO org.apache.hadoop.yarn.server.resourcemanager.rmapp.RMAppImpl: application_1584766611743_0005 State change from SUBMITTED to ACCEPTED on event=APP_ACCEPTED
2020-03-21 15:54:13,161 INFO org.apache.hadoop.yarn.server.resourcemanager.ApplicationMasterService: Registering app attempt : appattempt_1584766611743_0005_000001
2020-03-21 15:54:13,161 INFO org.apache.hadoop.yarn.server.resourcemanager.rmapp.attempt.RMAppAttemptImpl: appattempt_1584766611743_0005_000001 State change from NEW to SUBMITTED
2020-03-21 15:54:13,161 WARN org.apache.hadoop.yarn.server.resourcemanager.scheduler.capacity.LeafQueue: maximum-am-resource-percent is insufficient to start a single application in queue, it is likely set too low. skipping enforcement to allow at least one application to start
2020-03-21 15:54:13,161 WARN org.apache.hadoop.yarn.server.resourcemanager.scheduler.capacity.LeafQueue: maximum-am-resource-percent is insufficient to start a single application in queue for user, it is likely set too low. skipping enforcement to allow at least one application to start
2020-03-21 15:54:13,161 INFO org.apache.hadoop.yarn.server.resourcemanager.scheduler.capacity.LeafQueue: Application application_1584766611743_0005 from user: xidian activated in queue: default
2020-03-21 15:54:13,161 INFO org.apache.hadoop.yarn.server.resourcemanager.scheduler.capacity.LeafQueue: Application added - appId: application_1584766611743_0005 user: org.apache.hadoop.yarn.server.resourcemanager.scheduler.capacity.LeafQueue$User@4f596e55, leaf-queue: default #user-pending-applications: 0 #user-active-applications: 1 #queue-pending-applications: 0 #queue-active-applications: 1
2020-03-21 15:54:13,161 INFO org.apache.hadoop.yarn.server.resourcemanager.scheduler.capacity.CapacityScheduler: Added Application Attempt appattempt_1584766611743_0005_000001 to scheduler from user xidian in queue default
2020-03-21 15:54:13,162 INFO org.apache.hadoop.yarn.server.resourcemanager.rmapp.attempt.RMAppAttemptImpl: appattempt_1584766611743_0005_000001 State change from SUBMITTED to SCHEDULED
2020-03-21 15:54:13,223 INFO org.apache.hadoop.yarn.server.resourcemanager.rmcontainer.RMContainerImpl: container_1584766611743_0005_01_000001 Container Transitioned from NEW to ALLOCATED
2020-03-21 15:54:13,223 INFO org.apache.hadoop.yarn.server.resourcemanager.RMAuditLogger: USER=xidian	OPERATION=AM Allocated Container	TARGET=SchedulerApp	RESULT=SUCCESS	APPID=application_1584766611743_0005	CONTAINERID=container_1584766611743_0005_01_000001
2020-03-21 15:54:13,223 INFO org.apache.hadoop.yarn.server.resourcemanager.scheduler.SchedulerNode: Assigned container container_1584766611743_0005_01_000001 of capacity <memory:2048, vCores:1> on host dell:34479, which has 1 containers, <memory:2048, vCores:1> used and <memory:6144, vCores:7> available after allocation
2020-03-21 15:54:13,223 INFO org.apache.hadoop.yarn.server.resourcemanager.scheduler.capacity.LeafQueue: assignedContainer application attempt=appattempt_1584766611743_0005_000001 container=Container: [ContainerId: container_1584766611743_0005_01_000001, NodeId: dell:34479, NodeHttpAddress: dell:8042, Resource: <memory:2048, vCores:1>, Priority: 0, Token: null, ] queue=default: capacity=1.0, absoluteCapacity=1.0, usedResources=<memory:0, vCores:0>, usedCapacity=0.0, absoluteUsedCapacity=0.0, numApps=1, numContainers=0 clusterResource=<memory:8192, vCores:8> type=OFF_SWITCH requestedPartition=
2020-03-21 15:54:13,223 INFO org.apache.hadoop.yarn.server.resourcemanager.scheduler.capacity.ParentQueue: Re-sorting assigned queue: root.default stats: default: capacity=1.0, absoluteCapacity=1.0, usedResources=<memory:2048, vCores:1>, usedCapacity=0.25, absoluteUsedCapacity=0.25, numApps=1, numContainers=1
2020-03-21 15:54:13,223 INFO org.apache.hadoop.yarn.server.resourcemanager.scheduler.capacity.ParentQueue: assignedContainer queue=root usedCapacity=0.25 absoluteUsedCapacity=0.25 used=<memory:2048, vCores:1> cluster=<memory:8192, vCores:8>
2020-03-21 15:54:13,224 INFO org.apache.hadoop.yarn.server.resourcemanager.security.NMTokenSecretManagerInRM: Sending NMToken for nodeId : dell:34479 for container : container_1584766611743_0005_01_000001
2020-03-21 15:54:13,225 INFO org.apache.hadoop.yarn.server.resourcemanager.rmcontainer.RMContainerImpl: container_1584766611743_0005_01_000001 Container Transitioned from ALLOCATED to ACQUIRED
2020-03-21 15:54:13,225 INFO org.apache.hadoop.yarn.server.resourcemanager.security.NMTokenSecretManagerInRM: Clear node set for appattempt_1584766611743_0005_000001
2020-03-21 15:54:13,225 INFO org.apache.hadoop.yarn.server.resourcemanager.rmapp.attempt.RMAppAttemptImpl: Storing attempt: AppId: application_1584766611743_0005 AttemptId: appattempt_1584766611743_0005_000001 MasterContainer: Container: [ContainerId: container_1584766611743_0005_01_000001, NodeId: dell:34479, NodeHttpAddress: dell:8042, Resource: <memory:2048, vCores:1>, Priority: 0, Token: Token { kind: ContainerToken, service: 127.0.1.1:34479 }, ]
2020-03-21 15:54:13,225 INFO org.apache.hadoop.yarn.server.resourcemanager.rmapp.attempt.RMAppAttemptImpl: appattempt_1584766611743_0005_000001 State change from SCHEDULED to ALLOCATED_SAVING
2020-03-21 15:54:13,225 INFO org.apache.hadoop.yarn.server.resourcemanager.rmapp.attempt.RMAppAttemptImpl: appattempt_1584766611743_0005_000001 State change from ALLOCATED_SAVING to ALLOCATED
2020-03-21 15:54:13,225 INFO org.apache.hadoop.yarn.server.resourcemanager.amlauncher.AMLauncher: Launching masterappattempt_1584766611743_0005_000001
2020-03-21 15:54:13,227 INFO org.apache.hadoop.yarn.server.resourcemanager.amlauncher.AMLauncher: Setting up container Container: [ContainerId: container_1584766611743_0005_01_000001, NodeId: dell:34479, NodeHttpAddress: dell:8042, Resource: <memory:2048, vCores:1>, Priority: 0, Token: Token { kind: ContainerToken, service: 127.0.1.1:34479 }, ] for AM appattempt_1584766611743_0005_000001
2020-03-21 15:54:13,227 INFO org.apache.hadoop.yarn.server.resourcemanager.amlauncher.AMLauncher: Command to launch container container_1584766611743_0005_01_000001 : $JAVA_HOME/bin/java -Djava.io.tmpdir=$PWD/tmp -Dlog4j.configuration=container-log4j.properties -Dyarn.app.container.log.dir=<LOG_DIR> -Dyarn.app.container.log.filesize=0 -Dhadoop.root.logger=INFO,CLA -Dhadoop.root.logfile=syslog  -Xmx1024m org.apache.hadoop.mapreduce.v2.app.MRAppMaster 1><LOG_DIR>/stdout 2><LOG_DIR>/stderr 
2020-03-21 15:54:13,227 INFO org.apache.hadoop.yarn.server.resourcemanager.security.AMRMTokenSecretManager: Create AMRMToken for ApplicationAttempt: appattempt_1584766611743_0005_000001
2020-03-21 15:54:13,227 INFO org.apache.hadoop.yarn.server.resourcemanager.security.AMRMTokenSecretManager: Creating password for appattempt_1584766611743_0005_000001
2020-03-21 15:54:13,235 INFO org.apache.hadoop.yarn.server.resourcemanager.amlauncher.AMLauncher: Done launching container Container: [ContainerId: container_1584766611743_0005_01_000001, NodeId: dell:34479, NodeHttpAddress: dell:8042, Resource: <memory:2048, vCores:1>, Priority: 0, Token: Token { kind: ContainerToken, service: 127.0.1.1:34479 }, ] for AM appattempt_1584766611743_0005_000001
2020-03-21 15:54:13,236 INFO org.apache.hadoop.yarn.server.resourcemanager.rmapp.attempt.RMAppAttemptImpl: appattempt_1584766611743_0005_000001 State change from ALLOCATED to LAUNCHED
2020-03-21 15:54:14,224 INFO org.apache.hadoop.yarn.server.resourcemanager.rmcontainer.RMContainerImpl: container_1584766611743_0005_01_000001 Container Transitioned from ACQUIRED to RUNNING
2020-03-21 15:54:15,491 INFO org.apache.hadoop.yarn.server.resourcemanager.rmcontainer.RMContainerImpl: container_1584766611743_0005_01_000001 Container Transitioned from RUNNING to COMPLETED
2020-03-21 15:54:15,491 INFO org.apache.hadoop.yarn.server.resourcemanager.scheduler.common.fica.FiCaSchedulerApp: Completed container: container_1584766611743_0005_01_000001 in state: COMPLETED event:FINISHED
2020-03-21 15:54:15,491 INFO org.apache.hadoop.yarn.server.resourcemanager.RMAuditLogger: USER=xidian	OPERATION=AM Released Container	TARGET=SchedulerApp	RESULT=SUCCESS	APPID=application_1584766611743_0005	CONTAINERID=container_1584766611743_0005_01_000001
2020-03-21 15:54:15,491 INFO org.apache.hadoop.yarn.server.resourcemanager.scheduler.SchedulerNode: Released container container_1584766611743_0005_01_000001 of capacity <memory:2048, vCores:1> on host dell:34479, which currently has 0 containers, <memory:0, vCores:0> used and <memory:8192, vCores:8> available, release resources=true
2020-03-21 15:54:15,491 INFO org.apache.hadoop.yarn.server.resourcemanager.scheduler.capacity.LeafQueue: default used=<memory:0, vCores:0> numContainers=0 user=xidian user-resources=<memory:0, vCores:0>
2020-03-21 15:54:15,491 INFO org.apache.hadoop.yarn.server.resourcemanager.scheduler.capacity.LeafQueue: completedContainer container=Container: [ContainerId: container_1584766611743_0005_01_000001, NodeId: dell:34479, NodeHttpAddress: dell:8042, Resource: <memory:2048, vCores:1>, Priority: 0, Token: Token { kind: ContainerToken, service: 127.0.1.1:34479 }, ] queue=default: capacity=1.0, absoluteCapacity=1.0, usedResources=<memory:0, vCores:0>, usedCapacity=0.0, absoluteUsedCapacity=0.0, numApps=1, numContainers=0 cluster=<memory:8192, vCores:8>
2020-03-21 15:54:15,491 INFO org.apache.hadoop.yarn.server.resourcemanager.scheduler.capacity.ParentQueue: completedContainer queue=root usedCapacity=0.0 absoluteUsedCapacity=0.0 used=<memory:0, vCores:0> cluster=<memory:8192, vCores:8>
2020-03-21 15:54:15,491 INFO org.apache.hadoop.yarn.server.resourcemanager.rmapp.attempt.RMAppAttemptImpl: Updating application attempt appattempt_1584766611743_0005_000001 with final state: FAILED, and exit status: 126
2020-03-21 15:54:15,492 INFO org.apache.hadoop.yarn.server.resourcemanager.scheduler.capacity.ParentQueue: Re-sorting completed queue: root.default stats: default: capacity=1.0, absoluteCapacity=1.0, usedResources=<memory:0, vCores:0>, usedCapacity=0.0, absoluteUsedCapacity=0.0, numApps=1, numContainers=0
2020-03-21 15:54:15,492 INFO org.apache.hadoop.yarn.server.resourcemanager.scheduler.capacity.CapacityScheduler: Application attempt appattempt_1584766611743_0005_000001 released container container_1584766611743_0005_01_000001 on node: host: dell:34479 #containers=0 available=<memory:8192, vCores:8> used=<memory:0, vCores:0> with event: FINISHED
2020-03-21 15:54:15,492 INFO org.apache.hadoop.yarn.server.resourcemanager.rmapp.attempt.RMAppAttemptImpl: appattempt_1584766611743_0005_000001 State change from LAUNCHED to FINAL_SAVING
2020-03-21 15:54:15,492 INFO org.apache.hadoop.yarn.server.resourcemanager.ApplicationMasterService: Unregistering app attempt : appattempt_1584766611743_0005_000001
2020-03-21 15:54:15,492 INFO org.apache.hadoop.yarn.server.resourcemanager.security.AMRMTokenSecretManager: Application finished, removing password for appattempt_1584766611743_0005_000001
2020-03-21 15:54:15,492 INFO org.apache.hadoop.yarn.server.resourcemanager.rmapp.attempt.RMAppAttemptImpl: appattempt_1584766611743_0005_000001 State change from FINAL_SAVING to FAILED
2020-03-21 15:54:15,492 INFO org.apache.hadoop.yarn.server.resourcemanager.rmapp.RMAppImpl: The number of failed attempts is 1. The max attempts is 2
2020-03-21 15:54:15,492 INFO org.apache.hadoop.yarn.server.resourcemanager.scheduler.capacity.CapacityScheduler: Application Attempt appattempt_1584766611743_0005_000001 is done. finalState=FAILED
2020-03-21 15:54:15,492 INFO org.apache.hadoop.yarn.server.resourcemanager.ApplicationMasterService: Registering app attempt : appattempt_1584766611743_0005_000002
2020-03-21 15:54:15,492 INFO org.apache.hadoop.yarn.server.resourcemanager.scheduler.AppSchedulingInfo: Application application_1584766611743_0005 requests cleared
2020-03-21 15:54:15,492 INFO org.apache.hadoop.yarn.server.resourcemanager.rmapp.attempt.RMAppAttemptImpl: appattempt_1584766611743_0005_000002 State change from NEW to SUBMITTED
2020-03-21 15:54:15,492 INFO org.apache.hadoop.yarn.server.resourcemanager.scheduler.capacity.LeafQueue: Application removed - appId: application_1584766611743_0005 user: xidian queue: default #user-pending-applications: 0 #user-active-applications: 0 #queue-pending-applications: 0 #queue-active-applications: 0
2020-03-21 15:54:15,492 WARN org.apache.hadoop.yarn.server.resourcemanager.scheduler.capacity.LeafQueue: maximum-am-resource-percent is insufficient to start a single application in queue, it is likely set too low. skipping enforcement to allow at least one application to start
2020-03-21 15:54:15,492 WARN org.apache.hadoop.yarn.server.resourcemanager.scheduler.capacity.LeafQueue: maximum-am-resource-percent is insufficient to start a single application in queue for user, it is likely set too low. skipping enforcement to allow at least one application to start
2020-03-21 15:54:15,492 INFO org.apache.hadoop.yarn.server.resourcemanager.scheduler.capacity.LeafQueue: Application application_1584766611743_0005 from user: xidian activated in queue: default
2020-03-21 15:54:15,492 INFO org.apache.hadoop.yarn.server.resourcemanager.scheduler.capacity.LeafQueue: Application added - appId: application_1584766611743_0005 user: org.apache.hadoop.yarn.server.resourcemanager.scheduler.capacity.LeafQueue$User@583145c1, leaf-queue: default #user-pending-applications: 0 #user-active-applications: 1 #queue-pending-applications: 0 #queue-active-applications: 1
2020-03-21 15:54:15,492 INFO org.apache.hadoop.yarn.server.resourcemanager.scheduler.capacity.CapacityScheduler: Added Application Attempt appattempt_1584766611743_0005_000002 to scheduler from user xidian in queue default
2020-03-21 15:54:15,493 INFO org.apache.hadoop.yarn.server.resourcemanager.rmapp.attempt.RMAppAttemptImpl: appattempt_1584766611743_0005_000002 State change from SUBMITTED to SCHEDULED
2020-03-21 15:54:16,493 INFO org.apache.hadoop.yarn.server.resourcemanager.rmcontainer.RMContainerImpl: container_1584766611743_0005_02_000001 Container Transitioned from NEW to ALLOCATED
2020-03-21 15:54:16,493 INFO org.apache.hadoop.yarn.server.resourcemanager.RMAuditLogger: USER=xidian	OPERATION=AM Allocated Container	TARGET=SchedulerApp	RESULT=SUCCESS	APPID=application_1584766611743_0005	CONTAINERID=container_1584766611743_0005_02_000001
2020-03-21 15:54:16,493 INFO org.apache.hadoop.yarn.server.resourcemanager.scheduler.SchedulerNode: Assigned container container_1584766611743_0005_02_000001 of capacity <memory:2048, vCores:1> on host dell:34479, which has 1 containers, <memory:2048, vCores:1> used and <memory:6144, vCores:7> available after allocation
2020-03-21 15:54:16,493 INFO org.apache.hadoop.yarn.server.resourcemanager.scheduler.capacity.LeafQueue: assignedContainer application attempt=appattempt_1584766611743_0005_000002 container=Container: [ContainerId: container_1584766611743_0005_02_000001, NodeId: dell:34479, NodeHttpAddress: dell:8042, Resource: <memory:2048, vCores:1>, Priority: 0, Token: null, ] queue=default: capacity=1.0, absoluteCapacity=1.0, usedResources=<memory:0, vCores:0>, usedCapacity=0.0, absoluteUsedCapacity=0.0, numApps=1, numContainers=0 clusterResource=<memory:8192, vCores:8> type=OFF_SWITCH requestedPartition=
2020-03-21 15:54:16,493 INFO org.apache.hadoop.yarn.server.resourcemanager.scheduler.capacity.ParentQueue: Re-sorting assigned queue: root.default stats: default: capacity=1.0, absoluteCapacity=1.0, usedResources=<memory:2048, vCores:1>, usedCapacity=0.25, absoluteUsedCapacity=0.25, numApps=1, numContainers=1
2020-03-21 15:54:16,493 INFO org.apache.hadoop.yarn.server.resourcemanager.scheduler.capacity.ParentQueue: assignedContainer queue=root usedCapacity=0.25 absoluteUsedCapacity=0.25 used=<memory:2048, vCores:1> cluster=<memory:8192, vCores:8>
2020-03-21 15:54:16,495 INFO org.apache.hadoop.yarn.server.resourcemanager.security.NMTokenSecretManagerInRM: Sending NMToken for nodeId : dell:34479 for container : container_1584766611743_0005_02_000001
2020-03-21 15:54:16,497 INFO org.apache.hadoop.yarn.server.resourcemanager.rmcontainer.RMContainerImpl: container_1584766611743_0005_02_000001 Container Transitioned from ALLOCATED to ACQUIRED
2020-03-21 15:54:16,498 INFO org.apache.hadoop.yarn.server.resourcemanager.security.NMTokenSecretManagerInRM: Clear node set for appattempt_1584766611743_0005_000002
2020-03-21 15:54:16,498 INFO org.apache.hadoop.yarn.server.resourcemanager.rmapp.attempt.RMAppAttemptImpl: Storing attempt: AppId: application_1584766611743_0005 AttemptId: appattempt_1584766611743_0005_000002 MasterContainer: Container: [ContainerId: container_1584766611743_0005_02_000001, NodeId: dell:34479, NodeHttpAddress: dell:8042, Resource: <memory:2048, vCores:1>, Priority: 0, Token: Token { kind: ContainerToken, service: 127.0.1.1:34479 }, ]
2020-03-21 15:54:16,498 INFO org.apache.hadoop.yarn.server.resourcemanager.rmapp.attempt.RMAppAttemptImpl: appattempt_1584766611743_0005_000002 State change from SCHEDULED to ALLOCATED_SAVING
2020-03-21 15:54:16,498 INFO org.apache.hadoop.yarn.server.resourcemanager.rmapp.attempt.RMAppAttemptImpl: appattempt_1584766611743_0005_000002 State change from ALLOCATED_SAVING to ALLOCATED
2020-03-21 15:54:16,499 INFO org.apache.hadoop.yarn.server.resourcemanager.amlauncher.AMLauncher: Launching masterappattempt_1584766611743_0005_000002
2020-03-21 15:54:16,503 INFO org.apache.hadoop.yarn.server.resourcemanager.amlauncher.AMLauncher: Setting up container Container: [ContainerId: container_1584766611743_0005_02_000001, NodeId: dell:34479, NodeHttpAddress: dell:8042, Resource: <memory:2048, vCores:1>, Priority: 0, Token: Token { kind: ContainerToken, service: 127.0.1.1:34479 }, ] for AM appattempt_1584766611743_0005_000002
2020-03-21 15:54:16,503 INFO org.apache.hadoop.yarn.server.resourcemanager.amlauncher.AMLauncher: Command to launch container container_1584766611743_0005_02_000001 : $JAVA_HOME/bin/java -Djava.io.tmpdir=$PWD/tmp -Dlog4j.configuration=container-log4j.properties -Dyarn.app.container.log.dir=<LOG_DIR> -Dyarn.app.container.log.filesize=0 -Dhadoop.root.logger=INFO,CLA -Dhadoop.root.logfile=syslog  -Xmx1024m org.apache.hadoop.mapreduce.v2.app.MRAppMaster 1><LOG_DIR>/stdout 2><LOG_DIR>/stderr 
2020-03-21 15:54:16,503 INFO org.apache.hadoop.yarn.server.resourcemanager.security.AMRMTokenSecretManager: Create AMRMToken for ApplicationAttempt: appattempt_1584766611743_0005_000002
2020-03-21 15:54:16,503 INFO org.apache.hadoop.yarn.server.resourcemanager.security.AMRMTokenSecretManager: Creating password for appattempt_1584766611743_0005_000002
2020-03-21 15:54:16,514 INFO org.apache.hadoop.yarn.server.resourcemanager.amlauncher.AMLauncher: Done launching container Container: [ContainerId: container_1584766611743_0005_02_000001, NodeId: dell:34479, NodeHttpAddress: dell:8042, Resource: <memory:2048, vCores:1>, Priority: 0, Token: Token { kind: ContainerToken, service: 127.0.1.1:34479 }, ] for AM appattempt_1584766611743_0005_000002
2020-03-21 15:54:16,514 INFO org.apache.hadoop.yarn.server.resourcemanager.rmapp.attempt.RMAppAttemptImpl: appattempt_1584766611743_0005_000002 State change from ALLOCATED to LAUNCHED
2020-03-21 15:54:17,496 INFO org.apache.hadoop.yarn.server.resourcemanager.rmcontainer.RMContainerImpl: container_1584766611743_0005_02_000001 Container Transitioned from ACQUIRED to RUNNING
2020-03-21 15:54:18,719 INFO org.apache.hadoop.yarn.server.resourcemanager.rmcontainer.RMContainerImpl: container_1584766611743_0005_02_000001 Container Transitioned from RUNNING to COMPLETED
2020-03-21 15:54:18,719 INFO org.apache.hadoop.yarn.server.resourcemanager.scheduler.common.fica.FiCaSchedulerApp: Completed container: container_1584766611743_0005_02_000001 in state: COMPLETED event:FINISHED
2020-03-21 15:54:18,719 INFO org.apache.hadoop.yarn.server.resourcemanager.RMAuditLogger: USER=xidian	OPERATION=AM Released Container	TARGET=SchedulerApp	RESULT=SUCCESS	APPID=application_1584766611743_0005	CONTAINERID=container_1584766611743_0005_02_000001
2020-03-21 15:54:18,719 INFO org.apache.hadoop.yarn.server.resourcemanager.scheduler.SchedulerNode: Released container container_1584766611743_0005_02_000001 of capacity <memory:2048, vCores:1> on host dell:34479, which currently has 0 containers, <memory:0, vCores:0> used and <memory:8192, vCores:8> available, release resources=true
2020-03-21 15:54:18,719 INFO org.apache.hadoop.yarn.server.resourcemanager.rmapp.attempt.RMAppAttemptImpl: Updating application attempt appattempt_1584766611743_0005_000002 with final state: FAILED, and exit status: 126
2020-03-21 15:54:18,719 INFO org.apache.hadoop.yarn.server.resourcemanager.scheduler.capacity.LeafQueue: default used=<memory:0, vCores:0> numContainers=0 user=xidian user-resources=<memory:0, vCores:0>
2020-03-21 15:54:18,719 INFO org.apache.hadoop.yarn.server.resourcemanager.rmapp.attempt.RMAppAttemptImpl: appattempt_1584766611743_0005_000002 State change from LAUNCHED to FINAL_SAVING
2020-03-21 15:54:18,719 INFO org.apache.hadoop.yarn.server.resourcemanager.ApplicationMasterService: Unregistering app attempt : appattempt_1584766611743_0005_000002
2020-03-21 15:54:18,719 INFO org.apache.hadoop.yarn.server.resourcemanager.scheduler.capacity.LeafQueue: completedContainer container=Container: [ContainerId: container_1584766611743_0005_02_000001, NodeId: dell:34479, NodeHttpAddress: dell:8042, Resource: <memory:2048, vCores:1>, Priority: 0, Token: Token { kind: ContainerToken, service: 127.0.1.1:34479 }, ] queue=default: capacity=1.0, absoluteCapacity=1.0, usedResources=<memory:0, vCores:0>, usedCapacity=0.0, absoluteUsedCapacity=0.0, numApps=1, numContainers=0 cluster=<memory:8192, vCores:8>
2020-03-21 15:54:18,719 INFO org.apache.hadoop.yarn.server.resourcemanager.security.AMRMTokenSecretManager: Application finished, removing password for appattempt_1584766611743_0005_000002
2020-03-21 15:54:18,719 INFO org.apache.hadoop.yarn.server.resourcemanager.rmapp.attempt.RMAppAttemptImpl: appattempt_1584766611743_0005_000002 State change from FINAL_SAVING to FAILED
2020-03-21 15:54:18,719 INFO org.apache.hadoop.yarn.server.resourcemanager.scheduler.capacity.ParentQueue: completedContainer queue=root usedCapacity=0.0 absoluteUsedCapacity=0.0 used=<memory:0, vCores:0> cluster=<memory:8192, vCores:8>
2020-03-21 15:54:18,719 INFO org.apache.hadoop.yarn.server.resourcemanager.scheduler.capacity.ParentQueue: Re-sorting completed queue: root.default stats: default: capacity=1.0, absoluteCapacity=1.0, usedResources=<memory:0, vCores:0>, usedCapacity=0.0, absoluteUsedCapacity=0.0, numApps=1, numContainers=0
2020-03-21 15:54:18,719 INFO org.apache.hadoop.yarn.server.resourcemanager.rmapp.RMAppImpl: The number of failed attempts is 2. The max attempts is 2
2020-03-21 15:54:18,719 INFO org.apache.hadoop.yarn.server.resourcemanager.scheduler.capacity.CapacityScheduler: Application attempt appattempt_1584766611743_0005_000002 released container container_1584766611743_0005_02_000001 on node: host: dell:34479 #containers=0 available=<memory:8192, vCores:8> used=<memory:0, vCores:0> with event: FINISHED
2020-03-21 15:54:18,719 INFO org.apache.hadoop.yarn.server.resourcemanager.rmapp.RMAppImpl: Updating application application_1584766611743_0005 with final state: FAILED
2020-03-21 15:54:18,719 INFO org.apache.hadoop.yarn.server.resourcemanager.rmapp.RMAppImpl: application_1584766611743_0005 State change from ACCEPTED to FINAL_SAVING on event=ATTEMPT_FAILED
2020-03-21 15:54:18,719 INFO org.apache.hadoop.yarn.server.resourcemanager.recovery.RMStateStore: Updating info for app: application_1584766611743_0005
2020-03-21 15:54:18,719 INFO org.apache.hadoop.yarn.server.resourcemanager.scheduler.capacity.CapacityScheduler: Application Attempt appattempt_1584766611743_0005_000002 is done. finalState=FAILED
2020-03-21 15:54:18,719 INFO org.apache.hadoop.yarn.server.resourcemanager.rmapp.RMAppImpl: Application application_1584766611743_0005 failed 2 times due to AM Container for appattempt_1584766611743_0005_000002 exited with  exitCode: 126
For more detailed output, check application tracking page:http://dell:8088/cluster/app/application_1584766611743_0005Then, click on links to logs of each attempt.
Diagnostics: Exception from container-launch: 
ExitCodeException exitCode=126: Got permission denied while trying to connect to the Docker daemon socket at unix:///var/run/docker.sock: Get http://%2Fvar%2Frun%2Fdocker.sock/v1.40/containers/container_1584766611743_0005_02_000001/json: dial unix /var/run/docker.sock: connect: permission denied
/usr/bin/docker: Got permission denied while trying to connect to the Docker daemon socket at unix:///var/run/docker.sock: Post http://%2Fvar%2Frun%2Fdocker.sock/v1.40/containers/create?name=container_1584766611743_0005_02_000001: dial unix /var/run/docker.sock: connect: permission denied.
See '/usr/bin/docker run --help'.

	at org.apache.hadoop.util.Shell.runCommand(Shell.java:585)
	at org.apache.hadoop.util.Shell.run(Shell.java:482)
	at org.apache.hadoop.util.Shell$ShellCommandExecutor.execute(Shell.java:776)
	at org.apache.hadoop.yarn.server.nodemanager.DockerContainerExecutor.launchContainer(DockerContainerExecutor.java:247)
	at org.apache.hadoop.yarn.server.nodemanager.containermanager.launcher.ContainerLaunch.call(ContainerLaunch.java:302)
	at org.apache.hadoop.yarn.server.nodemanager.containermanager.launcher.ContainerLaunch.call(ContainerLaunch.java:82)
	at java.util.concurrent.FutureTask.run(FutureTask.java:266)
	at java.util.concurrent.ThreadPoolExecutor.runWorker(ThreadPoolExecutor.java:1142)
	at java.util.concurrent.ThreadPoolExecutor$Worker.run(ThreadPoolExecutor.java:617)
	at java.lang.Thread.run(Thread.java:748)


Container exited with a non-zero exit code 126
Failing this attempt. Failing the application.
2020-03-21 15:54:18,720 INFO org.apache.hadoop.yarn.server.resourcemanager.scheduler.AppSchedulingInfo: Application application_1584766611743_0005 requests cleared
2020-03-21 15:54:18,720 INFO org.apache.hadoop.yarn.server.resourcemanager.rmapp.RMAppImpl: application_1584766611743_0005 State change from FINAL_SAVING to FAILED on event=APP_UPDATE_SAVED
2020-03-21 15:54:18,720 WARN org.apache.hadoop.yarn.server.resourcemanager.RMAuditLogger: USER=xidian	OPERATION=Application Finished - Failed	TARGET=RMAppManager	RESULT=FAILURE	DESCRIPTION=App failed with state: FAILED	PERMISSIONS=Application application_1584766611743_0005 failed 2 times due to AM Container for appattempt_1584766611743_0005_000002 exited with  exitCode: 126
For more detailed output, check application tracking page:http://dell:8088/cluster/app/application_1584766611743_0005Then, click on links to logs of each attempt.
Diagnostics: Exception from container-launch: 
ExitCodeException exitCode=126: Got permission denied while trying to connect to the Docker daemon socket at unix:///var/run/docker.sock: Get http://%2Fvar%2Frun%2Fdocker.sock/v1.40/containers/container_1584766611743_0005_02_000001/json: dial unix /var/run/docker.sock: connect: permission denied
/usr/bin/docker: Got permission denied while trying to connect to the Docker daemon socket at unix:///var/run/docker.sock: Post http://%2Fvar%2Frun%2Fdocker.sock/v1.40/containers/create?name=container_1584766611743_0005_02_000001: dial unix /var/run/docker.sock: connect: permission denied.
See '/usr/bin/docker run --help'.

	at org.apache.hadoop.util.Shell.runCommand(Shell.java:585)
	at org.apache.hadoop.util.Shell.run(Shell.java:482)
	at org.apache.hadoop.util.Shell$ShellCommandExecutor.execute(Shell.java:776)
	at org.apache.hadoop.yarn.server.nodemanager.DockerContainerExecutor.launchContainer(DockerContainerExecutor.java:247)
	at org.apache.hadoop.yarn.server.nodemanager.containermanager.launcher.ContainerLaunch.call(ContainerLaunch.java:302)
	at org.apache.hadoop.yarn.server.nodemanager.containermanager.launcher.ContainerLaunch.call(ContainerLaunch.java:82)
	at java.util.concurrent.FutureTask.run(FutureTask.java:266)
	at java.util.concurrent.ThreadPoolExecutor.runWorker(ThreadPoolExecutor.java:1142)
	at java.util.concurrent.ThreadPoolExecutor$Worker.run(ThreadPoolExecutor.java:617)
	at java.lang.Thread.run(Thread.java:748)


Container exited with a non-zero exit code 126
Failing this attempt. Failing the application.	APPID=application_1584766611743_0005
2020-03-21 15:54:18,720 INFO org.apache.hadoop.yarn.server.resourcemanager.scheduler.capacity.LeafQueue: Application removed - appId: application_1584766611743_0005 user: xidian queue: default #user-pending-applications: 0 #user-active-applications: 0 #queue-pending-applications: 0 #queue-active-applications: 0
2020-03-21 15:54:18,720 INFO org.apache.hadoop.yarn.server.resourcemanager.scheduler.capacity.ParentQueue: Application removed - appId: application_1584766611743_0005 user: xidian leaf-queue of parent: root #applications: 0
2020-03-21 15:54:18,720 INFO org.apache.hadoop.yarn.server.resourcemanager.RMAppManager$ApplicationSummary: appId=application_1584766611743_0005,name=word count,user=xidian,queue=default,state=FAILED,trackingUrl=http://dell:8088/cluster/app/application_1584766611743_0005,appMasterHost=N/A,startTime=1584777253160,finishTime=1584777258719,finalStatus=FAILED,memorySeconds=9202,vcoreSeconds=4,preemptedAMContainers=0,preemptedNonAMContainers=0,preemptedResources=<memory:0\, vCores:0>,applicationType=MAPREDUCE
2020-03-21 16:12:38,253 INFO org.apache.hadoop.yarn.server.resourcemanager.ClientRMService: Allocated new applicationId: 6
2020-03-21 16:12:40,461 INFO org.apache.hadoop.yarn.server.resourcemanager.ClientRMService: Application with id 6 submitted by user xidian
2020-03-21 16:12:40,461 INFO org.apache.hadoop.yarn.server.resourcemanager.rmapp.RMAppImpl: Storing application with id application_1584766611743_0006
2020-03-21 16:12:40,461 INFO org.apache.hadoop.yarn.server.resourcemanager.RMAuditLogger: USER=xidian	IP=127.0.0.1	OPERATION=Submit Application Request	TARGET=ClientRMService	RESULT=SUCCESS	APPID=application_1584766611743_0006
2020-03-21 16:12:40,461 INFO org.apache.hadoop.yarn.server.resourcemanager.rmapp.RMAppImpl: application_1584766611743_0006 State change from NEW to NEW_SAVING on event=START
2020-03-21 16:12:40,462 INFO org.apache.hadoop.yarn.server.resourcemanager.recovery.RMStateStore: Storing info for app: application_1584766611743_0006
2020-03-21 16:12:40,462 INFO org.apache.hadoop.yarn.server.resourcemanager.rmapp.RMAppImpl: application_1584766611743_0006 State change from NEW_SAVING to SUBMITTED on event=APP_NEW_SAVED
2020-03-21 16:12:40,463 INFO org.apache.hadoop.yarn.server.resourcemanager.scheduler.capacity.ParentQueue: Application added - appId: application_1584766611743_0006 user: xidian leaf-queue of parent: root #applications: 1
2020-03-21 16:12:40,463 INFO org.apache.hadoop.yarn.server.resourcemanager.scheduler.capacity.CapacityScheduler: Accepted application application_1584766611743_0006 from user: xidian, in queue: default
2020-03-21 16:12:40,463 INFO org.apache.hadoop.yarn.server.resourcemanager.rmapp.RMAppImpl: application_1584766611743_0006 State change from SUBMITTED to ACCEPTED on event=APP_ACCEPTED
2020-03-21 16:12:40,464 INFO org.apache.hadoop.yarn.server.resourcemanager.ApplicationMasterService: Registering app attempt : appattempt_1584766611743_0006_000001
2020-03-21 16:12:40,464 INFO org.apache.hadoop.yarn.server.resourcemanager.rmapp.attempt.RMAppAttemptImpl: appattempt_1584766611743_0006_000001 State change from NEW to SUBMITTED
2020-03-21 16:12:40,464 WARN org.apache.hadoop.yarn.server.resourcemanager.scheduler.capacity.LeafQueue: maximum-am-resource-percent is insufficient to start a single application in queue, it is likely set too low. skipping enforcement to allow at least one application to start
2020-03-21 16:12:40,464 WARN org.apache.hadoop.yarn.server.resourcemanager.scheduler.capacity.LeafQueue: maximum-am-resource-percent is insufficient to start a single application in queue for user, it is likely set too low. skipping enforcement to allow at least one application to start
2020-03-21 16:12:40,464 INFO org.apache.hadoop.yarn.server.resourcemanager.scheduler.capacity.LeafQueue: Application application_1584766611743_0006 from user: xidian activated in queue: default
2020-03-21 16:12:40,464 INFO org.apache.hadoop.yarn.server.resourcemanager.scheduler.capacity.LeafQueue: Application added - appId: application_1584766611743_0006 user: org.apache.hadoop.yarn.server.resourcemanager.scheduler.capacity.LeafQueue$User@b9967a9, leaf-queue: default #user-pending-applications: 0 #user-active-applications: 1 #queue-pending-applications: 0 #queue-active-applications: 1
2020-03-21 16:12:40,464 INFO org.apache.hadoop.yarn.server.resourcemanager.scheduler.capacity.CapacityScheduler: Added Application Attempt appattempt_1584766611743_0006_000001 to scheduler from user xidian in queue default
2020-03-21 16:12:40,466 INFO org.apache.hadoop.yarn.server.resourcemanager.rmapp.attempt.RMAppAttemptImpl: appattempt_1584766611743_0006_000001 State change from SUBMITTED to SCHEDULED
2020-03-21 16:12:40,738 INFO org.apache.hadoop.yarn.server.resourcemanager.rmcontainer.RMContainerImpl: container_1584766611743_0006_01_000001 Container Transitioned from NEW to ALLOCATED
2020-03-21 16:12:40,738 INFO org.apache.hadoop.yarn.server.resourcemanager.RMAuditLogger: USER=xidian	OPERATION=AM Allocated Container	TARGET=SchedulerApp	RESULT=SUCCESS	APPID=application_1584766611743_0006	CONTAINERID=container_1584766611743_0006_01_000001
2020-03-21 16:12:40,738 INFO org.apache.hadoop.yarn.server.resourcemanager.scheduler.SchedulerNode: Assigned container container_1584766611743_0006_01_000001 of capacity <memory:2048, vCores:1> on host dell:34479, which has 1 containers, <memory:2048, vCores:1> used and <memory:6144, vCores:7> available after allocation
2020-03-21 16:12:40,738 INFO org.apache.hadoop.yarn.server.resourcemanager.scheduler.capacity.LeafQueue: assignedContainer application attempt=appattempt_1584766611743_0006_000001 container=Container: [ContainerId: container_1584766611743_0006_01_000001, NodeId: dell:34479, NodeHttpAddress: dell:8042, Resource: <memory:2048, vCores:1>, Priority: 0, Token: null, ] queue=default: capacity=1.0, absoluteCapacity=1.0, usedResources=<memory:0, vCores:0>, usedCapacity=0.0, absoluteUsedCapacity=0.0, numApps=1, numContainers=0 clusterResource=<memory:8192, vCores:8> type=OFF_SWITCH requestedPartition=
2020-03-21 16:12:40,738 INFO org.apache.hadoop.yarn.server.resourcemanager.scheduler.capacity.ParentQueue: Re-sorting assigned queue: root.default stats: default: capacity=1.0, absoluteCapacity=1.0, usedResources=<memory:2048, vCores:1>, usedCapacity=0.25, absoluteUsedCapacity=0.25, numApps=1, numContainers=1
2020-03-21 16:12:40,738 INFO org.apache.hadoop.yarn.server.resourcemanager.scheduler.capacity.ParentQueue: assignedContainer queue=root usedCapacity=0.25 absoluteUsedCapacity=0.25 used=<memory:2048, vCores:1> cluster=<memory:8192, vCores:8>
2020-03-21 16:12:40,739 INFO org.apache.hadoop.yarn.server.resourcemanager.security.NMTokenSecretManagerInRM: Sending NMToken for nodeId : dell:34479 for container : container_1584766611743_0006_01_000001
2020-03-21 16:12:40,741 INFO org.apache.hadoop.yarn.server.resourcemanager.rmcontainer.RMContainerImpl: container_1584766611743_0006_01_000001 Container Transitioned from ALLOCATED to ACQUIRED
2020-03-21 16:12:40,741 INFO org.apache.hadoop.yarn.server.resourcemanager.security.NMTokenSecretManagerInRM: Clear node set for appattempt_1584766611743_0006_000001
2020-03-21 16:12:40,741 INFO org.apache.hadoop.yarn.server.resourcemanager.rmapp.attempt.RMAppAttemptImpl: Storing attempt: AppId: application_1584766611743_0006 AttemptId: appattempt_1584766611743_0006_000001 MasterContainer: Container: [ContainerId: container_1584766611743_0006_01_000001, NodeId: dell:34479, NodeHttpAddress: dell:8042, Resource: <memory:2048, vCores:1>, Priority: 0, Token: Token { kind: ContainerToken, service: 127.0.1.1:34479 }, ]
2020-03-21 16:12:40,741 INFO org.apache.hadoop.yarn.server.resourcemanager.rmapp.attempt.RMAppAttemptImpl: appattempt_1584766611743_0006_000001 State change from SCHEDULED to ALLOCATED_SAVING
2020-03-21 16:12:40,741 INFO org.apache.hadoop.yarn.server.resourcemanager.rmapp.attempt.RMAppAttemptImpl: appattempt_1584766611743_0006_000001 State change from ALLOCATED_SAVING to ALLOCATED
2020-03-21 16:12:40,742 INFO org.apache.hadoop.yarn.server.resourcemanager.amlauncher.AMLauncher: Launching masterappattempt_1584766611743_0006_000001
2020-03-21 16:12:40,746 INFO org.apache.hadoop.yarn.server.resourcemanager.amlauncher.AMLauncher: Setting up container Container: [ContainerId: container_1584766611743_0006_01_000001, NodeId: dell:34479, NodeHttpAddress: dell:8042, Resource: <memory:2048, vCores:1>, Priority: 0, Token: Token { kind: ContainerToken, service: 127.0.1.1:34479 }, ] for AM appattempt_1584766611743_0006_000001
2020-03-21 16:12:40,746 INFO org.apache.hadoop.yarn.server.resourcemanager.amlauncher.AMLauncher: Command to launch container container_1584766611743_0006_01_000001 : $JAVA_HOME/bin/java -Djava.io.tmpdir=$PWD/tmp -Dlog4j.configuration=container-log4j.properties -Dyarn.app.container.log.dir=<LOG_DIR> -Dyarn.app.container.log.filesize=0 -Dhadoop.root.logger=INFO,CLA -Dhadoop.root.logfile=syslog  -Xmx1024m org.apache.hadoop.mapreduce.v2.app.MRAppMaster 1><LOG_DIR>/stdout 2><LOG_DIR>/stderr 
2020-03-21 16:12:40,746 INFO org.apache.hadoop.yarn.server.resourcemanager.security.AMRMTokenSecretManager: Create AMRMToken for ApplicationAttempt: appattempt_1584766611743_0006_000001
2020-03-21 16:12:40,746 INFO org.apache.hadoop.yarn.server.resourcemanager.security.AMRMTokenSecretManager: Creating password for appattempt_1584766611743_0006_000001
2020-03-21 16:12:40,761 INFO org.apache.hadoop.yarn.server.resourcemanager.amlauncher.AMLauncher: Done launching container Container: [ContainerId: container_1584766611743_0006_01_000001, NodeId: dell:34479, NodeHttpAddress: dell:8042, Resource: <memory:2048, vCores:1>, Priority: 0, Token: Token { kind: ContainerToken, service: 127.0.1.1:34479 }, ] for AM appattempt_1584766611743_0006_000001
2020-03-21 16:12:40,761 INFO org.apache.hadoop.yarn.server.resourcemanager.rmapp.attempt.RMAppAttemptImpl: appattempt_1584766611743_0006_000001 State change from ALLOCATED to LAUNCHED
2020-03-21 16:12:41,739 INFO org.apache.hadoop.yarn.server.resourcemanager.rmcontainer.RMContainerImpl: container_1584766611743_0006_01_000001 Container Transitioned from ACQUIRED to RUNNING
2020-03-21 16:12:43,277 INFO org.apache.hadoop.yarn.server.resourcemanager.rmcontainer.RMContainerImpl: container_1584766611743_0006_01_000001 Container Transitioned from RUNNING to COMPLETED
2020-03-21 16:12:43,278 INFO org.apache.hadoop.yarn.server.resourcemanager.scheduler.common.fica.FiCaSchedulerApp: Completed container: container_1584766611743_0006_01_000001 in state: COMPLETED event:FINISHED
2020-03-21 16:12:43,278 INFO org.apache.hadoop.yarn.server.resourcemanager.RMAuditLogger: USER=xidian	OPERATION=AM Released Container	TARGET=SchedulerApp	RESULT=SUCCESS	APPID=application_1584766611743_0006	CONTAINERID=container_1584766611743_0006_01_000001
2020-03-21 16:12:43,278 INFO org.apache.hadoop.yarn.server.resourcemanager.scheduler.SchedulerNode: Released container container_1584766611743_0006_01_000001 of capacity <memory:2048, vCores:1> on host dell:34479, which currently has 0 containers, <memory:0, vCores:0> used and <memory:8192, vCores:8> available, release resources=true
2020-03-21 16:12:43,278 INFO org.apache.hadoop.yarn.server.resourcemanager.scheduler.capacity.LeafQueue: default used=<memory:0, vCores:0> numContainers=0 user=xidian user-resources=<memory:0, vCores:0>
2020-03-21 16:12:43,278 INFO org.apache.hadoop.yarn.server.resourcemanager.scheduler.capacity.LeafQueue: completedContainer container=Container: [ContainerId: container_1584766611743_0006_01_000001, NodeId: dell:34479, NodeHttpAddress: dell:8042, Resource: <memory:2048, vCores:1>, Priority: 0, Token: Token { kind: ContainerToken, service: 127.0.1.1:34479 }, ] queue=default: capacity=1.0, absoluteCapacity=1.0, usedResources=<memory:0, vCores:0>, usedCapacity=0.0, absoluteUsedCapacity=0.0, numApps=1, numContainers=0 cluster=<memory:8192, vCores:8>
2020-03-21 16:12:43,278 INFO org.apache.hadoop.yarn.server.resourcemanager.scheduler.capacity.ParentQueue: completedContainer queue=root usedCapacity=0.0 absoluteUsedCapacity=0.0 used=<memory:0, vCores:0> cluster=<memory:8192, vCores:8>
2020-03-21 16:12:43,278 INFO org.apache.hadoop.yarn.server.resourcemanager.scheduler.capacity.ParentQueue: Re-sorting completed queue: root.default stats: default: capacity=1.0, absoluteCapacity=1.0, usedResources=<memory:0, vCores:0>, usedCapacity=0.0, absoluteUsedCapacity=0.0, numApps=1, numContainers=0
2020-03-21 16:12:43,278 INFO org.apache.hadoop.yarn.server.resourcemanager.scheduler.capacity.CapacityScheduler: Application attempt appattempt_1584766611743_0006_000001 released container container_1584766611743_0006_01_000001 on node: host: dell:34479 #containers=0 available=<memory:8192, vCores:8> used=<memory:0, vCores:0> with event: FINISHED
2020-03-21 16:12:43,278 INFO org.apache.hadoop.yarn.server.resourcemanager.rmapp.attempt.RMAppAttemptImpl: Updating application attempt appattempt_1584766611743_0006_000001 with final state: FAILED, and exit status: 126
2020-03-21 16:12:43,279 INFO org.apache.hadoop.yarn.server.resourcemanager.rmapp.attempt.RMAppAttemptImpl: appattempt_1584766611743_0006_000001 State change from LAUNCHED to FINAL_SAVING
2020-03-21 16:12:43,279 INFO org.apache.hadoop.yarn.server.resourcemanager.ApplicationMasterService: Unregistering app attempt : appattempt_1584766611743_0006_000001
2020-03-21 16:12:43,279 INFO org.apache.hadoop.yarn.server.resourcemanager.security.AMRMTokenSecretManager: Application finished, removing password for appattempt_1584766611743_0006_000001
2020-03-21 16:12:43,279 INFO org.apache.hadoop.yarn.server.resourcemanager.rmapp.attempt.RMAppAttemptImpl: appattempt_1584766611743_0006_000001 State change from FINAL_SAVING to FAILED
2020-03-21 16:12:43,280 INFO org.apache.hadoop.yarn.server.resourcemanager.rmapp.RMAppImpl: The number of failed attempts is 1. The max attempts is 2
2020-03-21 16:12:43,280 INFO org.apache.hadoop.yarn.server.resourcemanager.scheduler.capacity.CapacityScheduler: Application Attempt appattempt_1584766611743_0006_000001 is done. finalState=FAILED
2020-03-21 16:12:43,280 INFO org.apache.hadoop.yarn.server.resourcemanager.ApplicationMasterService: Registering app attempt : appattempt_1584766611743_0006_000002
2020-03-21 16:12:43,280 INFO org.apache.hadoop.yarn.server.resourcemanager.rmapp.attempt.RMAppAttemptImpl: appattempt_1584766611743_0006_000002 State change from NEW to SUBMITTED
2020-03-21 16:12:43,280 INFO org.apache.hadoop.yarn.server.resourcemanager.scheduler.AppSchedulingInfo: Application application_1584766611743_0006 requests cleared
2020-03-21 16:12:43,280 INFO org.apache.hadoop.yarn.server.resourcemanager.scheduler.capacity.LeafQueue: Application removed - appId: application_1584766611743_0006 user: xidian queue: default #user-pending-applications: 0 #user-active-applications: 0 #queue-pending-applications: 0 #queue-active-applications: 0
2020-03-21 16:12:43,280 WARN org.apache.hadoop.yarn.server.resourcemanager.scheduler.capacity.LeafQueue: maximum-am-resource-percent is insufficient to start a single application in queue, it is likely set too low. skipping enforcement to allow at least one application to start
2020-03-21 16:12:43,280 WARN org.apache.hadoop.yarn.server.resourcemanager.scheduler.capacity.LeafQueue: maximum-am-resource-percent is insufficient to start a single application in queue for user, it is likely set too low. skipping enforcement to allow at least one application to start
2020-03-21 16:12:43,280 INFO org.apache.hadoop.yarn.server.resourcemanager.scheduler.capacity.LeafQueue: Application application_1584766611743_0006 from user: xidian activated in queue: default
2020-03-21 16:12:43,280 INFO org.apache.hadoop.yarn.server.resourcemanager.scheduler.capacity.LeafQueue: Application added - appId: application_1584766611743_0006 user: org.apache.hadoop.yarn.server.resourcemanager.scheduler.capacity.LeafQueue$User@5de5d74f, leaf-queue: default #user-pending-applications: 0 #user-active-applications: 1 #queue-pending-applications: 0 #queue-active-applications: 1
2020-03-21 16:12:43,280 INFO org.apache.hadoop.yarn.server.resourcemanager.scheduler.capacity.CapacityScheduler: Added Application Attempt appattempt_1584766611743_0006_000002 to scheduler from user xidian in queue default
2020-03-21 16:12:43,283 INFO org.apache.hadoop.yarn.server.resourcemanager.rmapp.attempt.RMAppAttemptImpl: appattempt_1584766611743_0006_000002 State change from SUBMITTED to SCHEDULED
2020-03-21 16:12:44,276 INFO org.apache.hadoop.yarn.server.resourcemanager.rmcontainer.RMContainerImpl: container_1584766611743_0006_02_000001 Container Transitioned from NEW to ALLOCATED
2020-03-21 16:12:44,276 INFO org.apache.hadoop.yarn.server.resourcemanager.RMAuditLogger: USER=xidian	OPERATION=AM Allocated Container	TARGET=SchedulerApp	RESULT=SUCCESS	APPID=application_1584766611743_0006	CONTAINERID=container_1584766611743_0006_02_000001
2020-03-21 16:12:44,276 INFO org.apache.hadoop.yarn.server.resourcemanager.scheduler.SchedulerNode: Assigned container container_1584766611743_0006_02_000001 of capacity <memory:2048, vCores:1> on host dell:34479, which has 1 containers, <memory:2048, vCores:1> used and <memory:6144, vCores:7> available after allocation
2020-03-21 16:12:44,276 INFO org.apache.hadoop.yarn.server.resourcemanager.scheduler.capacity.LeafQueue: assignedContainer application attempt=appattempt_1584766611743_0006_000002 container=Container: [ContainerId: container_1584766611743_0006_02_000001, NodeId: dell:34479, NodeHttpAddress: dell:8042, Resource: <memory:2048, vCores:1>, Priority: 0, Token: null, ] queue=default: capacity=1.0, absoluteCapacity=1.0, usedResources=<memory:0, vCores:0>, usedCapacity=0.0, absoluteUsedCapacity=0.0, numApps=1, numContainers=0 clusterResource=<memory:8192, vCores:8> type=OFF_SWITCH requestedPartition=
2020-03-21 16:12:44,277 INFO org.apache.hadoop.yarn.server.resourcemanager.scheduler.capacity.ParentQueue: Re-sorting assigned queue: root.default stats: default: capacity=1.0, absoluteCapacity=1.0, usedResources=<memory:2048, vCores:1>, usedCapacity=0.25, absoluteUsedCapacity=0.25, numApps=1, numContainers=1
2020-03-21 16:12:44,277 INFO org.apache.hadoop.yarn.server.resourcemanager.scheduler.capacity.ParentQueue: assignedContainer queue=root usedCapacity=0.25 absoluteUsedCapacity=0.25 used=<memory:2048, vCores:1> cluster=<memory:8192, vCores:8>
2020-03-21 16:12:44,277 INFO org.apache.hadoop.yarn.server.resourcemanager.security.NMTokenSecretManagerInRM: Sending NMToken for nodeId : dell:34479 for container : container_1584766611743_0006_02_000001
2020-03-21 16:12:44,279 INFO org.apache.hadoop.yarn.server.resourcemanager.rmcontainer.RMContainerImpl: container_1584766611743_0006_02_000001 Container Transitioned from ALLOCATED to ACQUIRED
2020-03-21 16:12:44,279 INFO org.apache.hadoop.yarn.server.resourcemanager.security.NMTokenSecretManagerInRM: Clear node set for appattempt_1584766611743_0006_000002
2020-03-21 16:12:44,279 INFO org.apache.hadoop.yarn.server.resourcemanager.rmapp.attempt.RMAppAttemptImpl: Storing attempt: AppId: application_1584766611743_0006 AttemptId: appattempt_1584766611743_0006_000002 MasterContainer: Container: [ContainerId: container_1584766611743_0006_02_000001, NodeId: dell:34479, NodeHttpAddress: dell:8042, Resource: <memory:2048, vCores:1>, Priority: 0, Token: Token { kind: ContainerToken, service: 127.0.1.1:34479 }, ]
2020-03-21 16:12:44,279 INFO org.apache.hadoop.yarn.server.resourcemanager.rmapp.attempt.RMAppAttemptImpl: appattempt_1584766611743_0006_000002 State change from SCHEDULED to ALLOCATED_SAVING
2020-03-21 16:12:44,279 INFO org.apache.hadoop.yarn.server.resourcemanager.rmapp.attempt.RMAppAttemptImpl: appattempt_1584766611743_0006_000002 State change from ALLOCATED_SAVING to ALLOCATED
2020-03-21 16:12:44,279 INFO org.apache.hadoop.yarn.server.resourcemanager.amlauncher.AMLauncher: Launching masterappattempt_1584766611743_0006_000002
2020-03-21 16:12:44,282 INFO org.apache.hadoop.yarn.server.resourcemanager.amlauncher.AMLauncher: Setting up container Container: [ContainerId: container_1584766611743_0006_02_000001, NodeId: dell:34479, NodeHttpAddress: dell:8042, Resource: <memory:2048, vCores:1>, Priority: 0, Token: Token { kind: ContainerToken, service: 127.0.1.1:34479 }, ] for AM appattempt_1584766611743_0006_000002
2020-03-21 16:12:44,282 INFO org.apache.hadoop.yarn.server.resourcemanager.amlauncher.AMLauncher: Command to launch container container_1584766611743_0006_02_000001 : $JAVA_HOME/bin/java -Djava.io.tmpdir=$PWD/tmp -Dlog4j.configuration=container-log4j.properties -Dyarn.app.container.log.dir=<LOG_DIR> -Dyarn.app.container.log.filesize=0 -Dhadoop.root.logger=INFO,CLA -Dhadoop.root.logfile=syslog  -Xmx1024m org.apache.hadoop.mapreduce.v2.app.MRAppMaster 1><LOG_DIR>/stdout 2><LOG_DIR>/stderr 
2020-03-21 16:12:44,282 INFO org.apache.hadoop.yarn.server.resourcemanager.security.AMRMTokenSecretManager: Create AMRMToken for ApplicationAttempt: appattempt_1584766611743_0006_000002
2020-03-21 16:12:44,282 INFO org.apache.hadoop.yarn.server.resourcemanager.security.AMRMTokenSecretManager: Creating password for appattempt_1584766611743_0006_000002
2020-03-21 16:12:44,296 INFO org.apache.hadoop.yarn.server.resourcemanager.amlauncher.AMLauncher: Done launching container Container: [ContainerId: container_1584766611743_0006_02_000001, NodeId: dell:34479, NodeHttpAddress: dell:8042, Resource: <memory:2048, vCores:1>, Priority: 0, Token: Token { kind: ContainerToken, service: 127.0.1.1:34479 }, ] for AM appattempt_1584766611743_0006_000002
2020-03-21 16:12:44,296 INFO org.apache.hadoop.yarn.server.resourcemanager.rmapp.attempt.RMAppAttemptImpl: appattempt_1584766611743_0006_000002 State change from ALLOCATED to LAUNCHED
2020-03-21 16:12:45,277 INFO org.apache.hadoop.yarn.server.resourcemanager.rmcontainer.RMContainerImpl: container_1584766611743_0006_02_000001 Container Transitioned from ACQUIRED to RUNNING
2020-03-21 16:12:46,550 INFO org.apache.hadoop.yarn.server.resourcemanager.rmcontainer.RMContainerImpl: container_1584766611743_0006_02_000001 Container Transitioned from RUNNING to COMPLETED
2020-03-21 16:12:46,551 INFO org.apache.hadoop.yarn.server.resourcemanager.scheduler.common.fica.FiCaSchedulerApp: Completed container: container_1584766611743_0006_02_000001 in state: COMPLETED event:FINISHED
2020-03-21 16:12:46,551 INFO org.apache.hadoop.yarn.server.resourcemanager.RMAuditLogger: USER=xidian	OPERATION=AM Released Container	TARGET=SchedulerApp	RESULT=SUCCESS	APPID=application_1584766611743_0006	CONTAINERID=container_1584766611743_0006_02_000001
2020-03-21 16:12:46,551 INFO org.apache.hadoop.yarn.server.resourcemanager.scheduler.SchedulerNode: Released container container_1584766611743_0006_02_000001 of capacity <memory:2048, vCores:1> on host dell:34479, which currently has 0 containers, <memory:0, vCores:0> used and <memory:8192, vCores:8> available, release resources=true
2020-03-21 16:12:46,551 INFO org.apache.hadoop.yarn.server.resourcemanager.scheduler.capacity.LeafQueue: default used=<memory:0, vCores:0> numContainers=0 user=xidian user-resources=<memory:0, vCores:0>
2020-03-21 16:12:46,551 INFO org.apache.hadoop.yarn.server.resourcemanager.rmapp.attempt.RMAppAttemptImpl: Updating application attempt appattempt_1584766611743_0006_000002 with final state: FAILED, and exit status: 126
2020-03-21 16:12:46,551 INFO org.apache.hadoop.yarn.server.resourcemanager.scheduler.capacity.LeafQueue: completedContainer container=Container: [ContainerId: container_1584766611743_0006_02_000001, NodeId: dell:34479, NodeHttpAddress: dell:8042, Resource: <memory:2048, vCores:1>, Priority: 0, Token: Token { kind: ContainerToken, service: 127.0.1.1:34479 }, ] queue=default: capacity=1.0, absoluteCapacity=1.0, usedResources=<memory:0, vCores:0>, usedCapacity=0.0, absoluteUsedCapacity=0.0, numApps=1, numContainers=0 cluster=<memory:8192, vCores:8>
2020-03-21 16:12:46,551 INFO org.apache.hadoop.yarn.server.resourcemanager.scheduler.capacity.ParentQueue: completedContainer queue=root usedCapacity=0.0 absoluteUsedCapacity=0.0 used=<memory:0, vCores:0> cluster=<memory:8192, vCores:8>
2020-03-21 16:12:46,551 INFO org.apache.hadoop.yarn.server.resourcemanager.rmapp.attempt.RMAppAttemptImpl: appattempt_1584766611743_0006_000002 State change from LAUNCHED to FINAL_SAVING
2020-03-21 16:12:46,551 INFO org.apache.hadoop.yarn.server.resourcemanager.ApplicationMasterService: Unregistering app attempt : appattempt_1584766611743_0006_000002
2020-03-21 16:12:46,551 INFO org.apache.hadoop.yarn.server.resourcemanager.scheduler.capacity.ParentQueue: Re-sorting completed queue: root.default stats: default: capacity=1.0, absoluteCapacity=1.0, usedResources=<memory:0, vCores:0>, usedCapacity=0.0, absoluteUsedCapacity=0.0, numApps=1, numContainers=0
2020-03-21 16:12:46,551 INFO org.apache.hadoop.yarn.server.resourcemanager.security.AMRMTokenSecretManager: Application finished, removing password for appattempt_1584766611743_0006_000002
2020-03-21 16:12:46,551 INFO org.apache.hadoop.yarn.server.resourcemanager.scheduler.capacity.CapacityScheduler: Application attempt appattempt_1584766611743_0006_000002 released container container_1584766611743_0006_02_000001 on node: host: dell:34479 #containers=0 available=<memory:8192, vCores:8> used=<memory:0, vCores:0> with event: FINISHED
2020-03-21 16:12:46,551 INFO org.apache.hadoop.yarn.server.resourcemanager.rmapp.attempt.RMAppAttemptImpl: appattempt_1584766611743_0006_000002 State change from FINAL_SAVING to FAILED
2020-03-21 16:12:46,551 INFO org.apache.hadoop.yarn.server.resourcemanager.rmapp.RMAppImpl: The number of failed attempts is 2. The max attempts is 2
2020-03-21 16:12:46,551 INFO org.apache.hadoop.yarn.server.resourcemanager.rmapp.RMAppImpl: Updating application application_1584766611743_0006 with final state: FAILED
2020-03-21 16:12:46,551 INFO org.apache.hadoop.yarn.server.resourcemanager.rmapp.RMAppImpl: application_1584766611743_0006 State change from ACCEPTED to FINAL_SAVING on event=ATTEMPT_FAILED
2020-03-21 16:12:46,551 INFO org.apache.hadoop.yarn.server.resourcemanager.scheduler.capacity.CapacityScheduler: Application Attempt appattempt_1584766611743_0006_000002 is done. finalState=FAILED
2020-03-21 16:12:46,551 INFO org.apache.hadoop.yarn.server.resourcemanager.recovery.RMStateStore: Updating info for app: application_1584766611743_0006
2020-03-21 16:12:46,551 INFO org.apache.hadoop.yarn.server.resourcemanager.scheduler.AppSchedulingInfo: Application application_1584766611743_0006 requests cleared
2020-03-21 16:12:46,551 INFO org.apache.hadoop.yarn.server.resourcemanager.rmapp.RMAppImpl: Application application_1584766611743_0006 failed 2 times due to AM Container for appattempt_1584766611743_0006_000002 exited with  exitCode: 126
For more detailed output, check application tracking page:http://dell:8088/cluster/app/application_1584766611743_0006Then, click on links to logs of each attempt.
Diagnostics: Exception from container-launch: 
ExitCodeException exitCode=126: Got permission denied while trying to connect to the Docker daemon socket at unix:///var/run/docker.sock: Get http://%2Fvar%2Frun%2Fdocker.sock/v1.40/containers/container_1584766611743_0006_02_000001/json: dial unix /var/run/docker.sock: connect: permission denied
/usr/bin/docker: Got permission denied while trying to connect to the Docker daemon socket at unix:///var/run/docker.sock: Post http://%2Fvar%2Frun%2Fdocker.sock/v1.40/containers/create?name=container_1584766611743_0006_02_000001: dial unix /var/run/docker.sock: connect: permission denied.
See '/usr/bin/docker run --help'.

	at org.apache.hadoop.util.Shell.runCommand(Shell.java:585)
	at org.apache.hadoop.util.Shell.run(Shell.java:482)
	at org.apache.hadoop.util.Shell$ShellCommandExecutor.execute(Shell.java:776)
	at org.apache.hadoop.yarn.server.nodemanager.DockerContainerExecutor.launchContainer(DockerContainerExecutor.java:247)
	at org.apache.hadoop.yarn.server.nodemanager.containermanager.launcher.ContainerLaunch.call(ContainerLaunch.java:302)
	at org.apache.hadoop.yarn.server.nodemanager.containermanager.launcher.ContainerLaunch.call(ContainerLaunch.java:82)
	at java.util.concurrent.FutureTask.run(FutureTask.java:266)
	at java.util.concurrent.ThreadPoolExecutor.runWorker(ThreadPoolExecutor.java:1142)
	at java.util.concurrent.ThreadPoolExecutor$Worker.run(ThreadPoolExecutor.java:617)
	at java.lang.Thread.run(Thread.java:748)


Container exited with a non-zero exit code 126
Failing this attempt. Failing the application.
2020-03-21 16:12:46,551 INFO org.apache.hadoop.yarn.server.resourcemanager.scheduler.capacity.LeafQueue: Application removed - appId: application_1584766611743_0006 user: xidian queue: default #user-pending-applications: 0 #user-active-applications: 0 #queue-pending-applications: 0 #queue-active-applications: 0
2020-03-21 16:12:46,551 INFO org.apache.hadoop.yarn.server.resourcemanager.rmapp.RMAppImpl: application_1584766611743_0006 State change from FINAL_SAVING to FAILED on event=APP_UPDATE_SAVED
2020-03-21 16:12:46,552 INFO org.apache.hadoop.yarn.server.resourcemanager.scheduler.capacity.ParentQueue: Application removed - appId: application_1584766611743_0006 user: xidian leaf-queue of parent: root #applications: 0
2020-03-21 16:12:46,552 WARN org.apache.hadoop.yarn.server.resourcemanager.RMAuditLogger: USER=xidian	OPERATION=Application Finished - Failed	TARGET=RMAppManager	RESULT=FAILURE	DESCRIPTION=App failed with state: FAILED	PERMISSIONS=Application application_1584766611743_0006 failed 2 times due to AM Container for appattempt_1584766611743_0006_000002 exited with  exitCode: 126
For more detailed output, check application tracking page:http://dell:8088/cluster/app/application_1584766611743_0006Then, click on links to logs of each attempt.
Diagnostics: Exception from container-launch: 
ExitCodeException exitCode=126: Got permission denied while trying to connect to the Docker daemon socket at unix:///var/run/docker.sock: Get http://%2Fvar%2Frun%2Fdocker.sock/v1.40/containers/container_1584766611743_0006_02_000001/json: dial unix /var/run/docker.sock: connect: permission denied
/usr/bin/docker: Got permission denied while trying to connect to the Docker daemon socket at unix:///var/run/docker.sock: Post http://%2Fvar%2Frun%2Fdocker.sock/v1.40/containers/create?name=container_1584766611743_0006_02_000001: dial unix /var/run/docker.sock: connect: permission denied.
See '/usr/bin/docker run --help'.

	at org.apache.hadoop.util.Shell.runCommand(Shell.java:585)
	at org.apache.hadoop.util.Shell.run(Shell.java:482)
	at org.apache.hadoop.util.Shell$ShellCommandExecutor.execute(Shell.java:776)
	at org.apache.hadoop.yarn.server.nodemanager.DockerContainerExecutor.launchContainer(DockerContainerExecutor.java:247)
	at org.apache.hadoop.yarn.server.nodemanager.containermanager.launcher.ContainerLaunch.call(ContainerLaunch.java:302)
	at org.apache.hadoop.yarn.server.nodemanager.containermanager.launcher.ContainerLaunch.call(ContainerLaunch.java:82)
	at java.util.concurrent.FutureTask.run(FutureTask.java:266)
	at java.util.concurrent.ThreadPoolExecutor.runWorker(ThreadPoolExecutor.java:1142)
	at java.util.concurrent.ThreadPoolExecutor$Worker.run(ThreadPoolExecutor.java:617)
	at java.lang.Thread.run(Thread.java:748)


Container exited with a non-zero exit code 126
Failing this attempt. Failing the application.	APPID=application_1584766611743_0006
2020-03-21 16:12:46,552 INFO org.apache.hadoop.yarn.server.resourcemanager.RMAppManager$ApplicationSummary: appId=application_1584766611743_0006,name=word count,user=xidian,queue=default,state=FAILED,trackingUrl=http://dell:8088/cluster/app/application_1584766611743_0006,appMasterHost=N/A,startTime=1584778360461,finishTime=1584778366551,finalStatus=FAILED,memorySeconds=9856,vcoreSeconds=4,preemptedAMContainers=0,preemptedNonAMContainers=0,preemptedResources=<memory:0\, vCores:0>,applicationType=MAPREDUCE
2020-03-21 16:31:01,187 INFO org.apache.hadoop.yarn.server.resourcemanager.ClientRMService: Allocated new applicationId: 7
2020-03-21 16:31:02,021 INFO org.apache.hadoop.yarn.server.resourcemanager.ClientRMService: Application with id 7 submitted by user xidian
2020-03-21 16:31:02,021 INFO org.apache.hadoop.yarn.server.resourcemanager.rmapp.RMAppImpl: Storing application with id application_1584766611743_0007
2020-03-21 16:31:02,021 INFO org.apache.hadoop.yarn.server.resourcemanager.RMAuditLogger: USER=xidian	IP=127.0.0.1	OPERATION=Submit Application Request	TARGET=ClientRMService	RESULT=SUCCESS	APPID=application_1584766611743_0007
2020-03-21 16:31:02,021 INFO org.apache.hadoop.yarn.server.resourcemanager.rmapp.RMAppImpl: application_1584766611743_0007 State change from NEW to NEW_SAVING on event=START
2020-03-21 16:31:02,022 INFO org.apache.hadoop.yarn.server.resourcemanager.recovery.RMStateStore: Storing info for app: application_1584766611743_0007
2020-03-21 16:31:02,022 INFO org.apache.hadoop.yarn.server.resourcemanager.rmapp.RMAppImpl: application_1584766611743_0007 State change from NEW_SAVING to SUBMITTED on event=APP_NEW_SAVED
2020-03-21 16:31:02,022 INFO org.apache.hadoop.yarn.server.resourcemanager.scheduler.capacity.ParentQueue: Application added - appId: application_1584766611743_0007 user: xidian leaf-queue of parent: root #applications: 1
2020-03-21 16:31:02,022 INFO org.apache.hadoop.yarn.server.resourcemanager.scheduler.capacity.CapacityScheduler: Accepted application application_1584766611743_0007 from user: xidian, in queue: default
2020-03-21 16:31:02,022 INFO org.apache.hadoop.yarn.server.resourcemanager.rmapp.RMAppImpl: application_1584766611743_0007 State change from SUBMITTED to ACCEPTED on event=APP_ACCEPTED
2020-03-21 16:31:02,022 INFO org.apache.hadoop.yarn.server.resourcemanager.ApplicationMasterService: Registering app attempt : appattempt_1584766611743_0007_000001
2020-03-21 16:31:02,022 INFO org.apache.hadoop.yarn.server.resourcemanager.rmapp.attempt.RMAppAttemptImpl: appattempt_1584766611743_0007_000001 State change from NEW to SUBMITTED
2020-03-21 16:31:02,022 WARN org.apache.hadoop.yarn.server.resourcemanager.scheduler.capacity.LeafQueue: maximum-am-resource-percent is insufficient to start a single application in queue, it is likely set too low. skipping enforcement to allow at least one application to start
2020-03-21 16:31:02,022 WARN org.apache.hadoop.yarn.server.resourcemanager.scheduler.capacity.LeafQueue: maximum-am-resource-percent is insufficient to start a single application in queue for user, it is likely set too low. skipping enforcement to allow at least one application to start
2020-03-21 16:31:02,022 INFO org.apache.hadoop.yarn.server.resourcemanager.scheduler.capacity.LeafQueue: Application application_1584766611743_0007 from user: xidian activated in queue: default
2020-03-21 16:31:02,022 INFO org.apache.hadoop.yarn.server.resourcemanager.scheduler.capacity.LeafQueue: Application added - appId: application_1584766611743_0007 user: org.apache.hadoop.yarn.server.resourcemanager.scheduler.capacity.LeafQueue$User@59ca3160, leaf-queue: default #user-pending-applications: 0 #user-active-applications: 1 #queue-pending-applications: 0 #queue-active-applications: 1
2020-03-21 16:31:02,022 INFO org.apache.hadoop.yarn.server.resourcemanager.scheduler.capacity.CapacityScheduler: Added Application Attempt appattempt_1584766611743_0007_000001 to scheduler from user xidian in queue default
2020-03-21 16:31:02,023 INFO org.apache.hadoop.yarn.server.resourcemanager.rmapp.attempt.RMAppAttemptImpl: appattempt_1584766611743_0007_000001 State change from SUBMITTED to SCHEDULED
2020-03-21 16:31:02,649 INFO org.apache.hadoop.yarn.server.resourcemanager.rmcontainer.RMContainerImpl: container_1584766611743_0007_01_000001 Container Transitioned from NEW to ALLOCATED
2020-03-21 16:31:02,649 INFO org.apache.hadoop.yarn.server.resourcemanager.RMAuditLogger: USER=xidian	OPERATION=AM Allocated Container	TARGET=SchedulerApp	RESULT=SUCCESS	APPID=application_1584766611743_0007	CONTAINERID=container_1584766611743_0007_01_000001
2020-03-21 16:31:02,649 INFO org.apache.hadoop.yarn.server.resourcemanager.scheduler.SchedulerNode: Assigned container container_1584766611743_0007_01_000001 of capacity <memory:2048, vCores:1> on host dell:34479, which has 1 containers, <memory:2048, vCores:1> used and <memory:6144, vCores:7> available after allocation
2020-03-21 16:31:02,649 INFO org.apache.hadoop.yarn.server.resourcemanager.scheduler.capacity.LeafQueue: assignedContainer application attempt=appattempt_1584766611743_0007_000001 container=Container: [ContainerId: container_1584766611743_0007_01_000001, NodeId: dell:34479, NodeHttpAddress: dell:8042, Resource: <memory:2048, vCores:1>, Priority: 0, Token: null, ] queue=default: capacity=1.0, absoluteCapacity=1.0, usedResources=<memory:0, vCores:0>, usedCapacity=0.0, absoluteUsedCapacity=0.0, numApps=1, numContainers=0 clusterResource=<memory:8192, vCores:8> type=OFF_SWITCH requestedPartition=
2020-03-21 16:31:02,649 INFO org.apache.hadoop.yarn.server.resourcemanager.scheduler.capacity.ParentQueue: Re-sorting assigned queue: root.default stats: default: capacity=1.0, absoluteCapacity=1.0, usedResources=<memory:2048, vCores:1>, usedCapacity=0.25, absoluteUsedCapacity=0.25, numApps=1, numContainers=1
2020-03-21 16:31:02,649 INFO org.apache.hadoop.yarn.server.resourcemanager.scheduler.capacity.ParentQueue: assignedContainer queue=root usedCapacity=0.25 absoluteUsedCapacity=0.25 used=<memory:2048, vCores:1> cluster=<memory:8192, vCores:8>
2020-03-21 16:31:02,650 INFO org.apache.hadoop.yarn.server.resourcemanager.security.NMTokenSecretManagerInRM: Sending NMToken for nodeId : dell:34479 for container : container_1584766611743_0007_01_000001
2020-03-21 16:31:02,652 INFO org.apache.hadoop.yarn.server.resourcemanager.rmcontainer.RMContainerImpl: container_1584766611743_0007_01_000001 Container Transitioned from ALLOCATED to ACQUIRED
2020-03-21 16:31:02,652 INFO org.apache.hadoop.yarn.server.resourcemanager.security.NMTokenSecretManagerInRM: Clear node set for appattempt_1584766611743_0007_000001
2020-03-21 16:31:02,653 INFO org.apache.hadoop.yarn.server.resourcemanager.rmapp.attempt.RMAppAttemptImpl: Storing attempt: AppId: application_1584766611743_0007 AttemptId: appattempt_1584766611743_0007_000001 MasterContainer: Container: [ContainerId: container_1584766611743_0007_01_000001, NodeId: dell:34479, NodeHttpAddress: dell:8042, Resource: <memory:2048, vCores:1>, Priority: 0, Token: Token { kind: ContainerToken, service: 127.0.1.1:34479 }, ]
2020-03-21 16:31:02,653 INFO org.apache.hadoop.yarn.server.resourcemanager.rmapp.attempt.RMAppAttemptImpl: appattempt_1584766611743_0007_000001 State change from SCHEDULED to ALLOCATED_SAVING
2020-03-21 16:31:02,653 INFO org.apache.hadoop.yarn.server.resourcemanager.rmapp.attempt.RMAppAttemptImpl: appattempt_1584766611743_0007_000001 State change from ALLOCATED_SAVING to ALLOCATED
2020-03-21 16:31:02,654 INFO org.apache.hadoop.yarn.server.resourcemanager.amlauncher.AMLauncher: Launching masterappattempt_1584766611743_0007_000001
2020-03-21 16:31:02,657 INFO org.apache.hadoop.yarn.server.resourcemanager.amlauncher.AMLauncher: Setting up container Container: [ContainerId: container_1584766611743_0007_01_000001, NodeId: dell:34479, NodeHttpAddress: dell:8042, Resource: <memory:2048, vCores:1>, Priority: 0, Token: Token { kind: ContainerToken, service: 127.0.1.1:34479 }, ] for AM appattempt_1584766611743_0007_000001
2020-03-21 16:31:02,657 INFO org.apache.hadoop.yarn.server.resourcemanager.amlauncher.AMLauncher: Command to launch container container_1584766611743_0007_01_000001 : $JAVA_HOME/bin/java -Djava.io.tmpdir=$PWD/tmp -Dlog4j.configuration=container-log4j.properties -Dyarn.app.container.log.dir=<LOG_DIR> -Dyarn.app.container.log.filesize=0 -Dhadoop.root.logger=INFO,CLA -Dhadoop.root.logfile=syslog  -Xmx1024m org.apache.hadoop.mapreduce.v2.app.MRAppMaster 1><LOG_DIR>/stdout 2><LOG_DIR>/stderr 
2020-03-21 16:31:02,657 INFO org.apache.hadoop.yarn.server.resourcemanager.security.AMRMTokenSecretManager: Create AMRMToken for ApplicationAttempt: appattempt_1584766611743_0007_000001
2020-03-21 16:31:02,657 INFO org.apache.hadoop.yarn.server.resourcemanager.security.AMRMTokenSecretManager: Creating password for appattempt_1584766611743_0007_000001
2020-03-21 16:31:02,666 INFO org.apache.hadoop.yarn.server.resourcemanager.amlauncher.AMLauncher: Done launching container Container: [ContainerId: container_1584766611743_0007_01_000001, NodeId: dell:34479, NodeHttpAddress: dell:8042, Resource: <memory:2048, vCores:1>, Priority: 0, Token: Token { kind: ContainerToken, service: 127.0.1.1:34479 }, ] for AM appattempt_1584766611743_0007_000001
2020-03-21 16:31:02,666 INFO org.apache.hadoop.yarn.server.resourcemanager.rmapp.attempt.RMAppAttemptImpl: appattempt_1584766611743_0007_000001 State change from ALLOCATED to LAUNCHED
2020-03-21 16:31:03,649 INFO org.apache.hadoop.yarn.server.resourcemanager.rmcontainer.RMContainerImpl: container_1584766611743_0007_01_000001 Container Transitioned from ACQUIRED to RUNNING
2020-03-21 16:31:04,904 INFO org.apache.hadoop.yarn.server.resourcemanager.rmcontainer.RMContainerImpl: container_1584766611743_0007_01_000001 Container Transitioned from RUNNING to COMPLETED
2020-03-21 16:31:04,904 INFO org.apache.hadoop.yarn.server.resourcemanager.scheduler.common.fica.FiCaSchedulerApp: Completed container: container_1584766611743_0007_01_000001 in state: COMPLETED event:FINISHED
2020-03-21 16:31:04,904 INFO org.apache.hadoop.yarn.server.resourcemanager.RMAuditLogger: USER=xidian	OPERATION=AM Released Container	TARGET=SchedulerApp	RESULT=SUCCESS	APPID=application_1584766611743_0007	CONTAINERID=container_1584766611743_0007_01_000001
2020-03-21 16:31:04,904 INFO org.apache.hadoop.yarn.server.resourcemanager.scheduler.SchedulerNode: Released container container_1584766611743_0007_01_000001 of capacity <memory:2048, vCores:1> on host dell:34479, which currently has 0 containers, <memory:0, vCores:0> used and <memory:8192, vCores:8> available, release resources=true
2020-03-21 16:31:04,904 INFO org.apache.hadoop.yarn.server.resourcemanager.scheduler.capacity.LeafQueue: default used=<memory:0, vCores:0> numContainers=0 user=xidian user-resources=<memory:0, vCores:0>
2020-03-21 16:31:04,904 INFO org.apache.hadoop.yarn.server.resourcemanager.scheduler.capacity.LeafQueue: completedContainer container=Container: [ContainerId: container_1584766611743_0007_01_000001, NodeId: dell:34479, NodeHttpAddress: dell:8042, Resource: <memory:2048, vCores:1>, Priority: 0, Token: Token { kind: ContainerToken, service: 127.0.1.1:34479 }, ] queue=default: capacity=1.0, absoluteCapacity=1.0, usedResources=<memory:0, vCores:0>, usedCapacity=0.0, absoluteUsedCapacity=0.0, numApps=1, numContainers=0 cluster=<memory:8192, vCores:8>
2020-03-21 16:31:04,904 INFO org.apache.hadoop.yarn.server.resourcemanager.scheduler.capacity.ParentQueue: completedContainer queue=root usedCapacity=0.0 absoluteUsedCapacity=0.0 used=<memory:0, vCores:0> cluster=<memory:8192, vCores:8>
2020-03-21 16:31:04,904 INFO org.apache.hadoop.yarn.server.resourcemanager.rmapp.attempt.RMAppAttemptImpl: Updating application attempt appattempt_1584766611743_0007_000001 with final state: FAILED, and exit status: 126
2020-03-21 16:31:04,904 INFO org.apache.hadoop.yarn.server.resourcemanager.rmapp.attempt.RMAppAttemptImpl: appattempt_1584766611743_0007_000001 State change from LAUNCHED to FINAL_SAVING
2020-03-21 16:31:04,904 INFO org.apache.hadoop.yarn.server.resourcemanager.scheduler.capacity.ParentQueue: Re-sorting completed queue: root.default stats: default: capacity=1.0, absoluteCapacity=1.0, usedResources=<memory:0, vCores:0>, usedCapacity=0.0, absoluteUsedCapacity=0.0, numApps=1, numContainers=0
2020-03-21 16:31:04,905 INFO org.apache.hadoop.yarn.server.resourcemanager.scheduler.capacity.CapacityScheduler: Application attempt appattempt_1584766611743_0007_000001 released container container_1584766611743_0007_01_000001 on node: host: dell:34479 #containers=0 available=<memory:8192, vCores:8> used=<memory:0, vCores:0> with event: FINISHED
2020-03-21 16:31:04,905 INFO org.apache.hadoop.yarn.server.resourcemanager.ApplicationMasterService: Unregistering app attempt : appattempt_1584766611743_0007_000001
2020-03-21 16:31:04,905 INFO org.apache.hadoop.yarn.server.resourcemanager.security.AMRMTokenSecretManager: Application finished, removing password for appattempt_1584766611743_0007_000001
2020-03-21 16:31:04,905 INFO org.apache.hadoop.yarn.server.resourcemanager.rmapp.attempt.RMAppAttemptImpl: appattempt_1584766611743_0007_000001 State change from FINAL_SAVING to FAILED
2020-03-21 16:31:04,905 INFO org.apache.hadoop.yarn.server.resourcemanager.rmapp.RMAppImpl: The number of failed attempts is 1. The max attempts is 2
2020-03-21 16:31:04,905 INFO org.apache.hadoop.yarn.server.resourcemanager.ApplicationMasterService: Registering app attempt : appattempt_1584766611743_0007_000002
2020-03-21 16:31:04,905 INFO org.apache.hadoop.yarn.server.resourcemanager.scheduler.capacity.CapacityScheduler: Application Attempt appattempt_1584766611743_0007_000001 is done. finalState=FAILED
2020-03-21 16:31:04,905 INFO org.apache.hadoop.yarn.server.resourcemanager.rmapp.attempt.RMAppAttemptImpl: appattempt_1584766611743_0007_000002 State change from NEW to SUBMITTED
2020-03-21 16:31:04,905 INFO org.apache.hadoop.yarn.server.resourcemanager.scheduler.AppSchedulingInfo: Application application_1584766611743_0007 requests cleared
2020-03-21 16:31:04,905 INFO org.apache.hadoop.yarn.server.resourcemanager.scheduler.capacity.LeafQueue: Application removed - appId: application_1584766611743_0007 user: xidian queue: default #user-pending-applications: 0 #user-active-applications: 0 #queue-pending-applications: 0 #queue-active-applications: 0
2020-03-21 16:31:04,905 WARN org.apache.hadoop.yarn.server.resourcemanager.scheduler.capacity.LeafQueue: maximum-am-resource-percent is insufficient to start a single application in queue, it is likely set too low. skipping enforcement to allow at least one application to start
2020-03-21 16:31:04,905 WARN org.apache.hadoop.yarn.server.resourcemanager.scheduler.capacity.LeafQueue: maximum-am-resource-percent is insufficient to start a single application in queue for user, it is likely set too low. skipping enforcement to allow at least one application to start
2020-03-21 16:31:04,905 INFO org.apache.hadoop.yarn.server.resourcemanager.scheduler.capacity.LeafQueue: Application application_1584766611743_0007 from user: xidian activated in queue: default
2020-03-21 16:31:04,905 INFO org.apache.hadoop.yarn.server.resourcemanager.scheduler.capacity.LeafQueue: Application added - appId: application_1584766611743_0007 user: org.apache.hadoop.yarn.server.resourcemanager.scheduler.capacity.LeafQueue$User@b0768d5, leaf-queue: default #user-pending-applications: 0 #user-active-applications: 1 #queue-pending-applications: 0 #queue-active-applications: 1
2020-03-21 16:31:04,905 INFO org.apache.hadoop.yarn.server.resourcemanager.scheduler.capacity.CapacityScheduler: Added Application Attempt appattempt_1584766611743_0007_000002 to scheduler from user xidian in queue default
2020-03-21 16:31:04,905 INFO org.apache.hadoop.yarn.server.resourcemanager.rmapp.attempt.RMAppAttemptImpl: appattempt_1584766611743_0007_000002 State change from SUBMITTED to SCHEDULED
2020-03-21 16:31:05,905 INFO org.apache.hadoop.yarn.server.resourcemanager.rmcontainer.RMContainerImpl: container_1584766611743_0007_02_000001 Container Transitioned from NEW to ALLOCATED
2020-03-21 16:31:05,906 INFO org.apache.hadoop.yarn.server.resourcemanager.RMAuditLogger: USER=xidian	OPERATION=AM Allocated Container	TARGET=SchedulerApp	RESULT=SUCCESS	APPID=application_1584766611743_0007	CONTAINERID=container_1584766611743_0007_02_000001
2020-03-21 16:31:05,906 INFO org.apache.hadoop.yarn.server.resourcemanager.scheduler.SchedulerNode: Assigned container container_1584766611743_0007_02_000001 of capacity <memory:2048, vCores:1> on host dell:34479, which has 1 containers, <memory:2048, vCores:1> used and <memory:6144, vCores:7> available after allocation
2020-03-21 16:31:05,906 INFO org.apache.hadoop.yarn.server.resourcemanager.scheduler.capacity.LeafQueue: assignedContainer application attempt=appattempt_1584766611743_0007_000002 container=Container: [ContainerId: container_1584766611743_0007_02_000001, NodeId: dell:34479, NodeHttpAddress: dell:8042, Resource: <memory:2048, vCores:1>, Priority: 0, Token: null, ] queue=default: capacity=1.0, absoluteCapacity=1.0, usedResources=<memory:0, vCores:0>, usedCapacity=0.0, absoluteUsedCapacity=0.0, numApps=1, numContainers=0 clusterResource=<memory:8192, vCores:8> type=OFF_SWITCH requestedPartition=
2020-03-21 16:31:05,906 INFO org.apache.hadoop.yarn.server.resourcemanager.scheduler.capacity.ParentQueue: Re-sorting assigned queue: root.default stats: default: capacity=1.0, absoluteCapacity=1.0, usedResources=<memory:2048, vCores:1>, usedCapacity=0.25, absoluteUsedCapacity=0.25, numApps=1, numContainers=1
2020-03-21 16:31:05,906 INFO org.apache.hadoop.yarn.server.resourcemanager.scheduler.capacity.ParentQueue: assignedContainer queue=root usedCapacity=0.25 absoluteUsedCapacity=0.25 used=<memory:2048, vCores:1> cluster=<memory:8192, vCores:8>
2020-03-21 16:31:05,907 INFO org.apache.hadoop.yarn.server.resourcemanager.security.NMTokenSecretManagerInRM: Sending NMToken for nodeId : dell:34479 for container : container_1584766611743_0007_02_000001
2020-03-21 16:31:05,909 INFO org.apache.hadoop.yarn.server.resourcemanager.rmcontainer.RMContainerImpl: container_1584766611743_0007_02_000001 Container Transitioned from ALLOCATED to ACQUIRED
2020-03-21 16:31:05,909 INFO org.apache.hadoop.yarn.server.resourcemanager.security.NMTokenSecretManagerInRM: Clear node set for appattempt_1584766611743_0007_000002
2020-03-21 16:31:05,909 INFO org.apache.hadoop.yarn.server.resourcemanager.rmapp.attempt.RMAppAttemptImpl: Storing attempt: AppId: application_1584766611743_0007 AttemptId: appattempt_1584766611743_0007_000002 MasterContainer: Container: [ContainerId: container_1584766611743_0007_02_000001, NodeId: dell:34479, NodeHttpAddress: dell:8042, Resource: <memory:2048, vCores:1>, Priority: 0, Token: Token { kind: ContainerToken, service: 127.0.1.1:34479 }, ]
2020-03-21 16:31:05,909 INFO org.apache.hadoop.yarn.server.resourcemanager.rmapp.attempt.RMAppAttemptImpl: appattempt_1584766611743_0007_000002 State change from SCHEDULED to ALLOCATED_SAVING
2020-03-21 16:31:05,910 INFO org.apache.hadoop.yarn.server.resourcemanager.rmapp.attempt.RMAppAttemptImpl: appattempt_1584766611743_0007_000002 State change from ALLOCATED_SAVING to ALLOCATED
2020-03-21 16:31:05,911 INFO org.apache.hadoop.yarn.server.resourcemanager.amlauncher.AMLauncher: Launching masterappattempt_1584766611743_0007_000002
2020-03-21 16:31:05,914 INFO org.apache.hadoop.yarn.server.resourcemanager.amlauncher.AMLauncher: Setting up container Container: [ContainerId: container_1584766611743_0007_02_000001, NodeId: dell:34479, NodeHttpAddress: dell:8042, Resource: <memory:2048, vCores:1>, Priority: 0, Token: Token { kind: ContainerToken, service: 127.0.1.1:34479 }, ] for AM appattempt_1584766611743_0007_000002
2020-03-21 16:31:05,914 INFO org.apache.hadoop.yarn.server.resourcemanager.amlauncher.AMLauncher: Command to launch container container_1584766611743_0007_02_000001 : $JAVA_HOME/bin/java -Djava.io.tmpdir=$PWD/tmp -Dlog4j.configuration=container-log4j.properties -Dyarn.app.container.log.dir=<LOG_DIR> -Dyarn.app.container.log.filesize=0 -Dhadoop.root.logger=INFO,CLA -Dhadoop.root.logfile=syslog  -Xmx1024m org.apache.hadoop.mapreduce.v2.app.MRAppMaster 1><LOG_DIR>/stdout 2><LOG_DIR>/stderr 
2020-03-21 16:31:05,914 INFO org.apache.hadoop.yarn.server.resourcemanager.security.AMRMTokenSecretManager: Create AMRMToken for ApplicationAttempt: appattempt_1584766611743_0007_000002
2020-03-21 16:31:05,914 INFO org.apache.hadoop.yarn.server.resourcemanager.security.AMRMTokenSecretManager: Creating password for appattempt_1584766611743_0007_000002
2020-03-21 16:31:05,925 INFO org.apache.hadoop.yarn.server.resourcemanager.amlauncher.AMLauncher: Done launching container Container: [ContainerId: container_1584766611743_0007_02_000001, NodeId: dell:34479, NodeHttpAddress: dell:8042, Resource: <memory:2048, vCores:1>, Priority: 0, Token: Token { kind: ContainerToken, service: 127.0.1.1:34479 }, ] for AM appattempt_1584766611743_0007_000002
2020-03-21 16:31:05,925 INFO org.apache.hadoop.yarn.server.resourcemanager.rmapp.attempt.RMAppAttemptImpl: appattempt_1584766611743_0007_000002 State change from ALLOCATED to LAUNCHED
2020-03-21 16:31:06,907 INFO org.apache.hadoop.yarn.server.resourcemanager.rmcontainer.RMContainerImpl: container_1584766611743_0007_02_000001 Container Transitioned from ACQUIRED to RUNNING
2020-03-21 16:31:08,110 INFO org.apache.hadoop.yarn.server.resourcemanager.rmcontainer.RMContainerImpl: container_1584766611743_0007_02_000001 Container Transitioned from RUNNING to COMPLETED
2020-03-21 16:31:08,110 INFO org.apache.hadoop.yarn.server.resourcemanager.scheduler.common.fica.FiCaSchedulerApp: Completed container: container_1584766611743_0007_02_000001 in state: COMPLETED event:FINISHED
2020-03-21 16:31:08,110 INFO org.apache.hadoop.yarn.server.resourcemanager.RMAuditLogger: USER=xidian	OPERATION=AM Released Container	TARGET=SchedulerApp	RESULT=SUCCESS	APPID=application_1584766611743_0007	CONTAINERID=container_1584766611743_0007_02_000001
2020-03-21 16:31:08,110 INFO org.apache.hadoop.yarn.server.resourcemanager.scheduler.SchedulerNode: Released container container_1584766611743_0007_02_000001 of capacity <memory:2048, vCores:1> on host dell:34479, which currently has 0 containers, <memory:0, vCores:0> used and <memory:8192, vCores:8> available, release resources=true
2020-03-21 16:31:08,110 INFO org.apache.hadoop.yarn.server.resourcemanager.scheduler.capacity.LeafQueue: default used=<memory:0, vCores:0> numContainers=0 user=xidian user-resources=<memory:0, vCores:0>
2020-03-21 16:31:08,110 INFO org.apache.hadoop.yarn.server.resourcemanager.scheduler.capacity.LeafQueue: completedContainer container=Container: [ContainerId: container_1584766611743_0007_02_000001, NodeId: dell:34479, NodeHttpAddress: dell:8042, Resource: <memory:2048, vCores:1>, Priority: 0, Token: Token { kind: ContainerToken, service: 127.0.1.1:34479 }, ] queue=default: capacity=1.0, absoluteCapacity=1.0, usedResources=<memory:0, vCores:0>, usedCapacity=0.0, absoluteUsedCapacity=0.0, numApps=1, numContainers=0 cluster=<memory:8192, vCores:8>
2020-03-21 16:31:08,110 INFO org.apache.hadoop.yarn.server.resourcemanager.scheduler.capacity.ParentQueue: completedContainer queue=root usedCapacity=0.0 absoluteUsedCapacity=0.0 used=<memory:0, vCores:0> cluster=<memory:8192, vCores:8>
2020-03-21 16:31:08,110 INFO org.apache.hadoop.yarn.server.resourcemanager.rmapp.attempt.RMAppAttemptImpl: Updating application attempt appattempt_1584766611743_0007_000002 with final state: FAILED, and exit status: 126
2020-03-21 16:31:08,110 INFO org.apache.hadoop.yarn.server.resourcemanager.scheduler.capacity.ParentQueue: Re-sorting completed queue: root.default stats: default: capacity=1.0, absoluteCapacity=1.0, usedResources=<memory:0, vCores:0>, usedCapacity=0.0, absoluteUsedCapacity=0.0, numApps=1, numContainers=0
2020-03-21 16:31:08,110 INFO org.apache.hadoop.yarn.server.resourcemanager.rmapp.attempt.RMAppAttemptImpl: appattempt_1584766611743_0007_000002 State change from LAUNCHED to FINAL_SAVING
2020-03-21 16:31:08,111 INFO org.apache.hadoop.yarn.server.resourcemanager.scheduler.capacity.CapacityScheduler: Application attempt appattempt_1584766611743_0007_000002 released container container_1584766611743_0007_02_000001 on node: host: dell:34479 #containers=0 available=<memory:8192, vCores:8> used=<memory:0, vCores:0> with event: FINISHED
2020-03-21 16:31:08,111 INFO org.apache.hadoop.yarn.server.resourcemanager.ApplicationMasterService: Unregistering app attempt : appattempt_1584766611743_0007_000002
2020-03-21 16:31:08,111 INFO org.apache.hadoop.yarn.server.resourcemanager.security.AMRMTokenSecretManager: Application finished, removing password for appattempt_1584766611743_0007_000002
2020-03-21 16:31:08,111 INFO org.apache.hadoop.yarn.server.resourcemanager.rmapp.attempt.RMAppAttemptImpl: appattempt_1584766611743_0007_000002 State change from FINAL_SAVING to FAILED
2020-03-21 16:31:08,111 INFO org.apache.hadoop.yarn.server.resourcemanager.rmapp.RMAppImpl: The number of failed attempts is 2. The max attempts is 2
2020-03-21 16:31:08,111 INFO org.apache.hadoop.yarn.server.resourcemanager.rmapp.RMAppImpl: Updating application application_1584766611743_0007 with final state: FAILED
2020-03-21 16:31:08,111 INFO org.apache.hadoop.yarn.server.resourcemanager.rmapp.RMAppImpl: application_1584766611743_0007 State change from ACCEPTED to FINAL_SAVING on event=ATTEMPT_FAILED
2020-03-21 16:31:08,111 INFO org.apache.hadoop.yarn.server.resourcemanager.recovery.RMStateStore: Updating info for app: application_1584766611743_0007
2020-03-21 16:31:08,111 INFO org.apache.hadoop.yarn.server.resourcemanager.scheduler.capacity.CapacityScheduler: Application Attempt appattempt_1584766611743_0007_000002 is done. finalState=FAILED
2020-03-21 16:31:08,111 INFO org.apache.hadoop.yarn.server.resourcemanager.rmapp.RMAppImpl: Application application_1584766611743_0007 failed 2 times due to AM Container for appattempt_1584766611743_0007_000002 exited with  exitCode: 126
For more detailed output, check application tracking page:http://dell:8088/cluster/app/application_1584766611743_0007Then, click on links to logs of each attempt.
Diagnostics: Exception from container-launch: 
ExitCodeException exitCode=126: Got permission denied while trying to connect to the Docker daemon socket at unix:///var/run/docker.sock: Get http://%2Fvar%2Frun%2Fdocker.sock/v1.40/containers/container_1584766611743_0007_02_000001/json: dial unix /var/run/docker.sock: connect: permission denied
/usr/bin/docker: Got permission denied while trying to connect to the Docker daemon socket at unix:///var/run/docker.sock: Post http://%2Fvar%2Frun%2Fdocker.sock/v1.40/containers/create?name=container_1584766611743_0007_02_000001: dial unix /var/run/docker.sock: connect: permission denied.
See '/usr/bin/docker run --help'.

	at org.apache.hadoop.util.Shell.runCommand(Shell.java:585)
	at org.apache.hadoop.util.Shell.run(Shell.java:482)
	at org.apache.hadoop.util.Shell$ShellCommandExecutor.execute(Shell.java:776)
	at org.apache.hadoop.yarn.server.nodemanager.DockerContainerExecutor.launchContainer(DockerContainerExecutor.java:247)
	at org.apache.hadoop.yarn.server.nodemanager.containermanager.launcher.ContainerLaunch.call(ContainerLaunch.java:302)
	at org.apache.hadoop.yarn.server.nodemanager.containermanager.launcher.ContainerLaunch.call(ContainerLaunch.java:82)
	at java.util.concurrent.FutureTask.run(FutureTask.java:266)
	at java.util.concurrent.ThreadPoolExecutor.runWorker(ThreadPoolExecutor.java:1142)
	at java.util.concurrent.ThreadPoolExecutor$Worker.run(ThreadPoolExecutor.java:617)
	at java.lang.Thread.run(Thread.java:748)


Container exited with a non-zero exit code 126
Failing this attempt. Failing the application.
2020-03-21 16:31:08,111 INFO org.apache.hadoop.yarn.server.resourcemanager.scheduler.AppSchedulingInfo: Application application_1584766611743_0007 requests cleared
2020-03-21 16:31:08,111 INFO org.apache.hadoop.yarn.server.resourcemanager.rmapp.RMAppImpl: application_1584766611743_0007 State change from FINAL_SAVING to FAILED on event=APP_UPDATE_SAVED
2020-03-21 16:31:08,111 INFO org.apache.hadoop.yarn.server.resourcemanager.scheduler.capacity.LeafQueue: Application removed - appId: application_1584766611743_0007 user: xidian queue: default #user-pending-applications: 0 #user-active-applications: 0 #queue-pending-applications: 0 #queue-active-applications: 0
2020-03-21 16:31:08,111 WARN org.apache.hadoop.yarn.server.resourcemanager.RMAuditLogger: USER=xidian	OPERATION=Application Finished - Failed	TARGET=RMAppManager	RESULT=FAILURE	DESCRIPTION=App failed with state: FAILED	PERMISSIONS=Application application_1584766611743_0007 failed 2 times due to AM Container for appattempt_1584766611743_0007_000002 exited with  exitCode: 126
For more detailed output, check application tracking page:http://dell:8088/cluster/app/application_1584766611743_0007Then, click on links to logs of each attempt.
Diagnostics: Exception from container-launch: 
ExitCodeException exitCode=126: Got permission denied while trying to connect to the Docker daemon socket at unix:///var/run/docker.sock: Get http://%2Fvar%2Frun%2Fdocker.sock/v1.40/containers/container_1584766611743_0007_02_000001/json: dial unix /var/run/docker.sock: connect: permission denied
/usr/bin/docker: Got permission denied while trying to connect to the Docker daemon socket at unix:///var/run/docker.sock: Post http://%2Fvar%2Frun%2Fdocker.sock/v1.40/containers/create?name=container_1584766611743_0007_02_000001: dial unix /var/run/docker.sock: connect: permission denied.
See '/usr/bin/docker run --help'.

	at org.apache.hadoop.util.Shell.runCommand(Shell.java:585)
	at org.apache.hadoop.util.Shell.run(Shell.java:482)
	at org.apache.hadoop.util.Shell$ShellCommandExecutor.execute(Shell.java:776)
	at org.apache.hadoop.yarn.server.nodemanager.DockerContainerExecutor.launchContainer(DockerContainerExecutor.java:247)
	at org.apache.hadoop.yarn.server.nodemanager.containermanager.launcher.ContainerLaunch.call(ContainerLaunch.java:302)
	at org.apache.hadoop.yarn.server.nodemanager.containermanager.launcher.ContainerLaunch.call(ContainerLaunch.java:82)
	at java.util.concurrent.FutureTask.run(FutureTask.java:266)
	at java.util.concurrent.ThreadPoolExecutor.runWorker(ThreadPoolExecutor.java:1142)
	at java.util.concurrent.ThreadPoolExecutor$Worker.run(ThreadPoolExecutor.java:617)
	at java.lang.Thread.run(Thread.java:748)


Container exited with a non-zero exit code 126
Failing this attempt. Failing the application.	APPID=application_1584766611743_0007
2020-03-21 16:31:08,111 INFO org.apache.hadoop.yarn.server.resourcemanager.scheduler.capacity.ParentQueue: Application removed - appId: application_1584766611743_0007 user: xidian leaf-queue of parent: root #applications: 0
2020-03-21 16:31:08,111 INFO org.apache.hadoop.yarn.server.resourcemanager.RMAppManager$ApplicationSummary: appId=application_1584766611743_0007,name=word count,user=xidian,queue=default,state=FAILED,trackingUrl=http://dell:8088/cluster/app/application_1584766611743_0007,appMasterHost=N/A,startTime=1584779462021,finishTime=1584779468111,finalStatus=FAILED,memorySeconds=9135,vcoreSeconds=4,preemptedAMContainers=0,preemptedNonAMContainers=0,preemptedResources=<memory:0\, vCores:0>,applicationType=MAPREDUCE
2020-03-21 19:57:55,570 INFO org.apache.hadoop.yarn.server.resourcemanager.ClientRMService: Allocated new applicationId: 8
2020-03-21 19:57:56,393 INFO org.apache.hadoop.yarn.server.resourcemanager.ClientRMService: Application with id 8 submitted by user xidian
2020-03-21 19:57:56,393 INFO org.apache.hadoop.yarn.server.resourcemanager.rmapp.RMAppImpl: Storing application with id application_1584766611743_0008
2020-03-21 19:57:56,393 INFO org.apache.hadoop.yarn.server.resourcemanager.RMAuditLogger: USER=xidian	IP=127.0.0.1	OPERATION=Submit Application Request	TARGET=ClientRMService	RESULT=SUCCESS	APPID=application_1584766611743_0008
2020-03-21 19:57:56,393 INFO org.apache.hadoop.yarn.server.resourcemanager.rmapp.RMAppImpl: application_1584766611743_0008 State change from NEW to NEW_SAVING on event=START
2020-03-21 19:57:56,393 INFO org.apache.hadoop.yarn.server.resourcemanager.recovery.RMStateStore: Storing info for app: application_1584766611743_0008
2020-03-21 19:57:56,393 INFO org.apache.hadoop.yarn.server.resourcemanager.rmapp.RMAppImpl: application_1584766611743_0008 State change from NEW_SAVING to SUBMITTED on event=APP_NEW_SAVED
2020-03-21 19:57:56,393 INFO org.apache.hadoop.yarn.server.resourcemanager.scheduler.capacity.ParentQueue: Application added - appId: application_1584766611743_0008 user: xidian leaf-queue of parent: root #applications: 1
2020-03-21 19:57:56,393 INFO org.apache.hadoop.yarn.server.resourcemanager.scheduler.capacity.CapacityScheduler: Accepted application application_1584766611743_0008 from user: xidian, in queue: default
2020-03-21 19:57:56,394 INFO org.apache.hadoop.yarn.server.resourcemanager.rmapp.RMAppImpl: application_1584766611743_0008 State change from SUBMITTED to ACCEPTED on event=APP_ACCEPTED
2020-03-21 19:57:56,394 INFO org.apache.hadoop.yarn.server.resourcemanager.ApplicationMasterService: Registering app attempt : appattempt_1584766611743_0008_000001
2020-03-21 19:57:56,394 INFO org.apache.hadoop.yarn.server.resourcemanager.rmapp.attempt.RMAppAttemptImpl: appattempt_1584766611743_0008_000001 State change from NEW to SUBMITTED
2020-03-21 19:57:56,394 WARN org.apache.hadoop.yarn.server.resourcemanager.scheduler.capacity.LeafQueue: maximum-am-resource-percent is insufficient to start a single application in queue, it is likely set too low. skipping enforcement to allow at least one application to start
2020-03-21 19:57:56,394 WARN org.apache.hadoop.yarn.server.resourcemanager.scheduler.capacity.LeafQueue: maximum-am-resource-percent is insufficient to start a single application in queue for user, it is likely set too low. skipping enforcement to allow at least one application to start
2020-03-21 19:57:56,394 INFO org.apache.hadoop.yarn.server.resourcemanager.scheduler.capacity.LeafQueue: Application application_1584766611743_0008 from user: xidian activated in queue: default
2020-03-21 19:57:56,394 INFO org.apache.hadoop.yarn.server.resourcemanager.scheduler.capacity.LeafQueue: Application added - appId: application_1584766611743_0008 user: org.apache.hadoop.yarn.server.resourcemanager.scheduler.capacity.LeafQueue$User@4be3f233, leaf-queue: default #user-pending-applications: 0 #user-active-applications: 1 #queue-pending-applications: 0 #queue-active-applications: 1
2020-03-21 19:57:56,394 INFO org.apache.hadoop.yarn.server.resourcemanager.scheduler.capacity.CapacityScheduler: Added Application Attempt appattempt_1584766611743_0008_000001 to scheduler from user xidian in queue default
2020-03-21 19:57:56,395 INFO org.apache.hadoop.yarn.server.resourcemanager.rmapp.attempt.RMAppAttemptImpl: appattempt_1584766611743_0008_000001 State change from SUBMITTED to SCHEDULED
2020-03-21 19:57:56,850 INFO org.apache.hadoop.yarn.server.resourcemanager.rmcontainer.RMContainerImpl: container_1584766611743_0008_01_000001 Container Transitioned from NEW to ALLOCATED
2020-03-21 19:57:56,850 INFO org.apache.hadoop.yarn.server.resourcemanager.RMAuditLogger: USER=xidian	OPERATION=AM Allocated Container	TARGET=SchedulerApp	RESULT=SUCCESS	APPID=application_1584766611743_0008	CONTAINERID=container_1584766611743_0008_01_000001
2020-03-21 19:57:56,850 INFO org.apache.hadoop.yarn.server.resourcemanager.scheduler.SchedulerNode: Assigned container container_1584766611743_0008_01_000001 of capacity <memory:2048, vCores:1> on host dell:34479, which has 1 containers, <memory:2048, vCores:1> used and <memory:6144, vCores:7> available after allocation
2020-03-21 19:57:56,850 INFO org.apache.hadoop.yarn.server.resourcemanager.scheduler.capacity.LeafQueue: assignedContainer application attempt=appattempt_1584766611743_0008_000001 container=Container: [ContainerId: container_1584766611743_0008_01_000001, NodeId: dell:34479, NodeHttpAddress: dell:8042, Resource: <memory:2048, vCores:1>, Priority: 0, Token: null, ] queue=default: capacity=1.0, absoluteCapacity=1.0, usedResources=<memory:0, vCores:0>, usedCapacity=0.0, absoluteUsedCapacity=0.0, numApps=1, numContainers=0 clusterResource=<memory:8192, vCores:8> type=OFF_SWITCH requestedPartition=
2020-03-21 19:57:56,850 INFO org.apache.hadoop.yarn.server.resourcemanager.scheduler.capacity.ParentQueue: Re-sorting assigned queue: root.default stats: default: capacity=1.0, absoluteCapacity=1.0, usedResources=<memory:2048, vCores:1>, usedCapacity=0.25, absoluteUsedCapacity=0.25, numApps=1, numContainers=1
2020-03-21 19:57:56,850 INFO org.apache.hadoop.yarn.server.resourcemanager.scheduler.capacity.ParentQueue: assignedContainer queue=root usedCapacity=0.25 absoluteUsedCapacity=0.25 used=<memory:2048, vCores:1> cluster=<memory:8192, vCores:8>
2020-03-21 19:57:56,851 INFO org.apache.hadoop.yarn.server.resourcemanager.security.NMTokenSecretManagerInRM: Sending NMToken for nodeId : dell:34479 for container : container_1584766611743_0008_01_000001
2020-03-21 19:57:56,852 INFO org.apache.hadoop.yarn.server.resourcemanager.rmcontainer.RMContainerImpl: container_1584766611743_0008_01_000001 Container Transitioned from ALLOCATED to ACQUIRED
2020-03-21 19:57:56,852 INFO org.apache.hadoop.yarn.server.resourcemanager.security.NMTokenSecretManagerInRM: Clear node set for appattempt_1584766611743_0008_000001
2020-03-21 19:57:56,852 INFO org.apache.hadoop.yarn.server.resourcemanager.rmapp.attempt.RMAppAttemptImpl: Storing attempt: AppId: application_1584766611743_0008 AttemptId: appattempt_1584766611743_0008_000001 MasterContainer: Container: [ContainerId: container_1584766611743_0008_01_000001, NodeId: dell:34479, NodeHttpAddress: dell:8042, Resource: <memory:2048, vCores:1>, Priority: 0, Token: Token { kind: ContainerToken, service: 127.0.1.1:34479 }, ]
2020-03-21 19:57:56,852 INFO org.apache.hadoop.yarn.server.resourcemanager.rmapp.attempt.RMAppAttemptImpl: appattempt_1584766611743_0008_000001 State change from SCHEDULED to ALLOCATED_SAVING
2020-03-21 19:57:56,852 INFO org.apache.hadoop.yarn.server.resourcemanager.rmapp.attempt.RMAppAttemptImpl: appattempt_1584766611743_0008_000001 State change from ALLOCATED_SAVING to ALLOCATED
2020-03-21 19:57:56,852 INFO org.apache.hadoop.yarn.server.resourcemanager.amlauncher.AMLauncher: Launching masterappattempt_1584766611743_0008_000001
2020-03-21 19:57:56,854 INFO org.apache.hadoop.yarn.server.resourcemanager.amlauncher.AMLauncher: Setting up container Container: [ContainerId: container_1584766611743_0008_01_000001, NodeId: dell:34479, NodeHttpAddress: dell:8042, Resource: <memory:2048, vCores:1>, Priority: 0, Token: Token { kind: ContainerToken, service: 127.0.1.1:34479 }, ] for AM appattempt_1584766611743_0008_000001
2020-03-21 19:57:56,854 INFO org.apache.hadoop.yarn.server.resourcemanager.amlauncher.AMLauncher: Command to launch container container_1584766611743_0008_01_000001 : $JAVA_HOME/bin/java -Djava.io.tmpdir=$PWD/tmp -Dlog4j.configuration=container-log4j.properties -Dyarn.app.container.log.dir=<LOG_DIR> -Dyarn.app.container.log.filesize=0 -Dhadoop.root.logger=INFO,CLA -Dhadoop.root.logfile=syslog  -Xmx1024m org.apache.hadoop.mapreduce.v2.app.MRAppMaster 1><LOG_DIR>/stdout 2><LOG_DIR>/stderr 
2020-03-21 19:57:56,854 INFO org.apache.hadoop.yarn.server.resourcemanager.security.AMRMTokenSecretManager: Create AMRMToken for ApplicationAttempt: appattempt_1584766611743_0008_000001
2020-03-21 19:57:56,854 INFO org.apache.hadoop.yarn.server.resourcemanager.security.AMRMTokenSecretManager: Creating password for appattempt_1584766611743_0008_000001
2020-03-21 19:57:56,863 INFO org.apache.hadoop.yarn.server.resourcemanager.amlauncher.AMLauncher: Done launching container Container: [ContainerId: container_1584766611743_0008_01_000001, NodeId: dell:34479, NodeHttpAddress: dell:8042, Resource: <memory:2048, vCores:1>, Priority: 0, Token: Token { kind: ContainerToken, service: 127.0.1.1:34479 }, ] for AM appattempt_1584766611743_0008_000001
2020-03-21 19:57:56,863 INFO org.apache.hadoop.yarn.server.resourcemanager.rmapp.attempt.RMAppAttemptImpl: appattempt_1584766611743_0008_000001 State change from ALLOCATED to LAUNCHED
2020-03-21 19:57:57,852 INFO org.apache.hadoop.yarn.server.resourcemanager.rmcontainer.RMContainerImpl: container_1584766611743_0008_01_000001 Container Transitioned from ACQUIRED to RUNNING
2020-03-21 19:57:59,190 INFO org.apache.hadoop.yarn.server.resourcemanager.rmcontainer.RMContainerImpl: container_1584766611743_0008_01_000001 Container Transitioned from RUNNING to COMPLETED
2020-03-21 19:57:59,190 INFO org.apache.hadoop.yarn.server.resourcemanager.scheduler.common.fica.FiCaSchedulerApp: Completed container: container_1584766611743_0008_01_000001 in state: COMPLETED event:FINISHED
2020-03-21 19:57:59,190 INFO org.apache.hadoop.yarn.server.resourcemanager.RMAuditLogger: USER=xidian	OPERATION=AM Released Container	TARGET=SchedulerApp	RESULT=SUCCESS	APPID=application_1584766611743_0008	CONTAINERID=container_1584766611743_0008_01_000001
2020-03-21 19:57:59,190 INFO org.apache.hadoop.yarn.server.resourcemanager.scheduler.SchedulerNode: Released container container_1584766611743_0008_01_000001 of capacity <memory:2048, vCores:1> on host dell:34479, which currently has 0 containers, <memory:0, vCores:0> used and <memory:8192, vCores:8> available, release resources=true
2020-03-21 19:57:59,190 INFO org.apache.hadoop.yarn.server.resourcemanager.scheduler.capacity.LeafQueue: default used=<memory:0, vCores:0> numContainers=0 user=xidian user-resources=<memory:0, vCores:0>
2020-03-21 19:57:59,190 INFO org.apache.hadoop.yarn.server.resourcemanager.scheduler.capacity.LeafQueue: completedContainer container=Container: [ContainerId: container_1584766611743_0008_01_000001, NodeId: dell:34479, NodeHttpAddress: dell:8042, Resource: <memory:2048, vCores:1>, Priority: 0, Token: Token { kind: ContainerToken, service: 127.0.1.1:34479 }, ] queue=default: capacity=1.0, absoluteCapacity=1.0, usedResources=<memory:0, vCores:0>, usedCapacity=0.0, absoluteUsedCapacity=0.0, numApps=1, numContainers=0 cluster=<memory:8192, vCores:8>
2020-03-21 19:57:59,190 INFO org.apache.hadoop.yarn.server.resourcemanager.rmapp.attempt.RMAppAttemptImpl: Updating application attempt appattempt_1584766611743_0008_000001 with final state: FAILED, and exit status: 126
2020-03-21 19:57:59,190 INFO org.apache.hadoop.yarn.server.resourcemanager.scheduler.capacity.ParentQueue: completedContainer queue=root usedCapacity=0.0 absoluteUsedCapacity=0.0 used=<memory:0, vCores:0> cluster=<memory:8192, vCores:8>
2020-03-21 19:57:59,190 INFO org.apache.hadoop.yarn.server.resourcemanager.rmapp.attempt.RMAppAttemptImpl: appattempt_1584766611743_0008_000001 State change from LAUNCHED to FINAL_SAVING
2020-03-21 19:57:59,191 INFO org.apache.hadoop.yarn.server.resourcemanager.ApplicationMasterService: Unregistering app attempt : appattempt_1584766611743_0008_000001
2020-03-21 19:57:59,191 INFO org.apache.hadoop.yarn.server.resourcemanager.security.AMRMTokenSecretManager: Application finished, removing password for appattempt_1584766611743_0008_000001
2020-03-21 19:57:59,191 INFO org.apache.hadoop.yarn.server.resourcemanager.rmapp.attempt.RMAppAttemptImpl: appattempt_1584766611743_0008_000001 State change from FINAL_SAVING to FAILED
2020-03-21 19:57:59,191 INFO org.apache.hadoop.yarn.server.resourcemanager.scheduler.capacity.ParentQueue: Re-sorting completed queue: root.default stats: default: capacity=1.0, absoluteCapacity=1.0, usedResources=<memory:0, vCores:0>, usedCapacity=0.0, absoluteUsedCapacity=0.0, numApps=1, numContainers=0
2020-03-21 19:57:59,191 INFO org.apache.hadoop.yarn.server.resourcemanager.rmapp.RMAppImpl: The number of failed attempts is 1. The max attempts is 2
2020-03-21 19:57:59,191 INFO org.apache.hadoop.yarn.server.resourcemanager.scheduler.capacity.CapacityScheduler: Application attempt appattempt_1584766611743_0008_000001 released container container_1584766611743_0008_01_000001 on node: host: dell:34479 #containers=0 available=<memory:8192, vCores:8> used=<memory:0, vCores:0> with event: FINISHED
2020-03-21 19:57:59,191 INFO org.apache.hadoop.yarn.server.resourcemanager.scheduler.capacity.CapacityScheduler: Application Attempt appattempt_1584766611743_0008_000001 is done. finalState=FAILED
2020-03-21 19:57:59,191 INFO org.apache.hadoop.yarn.server.resourcemanager.scheduler.AppSchedulingInfo: Application application_1584766611743_0008 requests cleared
2020-03-21 19:57:59,191 INFO org.apache.hadoop.yarn.server.resourcemanager.scheduler.capacity.LeafQueue: Application removed - appId: application_1584766611743_0008 user: xidian queue: default #user-pending-applications: 0 #user-active-applications: 0 #queue-pending-applications: 0 #queue-active-applications: 0
2020-03-21 19:57:59,191 INFO org.apache.hadoop.yarn.server.resourcemanager.ApplicationMasterService: Registering app attempt : appattempt_1584766611743_0008_000002
2020-03-21 19:57:59,191 INFO org.apache.hadoop.yarn.server.resourcemanager.rmapp.attempt.RMAppAttemptImpl: appattempt_1584766611743_0008_000002 State change from NEW to SUBMITTED
2020-03-21 19:57:59,191 WARN org.apache.hadoop.yarn.server.resourcemanager.scheduler.capacity.LeafQueue: maximum-am-resource-percent is insufficient to start a single application in queue, it is likely set too low. skipping enforcement to allow at least one application to start
2020-03-21 19:57:59,191 WARN org.apache.hadoop.yarn.server.resourcemanager.scheduler.capacity.LeafQueue: maximum-am-resource-percent is insufficient to start a single application in queue for user, it is likely set too low. skipping enforcement to allow at least one application to start
2020-03-21 19:57:59,191 INFO org.apache.hadoop.yarn.server.resourcemanager.scheduler.capacity.LeafQueue: Application application_1584766611743_0008 from user: xidian activated in queue: default
2020-03-21 19:57:59,191 INFO org.apache.hadoop.yarn.server.resourcemanager.scheduler.capacity.LeafQueue: Application added - appId: application_1584766611743_0008 user: org.apache.hadoop.yarn.server.resourcemanager.scheduler.capacity.LeafQueue$User@38cf1baf, leaf-queue: default #user-pending-applications: 0 #user-active-applications: 1 #queue-pending-applications: 0 #queue-active-applications: 1
2020-03-21 19:57:59,191 INFO org.apache.hadoop.yarn.server.resourcemanager.scheduler.capacity.CapacityScheduler: Added Application Attempt appattempt_1584766611743_0008_000002 to scheduler from user xidian in queue default
2020-03-21 19:57:59,192 INFO org.apache.hadoop.yarn.server.resourcemanager.rmapp.attempt.RMAppAttemptImpl: appattempt_1584766611743_0008_000002 State change from SUBMITTED to SCHEDULED
2020-03-21 19:58:00,191 INFO org.apache.hadoop.yarn.server.resourcemanager.rmcontainer.RMContainerImpl: container_1584766611743_0008_02_000001 Container Transitioned from NEW to ALLOCATED
2020-03-21 19:58:00,191 INFO org.apache.hadoop.yarn.server.resourcemanager.RMAuditLogger: USER=xidian	OPERATION=AM Allocated Container	TARGET=SchedulerApp	RESULT=SUCCESS	APPID=application_1584766611743_0008	CONTAINERID=container_1584766611743_0008_02_000001
2020-03-21 19:58:00,191 INFO org.apache.hadoop.yarn.server.resourcemanager.scheduler.SchedulerNode: Assigned container container_1584766611743_0008_02_000001 of capacity <memory:2048, vCores:1> on host dell:34479, which has 1 containers, <memory:2048, vCores:1> used and <memory:6144, vCores:7> available after allocation
2020-03-21 19:58:00,191 INFO org.apache.hadoop.yarn.server.resourcemanager.scheduler.capacity.LeafQueue: assignedContainer application attempt=appattempt_1584766611743_0008_000002 container=Container: [ContainerId: container_1584766611743_0008_02_000001, NodeId: dell:34479, NodeHttpAddress: dell:8042, Resource: <memory:2048, vCores:1>, Priority: 0, Token: null, ] queue=default: capacity=1.0, absoluteCapacity=1.0, usedResources=<memory:0, vCores:0>, usedCapacity=0.0, absoluteUsedCapacity=0.0, numApps=1, numContainers=0 clusterResource=<memory:8192, vCores:8> type=OFF_SWITCH requestedPartition=
2020-03-21 19:58:00,191 INFO org.apache.hadoop.yarn.server.resourcemanager.scheduler.capacity.ParentQueue: Re-sorting assigned queue: root.default stats: default: capacity=1.0, absoluteCapacity=1.0, usedResources=<memory:2048, vCores:1>, usedCapacity=0.25, absoluteUsedCapacity=0.25, numApps=1, numContainers=1
2020-03-21 19:58:00,192 INFO org.apache.hadoop.yarn.server.resourcemanager.scheduler.capacity.ParentQueue: assignedContainer queue=root usedCapacity=0.25 absoluteUsedCapacity=0.25 used=<memory:2048, vCores:1> cluster=<memory:8192, vCores:8>
2020-03-21 19:58:00,192 INFO org.apache.hadoop.yarn.server.resourcemanager.security.NMTokenSecretManagerInRM: Sending NMToken for nodeId : dell:34479 for container : container_1584766611743_0008_02_000001
2020-03-21 19:58:00,195 INFO org.apache.hadoop.yarn.server.resourcemanager.rmcontainer.RMContainerImpl: container_1584766611743_0008_02_000001 Container Transitioned from ALLOCATED to ACQUIRED
2020-03-21 19:58:00,195 INFO org.apache.hadoop.yarn.server.resourcemanager.security.NMTokenSecretManagerInRM: Clear node set for appattempt_1584766611743_0008_000002
2020-03-21 19:58:00,195 INFO org.apache.hadoop.yarn.server.resourcemanager.rmapp.attempt.RMAppAttemptImpl: Storing attempt: AppId: application_1584766611743_0008 AttemptId: appattempt_1584766611743_0008_000002 MasterContainer: Container: [ContainerId: container_1584766611743_0008_02_000001, NodeId: dell:34479, NodeHttpAddress: dell:8042, Resource: <memory:2048, vCores:1>, Priority: 0, Token: Token { kind: ContainerToken, service: 127.0.1.1:34479 }, ]
2020-03-21 19:58:00,195 INFO org.apache.hadoop.yarn.server.resourcemanager.rmapp.attempt.RMAppAttemptImpl: appattempt_1584766611743_0008_000002 State change from SCHEDULED to ALLOCATED_SAVING
2020-03-21 19:58:00,195 INFO org.apache.hadoop.yarn.server.resourcemanager.rmapp.attempt.RMAppAttemptImpl: appattempt_1584766611743_0008_000002 State change from ALLOCATED_SAVING to ALLOCATED
2020-03-21 19:58:00,196 INFO org.apache.hadoop.yarn.server.resourcemanager.amlauncher.AMLauncher: Launching masterappattempt_1584766611743_0008_000002
2020-03-21 19:58:00,202 INFO org.apache.hadoop.yarn.server.resourcemanager.amlauncher.AMLauncher: Setting up container Container: [ContainerId: container_1584766611743_0008_02_000001, NodeId: dell:34479, NodeHttpAddress: dell:8042, Resource: <memory:2048, vCores:1>, Priority: 0, Token: Token { kind: ContainerToken, service: 127.0.1.1:34479 }, ] for AM appattempt_1584766611743_0008_000002
2020-03-21 19:58:00,202 INFO org.apache.hadoop.yarn.server.resourcemanager.amlauncher.AMLauncher: Command to launch container container_1584766611743_0008_02_000001 : $JAVA_HOME/bin/java -Djava.io.tmpdir=$PWD/tmp -Dlog4j.configuration=container-log4j.properties -Dyarn.app.container.log.dir=<LOG_DIR> -Dyarn.app.container.log.filesize=0 -Dhadoop.root.logger=INFO,CLA -Dhadoop.root.logfile=syslog  -Xmx1024m org.apache.hadoop.mapreduce.v2.app.MRAppMaster 1><LOG_DIR>/stdout 2><LOG_DIR>/stderr 
2020-03-21 19:58:00,202 INFO org.apache.hadoop.yarn.server.resourcemanager.security.AMRMTokenSecretManager: Create AMRMToken for ApplicationAttempt: appattempt_1584766611743_0008_000002
2020-03-21 19:58:00,202 INFO org.apache.hadoop.yarn.server.resourcemanager.security.AMRMTokenSecretManager: Creating password for appattempt_1584766611743_0008_000002
2020-03-21 19:58:00,220 INFO org.apache.hadoop.yarn.server.resourcemanager.amlauncher.AMLauncher: Done launching container Container: [ContainerId: container_1584766611743_0008_02_000001, NodeId: dell:34479, NodeHttpAddress: dell:8042, Resource: <memory:2048, vCores:1>, Priority: 0, Token: Token { kind: ContainerToken, service: 127.0.1.1:34479 }, ] for AM appattempt_1584766611743_0008_000002
2020-03-21 19:58:00,220 INFO org.apache.hadoop.yarn.server.resourcemanager.rmapp.attempt.RMAppAttemptImpl: appattempt_1584766611743_0008_000002 State change from ALLOCATED to LAUNCHED
2020-03-21 19:58:01,191 INFO org.apache.hadoop.yarn.server.resourcemanager.rmcontainer.RMContainerImpl: container_1584766611743_0008_02_000001 Container Transitioned from ACQUIRED to RUNNING
2020-03-21 19:58:02,423 INFO org.apache.hadoop.yarn.server.resourcemanager.rmcontainer.RMContainerImpl: container_1584766611743_0008_02_000001 Container Transitioned from RUNNING to COMPLETED
2020-03-21 19:58:02,423 INFO org.apache.hadoop.yarn.server.resourcemanager.scheduler.common.fica.FiCaSchedulerApp: Completed container: container_1584766611743_0008_02_000001 in state: COMPLETED event:FINISHED
2020-03-21 19:58:02,423 INFO org.apache.hadoop.yarn.server.resourcemanager.RMAuditLogger: USER=xidian	OPERATION=AM Released Container	TARGET=SchedulerApp	RESULT=SUCCESS	APPID=application_1584766611743_0008	CONTAINERID=container_1584766611743_0008_02_000001
2020-03-21 19:58:02,423 INFO org.apache.hadoop.yarn.server.resourcemanager.scheduler.SchedulerNode: Released container container_1584766611743_0008_02_000001 of capacity <memory:2048, vCores:1> on host dell:34479, which currently has 0 containers, <memory:0, vCores:0> used and <memory:8192, vCores:8> available, release resources=true
2020-03-21 19:58:02,423 INFO org.apache.hadoop.yarn.server.resourcemanager.scheduler.capacity.LeafQueue: default used=<memory:0, vCores:0> numContainers=0 user=xidian user-resources=<memory:0, vCores:0>
2020-03-21 19:58:02,423 INFO org.apache.hadoop.yarn.server.resourcemanager.rmapp.attempt.RMAppAttemptImpl: Updating application attempt appattempt_1584766611743_0008_000002 with final state: FAILED, and exit status: 126
2020-03-21 19:58:02,423 INFO org.apache.hadoop.yarn.server.resourcemanager.rmapp.attempt.RMAppAttemptImpl: appattempt_1584766611743_0008_000002 State change from LAUNCHED to FINAL_SAVING
2020-03-21 19:58:02,423 INFO org.apache.hadoop.yarn.server.resourcemanager.scheduler.capacity.LeafQueue: completedContainer container=Container: [ContainerId: container_1584766611743_0008_02_000001, NodeId: dell:34479, NodeHttpAddress: dell:8042, Resource: <memory:2048, vCores:1>, Priority: 0, Token: Token { kind: ContainerToken, service: 127.0.1.1:34479 }, ] queue=default: capacity=1.0, absoluteCapacity=1.0, usedResources=<memory:0, vCores:0>, usedCapacity=0.0, absoluteUsedCapacity=0.0, numApps=1, numContainers=0 cluster=<memory:8192, vCores:8>
2020-03-21 19:58:02,423 INFO org.apache.hadoop.yarn.server.resourcemanager.scheduler.capacity.ParentQueue: completedContainer queue=root usedCapacity=0.0 absoluteUsedCapacity=0.0 used=<memory:0, vCores:0> cluster=<memory:8192, vCores:8>
2020-03-21 19:58:02,423 INFO org.apache.hadoop.yarn.server.resourcemanager.scheduler.capacity.ParentQueue: Re-sorting completed queue: root.default stats: default: capacity=1.0, absoluteCapacity=1.0, usedResources=<memory:0, vCores:0>, usedCapacity=0.0, absoluteUsedCapacity=0.0, numApps=1, numContainers=0
2020-03-21 19:58:02,423 INFO org.apache.hadoop.yarn.server.resourcemanager.ApplicationMasterService: Unregistering app attempt : appattempt_1584766611743_0008_000002
2020-03-21 19:58:02,424 INFO org.apache.hadoop.yarn.server.resourcemanager.security.AMRMTokenSecretManager: Application finished, removing password for appattempt_1584766611743_0008_000002
2020-03-21 19:58:02,423 INFO org.apache.hadoop.yarn.server.resourcemanager.scheduler.capacity.CapacityScheduler: Application attempt appattempt_1584766611743_0008_000002 released container container_1584766611743_0008_02_000001 on node: host: dell:34479 #containers=0 available=<memory:8192, vCores:8> used=<memory:0, vCores:0> with event: FINISHED
2020-03-21 19:58:02,424 INFO org.apache.hadoop.yarn.server.resourcemanager.rmapp.attempt.RMAppAttemptImpl: appattempt_1584766611743_0008_000002 State change from FINAL_SAVING to FAILED
2020-03-21 19:58:02,424 INFO org.apache.hadoop.yarn.server.resourcemanager.rmapp.RMAppImpl: The number of failed attempts is 2. The max attempts is 2
2020-03-21 19:58:02,424 INFO org.apache.hadoop.yarn.server.resourcemanager.rmapp.RMAppImpl: Updating application application_1584766611743_0008 with final state: FAILED
2020-03-21 19:58:02,424 INFO org.apache.hadoop.yarn.server.resourcemanager.rmapp.RMAppImpl: application_1584766611743_0008 State change from ACCEPTED to FINAL_SAVING on event=ATTEMPT_FAILED
2020-03-21 19:58:02,424 INFO org.apache.hadoop.yarn.server.resourcemanager.recovery.RMStateStore: Updating info for app: application_1584766611743_0008
2020-03-21 19:58:02,424 INFO org.apache.hadoop.yarn.server.resourcemanager.scheduler.capacity.CapacityScheduler: Application Attempt appattempt_1584766611743_0008_000002 is done. finalState=FAILED
2020-03-21 19:58:02,424 INFO org.apache.hadoop.yarn.server.resourcemanager.rmapp.RMAppImpl: Application application_1584766611743_0008 failed 2 times due to AM Container for appattempt_1584766611743_0008_000002 exited with  exitCode: 126
For more detailed output, check application tracking page:http://dell:8088/cluster/app/application_1584766611743_0008Then, click on links to logs of each attempt.
Diagnostics: Exception from container-launch: 
ExitCodeException exitCode=126: Got permission denied while trying to connect to the Docker daemon socket at unix:///var/run/docker.sock: Get http://%2Fvar%2Frun%2Fdocker.sock/v1.40/containers/container_1584766611743_0008_02_000001/json: dial unix /var/run/docker.sock: connect: permission denied
/usr/bin/docker: Got permission denied while trying to connect to the Docker daemon socket at unix:///var/run/docker.sock: Post http://%2Fvar%2Frun%2Fdocker.sock/v1.40/containers/create?name=container_1584766611743_0008_02_000001: dial unix /var/run/docker.sock: connect: permission denied.
See '/usr/bin/docker run --help'.

	at org.apache.hadoop.util.Shell.runCommand(Shell.java:585)
	at org.apache.hadoop.util.Shell.run(Shell.java:482)
	at org.apache.hadoop.util.Shell$ShellCommandExecutor.execute(Shell.java:776)
	at org.apache.hadoop.yarn.server.nodemanager.DockerContainerExecutor.launchContainer(DockerContainerExecutor.java:247)
	at org.apache.hadoop.yarn.server.nodemanager.containermanager.launcher.ContainerLaunch.call(ContainerLaunch.java:302)
	at org.apache.hadoop.yarn.server.nodemanager.containermanager.launcher.ContainerLaunch.call(ContainerLaunch.java:82)
	at java.util.concurrent.FutureTask.run(FutureTask.java:266)
	at java.util.concurrent.ThreadPoolExecutor.runWorker(ThreadPoolExecutor.java:1142)
	at java.util.concurrent.ThreadPoolExecutor$Worker.run(ThreadPoolExecutor.java:617)
	at java.lang.Thread.run(Thread.java:748)


Container exited with a non-zero exit code 126
Failing this attempt. Failing the application.
2020-03-21 19:58:02,424 INFO org.apache.hadoop.yarn.server.resourcemanager.scheduler.AppSchedulingInfo: Application application_1584766611743_0008 requests cleared
2020-03-21 19:58:02,424 INFO org.apache.hadoop.yarn.server.resourcemanager.rmapp.RMAppImpl: application_1584766611743_0008 State change from FINAL_SAVING to FAILED on event=APP_UPDATE_SAVED
2020-03-21 19:58:02,424 INFO org.apache.hadoop.yarn.server.resourcemanager.scheduler.capacity.LeafQueue: Application removed - appId: application_1584766611743_0008 user: xidian queue: default #user-pending-applications: 0 #user-active-applications: 0 #queue-pending-applications: 0 #queue-active-applications: 0
2020-03-21 19:58:02,425 INFO org.apache.hadoop.yarn.server.resourcemanager.scheduler.capacity.ParentQueue: Application removed - appId: application_1584766611743_0008 user: xidian leaf-queue of parent: root #applications: 0
2020-03-21 19:58:02,425 WARN org.apache.hadoop.yarn.server.resourcemanager.RMAuditLogger: USER=xidian	OPERATION=Application Finished - Failed	TARGET=RMAppManager	RESULT=FAILURE	DESCRIPTION=App failed with state: FAILED	PERMISSIONS=Application application_1584766611743_0008 failed 2 times due to AM Container for appattempt_1584766611743_0008_000002 exited with  exitCode: 126
For more detailed output, check application tracking page:http://dell:8088/cluster/app/application_1584766611743_0008Then, click on links to logs of each attempt.
Diagnostics: Exception from container-launch: 
ExitCodeException exitCode=126: Got permission denied while trying to connect to the Docker daemon socket at unix:///var/run/docker.sock: Get http://%2Fvar%2Frun%2Fdocker.sock/v1.40/containers/container_1584766611743_0008_02_000001/json: dial unix /var/run/docker.sock: connect: permission denied
/usr/bin/docker: Got permission denied while trying to connect to the Docker daemon socket at unix:///var/run/docker.sock: Post http://%2Fvar%2Frun%2Fdocker.sock/v1.40/containers/create?name=container_1584766611743_0008_02_000001: dial unix /var/run/docker.sock: connect: permission denied.
See '/usr/bin/docker run --help'.

	at org.apache.hadoop.util.Shell.runCommand(Shell.java:585)
	at org.apache.hadoop.util.Shell.run(Shell.java:482)
	at org.apache.hadoop.util.Shell$ShellCommandExecutor.execute(Shell.java:776)
	at org.apache.hadoop.yarn.server.nodemanager.DockerContainerExecutor.launchContainer(DockerContainerExecutor.java:247)
	at org.apache.hadoop.yarn.server.nodemanager.containermanager.launcher.ContainerLaunch.call(ContainerLaunch.java:302)
	at org.apache.hadoop.yarn.server.nodemanager.containermanager.launcher.ContainerLaunch.call(ContainerLaunch.java:82)
	at java.util.concurrent.FutureTask.run(FutureTask.java:266)
	at java.util.concurrent.ThreadPoolExecutor.runWorker(ThreadPoolExecutor.java:1142)
	at java.util.concurrent.ThreadPoolExecutor$Worker.run(ThreadPoolExecutor.java:617)
	at java.lang.Thread.run(Thread.java:748)


Container exited with a non-zero exit code 126
Failing this attempt. Failing the application.	APPID=application_1584766611743_0008
2020-03-21 19:58:02,425 INFO org.apache.hadoop.yarn.server.resourcemanager.RMAppManager$ApplicationSummary: appId=application_1584766611743_0008,name=word count,user=xidian,queue=default,state=FAILED,trackingUrl=http://dell:8088/cluster/app/application_1584766611743_0008,appMasterHost=N/A,startTime=1584791876393,finishTime=1584791882424,finalStatus=FAILED,memorySeconds=9361,vcoreSeconds=4,preemptedAMContainers=0,preemptedNonAMContainers=0,preemptedResources=<memory:0\, vCores:0>,applicationType=MAPREDUCE
2020-03-21 20:05:55,441 ERROR org.apache.hadoop.yarn.server.resourcemanager.ResourceManager: RECEIVED SIGNAL 15: SIGTERM
2020-03-21 20:05:55,443 ERROR org.apache.hadoop.security.token.delegation.AbstractDelegationTokenSecretManager: ExpiredTokenRemover received java.lang.InterruptedException: sleep interrupted
2020-03-21 20:05:55,443 INFO org.mortbay.log: Stopped HttpServer2$SelectChannelConnectorWithSafeStartup@0.0.0.0:8088
2020-03-21 20:05:55,544 INFO org.apache.hadoop.ipc.Server: Stopping server on 8032
2020-03-21 20:05:55,548 INFO org.apache.hadoop.ipc.Server: Stopping IPC Server listener on 8032
2020-03-21 20:05:55,548 INFO org.apache.hadoop.ipc.Server: Stopping IPC Server Responder
2020-03-21 20:05:55,549 INFO org.apache.hadoop.ipc.Server: Stopping server on 8033
2020-03-21 20:05:55,551 INFO org.apache.hadoop.ipc.Server: Stopping IPC Server listener on 8033
2020-03-21 20:05:55,551 INFO org.apache.hadoop.ipc.Server: Stopping IPC Server Responder
2020-03-21 20:05:55,552 INFO org.apache.hadoop.yarn.server.resourcemanager.ResourceManager: Transitioning to standby state
2020-03-21 20:05:55,552 WARN org.apache.hadoop.yarn.server.resourcemanager.amlauncher.ApplicationMasterLauncher: org.apache.hadoop.yarn.server.resourcemanager.amlauncher.ApplicationMasterLauncher$LauncherThread interrupted. Returning.
2020-03-21 20:05:55,555 INFO org.apache.hadoop.ipc.Server: Stopping server on 8030
2020-03-21 20:05:55,569 INFO org.apache.hadoop.ipc.Server: Stopping IPC Server listener on 8030
2020-03-21 20:05:55,569 INFO org.apache.hadoop.ipc.Server: Stopping IPC Server Responder
2020-03-21 20:05:55,569 INFO org.apache.hadoop.ipc.Server: Stopping server on 8031
2020-03-21 20:05:55,574 INFO org.apache.hadoop.ipc.Server: Stopping IPC Server Responder
2020-03-21 20:05:55,574 INFO org.apache.hadoop.yarn.util.AbstractLivelinessMonitor: NMLivelinessMonitor thread interrupted
2020-03-21 20:05:55,577 INFO org.apache.hadoop.ipc.Server: Stopping IPC Server listener on 8031
2020-03-21 20:05:55,574 ERROR org.apache.hadoop.yarn.server.resourcemanager.ResourceManager: Returning, interrupted : java.lang.InterruptedException
2020-03-21 20:05:55,581 INFO org.apache.hadoop.yarn.event.AsyncDispatcher: AsyncDispatcher is draining to stop, igonring any new events.
2020-03-21 20:05:55,582 INFO org.apache.hadoop.yarn.util.AbstractLivelinessMonitor: org.apache.hadoop.yarn.server.resourcemanager.rmcontainer.ContainerAllocationExpirer thread interrupted
2020-03-21 20:05:55,582 ERROR org.apache.hadoop.security.token.delegation.AbstractDelegationTokenSecretManager: ExpiredTokenRemover received java.lang.InterruptedException: sleep interrupted
2020-03-21 20:05:55,582 INFO org.apache.hadoop.yarn.util.AbstractLivelinessMonitor: AMLivelinessMonitor thread interrupted
2020-03-21 20:05:55,582 INFO org.apache.hadoop.yarn.util.AbstractLivelinessMonitor: AMLivelinessMonitor thread interrupted
2020-03-21 20:05:55,583 INFO org.apache.hadoop.metrics2.impl.MetricsSystemImpl: Stopping ResourceManager metrics system...
2020-03-21 20:05:55,586 INFO org.apache.hadoop.metrics2.impl.MetricsSystemImpl: ResourceManager metrics system stopped.
2020-03-21 20:05:55,586 INFO org.apache.hadoop.metrics2.impl.MetricsSystemImpl: ResourceManager metrics system shutdown complete.
2020-03-21 20:05:55,586 INFO org.apache.hadoop.yarn.event.AsyncDispatcher: AsyncDispatcher is draining to stop, igonring any new events.
2020-03-21 20:05:55,587 INFO org.apache.hadoop.yarn.server.resourcemanager.ResourceManager: Transitioned to standby state
2020-03-21 20:05:55,587 INFO org.apache.hadoop.yarn.server.resourcemanager.ResourceManager: SHUTDOWN_MSG: 
/************************************************************
SHUTDOWN_MSG: Shutting down ResourceManager at dell/127.0.1.1
************************************************************/
2020-03-21 20:06:27,437 INFO org.apache.hadoop.yarn.server.resourcemanager.ResourceManager: STARTUP_MSG: 
/************************************************************
STARTUP_MSG: Starting ResourceManager
STARTUP_MSG:   host = dell/127.0.1.1
STARTUP_MSG:   args = []
STARTUP_MSG:   version = 2.7.7
STARTUP_MSG:   build = Unknown -r c1aad84bd27cd79c3d1a7dd58202a8c3ee1ed3ac; compiled by 'stevel' on 2018-07-18T22:47Z
STARTUP_MSG:   java = 1.8.0_131
************************************************************/
2020-03-21 20:06:27,443 INFO org.apache.hadoop.yarn.server.resourcemanager.ResourceManager: registered UNIX signal handlers for [TERM, HUP, INT]
2020-03-21 20:06:27,596 INFO org.apache.hadoop.conf.Configuration: found resource core-site.xml at file:/home/xidian/hadoop-2.7.7/etc/hadoop/core-site.xml
2020-03-21 20:06:27,655 INFO org.apache.hadoop.security.Groups: clearing userToGroupsMap cache
2020-03-21 20:06:27,684 INFO org.apache.hadoop.conf.Configuration: found resource yarn-site.xml at file:/home/xidian/hadoop-2.7.7/etc/hadoop/yarn-site.xml
2020-03-21 20:06:27,802 INFO org.apache.hadoop.yarn.event.AsyncDispatcher: Registering class org.apache.hadoop.yarn.server.resourcemanager.RMFatalEventType for class org.apache.hadoop.yarn.server.resourcemanager.ResourceManager$RMFatalEventDispatcher
2020-03-21 20:06:27,926 INFO org.apache.hadoop.yarn.server.resourcemanager.security.NMTokenSecretManagerInRM: NMTokenKeyRollingInterval: 86400000ms and NMTokenKeyActivationDelay: 900000ms
2020-03-21 20:06:27,928 INFO org.apache.hadoop.yarn.server.resourcemanager.security.RMContainerTokenSecretManager: ContainerTokenKeyRollingInterval: 86400000ms and ContainerTokenKeyActivationDelay: 900000ms
2020-03-21 20:06:27,931 INFO org.apache.hadoop.yarn.server.resourcemanager.security.AMRMTokenSecretManager: AMRMTokenKeyRollingInterval: 86400000ms and AMRMTokenKeyActivationDelay: 900000 ms
2020-03-21 20:06:27,949 INFO org.apache.hadoop.yarn.event.AsyncDispatcher: Registering class org.apache.hadoop.yarn.server.resourcemanager.recovery.RMStateStoreEventType for class org.apache.hadoop.yarn.server.resourcemanager.recovery.RMStateStore$ForwardingEventHandler
2020-03-21 20:06:27,950 INFO org.apache.hadoop.yarn.event.AsyncDispatcher: Registering class org.apache.hadoop.yarn.server.resourcemanager.NodesListManagerEventType for class org.apache.hadoop.yarn.server.resourcemanager.NodesListManager
2020-03-21 20:06:27,950 INFO org.apache.hadoop.yarn.server.resourcemanager.ResourceManager: Using Scheduler: org.apache.hadoop.yarn.server.resourcemanager.scheduler.capacity.CapacityScheduler
2020-03-21 20:06:27,958 INFO org.apache.hadoop.yarn.event.AsyncDispatcher: Registering class org.apache.hadoop.yarn.server.resourcemanager.scheduler.event.SchedulerEventType for class org.apache.hadoop.yarn.server.resourcemanager.ResourceManager$SchedulerEventDispatcher
2020-03-21 20:06:27,958 INFO org.apache.hadoop.yarn.event.AsyncDispatcher: Registering class org.apache.hadoop.yarn.server.resourcemanager.rmapp.RMAppEventType for class org.apache.hadoop.yarn.server.resourcemanager.ResourceManager$ApplicationEventDispatcher
2020-03-21 20:06:27,959 INFO org.apache.hadoop.yarn.event.AsyncDispatcher: Registering class org.apache.hadoop.yarn.server.resourcemanager.rmapp.attempt.RMAppAttemptEventType for class org.apache.hadoop.yarn.server.resourcemanager.ResourceManager$ApplicationAttemptEventDispatcher
2020-03-21 20:06:27,959 INFO org.apache.hadoop.yarn.event.AsyncDispatcher: Registering class org.apache.hadoop.yarn.server.resourcemanager.rmnode.RMNodeEventType for class org.apache.hadoop.yarn.server.resourcemanager.ResourceManager$NodeEventDispatcher
2020-03-21 20:06:27,991 INFO org.apache.hadoop.metrics2.impl.MetricsConfig: loaded properties from hadoop-metrics2.properties
2020-03-21 20:06:28,028 INFO org.apache.hadoop.metrics2.impl.MetricsSystemImpl: Scheduled snapshot period at 10 second(s).
2020-03-21 20:06:28,028 INFO org.apache.hadoop.metrics2.impl.MetricsSystemImpl: ResourceManager metrics system started
2020-03-21 20:06:28,036 INFO org.apache.hadoop.yarn.event.AsyncDispatcher: Registering class org.apache.hadoop.yarn.server.resourcemanager.RMAppManagerEventType for class org.apache.hadoop.yarn.server.resourcemanager.RMAppManager
2020-03-21 20:06:28,040 INFO org.apache.hadoop.yarn.event.AsyncDispatcher: Registering class org.apache.hadoop.yarn.server.resourcemanager.amlauncher.AMLauncherEventType for class org.apache.hadoop.yarn.server.resourcemanager.amlauncher.ApplicationMasterLauncher
2020-03-21 20:06:28,041 INFO org.apache.hadoop.yarn.server.resourcemanager.RMNMInfo: Registered RMNMInfo MBean
2020-03-21 20:06:28,043 INFO org.apache.hadoop.yarn.security.YarnAuthorizationProvider: org.apache.hadoop.yarn.security.ConfiguredYarnAuthorizer is instiantiated.
2020-03-21 20:06:28,043 INFO org.apache.hadoop.util.HostsFileReader: Refreshing hosts (include/exclude) list
2020-03-21 20:06:28,044 INFO org.apache.hadoop.conf.Configuration: found resource capacity-scheduler.xml at file:/home/xidian/hadoop-2.7.7/etc/hadoop/capacity-scheduler.xml
2020-03-21 20:06:28,070 INFO org.apache.hadoop.yarn.server.resourcemanager.scheduler.capacity.CapacitySchedulerConfiguration: max alloc mb per queue for root is undefined
2020-03-21 20:06:28,070 INFO org.apache.hadoop.yarn.server.resourcemanager.scheduler.capacity.CapacitySchedulerConfiguration: max alloc vcore per queue for root is undefined
2020-03-21 20:06:28,072 INFO org.apache.hadoop.yarn.server.resourcemanager.scheduler.capacity.ParentQueue: root, capacity=1.0, asboluteCapacity=1.0, maxCapacity=1.0, asboluteMaxCapacity=1.0, state=RUNNING, acls=ADMINISTER_QUEUE:*SUBMIT_APP:*, labels=*,
, reservationsContinueLooking=true
2020-03-21 20:06:28,072 INFO org.apache.hadoop.yarn.server.resourcemanager.scheduler.capacity.ParentQueue: Initialized parent-queue root name=root, fullname=root
2020-03-21 20:06:28,077 INFO org.apache.hadoop.yarn.server.resourcemanager.scheduler.capacity.CapacitySchedulerConfiguration: max alloc mb per queue for root.default is undefined
2020-03-21 20:06:28,077 INFO org.apache.hadoop.yarn.server.resourcemanager.scheduler.capacity.CapacitySchedulerConfiguration: max alloc vcore per queue for root.default is undefined
2020-03-21 20:06:28,078 INFO org.apache.hadoop.yarn.server.resourcemanager.scheduler.capacity.LeafQueue: Initializing default
capacity = 1.0 [= (float) configuredCapacity / 100 ]
asboluteCapacity = 1.0 [= parentAbsoluteCapacity * capacity ]
maxCapacity = 1.0 [= configuredMaxCapacity ]
absoluteMaxCapacity = 1.0 [= 1.0 maximumCapacity undefined, (parentAbsoluteMaxCapacity * maximumCapacity) / 100 otherwise ]
userLimit = 100 [= configuredUserLimit ]
userLimitFactor = 1.0 [= configuredUserLimitFactor ]
maxApplications = 10000 [= configuredMaximumSystemApplicationsPerQueue or (int)(configuredMaximumSystemApplications * absoluteCapacity)]
maxApplicationsPerUser = 10000 [= (int)(maxApplications * (userLimit / 100.0f) * userLimitFactor) ]
usedCapacity = 0.0 [= usedResourcesMemory / (clusterResourceMemory * absoluteCapacity)]
absoluteUsedCapacity = 0.0 [= usedResourcesMemory / clusterResourceMemory]
maxAMResourcePerQueuePercent = 0.1 [= configuredMaximumAMResourcePercent ]
minimumAllocationFactor = 0.875 [= (float)(maximumAllocationMemory - minimumAllocationMemory) / maximumAllocationMemory ]
maximumAllocation = <memory:8192, vCores:32> [= configuredMaxAllocation ]
numContainers = 0 [= currentNumContainers ]
state = RUNNING [= configuredState ]
acls = ADMINISTER_QUEUE:*SUBMIT_APP:* [= configuredAcls ]
nodeLocalityDelay = 40
labels=*,
nodeLocalityDelay = 40
reservationsContinueLooking = true
preemptionDisabled = true

2020-03-21 20:06:28,078 INFO org.apache.hadoop.yarn.server.resourcemanager.scheduler.capacity.CapacityScheduler: Initialized queue: default: capacity=1.0, absoluteCapacity=1.0, usedResources=<memory:0, vCores:0>, usedCapacity=0.0, absoluteUsedCapacity=0.0, numApps=0, numContainers=0
2020-03-21 20:06:28,078 INFO org.apache.hadoop.yarn.server.resourcemanager.scheduler.capacity.CapacityScheduler: Initialized queue: root: numChildQueue= 1, capacity=1.0, absoluteCapacity=1.0, usedResources=<memory:0, vCores:0>usedCapacity=0.0, numApps=0, numContainers=0
2020-03-21 20:06:28,078 INFO org.apache.hadoop.yarn.server.resourcemanager.scheduler.capacity.CapacityScheduler: Initialized root queue root: numChildQueue= 1, capacity=1.0, absoluteCapacity=1.0, usedResources=<memory:0, vCores:0>usedCapacity=0.0, numApps=0, numContainers=0
2020-03-21 20:06:28,078 INFO org.apache.hadoop.yarn.server.resourcemanager.scheduler.capacity.CapacityScheduler: Initialized queue mappings, override: false
2020-03-21 20:06:28,079 INFO org.apache.hadoop.yarn.server.resourcemanager.scheduler.capacity.CapacityScheduler: Initialized CapacityScheduler with calculator=class org.apache.hadoop.yarn.util.resource.DefaultResourceCalculator, minimumAllocation=<<memory:1024, vCores:1>>, maximumAllocation=<<memory:8192, vCores:32>>, asynchronousScheduling=false, asyncScheduleInterval=5ms
2020-03-21 20:06:28,084 INFO org.apache.hadoop.yarn.server.resourcemanager.metrics.SystemMetricsPublisher: YARN system metrics publishing service is not enabled
2020-03-21 20:06:28,084 INFO org.apache.hadoop.yarn.server.resourcemanager.ResourceManager: Transitioning to active state
2020-03-21 20:06:28,091 INFO org.apache.hadoop.yarn.server.resourcemanager.recovery.RMStateStore: Updating AMRMToken
2020-03-21 20:06:28,091 INFO org.apache.hadoop.yarn.server.resourcemanager.security.RMContainerTokenSecretManager: Rolling master-key for container-tokens
2020-03-21 20:06:28,092 INFO org.apache.hadoop.yarn.server.resourcemanager.security.NMTokenSecretManagerInRM: Rolling master-key for nm-tokens
2020-03-21 20:06:28,092 INFO org.apache.hadoop.security.token.delegation.AbstractDelegationTokenSecretManager: Updating the current master key for generating delegation tokens
2020-03-21 20:06:28,092 INFO org.apache.hadoop.yarn.server.resourcemanager.security.RMDelegationTokenSecretManager: storing master key with keyID 1
2020-03-21 20:06:28,092 INFO org.apache.hadoop.yarn.server.resourcemanager.recovery.RMStateStore: Storing RMDTMasterKey.
2020-03-21 20:06:28,093 INFO org.apache.hadoop.security.token.delegation.AbstractDelegationTokenSecretManager: Starting expired delegation token remover thread, tokenRemoverScanInterval=60 min(s)
2020-03-21 20:06:28,093 INFO org.apache.hadoop.security.token.delegation.AbstractDelegationTokenSecretManager: Updating the current master key for generating delegation tokens
2020-03-21 20:06:28,093 INFO org.apache.hadoop.yarn.server.resourcemanager.security.RMDelegationTokenSecretManager: storing master key with keyID 2
2020-03-21 20:06:28,093 INFO org.apache.hadoop.yarn.server.resourcemanager.recovery.RMStateStore: Storing RMDTMasterKey.
2020-03-21 20:06:28,094 INFO org.apache.hadoop.yarn.event.AsyncDispatcher: Registering class org.apache.hadoop.yarn.nodelabels.event.NodeLabelsStoreEventType for class org.apache.hadoop.yarn.nodelabels.CommonNodeLabelsManager$ForwardingEventHandler
2020-03-21 20:06:28,169 INFO org.apache.hadoop.ipc.CallQueueManager: Using callQueue: class java.util.concurrent.LinkedBlockingQueue queueCapacity: 5000
2020-03-21 20:06:28,178 INFO org.apache.hadoop.ipc.Server: Starting Socket Reader #1 for port 8031
2020-03-21 20:06:28,276 INFO org.apache.hadoop.yarn.factories.impl.pb.RpcServerFactoryPBImpl: Adding protocol org.apache.hadoop.yarn.server.api.ResourceTrackerPB to the server
2020-03-21 20:06:28,276 INFO org.apache.hadoop.ipc.Server: IPC Server Responder: starting
2020-03-21 20:06:28,276 INFO org.apache.hadoop.ipc.Server: IPC Server listener on 8031: starting
2020-03-21 20:06:28,358 INFO org.apache.hadoop.ipc.CallQueueManager: Using callQueue: class java.util.concurrent.LinkedBlockingQueue queueCapacity: 5000
2020-03-21 20:06:28,361 INFO org.apache.hadoop.ipc.Server: Starting Socket Reader #1 for port 8030
2020-03-21 20:06:28,367 INFO org.apache.hadoop.yarn.factories.impl.pb.RpcServerFactoryPBImpl: Adding protocol org.apache.hadoop.yarn.api.ApplicationMasterProtocolPB to the server
2020-03-21 20:06:28,367 INFO org.apache.hadoop.ipc.Server: IPC Server Responder: starting
2020-03-21 20:06:28,367 INFO org.apache.hadoop.ipc.Server: IPC Server listener on 8030: starting
2020-03-21 20:06:28,453 INFO org.apache.hadoop.ipc.CallQueueManager: Using callQueue: class java.util.concurrent.LinkedBlockingQueue queueCapacity: 5000
2020-03-21 20:06:28,453 INFO org.apache.hadoop.ipc.Server: Starting Socket Reader #1 for port 8032
2020-03-21 20:06:28,457 INFO org.apache.hadoop.yarn.factories.impl.pb.RpcServerFactoryPBImpl: Adding protocol org.apache.hadoop.yarn.api.ApplicationClientProtocolPB to the server
2020-03-21 20:06:28,457 INFO org.apache.hadoop.ipc.Server: IPC Server Responder: starting
2020-03-21 20:06:28,457 INFO org.apache.hadoop.ipc.Server: IPC Server listener on 8032: starting
2020-03-21 20:06:28,478 INFO org.apache.hadoop.yarn.server.resourcemanager.ResourceManager: Transitioned to active state
2020-03-21 20:06:28,559 INFO org.mortbay.log: Logging to org.slf4j.impl.Log4jLoggerAdapter(org.mortbay.log) via org.mortbay.log.Slf4jLog
2020-03-21 20:06:28,565 INFO org.apache.hadoop.security.authentication.server.AuthenticationFilter: Unable to initialize FileSignerSecretProvider, falling back to use random secrets.
2020-03-21 20:06:28,580 INFO org.apache.hadoop.http.HttpRequestLog: Http request log for http.requests.resourcemanager is not defined
2020-03-21 20:06:28,585 INFO org.apache.hadoop.http.HttpServer2: Added global filter 'safety' (class=org.apache.hadoop.http.HttpServer2$QuotingInputFilter)
2020-03-21 20:06:28,587 INFO org.apache.hadoop.http.HttpServer2: Added filter RMAuthenticationFilter (class=org.apache.hadoop.yarn.server.security.http.RMAuthenticationFilter) to context cluster
2020-03-21 20:06:28,587 INFO org.apache.hadoop.http.HttpServer2: Added filter RMAuthenticationFilter (class=org.apache.hadoop.yarn.server.security.http.RMAuthenticationFilter) to context logs
2020-03-21 20:06:28,587 INFO org.apache.hadoop.http.HttpServer2: Added filter RMAuthenticationFilter (class=org.apache.hadoop.yarn.server.security.http.RMAuthenticationFilter) to context static
2020-03-21 20:06:28,588 INFO org.apache.hadoop.http.HttpServer2: Added filter static_user_filter (class=org.apache.hadoop.http.lib.StaticUserWebFilter$StaticUserFilter) to context cluster
2020-03-21 20:06:28,588 INFO org.apache.hadoop.http.HttpServer2: Added filter static_user_filter (class=org.apache.hadoop.http.lib.StaticUserWebFilter$StaticUserFilter) to context logs
2020-03-21 20:06:28,588 INFO org.apache.hadoop.http.HttpServer2: Added filter static_user_filter (class=org.apache.hadoop.http.lib.StaticUserWebFilter$StaticUserFilter) to context static
2020-03-21 20:06:28,590 INFO org.apache.hadoop.http.HttpServer2: adding path spec: /cluster/*
2020-03-21 20:06:28,590 INFO org.apache.hadoop.http.HttpServer2: adding path spec: /ws/*
2020-03-21 20:06:28,794 INFO org.apache.hadoop.yarn.webapp.WebApps: Registered webapp guice modules
2020-03-21 20:06:28,796 INFO org.apache.hadoop.http.HttpServer2: Jetty bound to port 8088
2020-03-21 20:06:28,796 INFO org.mortbay.log: jetty-6.1.26
2020-03-21 20:06:28,811 INFO org.mortbay.log: Extract jar:file:/home/xidian/hadoop-2.7.7/share/hadoop/yarn/hadoop-yarn-common-2.7.7.jar!/webapps/cluster to /tmp/Jetty_0_0_0_0_8088_cluster____u0rgz3/webapp
2020-03-21 20:06:28,914 INFO org.apache.hadoop.security.token.delegation.AbstractDelegationTokenSecretManager: Updating the current master key for generating delegation tokens
2020-03-21 20:06:28,914 INFO org.apache.hadoop.security.token.delegation.AbstractDelegationTokenSecretManager: Starting expired delegation token remover thread, tokenRemoverScanInterval=60 min(s)
2020-03-21 20:06:28,914 INFO org.apache.hadoop.security.token.delegation.AbstractDelegationTokenSecretManager: Updating the current master key for generating delegation tokens
2020-03-21 20:06:29,652 INFO org.mortbay.log: Started HttpServer2$SelectChannelConnectorWithSafeStartup@0.0.0.0:8088
2020-03-21 20:06:29,652 INFO org.apache.hadoop.yarn.webapp.WebApps: Web app cluster started at 8088
2020-03-21 20:06:29,733 INFO org.apache.hadoop.ipc.CallQueueManager: Using callQueue: class java.util.concurrent.LinkedBlockingQueue queueCapacity: 100
2020-03-21 20:06:29,733 INFO org.apache.hadoop.ipc.Server: Starting Socket Reader #1 for port 8033
2020-03-21 20:06:29,736 INFO org.apache.hadoop.yarn.factories.impl.pb.RpcServerFactoryPBImpl: Adding protocol org.apache.hadoop.yarn.server.api.ResourceManagerAdministrationProtocolPB to the server
2020-03-21 20:06:29,736 INFO org.apache.hadoop.ipc.Server: IPC Server Responder: starting
2020-03-21 20:06:29,736 INFO org.apache.hadoop.ipc.Server: IPC Server listener on 8033: starting
2020-03-21 20:06:30,711 INFO org.apache.hadoop.yarn.util.RackResolver: Resolved dell to /default-rack
2020-03-21 20:06:30,712 INFO org.apache.hadoop.yarn.server.resourcemanager.ResourceTrackerService: NodeManager from node dell(cmPort: 34301 httpPort: 8042) registered with capability: <memory:8192, vCores:8>, assigned nodeId dell:34301
2020-03-21 20:06:30,714 INFO org.apache.hadoop.yarn.server.resourcemanager.rmnode.RMNodeImpl: dell:34301 Node Transitioned from NEW to RUNNING
2020-03-21 20:06:30,716 INFO org.apache.hadoop.yarn.server.resourcemanager.scheduler.capacity.CapacityScheduler: Added node dell:34301 clusterResource: <memory:8192, vCores:8>
2020-03-21 20:08:31,338 ERROR org.apache.hadoop.yarn.server.resourcemanager.ResourceManager: RECEIVED SIGNAL 15: SIGTERM
2020-03-21 20:08:31,339 ERROR org.apache.hadoop.security.token.delegation.AbstractDelegationTokenSecretManager: ExpiredTokenRemover received java.lang.InterruptedException: sleep interrupted
2020-03-21 20:08:31,340 INFO org.mortbay.log: Stopped HttpServer2$SelectChannelConnectorWithSafeStartup@0.0.0.0:8088
2020-03-21 20:08:31,441 INFO org.apache.hadoop.ipc.Server: Stopping server on 8032
2020-03-21 20:08:31,445 INFO org.apache.hadoop.ipc.Server: Stopping IPC Server listener on 8032
2020-03-21 20:08:31,445 INFO org.apache.hadoop.ipc.Server: Stopping server on 8033
2020-03-21 20:08:31,445 INFO org.apache.hadoop.ipc.Server: Stopping IPC Server Responder
2020-03-21 20:08:31,445 INFO org.apache.hadoop.ipc.Server: Stopping IPC Server Responder
2020-03-21 20:08:31,446 INFO org.apache.hadoop.ipc.Server: Stopping IPC Server listener on 8033
2020-03-21 20:08:31,446 INFO org.apache.hadoop.yarn.server.resourcemanager.ResourceManager: Transitioning to standby state
2020-03-21 20:08:31,446 WARN org.apache.hadoop.yarn.server.resourcemanager.amlauncher.ApplicationMasterLauncher: org.apache.hadoop.yarn.server.resourcemanager.amlauncher.ApplicationMasterLauncher$LauncherThread interrupted. Returning.
2020-03-21 20:08:31,447 INFO org.apache.hadoop.ipc.Server: Stopping server on 8030
2020-03-21 20:08:31,451 INFO org.apache.hadoop.ipc.Server: Stopping IPC Server listener on 8030
2020-03-21 20:08:31,451 INFO org.apache.hadoop.ipc.Server: Stopping server on 8031
2020-03-21 20:08:31,453 INFO org.apache.hadoop.ipc.Server: Stopping IPC Server listener on 8031
2020-03-21 20:08:31,454 INFO org.apache.hadoop.ipc.Server: Stopping IPC Server Responder
2020-03-21 20:08:31,455 INFO org.apache.hadoop.yarn.util.AbstractLivelinessMonitor: NMLivelinessMonitor thread interrupted
2020-03-21 20:08:31,456 INFO org.apache.hadoop.ipc.Server: Stopping IPC Server Responder
2020-03-21 20:08:31,455 ERROR org.apache.hadoop.yarn.server.resourcemanager.ResourceManager: Returning, interrupted : java.lang.InterruptedException
2020-03-21 20:08:31,458 INFO org.apache.hadoop.yarn.event.AsyncDispatcher: AsyncDispatcher is draining to stop, igonring any new events.
2020-03-21 20:08:31,459 INFO org.apache.hadoop.yarn.util.AbstractLivelinessMonitor: AMLivelinessMonitor thread interrupted
2020-03-21 20:08:31,459 INFO org.apache.hadoop.yarn.util.AbstractLivelinessMonitor: org.apache.hadoop.yarn.server.resourcemanager.rmcontainer.ContainerAllocationExpirer thread interrupted
2020-03-21 20:08:31,459 ERROR org.apache.hadoop.security.token.delegation.AbstractDelegationTokenSecretManager: ExpiredTokenRemover received java.lang.InterruptedException: sleep interrupted
2020-03-21 20:08:31,459 INFO org.apache.hadoop.yarn.util.AbstractLivelinessMonitor: AMLivelinessMonitor thread interrupted
2020-03-21 20:08:31,460 INFO org.apache.hadoop.metrics2.impl.MetricsSystemImpl: Stopping ResourceManager metrics system...
2020-03-21 20:08:31,462 INFO org.apache.hadoop.metrics2.impl.MetricsSystemImpl: ResourceManager metrics system stopped.
2020-03-21 20:08:31,463 INFO org.apache.hadoop.metrics2.impl.MetricsSystemImpl: ResourceManager metrics system shutdown complete.
2020-03-21 20:08:31,463 INFO org.apache.hadoop.yarn.event.AsyncDispatcher: AsyncDispatcher is draining to stop, igonring any new events.
2020-03-21 20:08:31,463 INFO org.apache.hadoop.yarn.server.resourcemanager.ResourceManager: Transitioned to standby state
2020-03-21 20:08:31,463 INFO org.apache.hadoop.yarn.server.resourcemanager.ResourceManager: SHUTDOWN_MSG: 
/************************************************************
SHUTDOWN_MSG: Shutting down ResourceManager at dell/127.0.1.1
************************************************************/
2020-03-21 20:09:27,086 INFO org.apache.hadoop.yarn.server.resourcemanager.ResourceManager: STARTUP_MSG: 
/************************************************************
STARTUP_MSG: Starting ResourceManager
STARTUP_MSG:   host = dell/127.0.1.1
STARTUP_MSG:   args = []
STARTUP_MSG:   version = 2.7.7
STARTUP_MSG:   build = Unknown -r c1aad84bd27cd79c3d1a7dd58202a8c3ee1ed3ac; compiled by 'stevel' on 2018-07-18T22:47Z
STARTUP_MSG:   java = 1.8.0_131
************************************************************/
2020-03-21 20:09:27,091 INFO org.apache.hadoop.yarn.server.resourcemanager.ResourceManager: registered UNIX signal handlers for [TERM, HUP, INT]
2020-03-21 20:09:27,249 INFO org.apache.hadoop.conf.Configuration: found resource core-site.xml at file:/home/xidian/hadoop-2.7.7/etc/hadoop/core-site.xml
2020-03-21 20:09:27,306 INFO org.apache.hadoop.security.Groups: clearing userToGroupsMap cache
2020-03-21 20:09:27,336 INFO org.apache.hadoop.conf.Configuration: found resource yarn-site.xml at file:/home/xidian/hadoop-2.7.7/etc/hadoop/yarn-site.xml
2020-03-21 20:09:27,567 INFO org.apache.hadoop.yarn.event.AsyncDispatcher: Registering class org.apache.hadoop.yarn.server.resourcemanager.RMFatalEventType for class org.apache.hadoop.yarn.server.resourcemanager.ResourceManager$RMFatalEventDispatcher
2020-03-21 20:09:27,736 INFO org.apache.hadoop.yarn.server.resourcemanager.security.NMTokenSecretManagerInRM: NMTokenKeyRollingInterval: 86400000ms and NMTokenKeyActivationDelay: 900000ms
2020-03-21 20:09:27,738 INFO org.apache.hadoop.yarn.server.resourcemanager.security.RMContainerTokenSecretManager: ContainerTokenKeyRollingInterval: 86400000ms and ContainerTokenKeyActivationDelay: 900000ms
2020-03-21 20:09:27,741 INFO org.apache.hadoop.yarn.server.resourcemanager.security.AMRMTokenSecretManager: AMRMTokenKeyRollingInterval: 86400000ms and AMRMTokenKeyActivationDelay: 900000 ms
2020-03-21 20:09:27,759 INFO org.apache.hadoop.yarn.event.AsyncDispatcher: Registering class org.apache.hadoop.yarn.server.resourcemanager.recovery.RMStateStoreEventType for class org.apache.hadoop.yarn.server.resourcemanager.recovery.RMStateStore$ForwardingEventHandler
2020-03-21 20:09:27,760 INFO org.apache.hadoop.yarn.event.AsyncDispatcher: Registering class org.apache.hadoop.yarn.server.resourcemanager.NodesListManagerEventType for class org.apache.hadoop.yarn.server.resourcemanager.NodesListManager
2020-03-21 20:09:27,760 INFO org.apache.hadoop.yarn.server.resourcemanager.ResourceManager: Using Scheduler: org.apache.hadoop.yarn.server.resourcemanager.scheduler.capacity.CapacityScheduler
2020-03-21 20:09:27,768 INFO org.apache.hadoop.yarn.event.AsyncDispatcher: Registering class org.apache.hadoop.yarn.server.resourcemanager.scheduler.event.SchedulerEventType for class org.apache.hadoop.yarn.server.resourcemanager.ResourceManager$SchedulerEventDispatcher
2020-03-21 20:09:27,769 INFO org.apache.hadoop.yarn.event.AsyncDispatcher: Registering class org.apache.hadoop.yarn.server.resourcemanager.rmapp.RMAppEventType for class org.apache.hadoop.yarn.server.resourcemanager.ResourceManager$ApplicationEventDispatcher
2020-03-21 20:09:27,769 INFO org.apache.hadoop.yarn.event.AsyncDispatcher: Registering class org.apache.hadoop.yarn.server.resourcemanager.rmapp.attempt.RMAppAttemptEventType for class org.apache.hadoop.yarn.server.resourcemanager.ResourceManager$ApplicationAttemptEventDispatcher
2020-03-21 20:09:27,769 INFO org.apache.hadoop.yarn.event.AsyncDispatcher: Registering class org.apache.hadoop.yarn.server.resourcemanager.rmnode.RMNodeEventType for class org.apache.hadoop.yarn.server.resourcemanager.ResourceManager$NodeEventDispatcher
2020-03-21 20:09:27,800 INFO org.apache.hadoop.metrics2.impl.MetricsConfig: loaded properties from hadoop-metrics2.properties
2020-03-21 20:09:27,837 INFO org.apache.hadoop.metrics2.impl.MetricsSystemImpl: Scheduled snapshot period at 10 second(s).
2020-03-21 20:09:27,837 INFO org.apache.hadoop.metrics2.impl.MetricsSystemImpl: ResourceManager metrics system started
2020-03-21 20:09:27,845 INFO org.apache.hadoop.yarn.event.AsyncDispatcher: Registering class org.apache.hadoop.yarn.server.resourcemanager.RMAppManagerEventType for class org.apache.hadoop.yarn.server.resourcemanager.RMAppManager
2020-03-21 20:09:27,850 INFO org.apache.hadoop.yarn.event.AsyncDispatcher: Registering class org.apache.hadoop.yarn.server.resourcemanager.amlauncher.AMLauncherEventType for class org.apache.hadoop.yarn.server.resourcemanager.amlauncher.ApplicationMasterLauncher
2020-03-21 20:09:27,851 INFO org.apache.hadoop.yarn.server.resourcemanager.RMNMInfo: Registered RMNMInfo MBean
2020-03-21 20:09:27,852 INFO org.apache.hadoop.yarn.security.YarnAuthorizationProvider: org.apache.hadoop.yarn.security.ConfiguredYarnAuthorizer is instiantiated.
2020-03-21 20:09:27,853 INFO org.apache.hadoop.util.HostsFileReader: Refreshing hosts (include/exclude) list
2020-03-21 20:09:27,854 INFO org.apache.hadoop.conf.Configuration: found resource capacity-scheduler.xml at file:/home/xidian/hadoop-2.7.7/etc/hadoop/capacity-scheduler.xml
2020-03-21 20:09:27,881 INFO org.apache.hadoop.yarn.server.resourcemanager.scheduler.capacity.CapacitySchedulerConfiguration: max alloc mb per queue for root is undefined
2020-03-21 20:09:27,881 INFO org.apache.hadoop.yarn.server.resourcemanager.scheduler.capacity.CapacitySchedulerConfiguration: max alloc vcore per queue for root is undefined
2020-03-21 20:09:27,883 INFO org.apache.hadoop.yarn.server.resourcemanager.scheduler.capacity.ParentQueue: root, capacity=1.0, asboluteCapacity=1.0, maxCapacity=1.0, asboluteMaxCapacity=1.0, state=RUNNING, acls=ADMINISTER_QUEUE:*SUBMIT_APP:*, labels=*,
, reservationsContinueLooking=true
2020-03-21 20:09:27,883 INFO org.apache.hadoop.yarn.server.resourcemanager.scheduler.capacity.ParentQueue: Initialized parent-queue root name=root, fullname=root
2020-03-21 20:09:27,889 INFO org.apache.hadoop.yarn.server.resourcemanager.scheduler.capacity.CapacitySchedulerConfiguration: max alloc mb per queue for root.default is undefined
2020-03-21 20:09:27,889 INFO org.apache.hadoop.yarn.server.resourcemanager.scheduler.capacity.CapacitySchedulerConfiguration: max alloc vcore per queue for root.default is undefined
2020-03-21 20:09:27,890 INFO org.apache.hadoop.yarn.server.resourcemanager.scheduler.capacity.LeafQueue: Initializing default
capacity = 1.0 [= (float) configuredCapacity / 100 ]
asboluteCapacity = 1.0 [= parentAbsoluteCapacity * capacity ]
maxCapacity = 1.0 [= configuredMaxCapacity ]
absoluteMaxCapacity = 1.0 [= 1.0 maximumCapacity undefined, (parentAbsoluteMaxCapacity * maximumCapacity) / 100 otherwise ]
userLimit = 100 [= configuredUserLimit ]
userLimitFactor = 1.0 [= configuredUserLimitFactor ]
maxApplications = 10000 [= configuredMaximumSystemApplicationsPerQueue or (int)(configuredMaximumSystemApplications * absoluteCapacity)]
maxApplicationsPerUser = 10000 [= (int)(maxApplications * (userLimit / 100.0f) * userLimitFactor) ]
usedCapacity = 0.0 [= usedResourcesMemory / (clusterResourceMemory * absoluteCapacity)]
absoluteUsedCapacity = 0.0 [= usedResourcesMemory / clusterResourceMemory]
maxAMResourcePerQueuePercent = 0.1 [= configuredMaximumAMResourcePercent ]
minimumAllocationFactor = 0.875 [= (float)(maximumAllocationMemory - minimumAllocationMemory) / maximumAllocationMemory ]
maximumAllocation = <memory:8192, vCores:32> [= configuredMaxAllocation ]
numContainers = 0 [= currentNumContainers ]
state = RUNNING [= configuredState ]
acls = ADMINISTER_QUEUE:*SUBMIT_APP:* [= configuredAcls ]
nodeLocalityDelay = 40
labels=*,
nodeLocalityDelay = 40
reservationsContinueLooking = true
preemptionDisabled = true

2020-03-21 20:09:27,890 INFO org.apache.hadoop.yarn.server.resourcemanager.scheduler.capacity.CapacityScheduler: Initialized queue: default: capacity=1.0, absoluteCapacity=1.0, usedResources=<memory:0, vCores:0>, usedCapacity=0.0, absoluteUsedCapacity=0.0, numApps=0, numContainers=0
2020-03-21 20:09:27,890 INFO org.apache.hadoop.yarn.server.resourcemanager.scheduler.capacity.CapacityScheduler: Initialized queue: root: numChildQueue= 1, capacity=1.0, absoluteCapacity=1.0, usedResources=<memory:0, vCores:0>usedCapacity=0.0, numApps=0, numContainers=0
2020-03-21 20:09:27,890 INFO org.apache.hadoop.yarn.server.resourcemanager.scheduler.capacity.CapacityScheduler: Initialized root queue root: numChildQueue= 1, capacity=1.0, absoluteCapacity=1.0, usedResources=<memory:0, vCores:0>usedCapacity=0.0, numApps=0, numContainers=0
2020-03-21 20:09:27,890 INFO org.apache.hadoop.yarn.server.resourcemanager.scheduler.capacity.CapacityScheduler: Initialized queue mappings, override: false
2020-03-21 20:09:27,890 INFO org.apache.hadoop.yarn.server.resourcemanager.scheduler.capacity.CapacityScheduler: Initialized CapacityScheduler with calculator=class org.apache.hadoop.yarn.util.resource.DefaultResourceCalculator, minimumAllocation=<<memory:1024, vCores:1>>, maximumAllocation=<<memory:8192, vCores:32>>, asynchronousScheduling=false, asyncScheduleInterval=5ms
2020-03-21 20:09:27,896 INFO org.apache.hadoop.yarn.server.resourcemanager.metrics.SystemMetricsPublisher: YARN system metrics publishing service is not enabled
2020-03-21 20:09:27,896 INFO org.apache.hadoop.yarn.server.resourcemanager.ResourceManager: Transitioning to active state
2020-03-21 20:09:27,903 INFO org.apache.hadoop.yarn.server.resourcemanager.recovery.RMStateStore: Updating AMRMToken
2020-03-21 20:09:27,903 INFO org.apache.hadoop.yarn.server.resourcemanager.security.RMContainerTokenSecretManager: Rolling master-key for container-tokens
2020-03-21 20:09:27,903 INFO org.apache.hadoop.yarn.server.resourcemanager.security.NMTokenSecretManagerInRM: Rolling master-key for nm-tokens
2020-03-21 20:09:27,903 INFO org.apache.hadoop.security.token.delegation.AbstractDelegationTokenSecretManager: Updating the current master key for generating delegation tokens
2020-03-21 20:09:27,904 INFO org.apache.hadoop.yarn.server.resourcemanager.security.RMDelegationTokenSecretManager: storing master key with keyID 1
2020-03-21 20:09:27,904 INFO org.apache.hadoop.yarn.server.resourcemanager.recovery.RMStateStore: Storing RMDTMasterKey.
2020-03-21 20:09:27,904 INFO org.apache.hadoop.security.token.delegation.AbstractDelegationTokenSecretManager: Starting expired delegation token remover thread, tokenRemoverScanInterval=60 min(s)
2020-03-21 20:09:27,904 INFO org.apache.hadoop.security.token.delegation.AbstractDelegationTokenSecretManager: Updating the current master key for generating delegation tokens
2020-03-21 20:09:27,904 INFO org.apache.hadoop.yarn.server.resourcemanager.security.RMDelegationTokenSecretManager: storing master key with keyID 2
2020-03-21 20:09:27,904 INFO org.apache.hadoop.yarn.server.resourcemanager.recovery.RMStateStore: Storing RMDTMasterKey.
2020-03-21 20:09:27,905 INFO org.apache.hadoop.yarn.event.AsyncDispatcher: Registering class org.apache.hadoop.yarn.nodelabels.event.NodeLabelsStoreEventType for class org.apache.hadoop.yarn.nodelabels.CommonNodeLabelsManager$ForwardingEventHandler
2020-03-21 20:09:27,981 INFO org.apache.hadoop.ipc.CallQueueManager: Using callQueue: class java.util.concurrent.LinkedBlockingQueue queueCapacity: 5000
2020-03-21 20:09:27,988 INFO org.apache.hadoop.ipc.Server: Starting Socket Reader #1 for port 8031
2020-03-21 20:09:28,089 INFO org.apache.hadoop.yarn.factories.impl.pb.RpcServerFactoryPBImpl: Adding protocol org.apache.hadoop.yarn.server.api.ResourceTrackerPB to the server
2020-03-21 20:09:28,089 INFO org.apache.hadoop.ipc.Server: IPC Server Responder: starting
2020-03-21 20:09:28,091 INFO org.apache.hadoop.ipc.Server: IPC Server listener on 8031: starting
2020-03-21 20:09:28,161 INFO org.apache.hadoop.ipc.CallQueueManager: Using callQueue: class java.util.concurrent.LinkedBlockingQueue queueCapacity: 5000
2020-03-21 20:09:28,164 INFO org.apache.hadoop.ipc.Server: Starting Socket Reader #1 for port 8030
2020-03-21 20:09:28,173 INFO org.apache.hadoop.yarn.factories.impl.pb.RpcServerFactoryPBImpl: Adding protocol org.apache.hadoop.yarn.api.ApplicationMasterProtocolPB to the server
2020-03-21 20:09:28,173 INFO org.apache.hadoop.ipc.Server: IPC Server listener on 8030: starting
2020-03-21 20:09:28,173 INFO org.apache.hadoop.ipc.Server: IPC Server Responder: starting
2020-03-21 20:09:28,274 INFO org.apache.hadoop.ipc.CallQueueManager: Using callQueue: class java.util.concurrent.LinkedBlockingQueue queueCapacity: 5000
2020-03-21 20:09:28,275 INFO org.apache.hadoop.ipc.Server: Starting Socket Reader #1 for port 8032
2020-03-21 20:09:28,279 INFO org.apache.hadoop.yarn.factories.impl.pb.RpcServerFactoryPBImpl: Adding protocol org.apache.hadoop.yarn.api.ApplicationClientProtocolPB to the server
2020-03-21 20:09:28,280 INFO org.apache.hadoop.ipc.Server: IPC Server Responder: starting
2020-03-21 20:09:28,280 INFO org.apache.hadoop.ipc.Server: IPC Server listener on 8032: starting
2020-03-21 20:09:28,320 INFO org.apache.hadoop.yarn.server.resourcemanager.ResourceManager: Transitioned to active state
2020-03-21 20:09:28,389 INFO org.mortbay.log: Logging to org.slf4j.impl.Log4jLoggerAdapter(org.mortbay.log) via org.mortbay.log.Slf4jLog
2020-03-21 20:09:28,393 INFO org.apache.hadoop.security.authentication.server.AuthenticationFilter: Unable to initialize FileSignerSecretProvider, falling back to use random secrets.
2020-03-21 20:09:28,397 INFO org.apache.hadoop.http.HttpRequestLog: Http request log for http.requests.resourcemanager is not defined
2020-03-21 20:09:28,402 INFO org.apache.hadoop.http.HttpServer2: Added global filter 'safety' (class=org.apache.hadoop.http.HttpServer2$QuotingInputFilter)
2020-03-21 20:09:28,405 INFO org.apache.hadoop.http.HttpServer2: Added filter RMAuthenticationFilter (class=org.apache.hadoop.yarn.server.security.http.RMAuthenticationFilter) to context cluster
2020-03-21 20:09:28,405 INFO org.apache.hadoop.http.HttpServer2: Added filter RMAuthenticationFilter (class=org.apache.hadoop.yarn.server.security.http.RMAuthenticationFilter) to context logs
2020-03-21 20:09:28,405 INFO org.apache.hadoop.http.HttpServer2: Added filter RMAuthenticationFilter (class=org.apache.hadoop.yarn.server.security.http.RMAuthenticationFilter) to context static
2020-03-21 20:09:28,405 INFO org.apache.hadoop.http.HttpServer2: Added filter static_user_filter (class=org.apache.hadoop.http.lib.StaticUserWebFilter$StaticUserFilter) to context cluster
2020-03-21 20:09:28,405 INFO org.apache.hadoop.http.HttpServer2: Added filter static_user_filter (class=org.apache.hadoop.http.lib.StaticUserWebFilter$StaticUserFilter) to context logs
2020-03-21 20:09:28,405 INFO org.apache.hadoop.http.HttpServer2: Added filter static_user_filter (class=org.apache.hadoop.http.lib.StaticUserWebFilter$StaticUserFilter) to context static
2020-03-21 20:09:28,408 INFO org.apache.hadoop.http.HttpServer2: adding path spec: /cluster/*
2020-03-21 20:09:28,408 INFO org.apache.hadoop.http.HttpServer2: adding path spec: /ws/*
2020-03-21 20:09:28,613 INFO org.apache.hadoop.yarn.webapp.WebApps: Registered webapp guice modules
2020-03-21 20:09:28,614 INFO org.apache.hadoop.http.HttpServer2: Jetty bound to port 8088
2020-03-21 20:09:28,614 INFO org.mortbay.log: jetty-6.1.26
2020-03-21 20:09:28,638 INFO org.mortbay.log: Extract jar:file:/home/xidian/hadoop-2.7.7/share/hadoop/yarn/hadoop-yarn-common-2.7.7.jar!/webapps/cluster to /tmp/Jetty_0_0_0_0_8088_cluster____u0rgz3/webapp
2020-03-21 20:09:28,775 INFO org.apache.hadoop.security.token.delegation.AbstractDelegationTokenSecretManager: Updating the current master key for generating delegation tokens
2020-03-21 20:09:28,775 INFO org.apache.hadoop.security.token.delegation.AbstractDelegationTokenSecretManager: Starting expired delegation token remover thread, tokenRemoverScanInterval=60 min(s)
2020-03-21 20:09:28,775 INFO org.apache.hadoop.security.token.delegation.AbstractDelegationTokenSecretManager: Updating the current master key for generating delegation tokens
2020-03-21 20:09:29,398 INFO org.mortbay.log: Started HttpServer2$SelectChannelConnectorWithSafeStartup@0.0.0.0:8088
2020-03-21 20:09:29,398 INFO org.apache.hadoop.yarn.webapp.WebApps: Web app cluster started at 8088
2020-03-21 20:09:29,474 INFO org.apache.hadoop.ipc.CallQueueManager: Using callQueue: class java.util.concurrent.LinkedBlockingQueue queueCapacity: 100
2020-03-21 20:09:29,475 INFO org.apache.hadoop.ipc.Server: Starting Socket Reader #1 for port 8033
2020-03-21 20:09:29,478 INFO org.apache.hadoop.yarn.factories.impl.pb.RpcServerFactoryPBImpl: Adding protocol org.apache.hadoop.yarn.server.api.ResourceManagerAdministrationProtocolPB to the server
2020-03-21 20:09:29,480 INFO org.apache.hadoop.ipc.Server: IPC Server Responder: starting
2020-03-21 20:09:29,481 INFO org.apache.hadoop.ipc.Server: IPC Server listener on 8033: starting
2020-03-21 20:09:30,280 INFO org.apache.hadoop.yarn.util.RackResolver: Resolved dell to /default-rack
2020-03-21 20:09:30,281 INFO org.apache.hadoop.yarn.server.resourcemanager.ResourceTrackerService: NodeManager from node dell(cmPort: 45321 httpPort: 8042) registered with capability: <memory:8192, vCores:8>, assigned nodeId dell:45321
2020-03-21 20:09:30,284 INFO org.apache.hadoop.yarn.server.resourcemanager.rmnode.RMNodeImpl: dell:45321 Node Transitioned from NEW to RUNNING
2020-03-21 20:09:30,287 INFO org.apache.hadoop.yarn.server.resourcemanager.scheduler.capacity.CapacityScheduler: Added node dell:45321 clusterResource: <memory:8192, vCores:8>
2020-03-21 20:19:27,854 INFO org.apache.hadoop.yarn.server.resourcemanager.scheduler.AbstractYarnScheduler: Release request cache is cleaned up
2020-03-21 20:25:47,731 ERROR org.apache.hadoop.yarn.server.resourcemanager.ResourceManager: RECEIVED SIGNAL 15: SIGTERM
2020-03-21 20:25:47,733 ERROR org.apache.hadoop.security.token.delegation.AbstractDelegationTokenSecretManager: ExpiredTokenRemover received java.lang.InterruptedException: sleep interrupted
2020-03-21 20:25:47,733 INFO org.mortbay.log: Stopped HttpServer2$SelectChannelConnectorWithSafeStartup@0.0.0.0:8088
2020-03-21 20:25:47,834 INFO org.apache.hadoop.ipc.Server: Stopping server on 8032
2020-03-21 20:25:47,838 INFO org.apache.hadoop.ipc.Server: Stopping IPC Server listener on 8032
2020-03-21 20:25:47,838 INFO org.apache.hadoop.ipc.Server: Stopping server on 8033
2020-03-21 20:25:47,839 INFO org.apache.hadoop.ipc.Server: Stopping IPC Server Responder
2020-03-21 20:25:47,840 INFO org.apache.hadoop.ipc.Server: Stopping IPC Server listener on 8033
2020-03-21 20:25:47,840 INFO org.apache.hadoop.ipc.Server: Stopping IPC Server Responder
2020-03-21 20:25:47,840 INFO org.apache.hadoop.yarn.server.resourcemanager.ResourceManager: Transitioning to standby state
2020-03-21 20:25:47,867 WARN org.apache.hadoop.yarn.server.resourcemanager.amlauncher.ApplicationMasterLauncher: org.apache.hadoop.yarn.server.resourcemanager.amlauncher.ApplicationMasterLauncher$LauncherThread interrupted. Returning.
2020-03-21 20:25:47,867 INFO org.apache.hadoop.ipc.Server: Stopping server on 8030
2020-03-21 20:25:47,870 INFO org.apache.hadoop.ipc.Server: Stopping IPC Server listener on 8030
2020-03-21 20:25:47,870 INFO org.apache.hadoop.ipc.Server: Stopping server on 8031
2020-03-21 20:25:47,873 INFO org.apache.hadoop.ipc.Server: Stopping IPC Server listener on 8031
2020-03-21 20:25:47,873 INFO org.apache.hadoop.ipc.Server: Stopping IPC Server Responder
2020-03-21 20:25:47,873 INFO org.apache.hadoop.yarn.util.AbstractLivelinessMonitor: NMLivelinessMonitor thread interrupted
2020-03-21 20:25:47,873 INFO org.apache.hadoop.ipc.Server: Stopping IPC Server Responder
2020-03-21 20:25:47,874 ERROR org.apache.hadoop.yarn.server.resourcemanager.ResourceManager: Returning, interrupted : java.lang.InterruptedException
2020-03-21 20:25:47,875 INFO org.apache.hadoop.yarn.event.AsyncDispatcher: AsyncDispatcher is draining to stop, igonring any new events.
2020-03-21 20:25:47,876 INFO org.apache.hadoop.yarn.util.AbstractLivelinessMonitor: AMLivelinessMonitor thread interrupted
2020-03-21 20:25:47,877 INFO org.apache.hadoop.yarn.util.AbstractLivelinessMonitor: AMLivelinessMonitor thread interrupted
2020-03-21 20:25:47,876 INFO org.apache.hadoop.yarn.util.AbstractLivelinessMonitor: org.apache.hadoop.yarn.server.resourcemanager.rmcontainer.ContainerAllocationExpirer thread interrupted
2020-03-21 20:25:47,876 ERROR org.apache.hadoop.security.token.delegation.AbstractDelegationTokenSecretManager: ExpiredTokenRemover received java.lang.InterruptedException: sleep interrupted
2020-03-21 20:25:47,879 INFO org.apache.hadoop.metrics2.impl.MetricsSystemImpl: Stopping ResourceManager metrics system...
2020-03-21 20:25:47,881 INFO org.apache.hadoop.metrics2.impl.MetricsSystemImpl: ResourceManager metrics system stopped.
2020-03-21 20:25:47,882 INFO org.apache.hadoop.metrics2.impl.MetricsSystemImpl: ResourceManager metrics system shutdown complete.
2020-03-21 20:25:47,882 INFO org.apache.hadoop.yarn.event.AsyncDispatcher: AsyncDispatcher is draining to stop, igonring any new events.
2020-03-21 20:25:47,883 INFO org.apache.hadoop.yarn.server.resourcemanager.ResourceManager: Transitioned to standby state
2020-03-21 20:25:47,883 INFO org.apache.hadoop.yarn.server.resourcemanager.ResourceManager: SHUTDOWN_MSG: 
/************************************************************
SHUTDOWN_MSG: Shutting down ResourceManager at dell/127.0.1.1
************************************************************/
2020-03-21 20:26:21,451 INFO org.apache.hadoop.yarn.server.resourcemanager.ResourceManager: STARTUP_MSG: 
/************************************************************
STARTUP_MSG: Starting ResourceManager
STARTUP_MSG:   host = dell/127.0.1.1
STARTUP_MSG:   args = []
STARTUP_MSG:   version = 2.7.7
STARTUP_MSG:   build = Unknown -r c1aad84bd27cd79c3d1a7dd58202a8c3ee1ed3ac; compiled by 'stevel' on 2018-07-18T22:47Z
STARTUP_MSG:   java = 1.8.0_131
************************************************************/
2020-03-21 20:26:21,456 INFO org.apache.hadoop.yarn.server.resourcemanager.ResourceManager: registered UNIX signal handlers for [TERM, HUP, INT]
2020-03-21 20:26:21,606 INFO org.apache.hadoop.conf.Configuration: found resource core-site.xml at file:/home/xidian/hadoop-2.7.7/etc/hadoop/core-site.xml
2020-03-21 20:26:21,663 INFO org.apache.hadoop.security.Groups: clearing userToGroupsMap cache
2020-03-21 20:26:21,704 INFO org.apache.hadoop.conf.Configuration: found resource yarn-site.xml at file:/home/xidian/hadoop-2.7.7/etc/hadoop/yarn-site.xml
2020-03-21 20:26:21,823 INFO org.apache.hadoop.yarn.event.AsyncDispatcher: Registering class org.apache.hadoop.yarn.server.resourcemanager.RMFatalEventType for class org.apache.hadoop.yarn.server.resourcemanager.ResourceManager$RMFatalEventDispatcher
2020-03-21 20:26:21,933 INFO org.apache.hadoop.yarn.server.resourcemanager.security.NMTokenSecretManagerInRM: NMTokenKeyRollingInterval: 86400000ms and NMTokenKeyActivationDelay: 900000ms
2020-03-21 20:26:21,936 INFO org.apache.hadoop.yarn.server.resourcemanager.security.RMContainerTokenSecretManager: ContainerTokenKeyRollingInterval: 86400000ms and ContainerTokenKeyActivationDelay: 900000ms
2020-03-21 20:26:21,940 INFO org.apache.hadoop.yarn.server.resourcemanager.security.AMRMTokenSecretManager: AMRMTokenKeyRollingInterval: 86400000ms and AMRMTokenKeyActivationDelay: 900000 ms
2020-03-21 20:26:21,960 INFO org.apache.hadoop.yarn.event.AsyncDispatcher: Registering class org.apache.hadoop.yarn.server.resourcemanager.recovery.RMStateStoreEventType for class org.apache.hadoop.yarn.server.resourcemanager.recovery.RMStateStore$ForwardingEventHandler
2020-03-21 20:26:21,961 INFO org.apache.hadoop.yarn.event.AsyncDispatcher: Registering class org.apache.hadoop.yarn.server.resourcemanager.NodesListManagerEventType for class org.apache.hadoop.yarn.server.resourcemanager.NodesListManager
2020-03-21 20:26:21,961 INFO org.apache.hadoop.yarn.server.resourcemanager.ResourceManager: Using Scheduler: org.apache.hadoop.yarn.server.resourcemanager.scheduler.capacity.CapacityScheduler
2020-03-21 20:26:21,971 INFO org.apache.hadoop.yarn.event.AsyncDispatcher: Registering class org.apache.hadoop.yarn.server.resourcemanager.scheduler.event.SchedulerEventType for class org.apache.hadoop.yarn.server.resourcemanager.ResourceManager$SchedulerEventDispatcher
2020-03-21 20:26:21,971 INFO org.apache.hadoop.yarn.event.AsyncDispatcher: Registering class org.apache.hadoop.yarn.server.resourcemanager.rmapp.RMAppEventType for class org.apache.hadoop.yarn.server.resourcemanager.ResourceManager$ApplicationEventDispatcher
2020-03-21 20:26:21,971 INFO org.apache.hadoop.yarn.event.AsyncDispatcher: Registering class org.apache.hadoop.yarn.server.resourcemanager.rmapp.attempt.RMAppAttemptEventType for class org.apache.hadoop.yarn.server.resourcemanager.ResourceManager$ApplicationAttemptEventDispatcher
2020-03-21 20:26:21,972 INFO org.apache.hadoop.yarn.event.AsyncDispatcher: Registering class org.apache.hadoop.yarn.server.resourcemanager.rmnode.RMNodeEventType for class org.apache.hadoop.yarn.server.resourcemanager.ResourceManager$NodeEventDispatcher
2020-03-21 20:26:22,008 INFO org.apache.hadoop.metrics2.impl.MetricsConfig: loaded properties from hadoop-metrics2.properties
2020-03-21 20:26:22,049 INFO org.apache.hadoop.metrics2.impl.MetricsSystemImpl: Scheduled snapshot period at 10 second(s).
2020-03-21 20:26:22,049 INFO org.apache.hadoop.metrics2.impl.MetricsSystemImpl: ResourceManager metrics system started
2020-03-21 20:26:22,056 INFO org.apache.hadoop.yarn.event.AsyncDispatcher: Registering class org.apache.hadoop.yarn.server.resourcemanager.RMAppManagerEventType for class org.apache.hadoop.yarn.server.resourcemanager.RMAppManager
2020-03-21 20:26:22,059 INFO org.apache.hadoop.yarn.event.AsyncDispatcher: Registering class org.apache.hadoop.yarn.server.resourcemanager.amlauncher.AMLauncherEventType for class org.apache.hadoop.yarn.server.resourcemanager.amlauncher.ApplicationMasterLauncher
2020-03-21 20:26:22,060 INFO org.apache.hadoop.yarn.server.resourcemanager.RMNMInfo: Registered RMNMInfo MBean
2020-03-21 20:26:22,061 INFO org.apache.hadoop.yarn.security.YarnAuthorizationProvider: org.apache.hadoop.yarn.security.ConfiguredYarnAuthorizer is instiantiated.
2020-03-21 20:26:22,062 INFO org.apache.hadoop.util.HostsFileReader: Refreshing hosts (include/exclude) list
2020-03-21 20:26:22,063 INFO org.apache.hadoop.conf.Configuration: found resource capacity-scheduler.xml at file:/home/xidian/hadoop-2.7.7/etc/hadoop/capacity-scheduler.xml
2020-03-21 20:26:22,092 INFO org.apache.hadoop.yarn.server.resourcemanager.scheduler.capacity.CapacitySchedulerConfiguration: max alloc mb per queue for root is undefined
2020-03-21 20:26:22,092 INFO org.apache.hadoop.yarn.server.resourcemanager.scheduler.capacity.CapacitySchedulerConfiguration: max alloc vcore per queue for root is undefined
2020-03-21 20:26:22,094 INFO org.apache.hadoop.yarn.server.resourcemanager.scheduler.capacity.ParentQueue: root, capacity=1.0, asboluteCapacity=1.0, maxCapacity=1.0, asboluteMaxCapacity=1.0, state=RUNNING, acls=ADMINISTER_QUEUE:*SUBMIT_APP:*, labels=*,
, reservationsContinueLooking=true
2020-03-21 20:26:22,094 INFO org.apache.hadoop.yarn.server.resourcemanager.scheduler.capacity.ParentQueue: Initialized parent-queue root name=root, fullname=root
2020-03-21 20:26:22,098 INFO org.apache.hadoop.yarn.server.resourcemanager.scheduler.capacity.CapacitySchedulerConfiguration: max alloc mb per queue for root.default is undefined
2020-03-21 20:26:22,098 INFO org.apache.hadoop.yarn.server.resourcemanager.scheduler.capacity.CapacitySchedulerConfiguration: max alloc vcore per queue for root.default is undefined
2020-03-21 20:26:22,099 INFO org.apache.hadoop.yarn.server.resourcemanager.scheduler.capacity.LeafQueue: Initializing default
capacity = 1.0 [= (float) configuredCapacity / 100 ]
asboluteCapacity = 1.0 [= parentAbsoluteCapacity * capacity ]
maxCapacity = 1.0 [= configuredMaxCapacity ]
absoluteMaxCapacity = 1.0 [= 1.0 maximumCapacity undefined, (parentAbsoluteMaxCapacity * maximumCapacity) / 100 otherwise ]
userLimit = 100 [= configuredUserLimit ]
userLimitFactor = 1.0 [= configuredUserLimitFactor ]
maxApplications = 10000 [= configuredMaximumSystemApplicationsPerQueue or (int)(configuredMaximumSystemApplications * absoluteCapacity)]
maxApplicationsPerUser = 10000 [= (int)(maxApplications * (userLimit / 100.0f) * userLimitFactor) ]
usedCapacity = 0.0 [= usedResourcesMemory / (clusterResourceMemory * absoluteCapacity)]
absoluteUsedCapacity = 0.0 [= usedResourcesMemory / clusterResourceMemory]
maxAMResourcePerQueuePercent = 0.1 [= configuredMaximumAMResourcePercent ]
minimumAllocationFactor = 0.875 [= (float)(maximumAllocationMemory - minimumAllocationMemory) / maximumAllocationMemory ]
maximumAllocation = <memory:8192, vCores:32> [= configuredMaxAllocation ]
numContainers = 0 [= currentNumContainers ]
state = RUNNING [= configuredState ]
acls = ADMINISTER_QUEUE:*SUBMIT_APP:* [= configuredAcls ]
nodeLocalityDelay = 40
labels=*,
nodeLocalityDelay = 40
reservationsContinueLooking = true
preemptionDisabled = true

2020-03-21 20:26:22,099 INFO org.apache.hadoop.yarn.server.resourcemanager.scheduler.capacity.CapacityScheduler: Initialized queue: default: capacity=1.0, absoluteCapacity=1.0, usedResources=<memory:0, vCores:0>, usedCapacity=0.0, absoluteUsedCapacity=0.0, numApps=0, numContainers=0
2020-03-21 20:26:22,099 INFO org.apache.hadoop.yarn.server.resourcemanager.scheduler.capacity.CapacityScheduler: Initialized queue: root: numChildQueue= 1, capacity=1.0, absoluteCapacity=1.0, usedResources=<memory:0, vCores:0>usedCapacity=0.0, numApps=0, numContainers=0
2020-03-21 20:26:22,099 INFO org.apache.hadoop.yarn.server.resourcemanager.scheduler.capacity.CapacityScheduler: Initialized root queue root: numChildQueue= 1, capacity=1.0, absoluteCapacity=1.0, usedResources=<memory:0, vCores:0>usedCapacity=0.0, numApps=0, numContainers=0
2020-03-21 20:26:22,099 INFO org.apache.hadoop.yarn.server.resourcemanager.scheduler.capacity.CapacityScheduler: Initialized queue mappings, override: false
2020-03-21 20:26:22,099 INFO org.apache.hadoop.yarn.server.resourcemanager.scheduler.capacity.CapacityScheduler: Initialized CapacityScheduler with calculator=class org.apache.hadoop.yarn.util.resource.DefaultResourceCalculator, minimumAllocation=<<memory:1024, vCores:1>>, maximumAllocation=<<memory:8192, vCores:32>>, asynchronousScheduling=false, asyncScheduleInterval=5ms
2020-03-21 20:26:22,105 INFO org.apache.hadoop.yarn.server.resourcemanager.metrics.SystemMetricsPublisher: YARN system metrics publishing service is not enabled
2020-03-21 20:26:22,105 INFO org.apache.hadoop.yarn.server.resourcemanager.ResourceManager: Transitioning to active state
2020-03-21 20:26:22,111 INFO org.apache.hadoop.yarn.server.resourcemanager.recovery.RMStateStore: Updating AMRMToken
2020-03-21 20:26:22,111 INFO org.apache.hadoop.yarn.server.resourcemanager.security.RMContainerTokenSecretManager: Rolling master-key for container-tokens
2020-03-21 20:26:22,111 INFO org.apache.hadoop.yarn.server.resourcemanager.security.NMTokenSecretManagerInRM: Rolling master-key for nm-tokens
2020-03-21 20:26:22,111 INFO org.apache.hadoop.security.token.delegation.AbstractDelegationTokenSecretManager: Updating the current master key for generating delegation tokens
2020-03-21 20:26:22,111 INFO org.apache.hadoop.yarn.server.resourcemanager.security.RMDelegationTokenSecretManager: storing master key with keyID 1
2020-03-21 20:26:22,111 INFO org.apache.hadoop.yarn.server.resourcemanager.recovery.RMStateStore: Storing RMDTMasterKey.
2020-03-21 20:26:22,112 INFO org.apache.hadoop.security.token.delegation.AbstractDelegationTokenSecretManager: Starting expired delegation token remover thread, tokenRemoverScanInterval=60 min(s)
2020-03-21 20:26:22,112 INFO org.apache.hadoop.security.token.delegation.AbstractDelegationTokenSecretManager: Updating the current master key for generating delegation tokens
2020-03-21 20:26:22,112 INFO org.apache.hadoop.yarn.server.resourcemanager.security.RMDelegationTokenSecretManager: storing master key with keyID 2
2020-03-21 20:26:22,112 INFO org.apache.hadoop.yarn.server.resourcemanager.recovery.RMStateStore: Storing RMDTMasterKey.
2020-03-21 20:26:22,113 INFO org.apache.hadoop.yarn.event.AsyncDispatcher: Registering class org.apache.hadoop.yarn.nodelabels.event.NodeLabelsStoreEventType for class org.apache.hadoop.yarn.nodelabels.CommonNodeLabelsManager$ForwardingEventHandler
2020-03-21 20:26:22,185 INFO org.apache.hadoop.ipc.CallQueueManager: Using callQueue: class java.util.concurrent.LinkedBlockingQueue queueCapacity: 5000
2020-03-21 20:26:22,195 INFO org.apache.hadoop.ipc.Server: Starting Socket Reader #1 for port 8031
2020-03-21 20:26:22,296 INFO org.apache.hadoop.yarn.factories.impl.pb.RpcServerFactoryPBImpl: Adding protocol org.apache.hadoop.yarn.server.api.ResourceTrackerPB to the server
2020-03-21 20:26:22,296 INFO org.apache.hadoop.ipc.Server: IPC Server Responder: starting
2020-03-21 20:26:22,296 INFO org.apache.hadoop.ipc.Server: IPC Server listener on 8031: starting
2020-03-21 20:26:22,370 INFO org.apache.hadoop.ipc.CallQueueManager: Using callQueue: class java.util.concurrent.LinkedBlockingQueue queueCapacity: 5000
2020-03-21 20:26:22,373 INFO org.apache.hadoop.ipc.Server: Starting Socket Reader #1 for port 8030
2020-03-21 20:26:22,378 INFO org.apache.hadoop.yarn.factories.impl.pb.RpcServerFactoryPBImpl: Adding protocol org.apache.hadoop.yarn.api.ApplicationMasterProtocolPB to the server
2020-03-21 20:26:22,378 INFO org.apache.hadoop.ipc.Server: IPC Server Responder: starting
2020-03-21 20:26:22,379 INFO org.apache.hadoop.ipc.Server: IPC Server listener on 8030: starting
2020-03-21 20:26:22,466 INFO org.apache.hadoop.ipc.CallQueueManager: Using callQueue: class java.util.concurrent.LinkedBlockingQueue queueCapacity: 5000
2020-03-21 20:26:22,467 INFO org.apache.hadoop.ipc.Server: Starting Socket Reader #1 for port 8032
2020-03-21 20:26:22,470 INFO org.apache.hadoop.yarn.factories.impl.pb.RpcServerFactoryPBImpl: Adding protocol org.apache.hadoop.yarn.api.ApplicationClientProtocolPB to the server
2020-03-21 20:26:22,470 INFO org.apache.hadoop.ipc.Server: IPC Server Responder: starting
2020-03-21 20:26:22,471 INFO org.apache.hadoop.ipc.Server: IPC Server listener on 8032: starting
2020-03-21 20:26:22,488 INFO org.apache.hadoop.yarn.server.resourcemanager.ResourceManager: Transitioned to active state
2020-03-21 20:26:22,571 INFO org.mortbay.log: Logging to org.slf4j.impl.Log4jLoggerAdapter(org.mortbay.log) via org.mortbay.log.Slf4jLog
2020-03-21 20:26:22,576 INFO org.apache.hadoop.security.authentication.server.AuthenticationFilter: Unable to initialize FileSignerSecretProvider, falling back to use random secrets.
2020-03-21 20:26:22,580 INFO org.apache.hadoop.http.HttpRequestLog: Http request log for http.requests.resourcemanager is not defined
2020-03-21 20:26:22,587 INFO org.apache.hadoop.http.HttpServer2: Added global filter 'safety' (class=org.apache.hadoop.http.HttpServer2$QuotingInputFilter)
2020-03-21 20:26:22,589 INFO org.apache.hadoop.http.HttpServer2: Added filter RMAuthenticationFilter (class=org.apache.hadoop.yarn.server.security.http.RMAuthenticationFilter) to context cluster
2020-03-21 20:26:22,589 INFO org.apache.hadoop.http.HttpServer2: Added filter RMAuthenticationFilter (class=org.apache.hadoop.yarn.server.security.http.RMAuthenticationFilter) to context logs
2020-03-21 20:26:22,590 INFO org.apache.hadoop.http.HttpServer2: Added filter RMAuthenticationFilter (class=org.apache.hadoop.yarn.server.security.http.RMAuthenticationFilter) to context static
2020-03-21 20:26:22,590 INFO org.apache.hadoop.http.HttpServer2: Added filter static_user_filter (class=org.apache.hadoop.http.lib.StaticUserWebFilter$StaticUserFilter) to context cluster
2020-03-21 20:26:22,590 INFO org.apache.hadoop.http.HttpServer2: Added filter static_user_filter (class=org.apache.hadoop.http.lib.StaticUserWebFilter$StaticUserFilter) to context logs
2020-03-21 20:26:22,590 INFO org.apache.hadoop.http.HttpServer2: Added filter static_user_filter (class=org.apache.hadoop.http.lib.StaticUserWebFilter$StaticUserFilter) to context static
2020-03-21 20:26:22,593 INFO org.apache.hadoop.http.HttpServer2: adding path spec: /cluster/*
2020-03-21 20:26:22,593 INFO org.apache.hadoop.http.HttpServer2: adding path spec: /ws/*
2020-03-21 20:26:22,805 INFO org.apache.hadoop.yarn.webapp.WebApps: Registered webapp guice modules
2020-03-21 20:26:22,806 INFO org.apache.hadoop.http.HttpServer2: Jetty bound to port 8088
2020-03-21 20:26:22,806 INFO org.mortbay.log: jetty-6.1.26
2020-03-21 20:26:22,825 INFO org.mortbay.log: Extract jar:file:/home/xidian/hadoop-2.7.7/share/hadoop/yarn/hadoop-yarn-common-2.7.7.jar!/webapps/cluster to /tmp/Jetty_0_0_0_0_8088_cluster____u0rgz3/webapp
2020-03-21 20:26:22,931 INFO org.apache.hadoop.security.token.delegation.AbstractDelegationTokenSecretManager: Updating the current master key for generating delegation tokens
2020-03-21 20:26:22,932 INFO org.apache.hadoop.security.token.delegation.AbstractDelegationTokenSecretManager: Starting expired delegation token remover thread, tokenRemoverScanInterval=60 min(s)
2020-03-21 20:26:22,932 INFO org.apache.hadoop.security.token.delegation.AbstractDelegationTokenSecretManager: Updating the current master key for generating delegation tokens
2020-03-21 20:26:23,635 INFO org.mortbay.log: Started HttpServer2$SelectChannelConnectorWithSafeStartup@0.0.0.0:8088
2020-03-21 20:26:23,635 INFO org.apache.hadoop.yarn.webapp.WebApps: Web app cluster started at 8088
2020-03-21 20:26:23,710 INFO org.apache.hadoop.ipc.CallQueueManager: Using callQueue: class java.util.concurrent.LinkedBlockingQueue queueCapacity: 100
2020-03-21 20:26:23,710 INFO org.apache.hadoop.ipc.Server: Starting Socket Reader #1 for port 8033
2020-03-21 20:26:23,713 INFO org.apache.hadoop.yarn.factories.impl.pb.RpcServerFactoryPBImpl: Adding protocol org.apache.hadoop.yarn.server.api.ResourceManagerAdministrationProtocolPB to the server
2020-03-21 20:26:23,713 INFO org.apache.hadoop.ipc.Server: IPC Server Responder: starting
2020-03-21 20:26:23,713 INFO org.apache.hadoop.ipc.Server: IPC Server listener on 8033: starting
2020-03-21 20:26:24,679 INFO org.apache.hadoop.yarn.util.RackResolver: Resolved dell to /default-rack
2020-03-21 20:26:24,680 INFO org.apache.hadoop.yarn.server.resourcemanager.ResourceTrackerService: NodeManager from node dell(cmPort: 41697 httpPort: 8042) registered with capability: <memory:8192, vCores:8>, assigned nodeId dell:41697
2020-03-21 20:26:24,682 INFO org.apache.hadoop.yarn.server.resourcemanager.rmnode.RMNodeImpl: dell:41697 Node Transitioned from NEW to RUNNING
2020-03-21 20:26:24,685 INFO org.apache.hadoop.yarn.server.resourcemanager.scheduler.capacity.CapacityScheduler: Added node dell:41697 clusterResource: <memory:8192, vCores:8>
2020-03-21 20:26:48,195 ERROR org.apache.hadoop.yarn.server.resourcemanager.ResourceManager: RECEIVED SIGNAL 15: SIGTERM
2020-03-21 20:26:48,197 ERROR org.apache.hadoop.security.token.delegation.AbstractDelegationTokenSecretManager: ExpiredTokenRemover received java.lang.InterruptedException: sleep interrupted
2020-03-21 20:26:48,197 INFO org.mortbay.log: Stopped HttpServer2$SelectChannelConnectorWithSafeStartup@0.0.0.0:8088
2020-03-21 20:26:48,298 INFO org.apache.hadoop.ipc.Server: Stopping server on 8032
2020-03-21 20:26:48,301 INFO org.apache.hadoop.ipc.Server: Stopping IPC Server listener on 8032
2020-03-21 20:26:48,301 INFO org.apache.hadoop.ipc.Server: Stopping server on 8033
2020-03-21 20:26:48,303 INFO org.apache.hadoop.ipc.Server: Stopping IPC Server Responder
2020-03-21 20:26:48,303 INFO org.apache.hadoop.ipc.Server: Stopping IPC Server listener on 8033
2020-03-21 20:26:48,304 INFO org.apache.hadoop.yarn.server.resourcemanager.ResourceManager: Transitioning to standby state
2020-03-21 20:26:48,305 WARN org.apache.hadoop.yarn.server.resourcemanager.amlauncher.ApplicationMasterLauncher: org.apache.hadoop.yarn.server.resourcemanager.amlauncher.ApplicationMasterLauncher$LauncherThread interrupted. Returning.
2020-03-21 20:26:48,305 INFO org.apache.hadoop.ipc.Server: Stopping IPC Server Responder
2020-03-21 20:26:48,305 INFO org.apache.hadoop.ipc.Server: Stopping server on 8030
2020-03-21 20:26:48,308 INFO org.apache.hadoop.ipc.Server: Stopping IPC Server listener on 8030
2020-03-21 20:26:48,308 INFO org.apache.hadoop.ipc.Server: Stopping server on 8031
2020-03-21 20:26:48,310 INFO org.apache.hadoop.ipc.Server: Stopping IPC Server Responder
2020-03-21 20:26:48,310 INFO org.apache.hadoop.ipc.Server: Stopping IPC Server listener on 8031
2020-03-21 20:26:48,311 INFO org.apache.hadoop.yarn.util.AbstractLivelinessMonitor: NMLivelinessMonitor thread interrupted
2020-03-21 20:26:48,311 INFO org.apache.hadoop.ipc.Server: Stopping IPC Server Responder
2020-03-21 20:26:48,311 ERROR org.apache.hadoop.yarn.server.resourcemanager.ResourceManager: Returning, interrupted : java.lang.InterruptedException
2020-03-21 20:26:48,314 INFO org.apache.hadoop.yarn.event.AsyncDispatcher: AsyncDispatcher is draining to stop, igonring any new events.
2020-03-21 20:26:48,316 INFO org.apache.hadoop.yarn.util.AbstractLivelinessMonitor: AMLivelinessMonitor thread interrupted
2020-03-21 20:26:48,316 ERROR org.apache.hadoop.security.token.delegation.AbstractDelegationTokenSecretManager: ExpiredTokenRemover received java.lang.InterruptedException: sleep interrupted
2020-03-21 20:26:48,316 INFO org.apache.hadoop.yarn.util.AbstractLivelinessMonitor: AMLivelinessMonitor thread interrupted
2020-03-21 20:26:48,321 INFO org.apache.hadoop.yarn.util.AbstractLivelinessMonitor: org.apache.hadoop.yarn.server.resourcemanager.rmcontainer.ContainerAllocationExpirer thread interrupted
2020-03-21 20:26:48,316 INFO org.apache.hadoop.metrics2.impl.MetricsSystemImpl: Stopping ResourceManager metrics system...
2020-03-21 20:26:48,328 INFO org.apache.hadoop.metrics2.impl.MetricsSystemImpl: ResourceManager metrics system stopped.
2020-03-21 20:26:48,328 INFO org.apache.hadoop.metrics2.impl.MetricsSystemImpl: ResourceManager metrics system shutdown complete.
2020-03-21 20:26:48,328 INFO org.apache.hadoop.yarn.event.AsyncDispatcher: AsyncDispatcher is draining to stop, igonring any new events.
2020-03-21 20:26:48,329 INFO org.apache.hadoop.yarn.server.resourcemanager.ResourceManager: Transitioned to standby state
2020-03-21 20:26:48,329 INFO org.apache.hadoop.yarn.server.resourcemanager.ResourceManager: SHUTDOWN_MSG: 
/************************************************************
SHUTDOWN_MSG: Shutting down ResourceManager at dell/127.0.1.1
************************************************************/
2020-03-21 20:27:31,660 INFO org.apache.hadoop.yarn.server.resourcemanager.ResourceManager: STARTUP_MSG: 
/************************************************************
STARTUP_MSG: Starting ResourceManager
STARTUP_MSG:   host = dell/127.0.1.1
STARTUP_MSG:   args = []
STARTUP_MSG:   version = 2.7.7
STARTUP_MSG:   build = Unknown -r c1aad84bd27cd79c3d1a7dd58202a8c3ee1ed3ac; compiled by 'stevel' on 2018-07-18T22:47Z
STARTUP_MSG:   java = 1.8.0_131
************************************************************/
2020-03-21 20:27:31,666 INFO org.apache.hadoop.yarn.server.resourcemanager.ResourceManager: registered UNIX signal handlers for [TERM, HUP, INT]
2020-03-21 20:27:31,823 INFO org.apache.hadoop.conf.Configuration: found resource core-site.xml at file:/home/xidian/hadoop-2.7.7/etc/hadoop/core-site.xml
2020-03-21 20:27:31,881 INFO org.apache.hadoop.security.Groups: clearing userToGroupsMap cache
2020-03-21 20:27:31,910 INFO org.apache.hadoop.conf.Configuration: found resource yarn-site.xml at file:/home/xidian/hadoop-2.7.7/etc/hadoop/yarn-site.xml
2020-03-21 20:27:32,030 INFO org.apache.hadoop.yarn.event.AsyncDispatcher: Registering class org.apache.hadoop.yarn.server.resourcemanager.RMFatalEventType for class org.apache.hadoop.yarn.server.resourcemanager.ResourceManager$RMFatalEventDispatcher
2020-03-21 20:27:32,148 INFO org.apache.hadoop.yarn.server.resourcemanager.security.NMTokenSecretManagerInRM: NMTokenKeyRollingInterval: 86400000ms and NMTokenKeyActivationDelay: 900000ms
2020-03-21 20:27:32,150 INFO org.apache.hadoop.yarn.server.resourcemanager.security.RMContainerTokenSecretManager: ContainerTokenKeyRollingInterval: 86400000ms and ContainerTokenKeyActivationDelay: 900000ms
2020-03-21 20:27:32,152 INFO org.apache.hadoop.yarn.server.resourcemanager.security.AMRMTokenSecretManager: AMRMTokenKeyRollingInterval: 86400000ms and AMRMTokenKeyActivationDelay: 900000 ms
2020-03-21 20:27:32,169 INFO org.apache.hadoop.yarn.event.AsyncDispatcher: Registering class org.apache.hadoop.yarn.server.resourcemanager.recovery.RMStateStoreEventType for class org.apache.hadoop.yarn.server.resourcemanager.recovery.RMStateStore$ForwardingEventHandler
2020-03-21 20:27:32,170 INFO org.apache.hadoop.yarn.event.AsyncDispatcher: Registering class org.apache.hadoop.yarn.server.resourcemanager.NodesListManagerEventType for class org.apache.hadoop.yarn.server.resourcemanager.NodesListManager
2020-03-21 20:27:32,170 INFO org.apache.hadoop.yarn.server.resourcemanager.ResourceManager: Using Scheduler: org.apache.hadoop.yarn.server.resourcemanager.scheduler.capacity.CapacityScheduler
2020-03-21 20:27:32,178 INFO org.apache.hadoop.yarn.event.AsyncDispatcher: Registering class org.apache.hadoop.yarn.server.resourcemanager.scheduler.event.SchedulerEventType for class org.apache.hadoop.yarn.server.resourcemanager.ResourceManager$SchedulerEventDispatcher
2020-03-21 20:27:32,178 INFO org.apache.hadoop.yarn.event.AsyncDispatcher: Registering class org.apache.hadoop.yarn.server.resourcemanager.rmapp.RMAppEventType for class org.apache.hadoop.yarn.server.resourcemanager.ResourceManager$ApplicationEventDispatcher
2020-03-21 20:27:32,179 INFO org.apache.hadoop.yarn.event.AsyncDispatcher: Registering class org.apache.hadoop.yarn.server.resourcemanager.rmapp.attempt.RMAppAttemptEventType for class org.apache.hadoop.yarn.server.resourcemanager.ResourceManager$ApplicationAttemptEventDispatcher
2020-03-21 20:27:32,179 INFO org.apache.hadoop.yarn.event.AsyncDispatcher: Registering class org.apache.hadoop.yarn.server.resourcemanager.rmnode.RMNodeEventType for class org.apache.hadoop.yarn.server.resourcemanager.ResourceManager$NodeEventDispatcher
2020-03-21 20:27:32,210 INFO org.apache.hadoop.metrics2.impl.MetricsConfig: loaded properties from hadoop-metrics2.properties
2020-03-21 20:27:32,243 INFO org.apache.hadoop.metrics2.impl.MetricsSystemImpl: Scheduled snapshot period at 10 second(s).
2020-03-21 20:27:32,243 INFO org.apache.hadoop.metrics2.impl.MetricsSystemImpl: ResourceManager metrics system started
2020-03-21 20:27:32,249 INFO org.apache.hadoop.yarn.event.AsyncDispatcher: Registering class org.apache.hadoop.yarn.server.resourcemanager.RMAppManagerEventType for class org.apache.hadoop.yarn.server.resourcemanager.RMAppManager
2020-03-21 20:27:32,253 INFO org.apache.hadoop.yarn.event.AsyncDispatcher: Registering class org.apache.hadoop.yarn.server.resourcemanager.amlauncher.AMLauncherEventType for class org.apache.hadoop.yarn.server.resourcemanager.amlauncher.ApplicationMasterLauncher
2020-03-21 20:27:32,254 INFO org.apache.hadoop.yarn.server.resourcemanager.RMNMInfo: Registered RMNMInfo MBean
2020-03-21 20:27:32,255 INFO org.apache.hadoop.yarn.security.YarnAuthorizationProvider: org.apache.hadoop.yarn.security.ConfiguredYarnAuthorizer is instiantiated.
2020-03-21 20:27:32,256 INFO org.apache.hadoop.util.HostsFileReader: Refreshing hosts (include/exclude) list
2020-03-21 20:27:32,257 INFO org.apache.hadoop.conf.Configuration: found resource capacity-scheduler.xml at file:/home/xidian/hadoop-2.7.7/etc/hadoop/capacity-scheduler.xml
2020-03-21 20:27:32,283 INFO org.apache.hadoop.yarn.server.resourcemanager.scheduler.capacity.CapacitySchedulerConfiguration: max alloc mb per queue for root is undefined
2020-03-21 20:27:32,283 INFO org.apache.hadoop.yarn.server.resourcemanager.scheduler.capacity.CapacitySchedulerConfiguration: max alloc vcore per queue for root is undefined
2020-03-21 20:27:32,285 INFO org.apache.hadoop.yarn.server.resourcemanager.scheduler.capacity.ParentQueue: root, capacity=1.0, asboluteCapacity=1.0, maxCapacity=1.0, asboluteMaxCapacity=1.0, state=RUNNING, acls=ADMINISTER_QUEUE:*SUBMIT_APP:*, labels=*,
, reservationsContinueLooking=true
2020-03-21 20:27:32,285 INFO org.apache.hadoop.yarn.server.resourcemanager.scheduler.capacity.ParentQueue: Initialized parent-queue root name=root, fullname=root
2020-03-21 20:27:32,290 INFO org.apache.hadoop.yarn.server.resourcemanager.scheduler.capacity.CapacitySchedulerConfiguration: max alloc mb per queue for root.default is undefined
2020-03-21 20:27:32,290 INFO org.apache.hadoop.yarn.server.resourcemanager.scheduler.capacity.CapacitySchedulerConfiguration: max alloc vcore per queue for root.default is undefined
2020-03-21 20:27:32,291 INFO org.apache.hadoop.yarn.server.resourcemanager.scheduler.capacity.LeafQueue: Initializing default
capacity = 1.0 [= (float) configuredCapacity / 100 ]
asboluteCapacity = 1.0 [= parentAbsoluteCapacity * capacity ]
maxCapacity = 1.0 [= configuredMaxCapacity ]
absoluteMaxCapacity = 1.0 [= 1.0 maximumCapacity undefined, (parentAbsoluteMaxCapacity * maximumCapacity) / 100 otherwise ]
userLimit = 100 [= configuredUserLimit ]
userLimitFactor = 1.0 [= configuredUserLimitFactor ]
maxApplications = 10000 [= configuredMaximumSystemApplicationsPerQueue or (int)(configuredMaximumSystemApplications * absoluteCapacity)]
maxApplicationsPerUser = 10000 [= (int)(maxApplications * (userLimit / 100.0f) * userLimitFactor) ]
usedCapacity = 0.0 [= usedResourcesMemory / (clusterResourceMemory * absoluteCapacity)]
absoluteUsedCapacity = 0.0 [= usedResourcesMemory / clusterResourceMemory]
maxAMResourcePerQueuePercent = 0.1 [= configuredMaximumAMResourcePercent ]
minimumAllocationFactor = 0.875 [= (float)(maximumAllocationMemory - minimumAllocationMemory) / maximumAllocationMemory ]
maximumAllocation = <memory:8192, vCores:32> [= configuredMaxAllocation ]
numContainers = 0 [= currentNumContainers ]
state = RUNNING [= configuredState ]
acls = ADMINISTER_QUEUE:*SUBMIT_APP:* [= configuredAcls ]
nodeLocalityDelay = 40
labels=*,
nodeLocalityDelay = 40
reservationsContinueLooking = true
preemptionDisabled = true

2020-03-21 20:27:32,291 INFO org.apache.hadoop.yarn.server.resourcemanager.scheduler.capacity.CapacityScheduler: Initialized queue: default: capacity=1.0, absoluteCapacity=1.0, usedResources=<memory:0, vCores:0>, usedCapacity=0.0, absoluteUsedCapacity=0.0, numApps=0, numContainers=0
2020-03-21 20:27:32,291 INFO org.apache.hadoop.yarn.server.resourcemanager.scheduler.capacity.CapacityScheduler: Initialized queue: root: numChildQueue= 1, capacity=1.0, absoluteCapacity=1.0, usedResources=<memory:0, vCores:0>usedCapacity=0.0, numApps=0, numContainers=0
2020-03-21 20:27:32,292 INFO org.apache.hadoop.yarn.server.resourcemanager.scheduler.capacity.CapacityScheduler: Initialized root queue root: numChildQueue= 1, capacity=1.0, absoluteCapacity=1.0, usedResources=<memory:0, vCores:0>usedCapacity=0.0, numApps=0, numContainers=0
2020-03-21 20:27:32,292 INFO org.apache.hadoop.yarn.server.resourcemanager.scheduler.capacity.CapacityScheduler: Initialized queue mappings, override: false
2020-03-21 20:27:32,292 INFO org.apache.hadoop.yarn.server.resourcemanager.scheduler.capacity.CapacityScheduler: Initialized CapacityScheduler with calculator=class org.apache.hadoop.yarn.util.resource.DefaultResourceCalculator, minimumAllocation=<<memory:1024, vCores:1>>, maximumAllocation=<<memory:8192, vCores:32>>, asynchronousScheduling=false, asyncScheduleInterval=5ms
2020-03-21 20:27:32,297 INFO org.apache.hadoop.yarn.server.resourcemanager.metrics.SystemMetricsPublisher: YARN system metrics publishing service is not enabled
2020-03-21 20:27:32,298 INFO org.apache.hadoop.yarn.server.resourcemanager.ResourceManager: Transitioning to active state
2020-03-21 20:27:32,304 INFO org.apache.hadoop.yarn.server.resourcemanager.recovery.RMStateStore: Updating AMRMToken
2020-03-21 20:27:32,304 INFO org.apache.hadoop.yarn.server.resourcemanager.security.RMContainerTokenSecretManager: Rolling master-key for container-tokens
2020-03-21 20:27:32,305 INFO org.apache.hadoop.yarn.server.resourcemanager.security.NMTokenSecretManagerInRM: Rolling master-key for nm-tokens
2020-03-21 20:27:32,305 INFO org.apache.hadoop.security.token.delegation.AbstractDelegationTokenSecretManager: Updating the current master key for generating delegation tokens
2020-03-21 20:27:32,305 INFO org.apache.hadoop.yarn.server.resourcemanager.security.RMDelegationTokenSecretManager: storing master key with keyID 1
2020-03-21 20:27:32,305 INFO org.apache.hadoop.yarn.server.resourcemanager.recovery.RMStateStore: Storing RMDTMasterKey.
2020-03-21 20:27:32,306 INFO org.apache.hadoop.security.token.delegation.AbstractDelegationTokenSecretManager: Starting expired delegation token remover thread, tokenRemoverScanInterval=60 min(s)
2020-03-21 20:27:32,306 INFO org.apache.hadoop.security.token.delegation.AbstractDelegationTokenSecretManager: Updating the current master key for generating delegation tokens
2020-03-21 20:27:32,306 INFO org.apache.hadoop.yarn.server.resourcemanager.security.RMDelegationTokenSecretManager: storing master key with keyID 2
2020-03-21 20:27:32,306 INFO org.apache.hadoop.yarn.server.resourcemanager.recovery.RMStateStore: Storing RMDTMasterKey.
2020-03-21 20:27:32,307 INFO org.apache.hadoop.yarn.event.AsyncDispatcher: Registering class org.apache.hadoop.yarn.nodelabels.event.NodeLabelsStoreEventType for class org.apache.hadoop.yarn.nodelabels.CommonNodeLabelsManager$ForwardingEventHandler
2020-03-21 20:27:32,398 INFO org.apache.hadoop.ipc.CallQueueManager: Using callQueue: class java.util.concurrent.LinkedBlockingQueue queueCapacity: 5000
2020-03-21 20:27:32,420 INFO org.apache.hadoop.ipc.Server: Starting Socket Reader #1 for port 8031
2020-03-21 20:27:32,524 INFO org.apache.hadoop.yarn.factories.impl.pb.RpcServerFactoryPBImpl: Adding protocol org.apache.hadoop.yarn.server.api.ResourceTrackerPB to the server
2020-03-21 20:27:32,524 INFO org.apache.hadoop.ipc.Server: IPC Server Responder: starting
2020-03-21 20:27:32,524 INFO org.apache.hadoop.ipc.Server: IPC Server listener on 8031: starting
2020-03-21 20:27:32,605 INFO org.apache.hadoop.ipc.CallQueueManager: Using callQueue: class java.util.concurrent.LinkedBlockingQueue queueCapacity: 5000
2020-03-21 20:27:32,609 INFO org.apache.hadoop.ipc.Server: Starting Socket Reader #1 for port 8030
2020-03-21 20:27:32,615 INFO org.apache.hadoop.yarn.factories.impl.pb.RpcServerFactoryPBImpl: Adding protocol org.apache.hadoop.yarn.api.ApplicationMasterProtocolPB to the server
2020-03-21 20:27:32,616 INFO org.apache.hadoop.ipc.Server: IPC Server Responder: starting
2020-03-21 20:27:32,616 INFO org.apache.hadoop.ipc.Server: IPC Server listener on 8030: starting
2020-03-21 20:27:32,716 INFO org.apache.hadoop.ipc.CallQueueManager: Using callQueue: class java.util.concurrent.LinkedBlockingQueue queueCapacity: 5000
2020-03-21 20:27:32,717 INFO org.apache.hadoop.ipc.Server: Starting Socket Reader #1 for port 8032
2020-03-21 20:27:32,720 INFO org.apache.hadoop.yarn.factories.impl.pb.RpcServerFactoryPBImpl: Adding protocol org.apache.hadoop.yarn.api.ApplicationClientProtocolPB to the server
2020-03-21 20:27:32,720 INFO org.apache.hadoop.ipc.Server: IPC Server Responder: starting
2020-03-21 20:27:32,720 INFO org.apache.hadoop.ipc.Server: IPC Server listener on 8032: starting
2020-03-21 20:27:32,740 INFO org.apache.hadoop.yarn.server.resourcemanager.ResourceManager: Transitioned to active state
2020-03-21 20:27:32,826 INFO org.mortbay.log: Logging to org.slf4j.impl.Log4jLoggerAdapter(org.mortbay.log) via org.mortbay.log.Slf4jLog
2020-03-21 20:27:32,832 INFO org.apache.hadoop.security.authentication.server.AuthenticationFilter: Unable to initialize FileSignerSecretProvider, falling back to use random secrets.
2020-03-21 20:27:32,842 INFO org.apache.hadoop.http.HttpRequestLog: Http request log for http.requests.resourcemanager is not defined
2020-03-21 20:27:32,856 INFO org.apache.hadoop.http.HttpServer2: Added global filter 'safety' (class=org.apache.hadoop.http.HttpServer2$QuotingInputFilter)
2020-03-21 20:27:32,860 INFO org.apache.hadoop.http.HttpServer2: Added filter RMAuthenticationFilter (class=org.apache.hadoop.yarn.server.security.http.RMAuthenticationFilter) to context cluster
2020-03-21 20:27:32,860 INFO org.apache.hadoop.http.HttpServer2: Added filter RMAuthenticationFilter (class=org.apache.hadoop.yarn.server.security.http.RMAuthenticationFilter) to context logs
2020-03-21 20:27:32,860 INFO org.apache.hadoop.http.HttpServer2: Added filter RMAuthenticationFilter (class=org.apache.hadoop.yarn.server.security.http.RMAuthenticationFilter) to context static
2020-03-21 20:27:32,861 INFO org.apache.hadoop.http.HttpServer2: Added filter static_user_filter (class=org.apache.hadoop.http.lib.StaticUserWebFilter$StaticUserFilter) to context cluster
2020-03-21 20:27:32,861 INFO org.apache.hadoop.http.HttpServer2: Added filter static_user_filter (class=org.apache.hadoop.http.lib.StaticUserWebFilter$StaticUserFilter) to context logs
2020-03-21 20:27:32,861 INFO org.apache.hadoop.http.HttpServer2: Added filter static_user_filter (class=org.apache.hadoop.http.lib.StaticUserWebFilter$StaticUserFilter) to context static
2020-03-21 20:27:32,864 INFO org.apache.hadoop.http.HttpServer2: adding path spec: /cluster/*
2020-03-21 20:27:32,864 INFO org.apache.hadoop.http.HttpServer2: adding path spec: /ws/*
2020-03-21 20:27:33,073 INFO org.apache.hadoop.yarn.webapp.WebApps: Registered webapp guice modules
2020-03-21 20:27:33,075 INFO org.apache.hadoop.http.HttpServer2: Jetty bound to port 8088
2020-03-21 20:27:33,075 INFO org.mortbay.log: jetty-6.1.26
2020-03-21 20:27:33,092 INFO org.mortbay.log: Extract jar:file:/home/xidian/hadoop-2.7.7/share/hadoop/yarn/hadoop-yarn-common-2.7.7.jar!/webapps/cluster to /tmp/Jetty_0_0_0_0_8088_cluster____u0rgz3/webapp
2020-03-21 20:27:33,203 INFO org.apache.hadoop.security.token.delegation.AbstractDelegationTokenSecretManager: Updating the current master key for generating delegation tokens
2020-03-21 20:27:33,203 INFO org.apache.hadoop.security.token.delegation.AbstractDelegationTokenSecretManager: Starting expired delegation token remover thread, tokenRemoverScanInterval=60 min(s)
2020-03-21 20:27:33,203 INFO org.apache.hadoop.security.token.delegation.AbstractDelegationTokenSecretManager: Updating the current master key for generating delegation tokens
2020-03-21 20:27:33,916 INFO org.mortbay.log: Started HttpServer2$SelectChannelConnectorWithSafeStartup@0.0.0.0:8088
2020-03-21 20:27:33,916 INFO org.apache.hadoop.yarn.webapp.WebApps: Web app cluster started at 8088
2020-03-21 20:27:33,998 INFO org.apache.hadoop.ipc.CallQueueManager: Using callQueue: class java.util.concurrent.LinkedBlockingQueue queueCapacity: 100
2020-03-21 20:27:33,998 INFO org.apache.hadoop.ipc.Server: Starting Socket Reader #1 for port 8033
2020-03-21 20:27:34,000 INFO org.apache.hadoop.yarn.factories.impl.pb.RpcServerFactoryPBImpl: Adding protocol org.apache.hadoop.yarn.server.api.ResourceManagerAdministrationProtocolPB to the server
2020-03-21 20:27:34,000 INFO org.apache.hadoop.ipc.Server: IPC Server Responder: starting
2020-03-21 20:27:34,000 INFO org.apache.hadoop.ipc.Server: IPC Server listener on 8033: starting
2020-03-21 20:27:34,933 INFO org.apache.hadoop.yarn.util.RackResolver: Resolved dell to /default-rack
2020-03-21 20:27:34,935 INFO org.apache.hadoop.yarn.server.resourcemanager.ResourceTrackerService: NodeManager from node dell(cmPort: 42225 httpPort: 8042) registered with capability: <memory:8192, vCores:8>, assigned nodeId dell:42225
2020-03-21 20:27:34,937 INFO org.apache.hadoop.yarn.server.resourcemanager.rmnode.RMNodeImpl: dell:42225 Node Transitioned from NEW to RUNNING
2020-03-21 20:27:34,940 INFO org.apache.hadoop.yarn.server.resourcemanager.scheduler.capacity.CapacityScheduler: Added node dell:42225 clusterResource: <memory:8192, vCores:8>
2020-03-21 20:30:15,484 INFO org.apache.hadoop.yarn.server.resourcemanager.ClientRMService: Allocated new applicationId: 1
2020-03-21 20:30:16,323 INFO org.apache.hadoop.yarn.server.resourcemanager.ClientRMService: Application with id 1 submitted by user xidian
2020-03-21 20:30:16,323 INFO org.apache.hadoop.yarn.server.resourcemanager.rmapp.RMAppImpl: Storing application with id application_1584793652298_0001
2020-03-21 20:30:16,324 INFO org.apache.hadoop.yarn.server.resourcemanager.RMAuditLogger: USER=xidian	IP=127.0.0.1	OPERATION=Submit Application Request	TARGET=ClientRMService	RESULT=SUCCESS	APPID=application_1584793652298_0001
2020-03-21 20:30:16,329 INFO org.apache.hadoop.yarn.server.resourcemanager.rmapp.RMAppImpl: application_1584793652298_0001 State change from NEW to NEW_SAVING on event=START
2020-03-21 20:30:16,329 INFO org.apache.hadoop.yarn.server.resourcemanager.recovery.RMStateStore: Storing info for app: application_1584793652298_0001
2020-03-21 20:30:16,330 INFO org.apache.hadoop.yarn.server.resourcemanager.rmapp.RMAppImpl: application_1584793652298_0001 State change from NEW_SAVING to SUBMITTED on event=APP_NEW_SAVED
2020-03-21 20:30:16,330 INFO org.apache.hadoop.yarn.server.resourcemanager.scheduler.capacity.ParentQueue: Application added - appId: application_1584793652298_0001 user: xidian leaf-queue of parent: root #applications: 1
2020-03-21 20:30:16,331 INFO org.apache.hadoop.yarn.server.resourcemanager.scheduler.capacity.CapacityScheduler: Accepted application application_1584793652298_0001 from user: xidian, in queue: default
2020-03-21 20:30:16,336 INFO org.apache.hadoop.yarn.server.resourcemanager.rmapp.RMAppImpl: application_1584793652298_0001 State change from SUBMITTED to ACCEPTED on event=APP_ACCEPTED
2020-03-21 20:30:16,354 INFO org.apache.hadoop.yarn.server.resourcemanager.ApplicationMasterService: Registering app attempt : appattempt_1584793652298_0001_000001
2020-03-21 20:30:16,355 INFO org.apache.hadoop.yarn.server.resourcemanager.rmapp.attempt.RMAppAttemptImpl: appattempt_1584793652298_0001_000001 State change from NEW to SUBMITTED
2020-03-21 20:30:16,362 WARN org.apache.hadoop.yarn.server.resourcemanager.scheduler.capacity.LeafQueue: maximum-am-resource-percent is insufficient to start a single application in queue, it is likely set too low. skipping enforcement to allow at least one application to start
2020-03-21 20:30:16,362 WARN org.apache.hadoop.yarn.server.resourcemanager.scheduler.capacity.LeafQueue: maximum-am-resource-percent is insufficient to start a single application in queue for user, it is likely set too low. skipping enforcement to allow at least one application to start
2020-03-21 20:30:16,362 INFO org.apache.hadoop.yarn.server.resourcemanager.scheduler.capacity.LeafQueue: Application application_1584793652298_0001 from user: xidian activated in queue: default
2020-03-21 20:30:16,362 INFO org.apache.hadoop.yarn.server.resourcemanager.scheduler.capacity.LeafQueue: Application added - appId: application_1584793652298_0001 user: org.apache.hadoop.yarn.server.resourcemanager.scheduler.capacity.LeafQueue$User@49e6b770, leaf-queue: default #user-pending-applications: 0 #user-active-applications: 1 #queue-pending-applications: 0 #queue-active-applications: 1
2020-03-21 20:30:16,362 INFO org.apache.hadoop.yarn.server.resourcemanager.scheduler.capacity.CapacityScheduler: Added Application Attempt appattempt_1584793652298_0001_000001 to scheduler from user xidian in queue default
2020-03-21 20:30:16,364 INFO org.apache.hadoop.yarn.server.resourcemanager.rmapp.attempt.RMAppAttemptImpl: appattempt_1584793652298_0001_000001 State change from SUBMITTED to SCHEDULED
2020-03-21 20:30:16,422 INFO org.apache.hadoop.yarn.server.resourcemanager.rmcontainer.RMContainerImpl: container_1584793652298_0001_01_000001 Container Transitioned from NEW to ALLOCATED
2020-03-21 20:30:16,422 INFO org.apache.hadoop.yarn.server.resourcemanager.RMAuditLogger: USER=xidian	OPERATION=AM Allocated Container	TARGET=SchedulerApp	RESULT=SUCCESS	APPID=application_1584793652298_0001	CONTAINERID=container_1584793652298_0001_01_000001
2020-03-21 20:30:16,422 INFO org.apache.hadoop.yarn.server.resourcemanager.scheduler.SchedulerNode: Assigned container container_1584793652298_0001_01_000001 of capacity <memory:2048, vCores:1> on host dell:42225, which has 1 containers, <memory:2048, vCores:1> used and <memory:6144, vCores:7> available after allocation
2020-03-21 20:30:16,422 INFO org.apache.hadoop.yarn.server.resourcemanager.scheduler.capacity.LeafQueue: assignedContainer application attempt=appattempt_1584793652298_0001_000001 container=Container: [ContainerId: container_1584793652298_0001_01_000001, NodeId: dell:42225, NodeHttpAddress: dell:8042, Resource: <memory:2048, vCores:1>, Priority: 0, Token: null, ] queue=default: capacity=1.0, absoluteCapacity=1.0, usedResources=<memory:0, vCores:0>, usedCapacity=0.0, absoluteUsedCapacity=0.0, numApps=1, numContainers=0 clusterResource=<memory:8192, vCores:8> type=OFF_SWITCH requestedPartition=
2020-03-21 20:30:16,423 INFO org.apache.hadoop.yarn.server.resourcemanager.scheduler.capacity.ParentQueue: Re-sorting assigned queue: root.default stats: default: capacity=1.0, absoluteCapacity=1.0, usedResources=<memory:2048, vCores:1>, usedCapacity=0.25, absoluteUsedCapacity=0.25, numApps=1, numContainers=1
2020-03-21 20:30:16,423 INFO org.apache.hadoop.yarn.server.resourcemanager.scheduler.capacity.ParentQueue: assignedContainer queue=root usedCapacity=0.25 absoluteUsedCapacity=0.25 used=<memory:2048, vCores:1> cluster=<memory:8192, vCores:8>
2020-03-21 20:30:16,432 INFO org.apache.hadoop.yarn.server.resourcemanager.security.NMTokenSecretManagerInRM: Sending NMToken for nodeId : dell:42225 for container : container_1584793652298_0001_01_000001
2020-03-21 20:30:16,440 INFO org.apache.hadoop.yarn.server.resourcemanager.rmcontainer.RMContainerImpl: container_1584793652298_0001_01_000001 Container Transitioned from ALLOCATED to ACQUIRED
2020-03-21 20:30:16,441 INFO org.apache.hadoop.yarn.server.resourcemanager.security.NMTokenSecretManagerInRM: Clear node set for appattempt_1584793652298_0001_000001
2020-03-21 20:30:16,444 INFO org.apache.hadoop.yarn.server.resourcemanager.rmapp.attempt.RMAppAttemptImpl: Storing attempt: AppId: application_1584793652298_0001 AttemptId: appattempt_1584793652298_0001_000001 MasterContainer: Container: [ContainerId: container_1584793652298_0001_01_000001, NodeId: dell:42225, NodeHttpAddress: dell:8042, Resource: <memory:2048, vCores:1>, Priority: 0, Token: Token { kind: ContainerToken, service: 127.0.1.1:42225 }, ]
2020-03-21 20:30:16,450 INFO org.apache.hadoop.yarn.server.resourcemanager.rmapp.attempt.RMAppAttemptImpl: appattempt_1584793652298_0001_000001 State change from SCHEDULED to ALLOCATED_SAVING
2020-03-21 20:30:16,451 INFO org.apache.hadoop.yarn.server.resourcemanager.rmapp.attempt.RMAppAttemptImpl: appattempt_1584793652298_0001_000001 State change from ALLOCATED_SAVING to ALLOCATED
2020-03-21 20:30:16,452 INFO org.apache.hadoop.yarn.server.resourcemanager.amlauncher.AMLauncher: Launching masterappattempt_1584793652298_0001_000001
2020-03-21 20:30:16,516 INFO org.apache.hadoop.yarn.server.resourcemanager.amlauncher.AMLauncher: Setting up container Container: [ContainerId: container_1584793652298_0001_01_000001, NodeId: dell:42225, NodeHttpAddress: dell:8042, Resource: <memory:2048, vCores:1>, Priority: 0, Token: Token { kind: ContainerToken, service: 127.0.1.1:42225 }, ] for AM appattempt_1584793652298_0001_000001
2020-03-21 20:30:16,516 INFO org.apache.hadoop.yarn.server.resourcemanager.amlauncher.AMLauncher: Command to launch container container_1584793652298_0001_01_000001 : $JAVA_HOME/bin/java -Djava.io.tmpdir=$PWD/tmp -Dlog4j.configuration=container-log4j.properties -Dyarn.app.container.log.dir=<LOG_DIR> -Dyarn.app.container.log.filesize=0 -Dhadoop.root.logger=INFO,CLA -Dhadoop.root.logfile=syslog  -Xmx1024m org.apache.hadoop.mapreduce.v2.app.MRAppMaster 1><LOG_DIR>/stdout 2><LOG_DIR>/stderr 
2020-03-21 20:30:16,517 INFO org.apache.hadoop.yarn.server.resourcemanager.security.AMRMTokenSecretManager: Create AMRMToken for ApplicationAttempt: appattempt_1584793652298_0001_000001
2020-03-21 20:30:16,519 INFO org.apache.hadoop.yarn.server.resourcemanager.security.AMRMTokenSecretManager: Creating password for appattempt_1584793652298_0001_000001
2020-03-21 20:30:16,686 INFO org.apache.hadoop.yarn.server.resourcemanager.amlauncher.AMLauncher: Done launching container Container: [ContainerId: container_1584793652298_0001_01_000001, NodeId: dell:42225, NodeHttpAddress: dell:8042, Resource: <memory:2048, vCores:1>, Priority: 0, Token: Token { kind: ContainerToken, service: 127.0.1.1:42225 }, ] for AM appattempt_1584793652298_0001_000001
2020-03-21 20:30:16,686 INFO org.apache.hadoop.yarn.server.resourcemanager.rmapp.attempt.RMAppAttemptImpl: appattempt_1584793652298_0001_000001 State change from ALLOCATED to LAUNCHED
2020-03-21 20:30:17,433 INFO org.apache.hadoop.yarn.server.resourcemanager.rmcontainer.RMContainerImpl: container_1584793652298_0001_01_000001 Container Transitioned from ACQUIRED to RUNNING
2020-03-21 20:30:21,236 INFO SecurityLogger.org.apache.hadoop.ipc.Server: Auth successful for appattempt_1584793652298_0001_000001 (auth:SIMPLE)
2020-03-21 20:30:21,242 INFO org.apache.hadoop.yarn.server.resourcemanager.ApplicationMasterService: AM registration appattempt_1584793652298_0001_000001
2020-03-21 20:30:21,242 INFO org.apache.hadoop.yarn.server.resourcemanager.RMAuditLogger: USER=xidian	IP=127.0.0.1	OPERATION=Register App Master	TARGET=ApplicationMasterService	RESULT=SUCCESS	APPID=application_1584793652298_0001	APPATTEMPTID=appattempt_1584793652298_0001_000001
2020-03-21 20:30:21,243 INFO org.apache.hadoop.yarn.server.resourcemanager.rmapp.attempt.RMAppAttemptImpl: appattempt_1584793652298_0001_000001 State change from LAUNCHED to RUNNING
2020-03-21 20:30:21,243 INFO org.apache.hadoop.yarn.server.resourcemanager.rmapp.RMAppImpl: application_1584793652298_0001 State change from ACCEPTED to RUNNING on event=ATTEMPT_REGISTERED
2020-03-21 20:30:22,441 INFO org.apache.hadoop.yarn.server.resourcemanager.rmcontainer.RMContainerImpl: container_1584793652298_0001_01_000002 Container Transitioned from NEW to ALLOCATED
2020-03-21 20:30:22,441 INFO org.apache.hadoop.yarn.server.resourcemanager.RMAuditLogger: USER=xidian	OPERATION=AM Allocated Container	TARGET=SchedulerApp	RESULT=SUCCESS	APPID=application_1584793652298_0001	CONTAINERID=container_1584793652298_0001_01_000002
2020-03-21 20:30:22,441 INFO org.apache.hadoop.yarn.server.resourcemanager.scheduler.SchedulerNode: Assigned container container_1584793652298_0001_01_000002 of capacity <memory:1024, vCores:1> on host dell:42225, which has 2 containers, <memory:3072, vCores:2> used and <memory:5120, vCores:6> available after allocation
2020-03-21 20:30:22,441 INFO org.apache.hadoop.yarn.server.resourcemanager.scheduler.capacity.LeafQueue: assignedContainer application attempt=appattempt_1584793652298_0001_000001 container=Container: [ContainerId: container_1584793652298_0001_01_000002, NodeId: dell:42225, NodeHttpAddress: dell:8042, Resource: <memory:1024, vCores:1>, Priority: 20, Token: null, ] queue=default: capacity=1.0, absoluteCapacity=1.0, usedResources=<memory:2048, vCores:1>, usedCapacity=0.25, absoluteUsedCapacity=0.25, numApps=1, numContainers=1 clusterResource=<memory:8192, vCores:8> type=NODE_LOCAL requestedPartition=
2020-03-21 20:30:22,442 INFO org.apache.hadoop.yarn.server.resourcemanager.scheduler.capacity.ParentQueue: Re-sorting assigned queue: root.default stats: default: capacity=1.0, absoluteCapacity=1.0, usedResources=<memory:3072, vCores:2>, usedCapacity=0.375, absoluteUsedCapacity=0.375, numApps=1, numContainers=2
2020-03-21 20:30:22,442 INFO org.apache.hadoop.yarn.server.resourcemanager.scheduler.capacity.ParentQueue: assignedContainer queue=root usedCapacity=0.375 absoluteUsedCapacity=0.375 used=<memory:3072, vCores:2> cluster=<memory:8192, vCores:8>
2020-03-21 20:30:23,295 INFO org.apache.hadoop.yarn.server.resourcemanager.security.NMTokenSecretManagerInRM: Sending NMToken for nodeId : dell:42225 for container : container_1584793652298_0001_01_000002
2020-03-21 20:30:23,298 INFO org.apache.hadoop.yarn.server.resourcemanager.rmcontainer.RMContainerImpl: container_1584793652298_0001_01_000002 Container Transitioned from ALLOCATED to ACQUIRED
2020-03-21 20:30:23,443 INFO org.apache.hadoop.yarn.server.resourcemanager.rmcontainer.RMContainerImpl: container_1584793652298_0001_01_000002 Container Transitioned from ACQUIRED to RUNNING
2020-03-21 20:30:24,312 INFO org.apache.hadoop.yarn.server.resourcemanager.scheduler.AppSchedulingInfo: checking for deactivate of application :application_1584793652298_0001
2020-03-21 20:30:27,452 INFO org.apache.hadoop.yarn.server.resourcemanager.rmcontainer.RMContainerImpl: container_1584793652298_0001_01_000003 Container Transitioned from NEW to ALLOCATED
2020-03-21 20:30:27,452 INFO org.apache.hadoop.yarn.server.resourcemanager.RMAuditLogger: USER=xidian	OPERATION=AM Allocated Container	TARGET=SchedulerApp	RESULT=SUCCESS	APPID=application_1584793652298_0001	CONTAINERID=container_1584793652298_0001_01_000003
2020-03-21 20:30:27,452 INFO org.apache.hadoop.yarn.server.resourcemanager.scheduler.SchedulerNode: Assigned container container_1584793652298_0001_01_000003 of capacity <memory:1024, vCores:1> on host dell:42225, which has 3 containers, <memory:4096, vCores:3> used and <memory:4096, vCores:5> available after allocation
2020-03-21 20:30:27,453 INFO org.apache.hadoop.yarn.server.resourcemanager.scheduler.capacity.LeafQueue: assignedContainer application attempt=appattempt_1584793652298_0001_000001 container=Container: [ContainerId: container_1584793652298_0001_01_000003, NodeId: dell:42225, NodeHttpAddress: dell:8042, Resource: <memory:1024, vCores:1>, Priority: 10, Token: null, ] queue=default: capacity=1.0, absoluteCapacity=1.0, usedResources=<memory:3072, vCores:2>, usedCapacity=0.375, absoluteUsedCapacity=0.375, numApps=1, numContainers=2 clusterResource=<memory:8192, vCores:8> type=OFF_SWITCH requestedPartition=
2020-03-21 20:30:27,453 INFO org.apache.hadoop.yarn.server.resourcemanager.scheduler.capacity.ParentQueue: Re-sorting assigned queue: root.default stats: default: capacity=1.0, absoluteCapacity=1.0, usedResources=<memory:4096, vCores:3>, usedCapacity=0.5, absoluteUsedCapacity=0.5, numApps=1, numContainers=3
2020-03-21 20:30:27,453 INFO org.apache.hadoop.yarn.server.resourcemanager.scheduler.capacity.ParentQueue: assignedContainer queue=root usedCapacity=0.5 absoluteUsedCapacity=0.5 used=<memory:4096, vCores:3> cluster=<memory:8192, vCores:8>
2020-03-21 20:30:28,329 INFO org.apache.hadoop.yarn.server.resourcemanager.rmcontainer.RMContainerImpl: container_1584793652298_0001_01_000003 Container Transitioned from ALLOCATED to ACQUIRED
2020-03-21 20:30:28,380 INFO org.apache.hadoop.yarn.server.resourcemanager.rmcontainer.RMContainerImpl: container_1584793652298_0001_01_000003 Container Transitioned from ACQUIRED to RUNNING
2020-03-21 20:30:28,381 INFO org.apache.hadoop.yarn.server.resourcemanager.rmcontainer.RMContainerImpl: container_1584793652298_0001_01_000002 Container Transitioned from RUNNING to COMPLETED
2020-03-21 20:30:28,381 INFO org.apache.hadoop.yarn.server.resourcemanager.scheduler.common.fica.FiCaSchedulerApp: Completed container: container_1584793652298_0001_01_000002 in state: COMPLETED event:FINISHED
2020-03-21 20:30:28,381 INFO org.apache.hadoop.yarn.server.resourcemanager.RMAuditLogger: USER=xidian	OPERATION=AM Released Container	TARGET=SchedulerApp	RESULT=SUCCESS	APPID=application_1584793652298_0001	CONTAINERID=container_1584793652298_0001_01_000002
2020-03-21 20:30:28,381 INFO org.apache.hadoop.yarn.server.resourcemanager.scheduler.SchedulerNode: Released container container_1584793652298_0001_01_000002 of capacity <memory:1024, vCores:1> on host dell:42225, which currently has 2 containers, <memory:3072, vCores:2> used and <memory:5120, vCores:6> available, release resources=true
2020-03-21 20:30:28,381 INFO org.apache.hadoop.yarn.server.resourcemanager.scheduler.capacity.LeafQueue: default used=<memory:3072, vCores:2> numContainers=2 user=xidian user-resources=<memory:3072, vCores:2>
2020-03-21 20:30:28,382 INFO org.apache.hadoop.yarn.server.resourcemanager.scheduler.capacity.LeafQueue: completedContainer container=Container: [ContainerId: container_1584793652298_0001_01_000002, NodeId: dell:42225, NodeHttpAddress: dell:8042, Resource: <memory:1024, vCores:1>, Priority: 20, Token: Token { kind: ContainerToken, service: 127.0.1.1:42225 }, ] queue=default: capacity=1.0, absoluteCapacity=1.0, usedResources=<memory:3072, vCores:2>, usedCapacity=0.375, absoluteUsedCapacity=0.375, numApps=1, numContainers=2 cluster=<memory:8192, vCores:8>
2020-03-21 20:30:28,382 INFO org.apache.hadoop.yarn.server.resourcemanager.scheduler.capacity.ParentQueue: completedContainer queue=root usedCapacity=0.375 absoluteUsedCapacity=0.375 used=<memory:3072, vCores:2> cluster=<memory:8192, vCores:8>
2020-03-21 20:30:28,382 INFO org.apache.hadoop.yarn.server.resourcemanager.scheduler.capacity.ParentQueue: Re-sorting completed queue: root.default stats: default: capacity=1.0, absoluteCapacity=1.0, usedResources=<memory:3072, vCores:2>, usedCapacity=0.375, absoluteUsedCapacity=0.375, numApps=1, numContainers=2
2020-03-21 20:30:28,382 INFO org.apache.hadoop.yarn.server.resourcemanager.scheduler.capacity.CapacityScheduler: Application attempt appattempt_1584793652298_0001_000001 released container container_1584793652298_0001_01_000002 on node: host: dell:42225 #containers=2 available=<memory:5120, vCores:6> used=<memory:3072, vCores:2> with event: FINISHED
2020-03-21 20:30:29,337 INFO org.apache.hadoop.yarn.server.resourcemanager.scheduler.AppSchedulingInfo: checking for deactivate of application :application_1584793652298_0001
2020-03-21 20:30:30,516 INFO org.apache.hadoop.yarn.server.resourcemanager.rmcontainer.RMContainerImpl: container_1584793652298_0001_01_000003 Container Transitioned from RUNNING to COMPLETED
2020-03-21 20:30:30,516 INFO org.apache.hadoop.yarn.server.resourcemanager.scheduler.common.fica.FiCaSchedulerApp: Completed container: container_1584793652298_0001_01_000003 in state: COMPLETED event:FINISHED
2020-03-21 20:30:30,516 INFO org.apache.hadoop.yarn.server.resourcemanager.RMAuditLogger: USER=xidian	OPERATION=AM Released Container	TARGET=SchedulerApp	RESULT=SUCCESS	APPID=application_1584793652298_0001	CONTAINERID=container_1584793652298_0001_01_000003
2020-03-21 20:30:30,516 INFO org.apache.hadoop.yarn.server.resourcemanager.scheduler.SchedulerNode: Released container container_1584793652298_0001_01_000003 of capacity <memory:1024, vCores:1> on host dell:42225, which currently has 1 containers, <memory:2048, vCores:1> used and <memory:6144, vCores:7> available, release resources=true
2020-03-21 20:30:30,516 INFO org.apache.hadoop.yarn.server.resourcemanager.scheduler.capacity.LeafQueue: default used=<memory:2048, vCores:1> numContainers=1 user=xidian user-resources=<memory:2048, vCores:1>
2020-03-21 20:30:30,517 INFO org.apache.hadoop.yarn.server.resourcemanager.scheduler.capacity.LeafQueue: completedContainer container=Container: [ContainerId: container_1584793652298_0001_01_000003, NodeId: dell:42225, NodeHttpAddress: dell:8042, Resource: <memory:1024, vCores:1>, Priority: 10, Token: Token { kind: ContainerToken, service: 127.0.1.1:42225 }, ] queue=default: capacity=1.0, absoluteCapacity=1.0, usedResources=<memory:2048, vCores:1>, usedCapacity=0.25, absoluteUsedCapacity=0.25, numApps=1, numContainers=1 cluster=<memory:8192, vCores:8>
2020-03-21 20:30:30,517 INFO org.apache.hadoop.yarn.server.resourcemanager.scheduler.capacity.ParentQueue: completedContainer queue=root usedCapacity=0.25 absoluteUsedCapacity=0.25 used=<memory:2048, vCores:1> cluster=<memory:8192, vCores:8>
2020-03-21 20:30:30,517 INFO org.apache.hadoop.yarn.server.resourcemanager.scheduler.capacity.ParentQueue: Re-sorting completed queue: root.default stats: default: capacity=1.0, absoluteCapacity=1.0, usedResources=<memory:2048, vCores:1>, usedCapacity=0.25, absoluteUsedCapacity=0.25, numApps=1, numContainers=1
2020-03-21 20:30:30,517 INFO org.apache.hadoop.yarn.server.resourcemanager.scheduler.capacity.CapacityScheduler: Application attempt appattempt_1584793652298_0001_000001 released container container_1584793652298_0001_01_000003 on node: host: dell:42225 #containers=1 available=<memory:6144, vCores:7> used=<memory:2048, vCores:1> with event: FINISHED
2020-03-21 20:30:33,527 INFO org.apache.hadoop.yarn.server.resourcemanager.rmcontainer.RMContainerImpl: container_1584793652298_0001_01_000004 Container Transitioned from NEW to ALLOCATED
2020-03-21 20:30:33,527 INFO org.apache.hadoop.yarn.server.resourcemanager.RMAuditLogger: USER=xidian	OPERATION=AM Allocated Container	TARGET=SchedulerApp	RESULT=SUCCESS	APPID=application_1584793652298_0001	CONTAINERID=container_1584793652298_0001_01_000004
2020-03-21 20:30:33,528 INFO org.apache.hadoop.yarn.server.resourcemanager.scheduler.SchedulerNode: Assigned container container_1584793652298_0001_01_000004 of capacity <memory:1024, vCores:1> on host dell:42225, which has 2 containers, <memory:3072, vCores:2> used and <memory:5120, vCores:6> available after allocation
2020-03-21 20:30:33,528 INFO org.apache.hadoop.yarn.server.resourcemanager.scheduler.capacity.LeafQueue: assignedContainer application attempt=appattempt_1584793652298_0001_000001 container=Container: [ContainerId: container_1584793652298_0001_01_000004, NodeId: dell:42225, NodeHttpAddress: dell:8042, Resource: <memory:1024, vCores:1>, Priority: 10, Token: null, ] queue=default: capacity=1.0, absoluteCapacity=1.0, usedResources=<memory:2048, vCores:1>, usedCapacity=0.25, absoluteUsedCapacity=0.25, numApps=1, numContainers=1 clusterResource=<memory:8192, vCores:8> type=OFF_SWITCH requestedPartition=
2020-03-21 20:30:33,528 INFO org.apache.hadoop.yarn.server.resourcemanager.scheduler.capacity.ParentQueue: Re-sorting assigned queue: root.default stats: default: capacity=1.0, absoluteCapacity=1.0, usedResources=<memory:3072, vCores:2>, usedCapacity=0.375, absoluteUsedCapacity=0.375, numApps=1, numContainers=2
2020-03-21 20:30:33,528 INFO org.apache.hadoop.yarn.server.resourcemanager.scheduler.capacity.ParentQueue: assignedContainer queue=root usedCapacity=0.375 absoluteUsedCapacity=0.375 used=<memory:3072, vCores:2> cluster=<memory:8192, vCores:8>
2020-03-21 20:30:34,376 INFO org.apache.hadoop.yarn.server.resourcemanager.rmcontainer.RMContainerImpl: container_1584793652298_0001_01_000004 Container Transitioned from ALLOCATED to ACQUIRED
2020-03-21 20:30:34,529 INFO org.apache.hadoop.yarn.server.resourcemanager.rmcontainer.RMContainerImpl: container_1584793652298_0001_01_000004 Container Transitioned from ACQUIRED to RUNNING
2020-03-21 20:30:35,383 INFO org.apache.hadoop.yarn.server.resourcemanager.scheduler.AppSchedulingInfo: checking for deactivate of application :application_1584793652298_0001
2020-03-21 20:30:36,521 INFO org.apache.hadoop.yarn.server.resourcemanager.rmcontainer.RMContainerImpl: container_1584793652298_0001_01_000004 Container Transitioned from RUNNING to COMPLETED
2020-03-21 20:30:36,522 INFO org.apache.hadoop.yarn.server.resourcemanager.scheduler.common.fica.FiCaSchedulerApp: Completed container: container_1584793652298_0001_01_000004 in state: COMPLETED event:FINISHED
2020-03-21 20:30:36,522 INFO org.apache.hadoop.yarn.server.resourcemanager.RMAuditLogger: USER=xidian	OPERATION=AM Released Container	TARGET=SchedulerApp	RESULT=SUCCESS	APPID=application_1584793652298_0001	CONTAINERID=container_1584793652298_0001_01_000004
2020-03-21 20:30:36,522 INFO org.apache.hadoop.yarn.server.resourcemanager.scheduler.SchedulerNode: Released container container_1584793652298_0001_01_000004 of capacity <memory:1024, vCores:1> on host dell:42225, which currently has 1 containers, <memory:2048, vCores:1> used and <memory:6144, vCores:7> available, release resources=true
2020-03-21 20:30:36,522 INFO org.apache.hadoop.yarn.server.resourcemanager.scheduler.capacity.LeafQueue: default used=<memory:2048, vCores:1> numContainers=1 user=xidian user-resources=<memory:2048, vCores:1>
2020-03-21 20:30:36,522 INFO org.apache.hadoop.yarn.server.resourcemanager.scheduler.capacity.LeafQueue: completedContainer container=Container: [ContainerId: container_1584793652298_0001_01_000004, NodeId: dell:42225, NodeHttpAddress: dell:8042, Resource: <memory:1024, vCores:1>, Priority: 10, Token: Token { kind: ContainerToken, service: 127.0.1.1:42225 }, ] queue=default: capacity=1.0, absoluteCapacity=1.0, usedResources=<memory:2048, vCores:1>, usedCapacity=0.25, absoluteUsedCapacity=0.25, numApps=1, numContainers=1 cluster=<memory:8192, vCores:8>
2020-03-21 20:30:36,522 INFO org.apache.hadoop.yarn.server.resourcemanager.scheduler.capacity.ParentQueue: completedContainer queue=root usedCapacity=0.25 absoluteUsedCapacity=0.25 used=<memory:2048, vCores:1> cluster=<memory:8192, vCores:8>
2020-03-21 20:30:36,522 INFO org.apache.hadoop.yarn.server.resourcemanager.scheduler.capacity.ParentQueue: Re-sorting completed queue: root.default stats: default: capacity=1.0, absoluteCapacity=1.0, usedResources=<memory:2048, vCores:1>, usedCapacity=0.25, absoluteUsedCapacity=0.25, numApps=1, numContainers=1
2020-03-21 20:30:36,522 INFO org.apache.hadoop.yarn.server.resourcemanager.scheduler.capacity.CapacityScheduler: Application attempt appattempt_1584793652298_0001_000001 released container container_1584793652298_0001_01_000004 on node: host: dell:42225 #containers=1 available=<memory:6144, vCores:7> used=<memory:2048, vCores:1> with event: FINISHED
2020-03-21 20:30:39,530 INFO org.apache.hadoop.yarn.server.resourcemanager.rmcontainer.RMContainerImpl: container_1584793652298_0001_01_000005 Container Transitioned from NEW to ALLOCATED
2020-03-21 20:30:39,530 INFO org.apache.hadoop.yarn.server.resourcemanager.RMAuditLogger: USER=xidian	OPERATION=AM Allocated Container	TARGET=SchedulerApp	RESULT=SUCCESS	APPID=application_1584793652298_0001	CONTAINERID=container_1584793652298_0001_01_000005
2020-03-21 20:30:39,530 INFO org.apache.hadoop.yarn.server.resourcemanager.scheduler.SchedulerNode: Assigned container container_1584793652298_0001_01_000005 of capacity <memory:1024, vCores:1> on host dell:42225, which has 2 containers, <memory:3072, vCores:2> used and <memory:5120, vCores:6> available after allocation
2020-03-21 20:30:39,531 INFO org.apache.hadoop.yarn.server.resourcemanager.scheduler.capacity.LeafQueue: assignedContainer application attempt=appattempt_1584793652298_0001_000001 container=Container: [ContainerId: container_1584793652298_0001_01_000005, NodeId: dell:42225, NodeHttpAddress: dell:8042, Resource: <memory:1024, vCores:1>, Priority: 10, Token: null, ] queue=default: capacity=1.0, absoluteCapacity=1.0, usedResources=<memory:2048, vCores:1>, usedCapacity=0.25, absoluteUsedCapacity=0.25, numApps=1, numContainers=1 clusterResource=<memory:8192, vCores:8> type=OFF_SWITCH requestedPartition=
2020-03-21 20:30:39,531 INFO org.apache.hadoop.yarn.server.resourcemanager.scheduler.capacity.ParentQueue: Re-sorting assigned queue: root.default stats: default: capacity=1.0, absoluteCapacity=1.0, usedResources=<memory:3072, vCores:2>, usedCapacity=0.375, absoluteUsedCapacity=0.375, numApps=1, numContainers=2
2020-03-21 20:30:39,531 INFO org.apache.hadoop.yarn.server.resourcemanager.scheduler.capacity.ParentQueue: assignedContainer queue=root usedCapacity=0.375 absoluteUsedCapacity=0.375 used=<memory:3072, vCores:2> cluster=<memory:8192, vCores:8>
2020-03-21 20:30:40,416 INFO org.apache.hadoop.yarn.server.resourcemanager.rmcontainer.RMContainerImpl: container_1584793652298_0001_01_000005 Container Transitioned from ALLOCATED to ACQUIRED
2020-03-21 20:30:40,532 INFO org.apache.hadoop.yarn.server.resourcemanager.rmcontainer.RMContainerImpl: container_1584793652298_0001_01_000005 Container Transitioned from ACQUIRED to RUNNING
2020-03-21 20:30:41,421 INFO org.apache.hadoop.yarn.server.resourcemanager.scheduler.AppSchedulingInfo: checking for deactivate of application :application_1584793652298_0001
2020-03-21 20:30:42,556 INFO org.apache.hadoop.yarn.server.resourcemanager.rmcontainer.RMContainerImpl: container_1584793652298_0001_01_000005 Container Transitioned from RUNNING to COMPLETED
2020-03-21 20:30:42,556 INFO org.apache.hadoop.yarn.server.resourcemanager.scheduler.common.fica.FiCaSchedulerApp: Completed container: container_1584793652298_0001_01_000005 in state: COMPLETED event:FINISHED
2020-03-21 20:30:42,556 INFO org.apache.hadoop.yarn.server.resourcemanager.RMAuditLogger: USER=xidian	OPERATION=AM Released Container	TARGET=SchedulerApp	RESULT=SUCCESS	APPID=application_1584793652298_0001	CONTAINERID=container_1584793652298_0001_01_000005
2020-03-21 20:30:42,556 INFO org.apache.hadoop.yarn.server.resourcemanager.scheduler.SchedulerNode: Released container container_1584793652298_0001_01_000005 of capacity <memory:1024, vCores:1> on host dell:42225, which currently has 1 containers, <memory:2048, vCores:1> used and <memory:6144, vCores:7> available, release resources=true
2020-03-21 20:30:42,556 INFO org.apache.hadoop.yarn.server.resourcemanager.scheduler.capacity.LeafQueue: default used=<memory:2048, vCores:1> numContainers=1 user=xidian user-resources=<memory:2048, vCores:1>
2020-03-21 20:30:42,556 INFO org.apache.hadoop.yarn.server.resourcemanager.scheduler.capacity.LeafQueue: completedContainer container=Container: [ContainerId: container_1584793652298_0001_01_000005, NodeId: dell:42225, NodeHttpAddress: dell:8042, Resource: <memory:1024, vCores:1>, Priority: 10, Token: Token { kind: ContainerToken, service: 127.0.1.1:42225 }, ] queue=default: capacity=1.0, absoluteCapacity=1.0, usedResources=<memory:2048, vCores:1>, usedCapacity=0.25, absoluteUsedCapacity=0.25, numApps=1, numContainers=1 cluster=<memory:8192, vCores:8>
2020-03-21 20:30:42,556 INFO org.apache.hadoop.yarn.server.resourcemanager.scheduler.capacity.ParentQueue: completedContainer queue=root usedCapacity=0.25 absoluteUsedCapacity=0.25 used=<memory:2048, vCores:1> cluster=<memory:8192, vCores:8>
2020-03-21 20:30:42,556 INFO org.apache.hadoop.yarn.server.resourcemanager.scheduler.capacity.ParentQueue: Re-sorting completed queue: root.default stats: default: capacity=1.0, absoluteCapacity=1.0, usedResources=<memory:2048, vCores:1>, usedCapacity=0.25, absoluteUsedCapacity=0.25, numApps=1, numContainers=1
2020-03-21 20:30:42,556 INFO org.apache.hadoop.yarn.server.resourcemanager.scheduler.capacity.CapacityScheduler: Application attempt appattempt_1584793652298_0001_000001 released container container_1584793652298_0001_01_000005 on node: host: dell:42225 #containers=1 available=<memory:6144, vCores:7> used=<memory:2048, vCores:1> with event: FINISHED
2020-03-21 20:30:44,436 INFO org.apache.hadoop.yarn.server.resourcemanager.ApplicationMasterService: blacklist are updated in Scheduler.blacklistAdditions: [dell], blacklistRemovals: []
2020-03-21 20:30:45,443 INFO org.apache.hadoop.yarn.server.resourcemanager.ApplicationMasterService: blacklist are updated in Scheduler.blacklistAdditions: [], blacklistRemovals: [dell]
2020-03-21 20:30:45,566 INFO org.apache.hadoop.yarn.server.resourcemanager.rmcontainer.RMContainerImpl: container_1584793652298_0001_01_000006 Container Transitioned from NEW to ALLOCATED
